Workbook
Name OLE_LINK10: Report!#REF!

Sheet Report
D2: 北京普析通用仪器有限责任公司 | M2: 文件编号
D3: T600T700系列紫外可见分光光度计整机检验原始记录表 | M3: 版本/修订
M4: 发布/修订日期
B5: 产品型号 | E5: 产品编号 | G5: 检验员 | M5: 检验日期 | O5: 复核员
B6: =IFERROR(VLOOKUP(MID(E6,3,5),对应信息!A:B,2,0),"")
B7: 温度(℃) | F7: 相对湿度(%) | M7: 检验结果
B8: 序号 | C8: 检验项目 | E8: 结果
B9: 1 | C9: 波长示值误差与重复性 | D9: 波长示值误差 氘灯： ±0.1nm 汞灯、镨钕： ±0.3nm 波长重复性 ≤0.1nm | F9: 波长段 | I9: B段 | P9: A段
F10: 检测工具 | I10: 镨钕滤光片 | K10: 氘灯 | L10: 氘灯 | M10: 汞灯
F11: 标准值(nm) | I11: =波长示值误差与重复性校验!B4 -> 807.4 | K11: =波长示值误差与重复性校验!B2 -> 656.1 | L11: =波长示值误差与重复性校验!B3 -> 486 | M11: =波长示值误差与重复性校验!B5 -> 546.1 | N11: =波长示值误差与重复性校验!B6 -> 435.8 | O11: =波长示值误差与重复性校验!B7 -> 365 | P11: =波长示值误差与重复性校验!B8 -> 253.7
F12: 测量值（nm） | I12: =波长示值误差与重复性校验!C4 -> 0 | K12: =波长示值误差与重复性校验!C2 -> 0 | L12: =波长示值误差与重复性校验!C3 -> 0 | M12: =波长示值误差与重复性校验!C5 -> 0 | N12: =波长示值误差与重复性校验!C6 -> 0 | O12: =波长示值误差与重复性校验!C7 -> 0 | P12: =波长示值误差与重复性校验!C8 -> 0
I13: =波长示值误差与重复性校验!D4 -> 0 | K13: =波长示值误差与重复性校验!D2 -> 0 | L13: =波长示值误差与重复性校验!D3 -> 0 | M13: =波长示值误差与重复性校验!D5 -> 0 | N13: =波长示值误差与重复性校验!D6 -> 0 | O13: =波长示值误差与重复性校验!D7 -> 0 | P13: =波长示值误差与重复性校验!D8 -> 0
I14: =波长示值误差与重复性校验!E4 -> 0 | K14: =波长示值误差与重复性校验!E2 -> 0 | L14: =波长示值误差与重复性校验!E3 -> 0 | M14: =波长示值误差与重复性校验!E5 -> 0 | N14: =波长示值误差与重复性校验!E6 -> 0 | O14: =波长示值误差与重复性校验!E7 -> 0 | P14: =波长示值误差与重复性校验!E8 -> 0
F15: 平均值(nm) | I15: =波长示值误差与重复性校验!F4 | K15: =波长示值误差与重复性校验!F2 | L15: =波长示值误差与重复性校验!F3 | M15: =波长示值误差与重复性校验!F5 | N15: =波长示值误差与重复性校验!F6 | O15: =波长示值误差与重复性校验!F7 | P15: =波长示值误差与重复性校验!F8
F16: 误差值(nm) | I16: =波长示值误差与重复性校验!G4 | K16: =波长示值误差与重复性校验!G2 | L16: =波长示值误差与重复性校验!G3 | M16: =波长示值误差与重复性校验!G5 | N16: =波长示值误差与重复性校验!G6 | O16: =波长示值误差与重复性校验!G7 | P16: =波长示值误差与重复性校验!G8
F17: 重复性(nm) | I17: =波长示值误差与重复性校验!H4 -> 0 | K17: =波长示值误差与重复性校验!H2 -> 0 | L17: =波长示值误差与重复性校验!H3 -> 0 | M17: =波长示值误差与重复性校验!H5 -> 0 | N17: =波长示值误差与重复性校验!H6 -> 0 | O17: =波长示值误差与重复性校验!H7 -> 0 | P17: =波长示值误差与重复性校验!H8 -> 0
C18: 波长示值误差与重复性 | D18: 波长示值误差 钬溶液： ±0.3nm 波长重复性 ≤0.1nm | F18: 检测工具 | I18: 钬溶液
F19: 标准值(nm) | I19: =波长示值误差与重复性校验!B9 -> 640.79 | K19: =波长示值误差与重复性校验!B10 -> 536.86 | L19: =波长示值误差与重复性校验!B11 -> 416.57 | M19: =波长示值误差与重复性校验!B12 -> 361.12 | N19: =波长示值误差与重复性校验!B13 -> 287.52 | O19: =波长示值误差与重复性校验!B14 -> 241.12
F20: 测量值（nm） | I20: =波长示值误差与重复性校验!C9 -> 0 | K20: =波长示值误差与重复性校验!C10 -> 0 | L20: =波长示值误差与重复性校验!C11 -> 0 | M20: =波长示值误差与重复性校验!C12 -> 0 | N20: =波长示值误差与重复性校验!C13 -> 0 | O20: =波长示值误差与重复性校验!C14 -> 0
I21: =波长示值误差与重复性校验!D9 -> 0 | K21: =波长示值误差与重复性校验!D10 -> 0 | L21: =波长示值误差与重复性校验!D11 -> 0 | M21: =波长示值误差与重复性校验!D12 -> 0 | N21: =波长示值误差与重复性校验!D13 -> 0 | O21: =波长示值误差与重复性校验!D14 -> 0
I22: =波长示值误差与重复性校验!E9 -> 0 | K22: =波长示值误差与重复性校验!E10 -> 0 | L22: =波长示值误差与重复性校验!E11 -> 0 | M22: =波长示值误差与重复性校验!E12 -> 0 | N22: =波长示值误差与重复性校验!E13 -> 0 | O22: =波长示值误差与重复性校验!E14 -> 0
F23: 平均值(nm) | I23: =波长示值误差与重复性校验!F9 | K23: =波长示值误差与重复性校验!F10 | L23: =波长示值误差与重复性校验!F11 | M23: =波长示值误差与重复性校验!F12 | N23: =波长示值误差与重复性校验!F13 | O23: =波长示值误差与重复性校验!F14
F24: 误差值(nm) | I24: =波长示值误差与重复性校验!G9 | K24: =波长示值误差与重复性校验!G10 | L24: =波长示值误差与重复性校验!G11 | M24: =波长示值误差与重复性校验!G12 | N24: =波长示值误差与重复性校验!G13 | O24: =波长示值误差与重复性校验!G14
F25: 重复性(nm) | I25: =波长示值误差与重复性校验!H9 -> 0 | K25: =波长示值误差与重复性校验!H10 -> 0 | L25: =波长示值误差与重复性校验!H11 -> 0 | M25: =波长示值误差与重复性校验!H12 -> 0 | N25: =波长示值误差与重复性校验!H13 -> 0 | O25: =波长示值误差与重复性校验!H14 -> 0
B26: 2 | C26: 透射比示值误差与重复性 (可见区） | D26: 透射比示值误差 ±0.3% 透射比重复性 ≤0.1% | F26: 检测工具 | I26: 10%中性滤光片、20%中性滤光片、30%中性滤光片 （以标定的标准值为准）
F28: 型号 | H28: 测量点 | J28: =透射比示值误差与重复性校验!B6 -> 635 | M28: =透射比示值误差与重复性校验!B7 -> 546 | O28: =透射比示值误差与重复性校验!B8 -> 440
F29: 10%中性滤光片 | H29: 标准值(%) | J29: =透射比示值误差与重复性校验!C6 -> 13.34 | M29: =透射比示值误差与重复性校验!C7 -> 15.91 | O29: =透射比示值误差与重复性校验!C8 -> 15.34
H30: 测量值(%) | J30: =透射比示值误差与重复性校验!D6 -> 0 | M30: =透射比示值误差与重复性校验!D7 -> 0 | O30: =透射比示值误差与重复性校验!D8 -> 0
J31: =透射比示值误差与重复性校验!E6 -> 0 | M31: =波长示值误差与重复性校验!D2 -> 0 | O31: =透射比示值误差与重复性校验!E8 -> 0
J32: =透射比示值误差与重复性校验!F6 -> 0 | M32: =透射比示值误差与重复性校验!F7 -> 0 | O32: =透射比示值误差与重复性校验!F8 -> 0
H33: 平均值(%) | J33: =透射比示值误差与重复性校验!G6 | M33: =透射比示值误差与重复性校验!G7 | O33: =透射比示值误差与重复性校验!G8
H34: 误差值(%) | J34: =透射比示值误差与重复性校验!H6 | M34: =透射比示值误差与重复性校验!H7 | O34: =透射比示值误差与重复性校验!H8
H35: 重复性(%) | J35: =透射比示值误差与重复性校验!I6 -> 0 | M35: =透射比示值误差与重复性校验!I7 -> 0 | O35: =透射比示值误差与重复性校验!I8 -> 0
F36: 20%中性滤光片 | H36: 标准值(%) | J36: =透射比示值误差与重复性校验!C9 -> 22.78 | M36: =透射比示值误差与重复性校验!C10 -> 29.12 | O36: =透射比示值误差与重复性校验!C11 -> 29.76
H37: 测量值(%) | J37: =透射比示值误差与重复性校验!D9 -> 0 | M37: =透射比示值误差与重复性校验!D10 -> 0 | O37: =透射比示值误差与重复性校验!D11 -> 0
J38: =透射比示值误差与重复性校验!E9 -> 0 | M38: =透射比示值误差与重复性校验!E10 -> 0 | O38: =透射比示值误差与重复性校验!E11 -> 0
J39: =透射比示值误差与重复性校验!F9 -> 0 | M39: =透射比示值误差与重复性校验!F10 -> 0 | O39: =透射比示值误差与重复性校验!F11 -> 0
H40: 平均值(%) | J40: =透射比示值误差与重复性校验!G9 | M40: =透射比示值误差与重复性校验!G10 | O40: =透射比示值误差与重复性校验!G11
H41: 误差值(%) | J41: =透射比示值误差与重复性校验!H9 | M41: =透射比示值误差与重复性校验!H10 | O41: =透射比示值误差与重复性校验!H11
H42: 重复性(%) | J42: =透射比示值误差与重复性校验!I9 -> 0 | M42: =透射比示值误差与重复性校验!I10 -> 0 | O42: =透射比示值误差与重复性校验!I11 -> 0
...

Sheet 基础信息
A1: 名称 | B1: 特征值 | C1: 标准值 | E1: 是否为光谱扫描 | F1: 灯状态 | G1: 灯状态 | H1: 较零物质 | I1: 光度方式 | J1: 光度方式 | K1: 扫描速度 | L1: 扫描速度 | M1: 扫描间隔(nm) | N1: 重复次数 | O1: 重复时间间隔(S) | P1: 光谱带宽(nm) | Q1: 增益 | R1: 响应时间
A2: 氘灯 | B2: 656.1 | C2: 656.1 | E2: 是 | F2: 钨灯 | G2: 0 | I2: Abs | J2: 0 | K2: 极慢 | L2: 0 | N2: 1 | P2: 0.2
A3: 低压汞灯A段 | B3: 253.7 | C3: 253.7 | E3: 否 | F3: 氘灯 | G3: 1 | H3: 其它 | I3: T% | J3: 1 | K3: 慢速 | L3: 1 | M3: 0.1 | N3: 2 | O3: 1 | P3: 0.5 | Q3: 1 | R3: 0.5
A4: 低压汞灯B段 | B4: 365.0,435.8,546.1 | C4: 365.0,435.8,546.1 | F4: 汞灯 | G4: 2 | I4: Es | J4: 2 | K4: 中速 | L4: 2 | M4: 0.2 | N4: 3 | O4: 2 | P4: 1.0 | Q4: 2 | R4: 1
A5: 镨钕滤光片 | B5: 739.2,,807.4 | C5: 739.2,,807.4 | I5: Er | J5: 3 | K5: 快速 | L5: 3 | M5: 0.5 | N5: 4 | P5: 2.0 | Q5: 3 | R5: 2
A6: 10%中性滤光片 | B6: 635.0,546.0,440.0 | I6: R% | J6: 4 | K6: 极快 | L6: 4 | M6: 1 | N6: 5 | P6: 5.0 | Q6: 4
A7: 20%中性滤光片 | B7: 635.0,546.0,440.1 | M7: 2 | Q7: 5
A8: 30%中性滤光片 | B8: 635.0,546.0,440.2 | M8: 5
A9: 重铬酸钾标准物质 | B9: 350313257235 | C9: 22.9,51.3,13.7,18.2
A10: 碘化钠溶液 | B10: 220
A11: 亚硝酸钠溶液 | B11: 340360

Sheet 测量结果表
A1: 项目编号 | B1: 仪器ID | C1: 标准值 | D1: 测量值（nm） | E1: 平均值 | F1: 误差值 | G1: 重复性 | H1: 检验员 | I1: 检验日期 | J1: 复核员 | K1: 检验地点 | L1: 温度 | M1: 湿度 | N1: 判定结果 | O1: 其他
A2: 1001 | B2: =MID(CELL("filename"),FIND("[",CELL("filename"),1)+1,FIND(".",CELL("filename"),1)-FIND("[",CELL("filename"),1)-1) -> T600T700 | D2: =波长示值误差与重复性校验!$C2&";"&波长示值误差与重复性校验!$D2&";"&波长示值误差与重复性校验!$E2 -> ;; | E2: =波长示值误差与重复性校验!$F2 | F2: =波长示值误差与重复性校验!$G2 | G2: =波长示值误差与重复性校验!$H2 -> 0 | H2: =#REF! -> #REF! | I2: =NOW() -> 44687.516 | J2: =#REF! -> #REF! | L2: =#REF! -> #REF! | M2: =#REF! -> #REF! | N2: =波长示值误差与重复性校验!$K2
A3: 1002 | B3: =MID(CELL("filename"),FIND("[",CELL("filename"),1)+1,FIND(".",CELL("filename"),1)-FIND("[",CELL("filename"),1)-1) -> T600T700 | D3: =波长示值误差与重复性校验!$C3&";"&波长示值误差与重复性校验!$D3&";"&波长示值误差与重复性校验!$E3 -> ;; | E3: =波长示值误差与重复性校验!$F3 | F3: =波长示值误差与重复性校验!$G3 | G3: =波长示值误差与重复性校验!$H3 -> 0 | H3: =#REF! -> #REF! | I3: =NOW() -> 44687.516 | J3: =#REF! -> #REF! | L3: =#REF! -> #REF! | M3: =#REF! -> #REF! | N3: =波长示值误差与重复性校验!$K3
A4: 1003 | B4: =MID(CELL("filename"),FIND("[",CELL("filename"),1)+1,FIND(".",CELL("filename"),1)-FIND("[",CELL("filename"),1)-1) -> T600T700 | D4: =波长示值误差与重复性校验!$C4&";"&波长示值误差与重复性校验!$D4&";"&波长示值误差与重复性校验!$E4 -> ;; | E4: =波长示值误差与重复性校验!$F4 | F4: =波长示值误差与重复性校验!$G4 | G4: =波长示值误差与重复性校验!$H4 -> 0 | H4: =#REF! -> #REF! | I4: =NOW() -> 44687.516 | J4: =#REF! -> #REF! | L4: =#REF! -> #REF! | M4: =#REF! -> #REF! | N4: =波长示值误差与重复性校验!$K4
A5: 1004 | B5: =MID(CELL("filename"),FIND("[",CELL("filename"),1)+1,FIND(".",CELL("filename"),1)-FIND("[",CELL("filename"),1)-1) -> T600T700 | D5: =波长示值误差与重复性校验!$C5&";"&波长示值误差与重复性校验!$D5&";"&波长示值误差与重复性校验!$E5 -> ;; | E5: =波长示值误差与重复性校验!$F5 | F5: =波长示值误差与重复性校验!$G5 | G5: =波长示值误差与重复性校验!$H5 -> 0 | H5: =#REF! -> #REF! | I5: =NOW() -> 44687.516 | J5: =#REF! -> #REF! | L5: =#REF! -> #REF! | M5: =#REF! -> #REF! | N5: =波长示值误差与重复性校验!$K5
A6: 1005 | B6: =MID(CELL("filename"),FIND("[",CELL("filename"),1)+1,FIND(".",CELL("filename"),1)-FIND("[",CELL("filename"),1)-1) -> T600T700 | D6: =波长示值误差与重复性校验!$C6&";"&波长示值误差与重复性校验!$D6&";"&波长示值误差与重复性校验!$E6 -> ;; | E6: =波长示值误差与重复性校验!$F6 | F6: =波长示值误差与重复性校验!$G6 | G6: =波长示值误差与重复性校验!$H6 -> 0 | H6: =#REF! -> #REF! | I6: =NOW() -> 44687.516 | J6: =#REF! -> #REF! | L6: =#REF! -> #REF! | M6: =#REF! -> #REF! | N6: =波长示值误差与重复性校验!$K6
A7: 1006 | B7: =MID(CELL("filename"),FIND("[",CELL("filename"),1)+1,FIND(".",CELL("filename"),1)-FIND("[",CELL("filename"),1)-1) -> T600T700 | D7: =波长示值误差与重复性校验!$C7&";"&波长示值误差与重复性校验!$D7&";"&波长示值误差与重复性校验!$E7 -> ;; | E7: =波长示值误差与重复性校验!$F7 | F7: =波长示值误差与重复性校验!$G7 | G7: =波长示值误差与重复性校验!$H7 -> 0 | H7: =#REF! -> #REF! | I7: =NOW() -> 44687.516 | J7: =#REF! -> #REF! | L7: =#REF! -> #REF! | M7: =#REF! -> #REF! | N7: =波长示值误差与重复性校验!$K7
A8: 1007 | B8: =MID(CELL("filename"),FIND("[",CELL("filename"),1)+1,FIND(".",CELL("filename"),1)-FIND("[",CELL("filename"),1)-1) -> T600T700 | D8: =波长示值误差与重复性校验!$C8&";"&波长示值误差与重复性校验!$D8&";"&波长示值误差与重复性校验!$E8 -> ;; | E8: =波长示值误差与重复性校验!$F8 | F8: =波长示值误差与重复性校验!$G8 | G8: =波长示值误差与重复性校验!$H8 -> 0 | H8: =#REF! -> #REF! | I8: =NOW() -> 44687.516 | J8: =#REF! -> #REF! | L8: =#REF! -> #REF! | M8: =#REF! -> #REF! | N8: =波长示值误差与重复性校验!$K8
A9: 1008 | B9: =MID(CELL("filename"),FIND("[",CELL("filename"),1)+1,FIND(".",CELL("filename"),1)-FIND("[",CELL("filename"),1)-1) -> T600T700 | D9: =波长示值误差与重复性校验!$C9&";"&波长示值误差与重复性校验!$D9&";"&波长示值误差与重复性校验!$E9 -> ;; | E9: =波长示值误差与重复性校验!$F9 | F9: =波长示值误差与重复性校验!$G9 | G9: =波长示值误差与重复性校验!$H9 -> 0 | H9: =#REF! -> #REF! | I9: =NOW() -> 44687.516 | J9: =#REF! -> #REF! | L9: =#REF! -> #REF! | M9: =#REF! -> #REF! | N9: =波长示值误差与重复性校验!$K9
A10: 1009 | B10: =MID(CELL("filename"),FIND("[",CELL("filename"),1)+1,FIND(".",CELL("filename"),1)-FIND("[",CELL("filename"),1)-1) -> T600T700 | D10: =波长示值误差与重复性校验!$C10&";"&波长示值误差与重复性校验!$D10&";"&波长示值误差与重复性校验!$E10 -> ;; | E10: =波长示值误差与重复性校验!$F10 | F10: =波长示值误差与重复性校验!$G10 | G10: =波长示值误差与重复性校验!$H10 -> 0 | H10: =#REF! -> #REF! | I10: =NOW() -> 44687.516 | J10: =#REF! -> #REF! | L10: =#REF! -> #REF! | M10: =#REF! -> #REF! | N10: =波长示值误差与重复性校验!$K10
A11: 1010 | B11: =MID(CELL("filename"),FIND("[",CELL("filename"),1)+1,FIND(".",CELL("filename"),1)-FIND("[",CELL("filename"),1)-1) -> T600T700 | D11: =波长示值误差与重复性校验!$C11&";"&波长示值误差与重复性校验!$D11&";"&波长示值误差与重复性校验!$E11 -> ;; | E11: =波长示值误差与重复性校验!$F11 | F11: =波长示值误差与重复性校验!$G11 | G11: =波长示值误差与重复性校验!$H11 -> 0 | H11: =#REF! -> #REF! | I11: =NOW() -> 44687.516 | J11: =#REF! -> #REF! | L11: =#REF! -> #REF! | M11: =#REF! -> #REF! | N11: =波长示值误差与重复性校验!$K11
A12: 1011 | B12: =MID(CELL("filename"),FIND("[",CELL("filename"),1)+1,FIND(".",CELL("filename"),1)-FIND("[",CELL("filename"),1)-1) -> T600T700 | D12: =波长示值误差与重复性校验!$C12&";"&波长示值误差与重复性校验!$D12&";"&波长示值误差与重复性校验!$E12 -> ;; | E12: =波长示值误差与重复性校验!$F12 | F12: =波长示值误差与重复性校验!$G12 | G12: =波长示值误差与重复性校验!$H12 -> 0 | H12: =#REF! -> #REF! | I12: =NOW() -> 44687.516 | J12: =#REF! -> #REF! | L12: =#REF! -> #REF! | M12: =#REF! -> #REF! | N12: =波长示值误差与重复性校验!$K12
A13: 1012 | B13: =MID(CELL("filename"),FIND("[",CELL("filename"),1)+1,FIND(".",CELL("filename"),1)-FIND("[",CELL("filename"),1)-1) -> T600T700 | D13: =波长示值误差与重复性校验!$C13&";"&波长示值误差与重复性校验!$D13&";"&波长示值误差与重复性校验!$E13 -> ;; | E13: =波长示值误差与重复性校验!$F13 | F13: =波长示值误差与重复性校验!$G13 | G13: =波长示值误差与重复性校验!$H13 -> 0 | H13: =#REF! -> #REF! | I13: =NOW() -> 44687.516 | J13: =#REF! -> #REF! | L13: =#REF! -> #REF! | M13: =#REF! -> #REF! | N13: =波长示值误差与重复性校验!$K13
A14: 1013 | B14: =MID(CELL("filename"),FIND("[",CELL("filename"),1)+1,FIND(".",CELL("filename"),1)-FIND("[",CELL("filename"),1)-1) -> T600T700 | D14: =波长示值误差与重复性校验!$C14&";"&波长示值误差与重复性校验!$D14&";"&波长示值误差与重复性校验!$E14 -> ;; | E14: =波长示值误差与重复性校验!$F14 | F14: =波长示值误差与重复性校验!$G14 | G14: =波长示值误差与重复性校验!$H14 -> 0 | H14: =#REF! -> #REF! | I14: =NOW() -> 44687.516 | J14: =#REF! -> #REF! | L14: =#REF! -> #REF! | M14: =#REF! -> #REF! | N14: =波长示值误差与重复性校验!$K14
A15: 2001 | B15: =MID(CELL("filename"),FIND("[",CELL("filename"),1)+1,FIND(".",CELL("filename"),1)-FIND("[",CELL("filename"),1)-1) -> T600T700 | C15: =透射比示值误差与重复性校验!$C2 -> 23.35 | D15: =透射比示值误差与重复性校验!$D2&";"&透射比示值误差与重复性校验!$E2&";"&透射比示值误差与重复性校验!$F2 -> ;; | E15: =透射比示值误差与重复性校验!$G2 | F15: =透射比示值误差与重复性校验!$H2 | G15: =透射比示值误差与重复性校验!$I2 -> 0 | H15: =#REF! -> #REF! | I15: =NOW() -> 44687.516 | J15: =#REF! -> #REF! | L15: =#REF! -> #REF! | M15: =#REF! -> #REF! | N15: =透射比示值误差与重复性校验!$L2
A16: 2002 | B16: =MID(CELL("filename"),FIND("[",CELL("filename"),1)+1,FIND(".",CELL("filename"),1)-FIND("[",CELL("filename"),1)-1) -> T600T700 | C16: =透射比示值误差与重复性校验!$C3 -> 51.54 | D16: =透射比示值误差与重复性校验!$D3&";"&透射比示值误差与重复性校验!$E3&";"&透射比示值误差与重复性校验!$F3 -> ;; | E16: =透射比示值误差与重复性校验!$G3 | F16: =透射比示值误差与重复性校验!$H3 | G16: =透射比示值误差与重复性校验!$I3 -> 0 | H16: =#REF! -> #REF! | I16: =NOW() -> 44687.516 | J16: =#REF! -> #REF! | L16: =#REF! -> #REF! | M16: =#REF! -> #REF! | N16: =透射比示值误差与重复性校验!$L3
A17: 2003 | B17: =MID(CELL("filename"),FIND("[",CELL("filename"),1)+1,FIND(".",CELL("filename"),1)-FIND("[",CELL("filename"),1)-1) -> T600T700 | C17: =透射比示值误差与重复性校验!$C4 -> 14.09 | D17: =透射比示值误差与重复性校验!$D4&";"&透射比示值误差与重复性校验!$E4&";"&透射比示值误差与重复性校验!$F4 -> ;; | E17: =透射比示值误差与重复性校验!$G4 | F17: =透射比示值误差与重复性校验!$H4 | G17: =透射比示值误差与重复性校验!$I4 -> 0 | H17: =#REF! -> #REF! | I17: =NOW() -> 44687.516 | J17: =#REF! -> #REF! | L17: =#REF! -> #REF! | M17: =#REF! -> #REF! | N17: =透射比示值误差与重复性校验!$L4
A18: 2004 | B18: =MID(CELL("filename"),FIND("[",CELL("filename"),1)+1,FIND(".",CELL("filename"),1)-FIND("[",CELL("filename"),1)-1) -> T600T700 | C18: =透射比示值误差与重复性校验!$C5 -> 18.53 | D18: =透射比示值误差与重复性校验!$D5&";"&透射比示值误差与重复性校验!$E5&";"&透射比示值误差与重复性校验!$F5 -> ;; | E18: =透射比示值误差与重复性校验!$G5 | F18: =透射比示值误差与重复性校验!$H5 | G18: =透射比示值误差与重复性校验!$I5 -> 0 | H18: =#REF! -> #REF! | I18: =NOW() -> 44687.516 | J18: =#REF! -> #REF! | L18: =#REF! -> #REF! | M18: =#REF! -> #REF! | N18: =透射比示值误差与重复性校验!$L5
A19: 2005 | B19: =MID(CELL("filename"),FIND("[",CELL("filename"),1)+1,FIND(".",CELL("filename"),1)-FIND("[",CELL("filename"),1)-1) -> T600T700 | C19: =透射比示值误差与重复性校验!$C6 -> 13.34 | D19: =透射比示值误差与重复性校验!$D6&";"&透射比示值误差与重复性校验!$E6&";"&透射比示值误差与重复性校验!$F6 -> ;; | E19: =透射比示值误差与重复性校验!$G6 | F19: =透射比示值误差与重复性校验!$H6 | G19: =透射比示值误差与重复性校验!$I6 -> 0 | H19: =#REF! -> #REF! | I19: =NOW() -> 44687.516 | J19: =#REF! -> #REF! | L19: =#REF! -> #REF! | M19: =#REF! -> #REF! | N19: =透射比示值误差与重复性校验!$L6
A20: 2006 | B20: =MID(CELL("filename"),FIND("[",CELL("filename"),1)+1,FIND(".",CELL("filename"),1)-FIND("[",CELL("filename"),1)-1) -> T600T700 | C20: =透射比示值误差与重复性校验!$C7 -> 15.91 | D20: =透射比示值误差与重复性校验!$D7&";"&透射比示值误差与重复性校验!$E7&";"&透射比示值误差与重复性校验!$F7 -> ;; | E20: =透射比示值误差与重复性校验!$G7 | F20: =透射比示值误差与重复性校验!$H7 | G20: =透射比示值误差与重复性校验!$I7 -> 0 | H20: =#REF! -> #REF! | I20: =NOW() -> 44687.516 | J20: =#REF! -> #REF! | L20: =#REF! -> #REF! | M20: =#REF! -> #REF! | N20: =透射比示值误差与重复性校验!$L7
A21: 2007 | B21: =MID(CELL("filename"),FIND("[",CELL("filename"),1)+1,FIND(".",CELL("filename"),1)-FIND("[",CELL("filename"),1)-1) -> T600T700 | C21: =透射比示值误差与重复性校验!$C8 -> 15.34 | D21: =透射比示值误差与重复性校验!$D8&";"&透射比示值误差与重复性校验!$E8&";"&透射比示值误差与重复性校验!$F8 -> ;; | E21: =透射比示值误差与重复性校验!$G8 | F21: =透射比示值误差与重复性校验!$H8 | G21: =透射比示值误差与重复性校验!$I8 -> 0 | H21: =#REF! -> #REF! | I21: =NOW() -> 44687.516 | J21: =#REF! -> #REF! | L21: =#REF! -> #REF! | M21: =#REF! -> #REF! | N21: =透射比示值误差与重复性校验!$L8
A22: 2008 | B22: =MID(CELL("filename"),FIND("[",CELL("filename"),1)+1,FIND(".",CELL("filename"),1)-FIND("[",CELL("filename"),1)-1) -> T600T700 | C22: =透射比示值误差与重复性校验!$C9 -> 22.78 | D22: =透射比示值误差与重复性校验!$D9&";"&透射比示值误差与重复性校验!$E9&";"&透射比示值误差与重复性校验!$F9 -> ;; | E22: =透射比示值误差与重复性校验!$G9 | F22: =透射比示值误差与重复性校验!$H9 | G22: =透射比示值误差与重复性校验!$I9 -> 0 | H22: =#REF! -> #REF! | I22: =NOW() -> 44687.516 | J22: =#REF! -> #REF! | L22: =#REF! -> #REF! | M22: =#REF! -> #REF! | N22: =透射比示值误差与重复性校验!$L9
A23: 2009 | B23: =MID(CELL("filename"),FIND("[",CELL("filename"),1)+1,FIND(".",CELL("filename"),1)-FIND("[",CELL("filename"),1)-1) -> T600T700 | C23: =透射比示值误差与重复性校验!$C10 -> 29.12 | D23: =透射比示值误差与重复性校验!$D10&";"&透射比示值误差与重复性校验!$E10&";"&透射比示值误差与重复性校验!$F10 -> ;; | E23: =透射比示值误差与重复性校验!$G10 | F23: =透射比示值误差与重复性校验!$H10 | G23: =透射比示值误差与重复性校验!$I10 -> 0 | H23: =#REF! -> #REF! | I23: =NOW() -> 44687.516 | J23: =#REF! -> #REF! | L23: =#REF! -> #REF! | M23: =#REF! -> #REF! | N23: =透射比示值误差与重复性校验!$L10
A24: 2010 | B24: =MID(CELL("filename"),FIND("[",CELL("filename"),1)+1,FIND(".",CELL("filename"),1)-FIND("[",CELL("filename"),1)-1) -> T600T700 | C24: =透射比示值误差与重复性校验!$C11 -> 29.76 | D24: =透射比示值误差与重复性校验!$D11&";"&透射比示值误差与重复性校验!$E11&";"&透射比示值误差与重复性校验!$F11 -> ;; | E24: =透射比示值误差与重复性校验!$G11 | F24: =透射比示值误差与重复性校验!$H11 | G24: =透射比示值误差与重复性校验!$I11 -> 0 | H24: =#REF! -> #REF! | I24: =NOW() -> 44687.516 | J24: =#REF! -> #REF! | L24: =#REF! -> #REF! | M24: =#REF! -> #REF! | N24: =透射比示值误差与重复性校验!$L11
A25: 2011 | B25: =MID(CELL("filename"),FIND("[",CELL("filename"),1)+1,FIND(".",CELL("filename"),1)-FIND("[",CELL("filename"),1)-1) -> T600T700 | C25: =透射比示值误差与重复性校验!$C12 -> 34.02 | D25: =透射比示值误差与重复性校验!$D12&";"&透射比示值误差与重复性校验!$E12&";"&透射比示值误差与重复性校验!$F12 -> ;; | E25: =透射比示值误差与重复性校验!$G12 | F25: =透射比示值误差与重复性校验!$H12 | G25: =透射比示值误差与重复性校验!$I12 -> 0 | H25: =#REF! -> #REF! | I25: =NOW() -> 44687.516 | J25: =#REF! -> #REF! | L25: =#REF! -> #REF! | M25: =#REF! -> #REF! | N25: =透射比示值误差与重复性校验!$L12
A26: 2012 | B26: =MID(CELL("filename"),FIND("[",CELL("filename"),1)+1,FIND(".",CELL("filename"),1)-FIND("[",CELL("filename"),1)-1) -> T600T700 | C26: =透射比示值误差与重复性校验!$C13 -> 40.5 | D26: =透射比示值误差与重复性校验!$D13&";"&透射比示值误差与重复性校验!$E13&";"&透射比示值误差与重复性校验!$F13 -> ;; | E26: =透射比示值误差与重复性校验!$G13 | F26: =透射比示值误差与重复性校验!$H13 | G26: =透射比示值误差与重复性校验!$I13 -> 0 | H26: =#REF! -> #REF! | I26: =NOW() -> 44687.516 | J26: =#REF! -> #REF! | L26: =#REF! -> #REF! | M26: =#REF! -> #REF! | N26: =透射比示值误差与重复性校验!$L13
A27: 2013 | B27: =MID(CELL("filename"),FIND("[",CELL("filename"),1)+1,FIND(".",CELL("filename"),1)-FIND("[",CELL("filename"),1)-1) -> T600T700 | C27: =透射比示值误差与重复性校验!$C14 -> 41 | D27: =透射比示值误差与重复性校验!$D14&";"&透射比示值误差与重复性校验!$E14&";"&透射比示值误差与重复性校验!$F14 -> ;; | E27: =透射比示值误差与重复性校验!$G14 | F27: =透射比示值误差与重复性校验!$H14 | G27: =透射比示值误差与重复性校验!$I14 -> 0 | H27: =#REF! -> #REF! | I27: =NOW() -> 44687.516 | J27: =#REF! -> #REF! | L27: =#REF! -> #REF! | M27: =#REF! -> #REF! | N27: =透射比示值误差与重复性校验!$L14
A28: 3001 | B28: =MID(CELL("filename"),FIND("[",CELL("filename"),1)+1,FIND(".",CELL("filename"),1)-FIND("[",CELL("filename"),1)-1) -> T600T700 | C28: =杂散光校验!$B2 -> 220 | D28: =杂散光校验!$C2&";"&杂散光校验!$D2&";"&杂散光校验!$E2 -> ;; | H28: =#REF! -> #REF! | I28: =NOW() -> 44687.516 | J28: =#REF! -> #REF! | L28: =#REF! -> #REF! | M28: =#REF! -> #REF! | N28: =杂散光校验!$G2
A29: 3002 | B29: =MID(CELL("filename"),FIND("[",CELL("filename"),1)+1,FIND(".",CELL("filename"),1)-FIND("[",CELL("filename"),1)-1) -> T600T700 | C29: =杂散光校验!$B3 -> 360 | D29: =杂散光校验!$C3&";"&杂散光校验!$D3&";"&杂散光校验!$E3 -> ;; | H29: =#REF! -> #REF! | I29: =NOW() -> 44687.516 | J29: =#REF! -> #REF! | L29: =#REF! -> #REF! | M29: =#REF! -> #REF! | N29: =杂散光校验!$G3
A30: 4001 | B30: =MID(CELL("filename"),FIND("[",CELL("filename"),1)+1,FIND(".",CELL("filename"),1)-FIND("[",CELL("filename"),1)-1) -> T600T700 | D30: =基线平直度检验!$B$2 -> 0 | H30: =#REF! -> #REF! | I30: =NOW() -> 44687.516 | J30: =#REF! -> #REF! | L30: =#REF! -> #REF! | M30: =#REF! -> #REF! | N30: =基线平直度检验!$D$2 -> 不合格
A31: 5001 | B31: =MID(CELL("filename"),FIND("[",CELL("filename"),1)+1,FIND(".",CELL("filename"),1)-FIND("[",CELL("filename"),1)-1) -> T600T700 | D31: =基线暗噪声检验!$B$2 -> 0 | H31: =#REF! -> #REF! | I31: =NOW() -> 44687.516 | J31: =#REF! -> #REF! | L31: =#REF! -> #REF! | M31: =#REF! -> #REF! | N31: =基线暗噪声检验!$D$2 -> 不合格
A32: 6001 | B32: =MID(CELL("filename"),FIND("[",CELL("filename"),1)+1,FIND(".",CELL("filename"),1)-FIND("[",CELL("filename"),1)-1) -> T600T700 | C32: =光谱带宽与仪器最小光谱带宽!$C2 -> 5 | D32: =光谱带宽与仪器最小光谱带宽!$D2 -> 0 | H32: =#REF! -> #REF! | I32: =NOW() -> 44687.516 | J32: =#REF! -> #REF! | L32: =#REF! -> #REF! | M32: =#REF! -> #REF! | N32: =光谱带宽与仪器最小光谱带宽!$G2 -> 不合格
A33: 6002 | B33: =MID(CELL("filename"),FIND("[",CELL("filename"),1)+1,FIND(".",CELL("filename"),1)-FIND("[",CELL("filename"),1)-1) -> T600T700 | C33: =光谱带宽与仪器最小光谱带宽!$C3 -> 2 | D33: =光谱带宽与仪器最小光谱带宽!$D3 -> 0 | H33: =#REF! -> #REF! | I33: =NOW() -> 44687.516 | J33: =#REF! -> #REF! | L33: =#REF! -> #REF! | M33: =#REF! -> #REF! | N33: =光谱带宽与仪器最小光谱带宽!$G3 -> 不合格
A34: 6003 | B34: =MID(CELL("filename"),FIND("[",CELL("filename"),1)+1,FIND(".",CELL("filename"),1)-FIND("[",CELL("filename"),1)-1) -> T600T700 | C34: =光谱带宽与仪器最小光谱带宽!$C4 -> 1 | D34: =光谱带宽与仪器最小光谱带宽!$D4 -> 0 | H34: =#REF! -> #REF! | I34: =NOW() -> 44687.516 | J34: =#REF! -> #REF! | L34: =#REF! -> #REF! | M34: =#REF! -> #REF! | N34: =光谱带宽与仪器最小光谱带宽!$G4 -> 不合格
A35: 6004 | B35: =MID(CELL("filename"),FIND("[",CELL("filename"),1)+1,FIND(".",CELL("filename"),1)-FIND("[",CELL("filename"),1)-1) -> T600T700 | C35: =光谱带宽与仪器最小光谱带宽!$C5 -> 0.5 | D35: =光谱带宽与仪器最小光谱带宽!$D5 -> 0 | H35: =#REF! -> #REF! | I35: =NOW() -> 44687.516 | J35: =#REF! -> #REF! | L35: =#REF! -> #REF! | M35: =#REF! -> #REF! | N35: =光谱带宽与仪器最小光谱带宽!$G5 -> 不合格
A36: 6005 | B36: =MID(CELL("filename"),FIND("[",CELL("filename"),1)+1,FIND(".",CELL("filename"),1)-FIND("[",CELL("filename"),1)-1) -> T600T700 | C36: =光谱带宽与仪器最小光谱带宽!$C6 -> 0.2 | D36: =光谱带宽与仪器最小光谱带宽!$D6 -> 0 | H36: =#REF! -> #REF! | I36: =NOW() -> 44687.516 | J36: =#REF! -> #REF! | L36: =#REF! -> #REF! | M36: =#REF! -> #REF! | N36: =光谱带宽与仪器最小光谱带宽!$G6 -> 不合格
A37: 7001 | B37: =MID(CELL("filename"),FIND("[",CELL("filename"),1)+1,FIND(".",CELL("filename"),1)-FIND("[",CELL("filename"),1)-1) -> T600T700 | C37: =噪声检验!$B2 -> 500 | D37: =噪声检验!$C2 -> 0 | H37: =#REF! -> #REF! | I37: =NOW() -> 44687.516 | J37: =#REF! -> #REF! | L37: =#REF! -> #REF! | M37: =#REF! -> #REF! | N37: =噪声检验!$E2 -> 不合格
A38: 7002 | B38: =MID(CELL("filename"),FIND("[",CELL("filename"),1)+1,FIND(".",CELL("filename"),1)-FIND("[",CELL("filename"),1)-1) -> T600T700 | C38: =噪声检验!$B3 -> 500 | D38: =噪声检验!$C3 -> 0 | H38: =#REF! -> #REF! | I38: =NOW() -> 44687.516 | J38: =#REF! -> #REF! | L38: =#REF! -> #REF! | M38: =#REF! -> #REF! | N38: =噪声检验!$E3 -> 不合格
A39: 7003 | B39: =MID(CELL("filename"),FIND("[",CELL("filename"),1)+1,FIND(".",CELL("filename"),1)-FIND("[",CELL("filename"),1)-1) -> T600T700 | C39: =噪声检验!$B4 -> 250 | D39: =噪声检验!$C4 -> 0 | H39: =#REF! -> #REF! | I39: =NOW() -> 44687.516 | J39: =#REF! -> #REF! | L39: =#REF! -> #REF! | M39: =#REF! -> #REF! | N39: =噪声检验!$E4 -> 不合格
A40: 7004 | B40: =MID(CELL("filename"),FIND("[",CELL("filename"),1)+1,FIND(".",CELL("filename"),1)-FIND("[",CELL("filename"),1)-1) -> T600T700 | C40: =噪声检验!$B5 -> 250 | D40: =噪声检验!$C5 -> 0 | H40: =#REF! -> #REF! | I40: =NOW() -> 44687.516 | J40: =#REF! -> #REF! | L40: =#REF! -> #REF! | M40: =#REF! -> #REF! | N40: =噪声检验!$E5 -> 不合格
...

Sheet 管理表
A1: 检验项目 | J1: 检测序列表
A2: 产品型号 | B2: 父项目编号 | C2: 父项目名称 | D2: 子项目编号 | E2: 子项目名称 | F2: 特征值 | G2: 可允许误差范围 | H2: 波长重复性 | J2: ID | K2: 仪器序列号 | L2: 产品型号 | M2: 其他信息
A3: T700S | B3: 1000 | C3: 波长示值误差与重复性校验 | D3: 1001 | E3: 氘灯 | F3: 656.1 | G3: 0.1 | H3: 0.1 | J3: 1 | K3: 28U1703-01-0013 | L3: T700S
A4: T700S | B4: 1000 | C4: 波长示值误差与重复性校验 | D4: 1002 | E4: 氘灯 | F4: 486 | G4: 0.1 | H4: 0.1 | J4: 2 | K4: 28U1703-01-0014 | L4: T700S
A5: T700S | B5: 1000 | C5: 波长示值误差与重复性校验 | D5: 1003 | E5: 镨钕滤光片 | F5: 807.4 | G5: 0.3 | H5: 0.1
A6: T700S | B6: 1000 | C6: 波长示值误差与重复性校验 | D6: 1004 | E6: 汞灯 | F6: 546.1 | G6: 0.3 | H6: 0.1
A7: T700S | B7: 1000 | C7: 波长示值误差与重复性校验 | D7: 1005 | E7: 汞灯 | F7: 435.8 | G7: 0.3 | H7: 0.1
A8: T700S | B8: 1000 | C8: 波长示值误差与重复性校验 | D8: 1006 | E8: 汞灯 | F8: 365 | G8: 0.3 | H8: 0.1
A9: T700S | B9: 1000 | C9: 波长示值误差与重复性校验 | D9: 1007 | E9: 汞灯 | F9: 253.7 | G9: 0.3 | H9: 0.1
A10: T700S | B10: 1000 | C10: 波长示值误差与重复性校验 | D10: 1008 | E10: 钬溶液 | F10: 640.79 | G10: 0.3 | H10: 0.1
A11: T700S | B11: 1000 | C11: 波长示值误差与重复性校验 | D11: 1009 | E11: 钬溶液 | F11: 536.86 | G11: 0.3 | H11: 0.1
A12: T700S | B12: 1000 | C12: 波长示值误差与重复性校验 | D12: 1010 | E12: 钬溶液 | F12: 416.57 | G12: 0.3 | H12: 0.1
A13: T700S | B13: 1000 | C13: 波长示值误差与重复性校验 | D13: 1011 | E13: 钬溶液 | F13: 361.12 | G13: 0.3 | H13: 0.1
A14: T700S | B14: 1000 | C14: 波长示值误差与重复性校验 | D14: 1012 | E14: 钬溶液 | F14: 287.52 | G14: 0.3 | H14: 0.1
A15: T700S | B15: 1000 | C15: 波长示值误差与重复性校验 | D15: 1013 | E15: 钬溶液 | F15: 241.12 | G15: 0.3 | H15: 0.1
A16: T700S | B16: 2000 | C16: 透射比示值误差与重复性校验 | D16: 2001 | E16: 紫外分光光度计标准物质GBW(E)130066 | F16: 350nm | G16: 0.3 | H16: 0.1
... A28: T700S | B28: 2000 | C28: 透射比示值误差与重复性校验 | D28: 2013 | E28: 30%中性滤光片 | F28: 440nm | G28: 0.3 | H28: 0.1
A29: T700S | B29: 3000 | C29: 杂散光校验 | D29: 3001 | E29: 碘化钠标准溶液 | F29: 220nm | G29: 0.01
A30: T700S | B30: 3000 | C30: 杂散光校验 | D30: 3002 | E30: 亚硝酸钠标准溶液 | F30: 360nm | G30: 0.02
A31: T700S | B31: 4000 | C31: 基线平直度检验 | D31: 4001 | E31: 基线平直度 | G31: 0.0005
A32: T700S | B32: 5000 | C32: 基线暗噪声检验 | D32: 5001 | E32: 基线暗噪声 | G32: 0.1
A33: T700S | B33: 6000 | C33: 光谱带宽与仪器最小光谱带宽 | D33: 6001 | E33: 氘灯5.0 | F33: 656.1 | G33: 20
A34: T700S | B34: 6000 | C34: 光谱带宽与仪器最小光谱带宽 | D34: 6002 | E34: 氘灯2.0 | F34: 656.1 | G34: 20
A35: T700S | B35: 6000 | C35: 光谱带宽与仪器最小光谱带宽 | D35: 6003 | E35: 氘灯1.0 | F35: 656.1 | G35: 20
A36: T700S | B36: 6000 | C36: 光谱带宽与仪器最小光谱带宽 | D36: 6004 | E36: 氘灯0.5 | F36: 656.1 | G36: 20
A37: T700S | B37: 6000 | C37: 光谱带宽与仪器最小光谱带宽 | D37: 6005 | E37: 氘灯0.2 | F37: 656.1 | G37: 20
A38: T700S | B38: 7000 | C38: 噪声检验 | D38: 7001 | E38: 500nm100%噪声 | F38: 500 | G38: 0.05
A39: T700S | B39: 7000 | C39: 噪声检验 | D39: 7002 | E39: 500nm0%噪声 | F39: 500 | G39: 0.005
A40: T700S | B40: 7000 | C40: 噪声检验 | D40: 7003 | E40: 250nm100%噪声 | F40: 250 | G40: 0.05
A41: T700S | B41: 7000 | C41: 噪声检验 | D41: 7004 | E41: 250nm0%噪声 | F41: 250 | G41: 0.005
A42: T700S | B42: 8000 | C42: 波长边缘噪声 | D42: 8001 | E42: 1090nm100%噪声 | F42: 1090 | G42: 0.1
A43: T700S | B43: 8000 | C43: 波长边缘噪声 | D43: 8002 | E43: 1090nm0%噪声 | F43: 1090 | G43: 0.02
A44: T700S | B44: 8000 | C44: 波长边缘噪声 | D44: 8003 | E44: 200nm100%噪声 | F44: 200 | G44: 0.1
A45: T700S | B45: 8000 | C45: 波长边缘噪声 | D45: 8004 | E45: 200nm0%噪声 | F45: 200 | G45: 0.02
A46: T700S | B46: 9000 | C46: 漂移检验 | D46: 9001 | E46: 漂移检验 | F46: 500nm | G46: 0.1

Sheet 对应信息
A1: 产品编号 | B1: 产品型号 | D1: 父项目名称 | E1: 父项目编号
A2: U1601 | B2: T600B | D2: 波长示值误差与重复性校验 | E2: 1000
A3: U1602 | B3: T600A | D3: 透射比示值误差与重复性校验 | E3: 2000
A4: U1603 | B4: T600S | D4: 杂散光校验 | E4: 3000
A5: U1604 | B5: T600AS | D5: 基线平直度检验 | E5: 4000
A6: U1701 | B6: T700B | D6: 基线暗噪声检验 | E6: 5000
A7: U1702 | B7: T700A | D7: 光谱带宽与仪器最小光谱带宽 | E7: 6000
A8: U1703 | B8: T700S | D8: 噪声检验 | E8: 7000
A9: U1704 | B9: T700AS | D9: 波长边缘噪声 | E9: 8000
D10: 漂移检验 | E10: 9000

Sheet 检测项信息
A1: 检测类别 | B1: 项目名称 | C1: 提示 | D1: 方法信息 | E1: 测量信息 | F1: 重复次数 | G1: 重复时间间隔 | H1: 特征值 | I1: 分析方法 | J1: 分析方法 | K1: 灯状态 | L1: 光度模式 | M1: 扫描速度 | N1: 起始波长 | O1: 终止波长 | P1: 扫描间隔 | Q1: 增益 | R1: 光谱带宽 | S1: 时间间隔 | T1: 扫描个数 | U1: 响应时间 | V1: 是否为光谱扫描 | W1: 暗电流物质 | X1: 校零物质 | Y1: 测量物质 | Z1: 父项目编号 | AA1: 子项目编号
A2: 波长示值误差与重复性校验 | B2: 氘灯(656.1) | D2: =IF(L2="","",字段对应!$B$10&"="&VLOOKUP(L2,基础信息!$I$2:$J$6,2,0)&";")&IF(M2="","",字段对应!$B$11&"="&VLOOKUP(M2,基础信息!$K$2:$L$6,2,0)&";")&IF(N2="","",字段对应!$C$2&"="&N2&","&O2&","&P2&";")&IF(Q2="","",字段对应!$B$13&"="&Q2&";")&IF(R2="","",字段对应!$B$14&"="&R2&";")&IF(U2="","",字段对应!$B$22&"="&U2&";")&IF(K2="","",字段对应!$B$21&"="&VLOOKUP(K2,基础信息!$F$2:$G$4,2,0)) -> PhotoMode=2;ScanSpeed=2;WlRange=660,650,0.1;Gain=4;Slit1=2.0;LampPos=1 | E2: =IF(W2="","",检测项信息!W2&":"&字段对应!$B$16&"|")&IF(X2="","",X2&":"&IF(V2="是",字段对应!$C$17,字段对应!$B$17&";"&IF(H2="","",字段对应!$B$15&"="&检测项信息!H2))&"|")&IF(Y2="",":",Y2&":")&IF(V2="是",字段对应!$C$18,字段对应!$B$18&";"&IF(H2="","",字段对应!$B$15&"="&检测项信息!H2)&IF(AND(T2="",S2=""),"",";"&字段对应!$B$20&"="&T2&";"&字段对应!$B$19&"="&S2)) -> 空气:Scan | F2: 3 | G2: 1 | H2: 656.1 | I2: =VLOOKUP(J2,字段对应!$D$2:$E$8,2,0) -> Validation.ViewModel.DataStructure.FindPeakAndAverageUVTestTool | J2: 寻峰 | K2: 氘灯 | L2: Es | M2: 中速 | N2: 660 | O2: 650 | P2: 0.1 | Q2: 4 | R2: 2.0 | V2: 是 | Y2: 空气 | Z2: =VLOOKUP(A2,对应信息!$D$2:$E$10,2,0) -> 1000 | AA2: 1001
A3: 波长示值误差与重复性校验 | B3: 氘灯(486.0) | D3: =IF(L3="","",字段对应!$B$10&"="&VLOOKUP(L3,基础信息!$I$2:$J$6,2,0)&";")&IF(M3="","",字段对应!$B$11&"="&VLOOKUP(M3,基础信息!$K$2:$L$6,2,0)&";")&IF(N3="","",字段对应!$C$2&"="&N3&","&O3&","&P3&";")&IF(Q3="","",字段对应!$B$13&"="&Q3&";")&IF(R3="","",字段对应!$B$14&"="&R3&";")&IF(U3="","",字段对应!$B$22&"="&U3&";")&IF(K3="","",字段对应!$B$21&"="&VLOOKUP(K3,基础信息!$F$2:$G$4,2,0)) -> PhotoMode=2;ScanSpeed=2;WlRange=490,480,0.1;Gain=4;Slit1=2.0;LampPos=1 | E3: =IF(W3="","",检测项信息!W3&":"&字段对应!$B$16&"|")&IF(X3="","",X3&":"&IF(V3="是",字段对应!$C$17,字段对应!$B$17&";"&IF(H3="","",字段对应!$B$15&"="&检测项信息!H3))&"|")&IF(Y3="",":",Y3&":")&IF(V3="是",字段对应!$C$18,字段对应!$B$18&";"&IF(H3="","",字段对应!$B$15&"="&检测项信息!H3)&IF(AND(T3="",S3=""),"",";"&字段对应!$B$20&"="&T3&";"&字段对应!$B$19&"="&S3)) -> 空气:Scan | F3: 3 | G3: 1 | H3: 486 | I3: =VLOOKUP(J3,字段对应!$D$2:$E$8,2,0) -> Validation.ViewModel.DataStructure.FindPeakAndAverageUVTestTool | J3: 寻峰 | K3: 氘灯 | L3: Es | M3: 中速 | N3: 490 | O3: 480 | P3: 0.1 | Q3: 4 | R3: 2.0 | V3: 是 | Y3: 空气 | Z3: =VLOOKUP(A3,对应信息!$D$2:$E$10,2,0) -> 1000 | AA3: =IF(Z2=Z3,AA2+1,Z3+1) -> 1002
A4: 波长示值误差与重复性校验 | B4: 镨钕滤光片 | D4: =IF(L4="","",字段对应!$B$10&"="&VLOOKUP(L4,基础信息!$I$2:$J$6,2,0)&";")&IF(M4="","",字段对应!$B$11&"="&VLOOKUP(M4,基础信息!$K$2:$L$6,2,0)&";")&IF(N4="","",字段对应!$C$2&"="&N4&","&O4&","&P4&";")&IF(Q4="","",字段对应!$B$13&"="&Q4&";")&IF(R4="","",字段对应!$B$14&"="&R4&";")&IF(U4="","",字段对应!$B$22&"="&U4&";")&IF(K4="","",字段对应!$B$21&"="&VLOOKUP(K4,基础信息!$F$2:$G$4,2,0)) -> PhotoMode=0;ScanSpeed=2;WlRange=810,800,0.1;Gain=2;Slit1=2.0;LampPos=0 | E4: =IF(W4="","",检测项信息!W4&":"&字段对应!$B$16&"|")&IF(X4="","",X4&":"&IF(V4="是",字段对应!$C$17,字段对应!$B$17&";"&IF(H4="","",字段对应!$B$15&"="&检测项信息!H4))&"|")&IF(Y4="",":",Y4&":")&IF(V4="是",字段对应!$C$18,字段对应!$B$18&";"&IF(H4="","",字段对应!$B$15&"="&检测项信息!H4)&IF(AND(T4="",S4=""),"",";"&字段对应!$B$20&"="&T4&";"&字段对应!$B$19&"="&S4)) -> 黑挡块:Dark|空气:BaseLine|镨钕滤光片:Scan | F4: 3 | G4: 1 | H4: 807.4 | I4: =VLOOKUP(J4,字段对应!$D$2:$E$8,2,0) -> Validation.ViewModel.DataStructure.FindPeakAndAverageUVTestTool | J4: 寻峰 | K4: 钨灯 | L4: Abs | M4: 中速 | N4: 810 | O4: 800 | P4: 0.1 | Q4: 2 | R4: 2.0 | V4: 是 | W4: 黑挡块 | X4: 空气 | Y4: 镨钕滤光片 | Z4: =VLOOKUP(A4,对应信息!$D$2:$E$10,2,0) -> 1000 | AA4: =IF(Z3=Z4,AA3+1,Z4+1) -> 1003
A5: 波长示值误差与重复性校验 | B5: 钬溶液 | D5: =IF(L5="","",字段对应!$B$10&"="&VLOOKUP(L5,基础信息!$I$2:$J$6,2,0)&";")&IF(M5="","",字段对应!$B$11&"="&VLOOKUP(M5,基础信息!$K$2:$L$6,2,0)&";")&IF(N5="","",字段对应!$C$2&"="&N5&","&O5&","&P5&";")&IF(Q5="","",字段对应!$B$13&"="&Q5&";")&IF(R5="","",字段对应!$B$14&"="&R5&";")&IF(U5="","",字段对应!$B$22&"="&U5&";")&IF(K5="","",字段对应!$B$21&"="&VLOOKUP(K5,基础信息!$F$2:$G$4,2,0)) -> PhotoMode=0;ScanSpeed=2;WlRange=645,235,0.1;Slit1=2.0; | E5: =IF(W5="","",检测项信息!W5&":"&字段对应!$B$16&"|")&IF(X5="","",X5&":"&IF(V5="是",字段对应!$C$17,字段对应!$B$17&";"&IF(H5="","",字段对应!$B$15&"="&检测项信息!H5))&"|")&IF(Y5="",":",Y5&":")&IF(V5="是",字段对应!$C$18,字段对应!$B$18&";"&IF(H5="","",字段对应!$B$15&"="&检测项信息!H5)&IF(AND(T5="",S5=""),"",";"&字段对应!$B$20&"="&T5&";"&字段对应!$B$19&"="&S5)) -> 黑挡块:Dark|空气:BaseLine|钬溶液:Scan | F5: 3 | G5: 1 | H5: 640.79,536.86,416.57,361.12,287.52,241.12 | I5: =VLOOKUP(J5,字段对应!$D$2:$E$8,2,0) -> Validation.ViewModel.DataStructure.FindPeakAndAverageUVTestTool | J5: 寻峰 | L5: Abs | M5: 中速 | N5: 645 | O5: 235 | P5: 0.1 | R5: 2.0 | V5: 是 | W5: 黑挡块 | X5: 空气 | Y5: 钬溶液 | Z5: =VLOOKUP(A5,对应信息!$D$2:$E$10,2,0) -> 1000 | AA5: =IF(Z4=Z5,AA4+1,Z5+1) -> 1004
A6: 波长示值误差与重复性校验 | B6: 汞灯 | D6: =IF(L6="","",字段对应!$B$10&"="&VLOOKUP(L6,基础信息!$I$2:$J$6,2,0)&";")&IF(M6="","",字段对应!$B$11&"="&VLOOKUP(M6,基础信息!$K$2:$L$6,2,0)&";")&IF(N6="","",字段对应!$C$2&"="&N6&","&O6&","&P6&";")&IF(Q6="","",字段对应!$B$13&"="&Q6&";")&IF(R6="","",字段对应!$B$14&"="&R6&";")&IF(U6="","",字段对应!$B$22&"="&U6&";")&IF(K6="","",字段对应!$B$21&"="&VLOOKUP(K6,基础信息!$F$2:$G$4,2,0)) -> PhotoMode=2;ScanSpeed=2;WlRange=550,300,0.1;Gain=4;Slit1=2.0;LampPos=2 | E6: =IF(W6="","",检测项信息!W6&":"&字段对应!$B$16&"|")&IF(X6="","",X6&":"&IF(V6="是",字段对应!$C$17,字段对应!$B$17&";"&IF(H6="","",字段对应!$B$15&"="&检测项信息!H6))&"|")&IF(Y6="",":",Y6&":")&IF(V6="是",字段对应!$C$18,字段对应!$B$18&";"&IF(H6="","",字段对应!$B$15&"="&检测项信息!H6)&IF(AND(T6="",S6=""),"",";"&字段对应!$B$20&"="&T6&";"&字段对应!$B$19&"="&S6)) -> 黑挡块:Dark|汞灯:BaseLine|空气:Scan | F6: 3 | G6: 1 | H6: 365.0,435.8,546.1 | I6: =VLOOKUP(J6,字段对应!$D$2:$E$8,2,0) -> Validation.ViewModel.DataStructure.FindPeakAndAverageUVTestTool | J6: 寻峰 | K6: 汞灯 | L6: Es | M6: 中速 | N6: 550 | O6: 300 | P6: 0.1 | Q6: 4 | R6: 2.0 | V6: 是 | W6: 黑挡块 | X6: 汞灯 | Y6: 空气 | Z6: =VLOOKUP(A6,对应信息!$D$2:$E$10,2,0) -> 1000 | AA6: =IF(Z5=Z6,AA5+1,Z6+1) -> 1005
A7: 波长示值误差与重复性校验 | B7: 汞灯(253.7) | D7: =IF(L7="","",字段对应!$B$10&"="&VLOOKUP(L7,基础信息!$I$2:$J$6,2,0)&";")&IF(M7="","",字段对应!$B$11&"="&VLOOKUP(M7,基础信息!$K$2:$L$6,2,0)&";")&IF(N7="","",字段对应!$C$2&"="&N7&","&O7&","&P7&";")&IF(Q7="","",字段对应!$B$13&"="&Q7&";")&IF(R7="","",字段对应!$B$14&"="&R7&";")&IF(U7="","",字段对应!$B$22&"="&U7&";")&IF(K7="","",字段对应!$B$21&"="&VLOOKUP(K7,基础信息!$F$2:$G$4,2,0)) -> PhotoMode=2;ScanSpeed=2;WlRange=300,250,0.1;Gain=4;Slit1=2.0;LampPos=2 | E7: =IF(W7="","",检测项信息!W7&":"&字段对应!$B$16&"|")&IF(X7="","",X7&":"&IF(V7="是",字段对应!$C$17,字段对应!$B$17&";"&IF(H7="","",字段对应!$B$15&"="&检测项信息!H7))&"|")&IF(Y7="",":",Y7&":")&IF(V7="是",字段对应!$C$18,字段对应!$B$18&";"&IF(H7="","",字段对应!$B$15&"="&检测项信息!H7)&IF(AND(T7="",S7=""),"",";"&字段对应!$B$20&"="&T7&";"&字段对应!$B$19&"="&S7)) -> 黑挡块:Dark|汞灯:BaseLine|空气:Scan | F7: 3 | G7: 1 | H7: 253.7 | I7: =VLOOKUP(J7,字段对应!$D$2:$E$8,2,0) -> Validation.ViewModel.DataStructure.FindPeakAndAverageUVTestTool | J7: 寻峰 | K7: 汞灯 | L7: Es | M7: 中速 | N7: 300 | O7: 250 | P7: 0.1 | Q7: 4 | R7: 2.0 | V7: 是 | W7: 黑挡块 | X7: 汞灯 | Y7: 空气 | Z7: =VLOOKUP(A7,对应信息!$D$2:$E$10,2,0) -> 1000 | AA7: =IF(Z6=Z7,AA6+1,Z7+1) -> 1006
A8: 光谱带宽与仪器最小光谱带宽 | B8: 氘灯5.0 | D8: =IF(L8="","",字段对应!$B$10&"="&VLOOKUP(L8,基础信息!$I$2:$J$6,2,0)&";")&IF(M8="","",字段对应!$B$11&"="&VLOOKUP(M8,基础信息!$K$2:$L$6,2,0)&";")&IF(N8="","",字段对应!$C$2&"="&N8&","&O8&","&P8&";")&IF(Q8="","",字段对应!$B$13&"="&Q8&";")&IF(R8="","",字段对应!$B$14&"="&R8&";")&IF(U8="","",字段对应!$B$22&"="&U8&";")&IF(K8="","",字段对应!$B$21&"="&VLOOKUP(K8,基础信息!$F$2:$G$4,2,0)) -> PhotoMode=2;ScanSpeed=2;WlRange=662,650,0.1;Gain=4;Slit1=5.0;LampPos=1 | E8: =IF(W8="","",检测项信息!W8&":"&字段对应!$B$16&"|")&IF(X8="","",X8&":"&IF(V8="是",字段对应!$C$17,字段对应!$B$17&";"&IF(H8="","",字段对应!$B$15&"="&检测项信息!H8))&"|")&IF(Y8="",":",Y8&":")&IF(V8="是",字段对应!$C$18,字段对应!$B$18&";"&IF(H8="","",字段对应!$B$15&"="&检测项信息!H8)&IF(AND(T8="",S8=""),"",";"&字段对应!$B$20&"="&T8&";"&字段对应!$B$19&"="&S8)) -> 氘灯5.0:Dark|空气:Scan | F8: 1 | H8: 656.1 | I8: =VLOOKUP(J8,字段对应!$D$2:$E$8,2,0) -> Validation.ViewModel.DataStructure.FindHalfPeakUVTestTool | J8: 求半峰宽 | K8: 氘灯 | L8: Es | M8: 中速 | N8: 662 | O8: 650 | P8: 0.1 | Q8: 4 | R8: 5.0 | V8: 是 | W8: 氘灯5.0 | Y8: 空气 | Z8: =VLOOKUP(A8,对应信息!$D$2:$E$10,2,0) -> 6000 | AA8: =IF(Z6=Z8,AA6+1,Z8+1) -> 6001
A9: 光谱带宽与仪器最小光谱带宽 | B9: 氘灯2.0 | D9: =IF(L9="","",字段对应!$B$10&"="&VLOOKUP(L9,基础信息!$I$2:$J$6,2,0)&";")&IF(M9="","",字段对应!$B$11&"="&VLOOKUP(M9,基础信息!$K$2:$L$6,2,0)&";")&IF(N9="","",字段对应!$C$2&"="&N9&","&O9&","&P9&";")&IF(Q9="","",字段对应!$B$13&"="&Q9&";")&IF(R9="","",字段对应!$B$14&"="&R9&";")&IF(U9="","",字段对应!$B$22&"="&U9&";")&IF(K9="","",字段对应!$B$21&"="&VLOOKUP(K9,基础信息!$F$2:$G$4,2,0)) -> PhotoMode=2;ScanSpeed=2;WlRange=660,650,0.1;Gain=4;Slit1=2.0;LampPos=1 | E9: =IF(W9="","",检测项信息!W9&":"&字段对应!$B$16&"|")&IF(X9="","",X9&":"&IF(V9="是",字段对应!$C$17,字段对应!$B$17&";"&IF(H9="","",字段对应!$B$15&"="&检测项信息!H9))&"|")&IF(Y9="",":",Y9&":")&IF(V9="是",字段对应!$C$18,字段对应!$B$18&";"&IF(H9="","",字段对应!$B$15&"="&检测项信息!H9)&IF(AND(T9="",S9=""),"",";"&字段对应!$B$20&"="&T9&";"&字段对应!$B$19&"="&S9)) -> 空气:Scan | F9: 1 | H9: 656.1 | I9: =VLOOKUP(J9,字段对应!$D$2:$E$8,2,0) -> Validation.ViewModel.DataStructure.FindHalfPeakUVTestTool | J9: 求半峰宽 | K9: 氘灯 | L9: Es | M9: 中速 | N9: 660 | O9: 650 | P9: 0.1 | Q9: 4 | R9: 2.0 | V9: 是 | Y9: 空气 | Z9: =VLOOKUP(A9,对应信息!$D$2:$E$10,2,0) -> 6000 | AA9: =IF(Z8=Z9,AA8+1,Z9+1) -> 6002
A10: 光谱带宽与仪器最小光谱带宽 | B10: 氘灯1.0 | D10: =IF(L10="","",字段对应!$B$10&"="&VLOOKUP(L10,基础信息!$I$2:$J$6,2,0)&";")&IF(M10="","",字段对应!$B$11&"="&VLOOKUP(M10,基础信息!$K$2:$L$6,2,0)&";")&IF(N10="","",字段对应!$C$2&"="&N10&","&O10&","&P10&";")&IF(Q10="","",字段对应!$B$13&"="&Q10&";")&IF(R10="","",字段对应!$B$14&"="&R10&";")&IF(U10="","",字段对应!$B$22&"="&U10&";")&IF(K10="","",字段对应!$B$21&"="&VLOOKUP(K10,基础信息!$F$2:$G$4,2,0)) -> PhotoMode=2;ScanSpeed=2;WlRange=660,650,0.1;Gain=4;Slit1=1.0;LampPos=1 | E10: =IF(W10="","",检测项信息!W10&":"&字段对应!$B$16&"|")&IF(X10="","",X10&":"&IF(V10="是",字段对应!$C$17,字段对应!$B$17&";"&IF(H10="","",字段对应!$B$15&"="&检测项信息!H10))&"|")&IF(Y10="",":",Y10&":")&IF(V10="是",字段对应!$C$18,字段对应!$B$18&";"&IF(H10="","",字段对应!$B$15&"="&检测项信息!H10)&IF(AND(T10="",S10=""),"",";"&字段对应!$B$20&"="&T10&";"&字段对应!$B$19&"="&S10)) -> 氘灯1.0:Dark|空气:Scan | F10: 1 | H10: 656.1 | I10: =VLOOKUP(J10,字段对应!$D$2:$E$8,2,0) -> Validation.ViewModel.DataStructure.FindHalfPeakUVTestTool | J10: 求半峰宽 | K10: 氘灯 | L10: Es | M10: 中速 | N10: 660 | O10: 650 | P10: 0.1 | Q10: 4 | R10: 1.0 | V10: 是 | W10: 氘灯1.0 | Y10: 空气 | Z10: =VLOOKUP(A10,对应信息!$D$2:$E$10,2,0) -> 6000 | AA10: =IF(Z9=Z10,AA9+1,Z10+1) -> 6003
A11: 光谱带宽与仪器最小光谱带宽 | B11: 氘灯0.5 | D11: =IF(L11="","",字段对应!$B$10&"="&VLOOKUP(L11,基础信息!$I$2:$J$6,2,0)&";")&IF(M11="","",字段对应!$B$11&"="&VLOOKUP(M11,基础信息!$K$2:$L$6,2,0)&";")&IF(N11="","",字段对应!$C$2&"="&N11&","&O11&","&P11&";")&IF(Q11="","",字段对应!$B$13&"="&Q11&";")&IF(R11="","",字段对应!$B$14&"="&R11&";")&IF(U11="","",字段对应!$B$22&"="&U11&";")&IF(K11="","",字段对应!$B$21&"="&VLOOKUP(K11,基础信息!$F$2:$G$4,2,0)) -> PhotoMode=2;ScanSpeed=2;WlRange=660,650,0.1;Gain=4;Slit1=0.5;LampPos=1 | E11: =IF(W11="","",检测项信息!W11&":"&字段对应!$B$16&"|")&IF(X11="","",X11&":"&IF(V11="是",字段对应!$C$17,字段对应!$B$17&";"&IF(H11="","",字段对应!$B$15&"="&检测项信息!H11))&"|")&IF(Y11="",":",Y11&":")&IF(V11="是",字段对应!$C$18,字段对应!$B$18&";"&IF(H11="","",字段对应!$B$15&"="&检测项信息!H11)&IF(AND(T11="",S11=""),"",";"&字段对应!$B$20&"="&T11&";"&字段对应!$B$19&"="&S11)) -> 氘灯0.5:Dark|空气:Scan | F11: 1 | H11: 656.1 | I11: =VLOOKUP(J11,字段对应!$D$2:$E$8,2,0) -> Validation.ViewModel.DataStructure.FindHalfPeakUVTestTool | J11: 求半峰宽 | K11: 氘灯 | L11: Es | M11: 中速 | N11: 660 | O11: 650 | P11: 0.1 | Q11: 4 | R11: 0.5 | V11: 是 | W11: 氘灯0.5 | Y11: 空气 | Z11: =VLOOKUP(A11,对应信息!$D$2:$E$10,2,0) -> 6000 | AA11: =IF(Z10=Z11,AA10+1,Z11+1) -> 6004
A12: 光谱带宽与仪器最小光谱带宽 | B12: 氘灯0.2 | D12: =IF(L12="","",字段对应!$B$10&"="&VLOOKUP(L12,基础信息!$I$2:$J$6,2,0)&";")&IF(M12="","",字段对应!$B$11&"="&VLOOKUP(M12,基础信息!$K$2:$L$6,2,0)&";")&IF(N12="","",字段对应!$C$2&"="&N12&","&O12&","&P12&";")&IF(Q12="","",字段对应!$B$13&"="&Q12&";")&IF(R12="","",字段对应!$B$14&"="&R12&";")&IF(U12="","",字段对应!$B$22&"="&U12&";")&IF(K12="","",字段对应!$B$21&"="&VLOOKUP(K12,基础信息!$F$2:$G$4,2,0)) -> PhotoMode=2;ScanSpeed=2;WlRange=660,650,0.1;Gain=4;Slit1=0.2;LampPos=1 | E12: =IF(W12="","",检测项信息!W12&":"&字段对应!$B$16&"|")&IF(X12="","",X12&":"&IF(V12="是",字段对应!$C$17,字段对应!$B$17&";"&IF(H12="","",字段对应!$B$15&"="&检测项信息!H12))&"|")&IF(Y12="",":",Y12&":")&IF(V12="是",字段对应!$C$18,字段对应!$B$18&";"&IF(H12="","",字段对应!$B$15&"="&检测项信息!H12)&IF(AND(T12="",S12=""),"",";"&字段对应!$B$20&"="&T12&";"&字段对应!$B$19&"="&S12)) -> 氘灯0.2:Dark|空气:Scan | F12: 1 | H12: 656.1 | I12: =VLOOKUP(J12,字段对应!$D$2:$E$8,2,0) -> Validation.ViewModel.DataStructure.FindHalfPeakUVTestTool | J12: 求半峰宽 | K12: 氘灯 | L12: Es | M12: 中速 | N12: 660 | O12: 650 | P12: 0.1 | Q12: 4 | R12: 0.2 | V12: 是 | W12: 氘灯0.2 | Y12: 空气 | Z12: =VLOOKUP(A12,对应信息!$D$2:$E$10,2,0) -> 6000 | AA12: =IF(Z11=Z12,AA11+1,Z12+1) -> 6005
A13: 基线平直度检验 | B13: 基线平直度 | D13: =IF(L13="","",字段对应!$B$10&"="&VLOOKUP(L13,基础信息!$I$2:$J$6,2,0)&";")&IF(M13="","",字段对应!$B$11&"="&VLOOKUP(M13,基础信息!$K$2:$L$6,2,0)&";")&IF(N13="","",字段对应!$C$2&"="&N13&","&O13&","&P13&";")&IF(Q13="","",字段对应!$B$13&"="&Q13&";")&IF(R13="","",字段对应!$B$14&"="&R13&";")&IF(U13="","",字段对应!$B$22&"="&U13&";")&IF(K13="","",字段对应!$B$21&"="&VLOOKUP(K13,基础信息!$F$2:$G$4,2,0)) -> PhotoMode=0;ScanSpeed=2;WlRange=1090,200,1;Slit1=2.0; | E13: =IF(W13="","",检测项信息!W13&":"&字段对应!$B$16&"|")&IF(X13="","",X13&":"&IF(V13="是",字段对应!$C$17,字段对应!$B$17&";"&IF(H13="","",字段对应!$B$15&"="&检测项信息!H13))&"|")&IF(Y13="",":",Y13&":")&IF(V13="是",字段对应!$C$18,字段对应!$B$18&";"&IF(H13="","",字段对应!$B$15&"="&检测项信息!H13)&IF(AND(T13="",S13=""),"",";"&字段对应!$B$20&"="&T13&";"&字段对应!$B$19&"="&S13)) -> 黑挡块:Dark|空气:BaseLine|空气:Scan | F13: 1 | I13: =VLOOKUP(J13,字段对应!$D$2:$E$8,2,0) -> Validation.ViewModel.DataStructure.GetMaxDIstanceUVTestTool | J13: 求最大偏移量 | L13: Abs | M13: 中速 | N13: 1090 | O13: 200 | P13: 1 | R13: 2.0 | V13: 是 | W13: 黑挡块 | X13: 空气 | Y13: 空气 | Z13: =VLOOKUP(A13,对应信息!$D$2:$E$10,2,0) -> 4000 | AA13: =IF(Z12=Z13,AA12+1,Z13+1) -> 4001
A14: 基线暗噪声检验 | B14: 基线暗噪声 | D14: =IF(L14="","",字段对应!$B$10&"="&VLOOKUP(L14,基础信息!$I$2:$J$6,2,0)&";")&IF(M14="","",字段对应!$B$11&"="&VLOOKUP(M14,基础信息!$K$2:$L$6,2,0)&";")&IF(N14="","",字段对应!$C$2&"="&N14&","&O14&","&P14&";")&IF(Q14="","",字段对应!$B$13&"="&Q14&";")&IF(R14="","",字段对应!$B$14&"="&R14&";")&IF(U14="","",字段对应!$B$22&"="&U14&";")&IF(K14="","",字段对应!$B$21&"="&VLOOKUP(K14,基础信息!$F$2:$G$4,2,0)) -> PhotoMode=1;ScanSpeed=2;WlRange=1090,190,1; | E14: =IF(W14="","",检测项信息!W14&":"&字段对应!$B$16&"|")&IF(X14="","",X14&":"&IF(V14="是",字段对应!$C$17,字段对应!$B$17&";"&IF(H14="","",字段对应!$B$15&"="&检测项信息!H14))&"|")&IF(Y14="",":",Y14&":")&IF(V14="是",字段对应!$C$18,字段对应!$B$18&";"&IF(H14="","",字段对应!$B$15&"="&检测项信息!H14)&IF(AND(T14="",S14=""),"",";"&字段对应!$B$20&"="&T14&";"&字段对应!$B$19&"="&S14)) -> 黑挡块:Dark|空气:BaseLine|黑挡块:Scan | F14: 1 | I14: =VLOOKUP(J14,字段对应!$D$2:$E$8,2,0) -> Validation.ViewModel.DataStructure.GetMaxDIstanceUVTestTool | J14: 求最大偏移量 | L14: T% | M14: 中速 | N14: 1090 | O14: 190 | P14: 1 | V14: 是 | W14: 黑挡块 | X14: 空气 | Y14: 黑挡块 | Z14: =VLOOKUP(A14,对应信息!$D$2:$E$10,2,0) -> 5000 | AA14: =IF(Z13=Z14,AA13+1,Z14+1) -> 5001
A15: 噪声检验 | B15: 500nm100%噪声 | D15: =IF(L15="","",字段对应!$B$10&"="&VLOOKUP(L15,基础信息!$I$2:$J$6,2,0)&";")&IF(M15="","",字段对应!$B$11&"="&VLOOKUP(M15,基础信息!$K$2:$L$6,2,0)&";")&IF(N15="","",字段对应!$C$2&"="&N15&","&O15&","&P15&";")&IF(Q15="","",字段对应!$B$13&"="&Q15&";")&IF(R15="","",字段对应!$B$14&"="&R15&";")&IF(U15="","",字段对应!$B$22&"="&U15&";")&IF(K15="","",字段对应!$B$21&"="&VLOOKUP(K15,基础信息!$F$2:$G$4,2,0)) -> PhotoMode=1;ScanSpeed=2;Slit1=2.0;ResponseTime=0.5; | E15: =IF(W15="","",检测项信息!W15&":"&字段对应!$B$16&"|")&IF(X15="","",X15&":"&IF(V15="是",字段对应!$C$17,字段对应!$B$17&";"&IF(H15="","",字段对应!$B$15&"="&检测项信息!H15))&"|")&IF(Y15="",":",Y15&":")&IF(V15="是",字段对应!$C$18,字段对应!$B$18&";"&IF(H15="","",字段对应!$B$15&"="&检测项信息!H15)&IF(AND(T15="",S15=""),"",";"&字段对应!$B$20&"="&T15&";"&字段对应!$B$19&"="&S15)) -> 黑挡块:Dark|空气:Zero;Wl=500|空气:Measure;Wl=500;totalcount=120;timeinterval=1 | F15: 1 | H15: 500 | I15: =VLOOKUP(J15,字段对应!$D$2:$E$8,2,0) -> Validation.ViewModel.DataStructure.FindMaxOffsetUVTestTool | J15: 最大最小值差 | L15: T% | M15: 中速 | R15: 2.0 | S15: 1 | T15: 120 | U15: 0.5 | V15: 否 | W15: 黑挡块 | X15: 空气 | Y15: 空气 | Z15: =VLOOKUP(A15,对应信息!$D$2:$E$10,2,0) -> 7000 | AA15: =IF(Z14=Z15,AA14+1,Z15+1) -> 7001
A16: 噪声检验 | B16: 500nm0%噪声 | D16: =IF(L16="","",字段对应!$B$10&"="&VLOOKUP(L16,基础信息!$I$2:$J$6,2,0)&";")&IF(M16="","",字段对应!$B$11&"="&VLOOKUP(M16,基础信息!$K$2:$L$6,2,0)&";")&IF(N16="","",字段对应!$C$2&"="&N16&","&O16&","&P16&";")&IF(Q16="","",字段对应!$B$13&"="&Q16&";")&IF(R16="","",字段对应!$B$14&"="&R16&";")&IF(U16="","",字段对应!$B$22&"="&U16&";")&IF(K16="","",字段对应!$B$21&"="&VLOOKUP(K16,基础信息!$F$2:$G$4,2,0)) -> PhotoMode=1;ScanSpeed=2;Slit1=2.0;ResponseTime=0.5; | E16: =IF(W16="","",检测项信息!W16&":"&字段对应!$B$16&"|")&IF(X16="","",X16&":"&IF(V16="是",字段对应!$C$17,字段对应!$B$17&";"&IF(H16="","",字段对应!$B$15&"="&检测项信息!H16))&"|")&IF(Y16="",":",Y16&":")&IF(V16="是",字段对应!$C$18,字段对应!$B$18&";"&IF(H16="","",字段对应!$B$15&"="&检测项信息!H16)&IF(AND(T16="",S16=""),"",";"&字段对应!$B$20&"="&T16&";"&字段对应!$B$19&"="&S16)) -> 黑挡块:Dark|空气:Zero;Wl=500|黑挡块:Measure;Wl=500;totalcount=120;timeinterval=1 | F16: 1 | H16: 500 | I16: =VLOOKUP(J16,字段对应!$D$2:$E$8,2,0) -> Validation.ViewModel.DataStructure.FindMaxOffsetUVTestTool | J16: 最大最小值差 | L16: T% | M16: 中速 | R16: 2.0 | S16: 1 | T16: 120 | U16: 0.5 | V16: 否 | W16: 黑挡块 | X16: 空气 | Y16: 黑挡块 | Z16: =VLOOKUP(A16,对应信息!$D$2:$E$10,2,0) -> 7000 | AA16: =IF(Z15=Z16,AA15+1,Z16+1) -> 7002
A17: 噪声检验 | B17: 250nm100%噪声 | D17: =IF(L17="","",字段对应!$B$10&"="&VLOOKUP(L17,基础信息!$I$2:$J$6,2,0)&";")&IF(M17="","",字段对应!$B$11&"="&VLOOKUP(M17,基础信息!$K$2:$L$6,2,0)&";")&IF(N17="","",字段对应!$C$2&"="&N17&","&O17&","&P17&";")&IF(Q17="","",字段对应!$B$13&"="&Q17&";")&IF(R17="","",字段对应!$B$14&"="&R17&";")&IF(U17="","",字段对应!$B$22&"="&U17&";")&IF(K17="","",字段对应!$B$21&"="&VLOOKUP(K17,基础信息!$F$2:$G$4,2,0)) -> PhotoMode=1;ScanSpeed=2;Slit1=2.0;ResponseTime=0.5; | E17: =IF(W17="","",检测项信息!W17&":"&字段对应!$B$16&"|")&IF(X17="","",X17&":"&IF(V17="是",字段对应!$C$17,字段对应!$B$17&";"&IF(H17="","",字段对应!$B$15&"="&检测项信息!H17))&"|")&IF(Y17="",":",Y17&":")&IF(V17="是",字段对应!$C$18,字段对应!$B$18&";"&IF(H17="","",字段对应!$B$15&"="&检测项信息!H17)&IF(AND(T17="",S17=""),"",";"&字段对应!$B$20&"="&T17&";"&字段对应!$B$19&"="&S17)) -> 黑挡块:Dark|空气:Zero;Wl=250|空气:Measure;Wl=250;totalcount=120;timeinterval=1 | F17: 1 | H17: 250 | I17: =VLOOKUP(J17,字段对应!$D$2:$E$8,2,0) -> Validation.ViewModel.DataStructure.FindMaxOffsetUVTestTool | J17: 最大最小值差 | L17: T% | M17: 中速 | R17: 2.0 | S17: 1 | T17: 120 | U17: 0.5 | V17: 否 | W17: 黑挡块 | X17: 空气 | Y17: 空气 | Z17: =VLOOKUP(A17,对应信息!$D$2:$E$10,2,0) -> 7000 | AA17: =IF(Z16=Z17,AA16+1,Z17+1) -> 7003
A18: 噪声检验 | B18: 250nm0%噪声 | D18: =IF(L18="","",字段对应!$B$10&"="&VLOOKUP(L18,基础信息!$I$2:$J$6,2,0)&";")&IF(M18="","",字段对应!$B$11&"="&VLOOKUP(M18,基础信息!$K$2:$L$6,2,0)&";")&IF(N18="","",字段对应!$C$2&"="&N18&","&O18&","&P18&";")&IF(Q18="","",字段对应!$B$13&"="&Q18&";")&IF(R18="","",字段对应!$B$14&"="&R18&";")&IF(U18="","",字段对应!$B$22&"="&U18&";")&IF(K18="","",字段对应!$B$21&"="&VLOOKUP(K18,基础信息!$F$2:$G$4,2,0)) -> PhotoMode=1;ScanSpeed=2;Slit1=2.0;ResponseTime=0.5; | E18: =IF(W18="","",检测项信息!W18&":"&字段对应!$B$16&"|")&IF(X18="","",X18&":"&IF(V18="是",字段对应!$C$17,字段对应!$B$17&";"&IF(H18="","",字段对应!$B$15&"="&检测项信息!H18))&"|")&IF(Y18="",":",Y18&":")&IF(V18="是",字段对应!$C$18,字段对应!$B$18&";"&IF(H18="","",字段对应!$B$15&"="&检测项信息!H18)&IF(AND(T18="",S18=""),"",";"&字段对应!$B$20&"="&T18&";"&字段对应!$B$19&"="&S18)) -> 黑挡块:Dark|空气:Zero;Wl=250|黑挡块:Measure;Wl=250;totalcount=120;timeinterval=1 | F18: 1 | H18: 250 | I18: =VLOOKUP(J18,字段对应!$D$2:$E$8,2,0) -> Validation.ViewModel.DataStructure.FindMaxOffsetUVTestTool | J18: 最大最小值差 | L18: T% | M18: 中速 | R18: 2.0 | S18: 1 | T18: 120 | U18: 0.5 | V18: 否 | W18: 黑挡块 | X18: 空气 | Y18: 黑挡块 | Z18: =VLOOKUP(A18,对应信息!$D$2:$E$10,2,0) -> 7000 | AA18: =IF(Z17=Z18,AA17+1,Z18+1) -> 7004
A19: 波长边缘噪声 | B19: 1090nm100%噪声 | D19: =IF(L19="","",字段对应!$B$10&"="&VLOOKUP(L19,基础信息!$I$2:$J$6,2,0)&";")&IF(M19="","",字段对应!$B$11&"="&VLOOKUP(M19,基础信息!$K$2:$L$6,2,0)&";")&IF(N19="","",字段对应!$C$2&"="&N19&","&O19&","&P19&";")&IF(Q19="","",字段对应!$B$13&"="&Q19&";")&IF(R19="","",字段对应!$B$14&"="&R19&";")&IF(U19="","",字段对应!$B$22&"="&U19&";")&IF(K19="","",字段对应!$B$21&"="&VLOOKUP(K19,基础信息!$F$2:$G$4,2,0)) -> PhotoMode=1;ScanSpeed=2;Slit1=2.0;ResponseTime=0.5; | E19: =IF(W19="","",检测项信息!W19&":"&字段对应!$B$16&"|")&IF(X19="","",X19&":"&IF(V19="是",字段对应!$C$17,字段对应!$B$17&";"&IF(H19="","",字段对应!$B$15&"="&检测项信息!H19))&"|")&IF(Y19="",":",Y19&":")&IF(V19="是",字段对应!$C$18,字段对应!$B$18&";"&IF(H19="","",字段对应!$B$15&"="&检测项信息!H19)&IF(AND(T19="",S19=""),"",";"&字段对应!$B$20&"="&T19&";"&字段对应!$B$19&"="&S19)) -> 黑挡块:Dark|空气:Zero;Wl=1090|空气:Measure;Wl=1090;totalcount=180;timeinterval=1 | F19: 1 | H19: 1090 | I19: =VLOOKUP(J19,字段对应!$D$2:$E$8,2,0) -> Validation.ViewModel.DataStructure.FindMaxOffsetUVTestTool | J19: 最大最小值差 | L19: T% | M19: 中速 | R19: 2.0 | S19: 1 | T19: 180 | U19: 0.5 | V19: 否 | W19: 黑挡块 | X19: 空气 | Y19: 空气 | Z19: =VLOOKUP(A19,对应信息!$D$2:$E$10,2,0) -> 8000 | AA19: =IF(Z18=Z19,AA18+1,Z19+1) -> 8001
A20: 波长边缘噪声 | B20: 1090nm0%噪声 | D20: =IF(L20="","",字段对应!$B$10&"="&VLOOKUP(L20,基础信息!$I$2:$J$6,2,0)&";")&IF(M20="","",字段对应!$B$11&"="&VLOOKUP(M20,基础信息!$K$2:$L$6,2,0)&";")&IF(N20="","",字段对应!$C$2&"="&N20&","&O20&","&P20&";")&IF(Q20="","",字段对应!$B$13&"="&Q20&";")&IF(R20="","",字段对应!$B$14&"="&R20&";")&IF(U20="","",字段对应!$B$22&"="&U20&";")&IF(K20="","",字段对应!$B$21&"="&VLOOKUP(K20,基础信息!$F$2:$G$4,2,0)) -> PhotoMode=1;ScanSpeed=2;Slit1=2.0;ResponseTime=0.5; | E20: =IF(W20="","",检测项信息!W20&":"&字段对应!$B$16&"|")&IF(X20="","",X20&":"&IF(V20="是",字段对应!$C$17,字段对应!$B$17&";"&IF(H20="","",字段对应!$B$15&"="&检测项信息!H20))&"|")&IF(Y20="",":",Y20&":")&IF(V20="是",字段对应!$C$18,字段对应!$B$18&";"&IF(H20="","",字段对应!$B$15&"="&检测项信息!H20)&IF(AND(T20="",S20=""),"",";"&字段对应!$B$20&"="&T20&";"&字段对应!$B$19&"="&S20)) -> 黑挡块:Dark|空气:Zero;Wl=1090|黑挡块:Measure;Wl=1090;totalcount=180;timeinterval=1 | F20: 1 | H20: 1090 | I20: =VLOOKUP(J20,字段对应!$D$2:$E$8,2,0) -> Validation.ViewModel.DataStructure.FindMaxOffsetUVTestTool | J20: 最大最小值差 | L20: T% | M20: 中速 | R20: 2.0 | S20: 1 | T20: 180 | U20: 0.5 | V20: 否 | W20: 黑挡块 | X20: 空气 | Y20: 黑挡块 | Z20: =VLOOKUP(A20,对应信息!$D$2:$E$10,2,0) -> 8000 | AA20: =IF(Z19=Z20,AA19+1,Z20+1) -> 8002
A21: 波长边缘噪声 | B21: 200nm100%噪声 | D21: =IF(L21="","",字段对应!$B$10&"="&VLOOKUP(L21,基础信息!$I$2:$J$6,2,0)&";")&IF(M21="","",字段对应!$B$11&"="&VLOOKUP(M21,基础信息!$K$2:$L$6,2,0)&";")&IF(N21="","",字段对应!$C$2&"="&N21&","&O21&","&P21&";")&IF(Q21="","",字段对应!$B$13&"="&Q21&";")&IF(R21="","",字段对应!$B$14&"="&R21&";")&IF(U21="","",字段对应!$B$22&"="&U21&";")&IF(K21="","",字段对应!$B$21&"="&VLOOKUP(K21,基础信息!$F$2:$G$4,2,0)) -> PhotoMode=1;ScanSpeed=2;Slit1=2.0;ResponseTime=0.5; | E21: =IF(W21="","",检测项信息!W21&":"&字段对应!$B$16&"|")&IF(X21="","",X21&":"&IF(V21="是",字段对应!$C$17,字段对应!$B$17&";"&IF(H21="","",字段对应!$B$15&"="&检测项信息!H21))&"|")&IF(Y21="",":",Y21&":")&IF(V21="是",字段对应!$C$18,字段对应!$B$18&";"&IF(H21="","",字段对应!$B$15&"="&检测项信息!H21)&IF(AND(T21="",S21=""),"",";"&字段对应!$B$20&"="&T21&";"&字段对应!$B$19&"="&S21)) -> 黑挡块:Dark|空气:Zero;Wl=200|空气:Measure;Wl=200;totalcount=180;timeinterval=1 | F21: 1 | H21: 200 | I21: =VLOOKUP(J21,字段对应!$D$2:$E$8,2,0) -> Validation.ViewModel.DataStructure.FindMaxOffsetUVTestTool | J21: 最大最小值差 | L21: T% | M21: 中速 | R21: 2.0 | S21: 1 | T21: 180 | U21: 0.5 | V21: 否 | W21: 黑挡块 | X21: 空气 | Y21: 空气 | Z21: =VLOOKUP(A21,对应信息!$D$2:$E$10,2,0) -> 8000 | AA21: =IF(Z20=Z21,AA20+1,Z21+1) -> 8003
A22: 波长边缘噪声 | B22: 200nm0%噪声 | D22: =IF(L22="","",字段对应!$B$10&"="&VLOOKUP(L22,基础信息!$I$2:$J$6,2,0)&";")&IF(M22="","",字段对应!$B$11&"="&VLOOKUP(M22,基础信息!$K$2:$L$6,2,0)&";")&IF(N22="","",字段对应!$C$2&"="&N22&","&O22&","&P22&";")&IF(Q22="","",字段对应!$B$13&"="&Q22&";")&IF(R22="","",字段对应!$B$14&"="&R22&";")&IF(U22="","",字段对应!$B$22&"="&U22&";")&IF(K22="","",字段对应!$B$21&"="&VLOOKUP(K22,基础信息!$F$2:$G$4,2,0)) -> PhotoMode=1;ScanSpeed=2;Slit1=2.0;ResponseTime=0.5; | E22: =IF(W22="","",检测项信息!W22&":"&字段对应!$B$16&"|")&IF(X22="","",X22&":"&IF(V22="是",字段对应!$C$17,字段对应!$B$17&";"&IF(H22="","",字段对应!$B$15&"="&检测项信息!H22))&"|")&IF(Y22="",":",Y22&":")&IF(V22="是",字段对应!$C$18,字段对应!$B$18&";"&IF(H22="","",字段对应!$B$15&"="&检测项信息!H22)&IF(AND(T22="",S22=""),"",";"&字段对应!$B$20&"="&T22&";"&字段对应!$B$19&"="&S22)) -> 黑挡块:Dark|空气:Zero;Wl=200|黑挡块:Measure;Wl=200;totalcount=180;timeinterval=1 | F22: 1 | H22: 200 | I22: =VLOOKUP(J22,字段对应!$D$2:$E$8,2,0) -> Validation.ViewModel.DataStructure.FindMaxOffsetUVTestTool | J22: 最大最小值差 | L22: T% | M22: 中速 | R22: 2.0 | S22: 1 | T22: 180 | U22: 0.5 | V22: 否 | W22: 黑挡块 | X22: 空气 | Y22: 黑挡块 | Z22: =VLOOKUP(A22,对应信息!$D$2:$E$10,2,0) -> 8000 | AA22: =IF(Z21=Z22,AA21+1,Z22+1) -> 8004
A23: 杂散光校验 | B23: 220nm杂散光 | D23: =IF(L23="","",字段对应!$B$10&"="&VLOOKUP(L23,基础信息!$I$2:$J$6,2,0)&";")&IF(M23="","",字段对应!$B$11&"="&VLOOKUP(M23,基础信息!$K$2:$L$6,2,0)&";")&IF(N23="","",字段对应!$C$2&"="&N23&","&O23&","&P23&";")&IF(Q23="","",字段对应!$B$13&"="&Q23&";")&IF(R23="","",字段对应!$B$14&"="&R23&";")&IF(U23="","",字段对应!$B$22&"="&U23&";")&IF(K23="","",字段对应!$B$21&"="&VLOOKUP(K23,基础信息!$F$2:$G$4,2,0)) -> PhotoMode=1;ScanSpeed=2;Slit1=2.0; | E23: =IF(W23="","",检测项信息!W23&":"&字段对应!$B$16&"|")&IF(X23="","",X23&":"&IF(V23="是",字段对应!$C$17,字段对应!$B$17&";"&IF(H23="","",字段对应!$B$15&"="&检测项信息!H23))&"|")&IF(Y23="",":",Y23&":")&IF(V23="是",字段对应!$C$18,字段对应!$B$18&";"&IF(H23="","",字段对应!$B$15&"="&检测项信息!H23)&IF(AND(T23="",S23=""),"",";"&字段对应!$B$20&"="&T23&";"&字段对应!$B$19&"="&S23)) -> 黑挡块:Dark|蒸馏水:Zero;Wl=220|碘化钠溶液:Measure;Wl=220 | F23: 3 | G23: 1 | H23: 220 | I23: =VLOOKUP(J23,字段对应!$D$2:$E$8,2,0) -> Validation.ViewModel.DataStructure.WlPointsUVTestTool | J23: 多次测量 | L23: T% | M23: 中速 | R23: 2.0 | V23: 否 | W23: 黑挡块 | X23: 蒸馏水 | Y23: 碘化钠溶液 | Z23: =VLOOKUP(A23,对应信息!$D$2:$E$10,2,0) -> 3000 | AA23: =IF(Z22=Z23,AA22+1,Z23+1) -> 3001
A24: 杂散光校验 | B24: 360nm杂散光 | D24: =IF(L24="","",字段对应!$B$10&"="&VLOOKUP(L24,基础信息!$I$2:$J$6,2,0)&";")&IF(M24="","",字段对应!$B$11&"="&VLOOKUP(M24,基础信息!$K$2:$L$6,2,0)&";")&IF(N24="","",字段对应!$C$2&"="&N24&","&O24&","&P24&";")&IF(Q24="","",字段对应!$B$13&"="&Q24&";")&IF(R24="","",字段对应!$B$14&"="&R24&";")&IF(U24="","",字段对应!$B$22&"="&U24&";")&IF(K24="","",字段对应!$B$21&"="&VLOOKUP(K24,基础信息!$F$2:$G$4,2,0)) -> PhotoMode=1;ScanSpeed=2;Slit1=2.0; | E24: =IF(W24="","",检测项信息!W24&":"&字段对应!$B$16&"|")&IF(X24="","",X24&":"&IF(V24="是",字段对应!$C$17,字段对应!$B$17&";"&IF(H24="","",字段对应!$B$15&"="&检测项信息!H24))&"|")&IF(Y24="",":",Y24&":")&IF(V24="是",字段对应!$C$18,字段对应!$B$18&";"&IF(H24="","",字段对应!$B$15&"="&检测项信息!H24)&IF(AND(T24="",S24=""),"",";"&字段对应!$B$20&"="&T24&";"&字段对应!$B$19&"="&S24)) -> 黑挡块:Dark|蒸馏水:Zero;Wl=360|亚硝酸钠溶液:Measure;Wl=360 | F24: 3 | G24: 1 | H24: 360 | I24: =VLOOKUP(J24,字段对应!$D$2:$E$8,2,0) -> Validation.ViewModel.DataStructure.WlPointsUVTestTool | J24: 多次测量 | L24: T% | M24: 中速 | R24: 2.0 | V24: 否 | W24: 黑挡块 | X24: 蒸馏水 | Y24: 亚硝酸钠溶液 | Z24: =VLOOKUP(A24,对应信息!$D$2:$E$10,2,0) -> 3000 | AA24: =IF(Z23=Z24,AA23+1,Z24+1) -> 3002
A25: 透射比示值误差与重复性校验 | B25: 紫外分光光度计标准物质GBW(E)130066 | D25: =IF(L25="","",字段对应!$B$10&"="&VLOOKUP(L25,基础信息!$I$2:$J$6,2,0)&";")&IF(M25="","",字段对应!$B$11&"="&VLOOKUP(M25,基础信息!$K$2:$L$6,2,0)&";")&IF(N25="","",字段对应!$C$2&"="&N25&","&O25&","&P25&";")&IF(Q25="","",字段对应!$B$13&"="&Q25&";")&IF(R25="","",字段对应!$B$14&"="&R25&";")&IF(U25="","",字段对应!$B$22&"="&U25&";")&IF(K25="","",字段对应!$B$21&"="&VLOOKUP(K25,基础信息!$F$2:$G$4,2,0)) -> PhotoMode=1;ScanSpeed=2;Slit1=2.0; | E25: =IF(W25="","",检测项信息!W25&":"&字段对应!$B$16&"|")&IF(X25="","",X25&":"&IF(V25="是",字段对应!$C$17,字段对应!$B$17&";"&IF(H25="","",字段对应!$B$15&"="&检测项信息!H25))&"|")&IF(Y25="",":",Y25&":")&IF(V25="是",字段对应!$C$18,字段对应!$B$18&";"&IF(H25="","",字段对应!$B$15&"="&检测项信息!H25)&IF(AND(T25="",S25=""),"",";"&字段对应!$B$20&"="&T25&";"&字段对应!$B$19&"="&S25)) -> 黑挡块:Dark|紫外分光光度计标准物质GBW(E)130066:Zero;Wl=350,313,257,235|紫外分光光度计标准物质GBW(E)130066:Measure;Wl=350,313,257,235 | F25: 3 | G25: 1 | H25: 350,313,257,235 | I25: =VLOOKUP(J25,字段对应!$D$2:$E$8,2,0) -> Validation.ViewModel.DataStructure.WlPointsAndAverageUVTestTool | J25: 求平均 | L25: T% | M25: 中速 | R25: 2.0 | V25: 否 | W25: 黑挡块 | X25: 紫外分光光度计标准物质GBW(E)130066 | Y25: 紫外分光光度计标准物质GBW(E)130066 | Z25: =VLOOKUP(A25,对应信息!$D$2:$E$10,2,0) -> 2000 | AA25: =IF(Z24=Z25,AA24+1,Z25+1) -> 2001
A26: 透射比示值误差与重复性校验 | B26: 10%中性滤光片 | D26: =IF(L26="","",字段对应!$B$10&"="&VLOOKUP(L26,基础信息!$I$2:$J$6,2,0)&";")&IF(M26="","",字段对应!$B$11&"="&VLOOKUP(M26,基础信息!$K$2:$L$6,2,0)&";")&IF(N26="","",字段对应!$C$2&"="&N26&","&O26&","&P26&";")&IF(Q26="","",字段对应!$B$13&"="&Q26&";")&IF(R26="","",字段对应!$B$14&"="&R26&";")&IF(U26="","",字段对应!$B$22&"="&U26&";")&IF(K26="","",字段对应!$B$21&"="&VLOOKUP(K26,基础信息!$F$2:$G$4,2,0)) -> PhotoMode=1;ScanSpeed=2;Slit1=2.0; | E26: =IF(W26="","",检测项信息!W26&":"&字段对应!$B$16&"|")&IF(X26="","",X26&":"&IF(V26="是",字段对应!$C$17,字段对应!$B$17&";"&IF(H26="","",字段对应!$B$15&"="&检测项信息!H26))&"|")&IF(Y26="",":",Y26&":")&IF(V26="是",字段对应!$C$18,字段对应!$B$18&";"&IF(H26="","",字段对应!$B$15&"="&检测项信息!H26)&IF(AND(T26="",S26=""),"",";"&字段对应!$B$20&"="&T26&";"&字段对应!$B$19&"="&S26)) -> 黑挡块:Dark|空气:Zero;Wl=635,546,440|10%中性滤光片:Measure;Wl=635,546,440 | F26: 3 | G26: 1 | H26: 635,546,440 | I26: =VLOOKUP(J26,字段对应!$D$2:$E$8,2,0) -> Validation.ViewModel.DataStructure.WlPointsAndAverageUVTestTool | J26: 求平均 | L26: T% | M26: 中速 | R26: 2.0 | V26: 否 | W26: 黑挡块 | X26: 空气 | Y26: 10%中性滤光片 | Z26: =VLOOKUP(A26,对应信息!$D$2:$E$10,2,0) -> 2000 | AA26: =IF(Z25=Z26,AA25+1,Z26+1) -> 2002
A27: 透射比示值误差与重复性校验 | B27: 20%中性滤光片 | D27: =IF(L27="","",字段对应!$B$10&"="&VLOOKUP(L27,基础信息!$I$2:$J$6,2,0)&";")&IF(M27="","",字段对应!$B$11&"="&VLOOKUP(M27,基础信息!$K$2:$L$6,2,0)&";")&IF(N27="","",字段对应!$C$2&"="&N27&","&O27&","&P27&";")&IF(Q27="","",字段对应!$B$13&"="&Q27&";")&IF(R27="","",字段对应!$B$14&"="&R27&";")&IF(U27="","",字段对应!$B$22&"="&U27&";")&IF(K27="","",字段对应!$B$21&"="&VLOOKUP(K27,基础信息!$F$2:$G$4,2,0)) -> PhotoMode=1;ScanSpeed=2;Slit1=2.0; | E27: =IF(W27="","",检测项信息!W27&":"&字段对应!$B$16&"|")&IF(X27="","",X27&":"&IF(V27="是",字段对应!$C$17,字段对应!$B$17&";"&IF(H27="","",字段对应!$B$15&"="&检测项信息!H27))&"|")&IF(Y27="",":",Y27&":")&IF(V27="是",字段对应!$C$18,字段对应!$B$18&";"&IF(H27="","",字段对应!$B$15&"="&检测项信息!H27)&IF(AND(T27="",S27=""),"",";"&字段对应!$B$20&"="&T27&";"&字段对应!$B$19&"="&S27)) -> 黑挡块:Dark|空气:Zero;Wl=635,546,440|20%中性滤光片:Measure;Wl=635,546,440 | F27: 3 | G27: 1 | H27: 635,546,440 | I27: =VLOOKUP(J27,字段对应!$D$2:$E$8,2,0) -> Validation.ViewModel.DataStructure.WlPointsAndAverageUVTestTool | J27: 求平均 | L27: T% | M27: 中速 | R27: 2.0 | V27: 否 | W27: 黑挡块 | X27: 空气 | Y27: 20%中性滤光片 | Z27: =VLOOKUP(A27,对应信息!$D$2:$E$10,2,0) -> 2000 | AA27: =IF(Z26=Z27,AA26+1,Z27+1) -> 2003
A28: 透射比示值误差与重复性校验 | B28: 30%中性滤光片 | D28: =IF(L28="","",字段对应!$B$10&"="&VLOOKUP(L28,基础信息!$I$2:$J$6,2,0)&";")&IF(M28="","",字段对应!$B$11&"="&VLOOKUP(M28,基础信息!$K$2:$L$6,2,0)&";")&IF(N28="","",字段对应!$C$2&"="&N28&","&O28&","&P28&";")&IF(Q28="","",字段对应!$B$13&"="&Q28&";")&IF(R28="","",字段对应!$B$14&"="&R28&";")&IF(U28="","",字段对应!$B$22&"="&U28&";")&IF(K28="","",字段对应!$B$21&"="&VLOOKUP(K28,基础信息!$F$2:$G$4,2,0)) -> PhotoMode=1;ScanSpeed=2;Slit1=2.0; | E28: =IF(W28="","",检测项信息!W28&":"&字段对应!$B$16&"|")&IF(X28="","",X28&":"&IF(V28="是",字段对应!$C$17,字段对应!$B$17&";"&IF(H28="","",字段对应!$B$15&"="&检测项信息!H28))&"|")&IF(Y28="",":",Y28&":")&IF(V28="是",字段对应!$C$18,字段对应!$B$18&";"&IF(H28="","",字段对应!$B$15&"="&检测项信息!H28)&IF(AND(T28="",S28=""),"",";"&字段对应!$B$20&"="&T28&";"&字段对应!$B$19&"="&S28)) -> 黑挡块:Dark|空气:Zero;Wl=635,546,440|30%中性滤光片:Measure;Wl=635,546,440 | F28: 3 | G28: 1 | H28: 635,546,440 | I28: =VLOOKUP(J28,字段对应!$D$2:$E$8,2,0) -> Validation.ViewModel.DataStructure.WlPointsAndAverageUVTestTool | J28: 求平均 | L28: T% | M28: 中速 | R28: 2.0 | V28: 否 | W28: 黑挡块 | X28: 空气 | Y28: 30%中性滤光片 | Z28: =VLOOKUP(A28,对应信息!$D$2:$E$10,2,0) -> 2000 | AA28: =IF(Z27=Z28,AA27+1,Z28+1) -> 2004
A29: 漂移检验 | B29: 漂移检验 | C29: 仪器预热1小时之后进行检验 | D29: =IF(L29="","",字段对应!$B$10&"="&VLOOKUP(L29,基础信息!$I$2:$J$6,2,0)&";")&IF(M29="","",字段对应!$B$11&"="&VLOOKUP(M29,基础信息!$K$2:$L$6,2,0)&";")&IF(N29="","",字段对应!$C$2&"="&N29&","&O29&","&P29&";")&IF(Q29="","",字段对应!$B$13&"="&Q29&";")&IF(R29="","",字段对应!$B$14&"="&R29&";")&IF(U29="","",字段对应!$B$22&"="&U29&";")&IF(K29="","",字段对应!$B$21&"="&VLOOKUP(K29,基础信息!$F$2:$G$4,2,0)) -> PhotoMode=1;ScanSpeed=2;Slit1=2.0;ResponseTime=0.5; | E29: =IF(W29="","",检测项信息!W29&":"&字段对应!$B$16&"|")&IF(X29="","",X29&":"&IF(V29="是",字段对应!$C$17,字段对应!$B$17&";"&IF(H29="","",字段对应!$B$15&"="&检测项信息!H29))&"|")&IF(Y29="",":",Y29&":")&IF(V29="是",字段对应!$C$18,字段对应!$B$18&";"&IF(H29="","",字段对应!$B$15&"="&检测项信息!H29)&IF(AND(T29="",S29=""),"",";"&字段对应!$B$20&"="&T29&";"&字段对应!$B$19&"="&S29)) -> 黑挡块:Dark|空气:Zero;Wl=500|空气:Measure;Wl=500;totalcount=3600;timeinterval=1 | F29: 1 | H29: 500 | I29: =VLOOKUP(J29,字段对应!$D$2:$E$8,2,0) -> Validation.ViewModel.DataStructure.FindMaxOffsetUVTestTool | J29: 最大最小值差 | L29: T% | M29: 中速 | R29: 2.0 | S29: 1 | T29: 3600 | U29: 0.5 | V29: 否 | W29: 黑挡块 | X29: 空气 | Y29: 空气 | Z29: =VLOOKUP(A29,对应信息!$D$2:$E$10,2,0) -> 9000 | AA29: =IF(Z28=Z29,AA28+1,Z29+1) -> 9001

Sheet 标准值
A1: 测试项 | B1: 检测工具 | C1: 特征值 | D1: 标准值（%）
A2: 透射比示值误差与重复性校验 | B2: 紫外分光光度计标准物质GBW(E)130066 | C2: 350nm | D2: 23.35
C3: 313nm | D3: 51.54
C4: 257nm | D4: 14.09
C5: 235nm | D5: 18.53
B6: 10%中性滤光片 | C6: 635nm | D6: 13.34
C7: 546nm | D7: 15.91
C8: 440nm | D8: 15.34
B9: 20%中性滤光片 | C9: 635nm | D9: 22.78
C10: 546nm | D10: 29.12
C11: 440nm | D11: 29.76
B12: 30%中性滤光片 | C12: 635nm | D12: 34.02
C13: 546nm | D13: 40.5
C14: 440nm | D14: 41
A15: 波长示值误差与重复性校验 | B15: 镨钕滤光片 | C15: 807.4
B16: 钬溶液 | C16: 640.79
C17: 536.86
C18: 416.57
C19: 361.12
C20: 287.52
C21: 241.12
A23: 修改标准值时，该仪器对应的模板文件必须未打开，同时修改后光标要在未修改的单元格内！方可保存成功！

Sheet 字段对应
A1: 仪器方法标记 | B1: 仪器方法字段 | D1: 算法标记 | E1: 算法字段
A2: 起始波长 | B2: StartWl | C2: WlRange | D2: 寻峰 | E2: Validation.ViewModel.DataStructure.FindPeakAndAverageUVTestTool
A3: 终止波长 | B3: EndWl | D3: 求平均 | E3: Validation.ViewModel.DataStructure.WlPointsAndAverageUVTestTool
A4: 重复次数 | B4: RepeatTimes | D4: 多次测量 | E4: Validation.ViewModel.DataStructure.WlPointsUVTestTool
A5: 重复时间间隔 | B5: RepeatInterval | D5: 最大最小值差 | E5: Validation.ViewModel.DataStructure.FindMaxOffsetUVTestTool
A6: 方法信息 | B6: MethodStr | D6: 求半峰宽 | E6: Validation.ViewModel.DataStructure.FindHalfPeakUVTestTool
