Workbook
Name OLE_LINK10: Report!#REF!

Sheet Report
C1: 北京普析通用仪器有限责任公司 | L1: 文件编号 | N1: KF/R-01-003
C2: T400系列紫外可见分光光度计整机检验原始记录表 | L2: 版本/修订 | N2: B/0
L3: 发布/修订日期 | N3: 41010
A4: 产品型号 | D4: 产品编号 | H4: 检验员 | L4: 检验日期 | N4: 复核员
A5: =IFERROR(VLOOKUP(MID(D5,5,4),对应信息!A:B,2,0),"")
A6: 温度(℃) | E6: 相对湿度(%) | L6: 检验结果
A7: 序号 | B7: 检验项目 | E7: 结果
A8: 1 | B8: 波长示值误差与重复性 | C8: 波长示值误差 镨钕： ±1.4nm 波长重复性 ≤0.4nm | E8: 波长段 | H8: B段
E9: 检测工具 | H9: 镨钕滤光片 | K9: 钬溶液
E10: 标准值(nm) | H10: =波长示值误差与重复性校验!B2 -> 807.4 | K10: =波长示值误差与重复性校验!B3 -> 640.7 | L10: =波长示值误差与重复性校验!B4 -> 536.8 | M10: =波长示值误差与重复性校验!B5 -> 416.5 | N10: =波长示值误差与重复性校验!B6 -> 361.0
E11: 测量值（nm） | H11: =波长示值误差与重复性校验!C2 -> 0 | K11: =波长示值误差与重复性校验!C3 -> 0 | L11: =波长示值误差与重复性校验!C4 -> 0 | M11: =波长示值误差与重复性校验!C5 -> 0 | N11: =波长示值误差与重复性校验!C6 -> 0
H12: =波长示值误差与重复性校验!D2 -> 0 | K12: =波长示值误差与重复性校验!D3 -> 0 | L12: =波长示值误差与重复性校验!D4 -> 0 | M12: =波长示值误差与重复性校验!D5 -> 0 | N12: =波长示值误差与重复性校验!D6 -> 0
H13: =波长示值误差与重复性校验!E2 -> 0 | K13: =波长示值误差与重复性校验!E3 -> 0 | L13: =波长示值误差与重复性校验!E4 -> 0 | M13: =波长示值误差与重复性校验!E5 -> 0 | N13: =波长示值误差与重复性校验!E6 -> 0
E14: 平均值(nm) | H14: =波长示值误差与重复性校验!F2 | K14: =波长示值误差与重复性校验!F3 | L14: =波长示值误差与重复性校验!F4 | M14: =波长示值误差与重复性校验!F5 | N14: =波长示值误差与重复性校验!F6
E15: 误差值(nm) | H15: =波长示值误差与重复性校验!G2 | K15: =波长示值误差与重复性校验!G3 | L15: =波长示值误差与重复性校验!G4 | M15: =波长示值误差与重复性校验!G5 | N15: =波长示值误差与重复性校验!G6
E16: 重复性(nm) | H16: =波长示值误差与重复性校验!H2 -> 0 | K16: =波长示值误差与重复性校验!H3 -> 0 | L16: =波长示值误差与重复性校验!H4 -> 0 | M16: =波长示值误差与重复性校验!H5 -> 0 | N16: =波长示值误差与重复性校验!H6 -> 0
A18: 2 | B18: 透射比示值误差与重复性 (可见区） | C18: 透射比示值误差 ±0.3% 透射比重复性 ≤0.15% | E18: 检测工具 | H18: 10%中性滤光片、20%中性滤光片、30%中性滤光片 （以标定的标准值为准）
E20: 型号 | G20: 测量点 | I20: =透射比示值误差与重复性校验!B2 -> 635 | L20: =透射比示值误差与重复性校验!B3 -> 546 | N20: =透射比示值误差与重复性校验!B4 -> 440
E21: 10%中性滤光片 | G21: 标准值(%) | I21: =透射比示值误差与重复性校验!C2 -> 7.57 | L21: =透射比示值误差与重复性校验!C3 -> 10.1 | N21: =透射比示值误差与重复性校验!C4 -> 10.07
G22: 测量值(%) | I22: =透射比示值误差与重复性校验!D2 -> 0 | L22: =透射比示值误差与重复性校验!D3 -> 0 | N22: =透射比示值误差与重复性校验!D4 -> 0
I23: =透射比示值误差与重复性校验!E2 -> 0 | L23: =透射比示值误差与重复性校验!E3 -> 0 | N23: =透射比示值误差与重复性校验!E4 -> 0
I24: =透射比示值误差与重复性校验!F2 -> 0 | L24: =透射比示值误差与重复性校验!F3 -> 0 | N24: =透射比示值误差与重复性校验!F4 -> 0
G25: 平均值(%) | I25: =透射比示值误差与重复性校验!G2 | L25: =透射比示值误差与重复性校验!G3 | N25: =透射比示值误差与重复性校验!G4
G26: 误差值(%) | I26: =透射比示值误差与重复性校验!H2 | L26: =透射比示值误差与重复性校验!H3 | N26: =透射比示值误差与重复性校验!H4
G27: 重复性(%) | I27: =透射比示值误差与重复性校验!I2 -> 0 | L27: =透射比示值误差与重复性校验!I3 -> 0 | N27: =透射比示值误差与重复性校验!I4 -> 0
E28: 20%中性滤光片 | G28: 标准值(%) | I28: =透射比示值误差与重复性校验!C5 -> 18.98 | L28: =透射比示值误差与重复性校验!C6 -> 20.09 | N28: =透射比示值误差与重复性校验!C7 -> 20.91
G29: 测量值(%) | I29: =透射比示值误差与重复性校验!D5 -> 0 | L29: =透射比示值误差与重复性校验!D6 -> 0 | N29: =透射比示值误差与重复性校验!D7 -> 0
I30: =透射比示值误差与重复性校验!E5 -> 0 | L30: =透射比示值误差与重复性校验!E6 -> 0 | N30: =透射比示值误差与重复性校验!E7 -> 0
I31: =透射比示值误差与重复性校验!F5 -> 0 | L31: =透射比示值误差与重复性校验!F6 -> 0 | N31: =透射比示值误差与重复性校验!F7 -> 0
G32: 平均值(%) | I32: =透射比示值误差与重复性校验!G5 | L32: =透射比示值误差与重复性校验!G6 | N32: =透射比示值误差与重复性校验!G7
G33: 误差值(%) | I33: =透射比示值误差与重复性校验!H5 | L33: =透射比示值误差与重复性校验!H6 | N33: =透射比示值误差与重复性校验!H7
G34: 重复性(%) | I34: =透射比示值误差与重复性校验!I5 -> 0 | L34: =透射比示值误差与重复性校验!I6 -> 0 | N34: =透射比示值误差与重复性校验!I7 -> 0
A35: 2 | B35: 透射比示值误差与重复性 (可见区） | C35: 透射比示值误差 ±0.3% 透射比重复性 ≤0.15% | E35: 30%中性滤光片 | G35: 标准值(%) | I35: =透射比示值误差与重复性校验!C8 -> 29.96 | L35: =透射比示值误差与重复性校验!C9 -> 30.43 | N35: =透射比示值误差与重复性校验!C10 -> 28.88
G36: 测量值(%) | I36: =透射比示值误差与重复性校验!D8 -> 0 | L36: =透射比示值误差与重复性校验!D9 -> 0 | N36: =透射比示值误差与重复性校验!D10 -> 0
I37: =透射比示值误差与重复性校验!E8 -> 0 | L37: =透射比示值误差与重复性校验!E9 -> 0 | N37: =透射比示值误差与重复性校验!E10 -> 0
I38: =透射比示值误差与重复性校验!F8 -> 0 | L38: =透射比示值误差与重复性校验!F9 -> 0 | N38: =透射比示值误差与重复性校验!F10 -> 0
G39: 平均值(%) | I39: =透射比示值误差与重复性校验!G8 | L39: =透射比示值误差与重复性校验!G9 | N39: =透射比示值误差与重复性校验!G10
G40: 误差值(%) | I40: =透射比示值误差与重复性校验!H8 | L40: =透射比示值误差与重复性校验!H9 | N40: =透射比示值误差与重复性校验!H10
G41: 重复性(%) | I41: =透射比示值误差与重复性校验!I8 -> 0 | L41: =透射比示值误差与重复性校验!I9 -> 0 | N41: =透射比示值误差与重复性校验!I10 -> 0
A42: 3 | B42: 杂散光 | E42: 检验工具 | J42: 1 | K42: 2 | L42: 3 | M42: 结果
...

Sheet 基础信息
A1: 名称 | B1: 特征值 | C1: 标准值 | E1: 是否为光谱扫描 | F1: 灯状态 | G1: 灯状态 | H1: 较零物质 | I1: 光度方式 | J1: 光度方式 | K1: 扫描速度 | L1: 扫描速度 | M1: 扫描间隔(nm) | N1: 重复次数 | O1: 重复时间间隔(S) | P1: 光谱带宽(nm) | Q1: 增益 | R1: 响应时间
A2: 氘灯 | B2: 656.1 | C2: 656.1 | E2: 是 | F2: 钨灯 | G2: 0 | I2: Abs | J2: 0 | K2: 快速 | L2: 0 | N2: 1 | P2: 0.2
A3: 低压汞灯A段 | B3: 253.7 | C3: 253.7 | E3: 否 | F3: 氘灯 | G3: 1 | H3: 其它 | I3: T% | J3: 1 | K3: 中速 | L3: 1 | M3: 0.02 | N3: 2 | O3: 1 | P3: 0.5 | Q3: 1 | R3: 0.5
A4: 低压汞灯B段 | B4: 365.0,435.8,546.1 | C4: 365.0,435.8,546.1 | F4: 汞灯 | G4: 2 | I4: Es | J4: 2 | K4: 慢速 | L4: 2 | M4: 0.1 | N4: 3 | O4: 2 | P4: 1.0 | Q4: 2 | R4: 1
A5: 镨钕滤光片 | B5: 739.2,,807.4 | C5: 739.2,,807.4 | I5: Er | J5: 3 | K5: 最慢速 | L5: 3 | M5: 0.2 | N5: 4 | P5: 2.0 | Q5: 3 | R5: 2
A6: 10%中性滤光片 | B6: 635.0,546.0,440.0 | I6: R% | J6: 4 | M6: 0.5 | N6: 5 | P6: 5.0 | Q6: 4
A7: 20%中性滤光片 | B7: 635.0,546.0,440.1 | M7: 1 | Q7: 5
A8: 30%中性滤光片 | B8: 635.0,546.0,440.2 | M8: 2
A9: 重铬酸钾标准物质 | B9: 350313257235 | C9: 22.9,51.3,13.7,18.2 | M9: 5
A10: 碘化钠溶液 | B10: 220
A11: 亚硝酸钠溶液 | B11: 340360

Sheet 测量结果表
A1: 项目编号 | B1: 仪器ID | C1: 标准值 | D1: 测量值（nm） | E1: 平均值 | F1: 误差值 | G1: 重复性 | H1: 检验员 | I1: 检验日期 | J1: 复核员 | K1: 检验地点 | L1: 温度 | M1: 湿度 | N1: 判定结果 | O1: 其他 | P1: 子项目编号-与检测项信息对应的
A2: 1003 | B2: =MID(CELL("filename"),FIND("[",CELL("filename"),1)+1,FIND(".",CELL("filename"),1)-FIND("[",CELL("filename"),1)-1) -> T400 | D2: =波长示值误差与重复性校验!$C2&";"&波长示值误差与重复性校验!$D2&";"&波长示值误差与重复性校验!$E2 -> ;; | E2: =波长示值误差与重复性校验!$F2 | F2: =波长示值误差与重复性校验!$G2 | G2: =波长示值误差与重复性校验!$H2 -> 0 | H2: =Report!$F$5 -> 0 | I2: =NOW() -> 45881.669 | J2: =Report!$N$5 -> 0 | L2: =Report!$C$6 -> 0 | M2: =Report!$H$6 -> 0 | N2: =波长示值误差与重复性校验!$K2 -> 未检测 | P2: 1003
A3: 1008 | B3: =MID(CELL("filename"),FIND("[",CELL("filename"),1)+1,FIND(".",CELL("filename"),1)-FIND("[",CELL("filename"),1)-1) -> T400 | D3: =波长示值误差与重复性校验!$C3&";"&波长示值误差与重复性校验!$D3&";"&波长示值误差与重复性校验!$E3 -> ;; | E3: =波长示值误差与重复性校验!$F3 | F3: =波长示值误差与重复性校验!$G3 | G3: =波长示值误差与重复性校验!$H3 -> 0 | H3: =Report!$F$5 -> 0 | I3: =NOW() -> 45881.669 | J3: =Report!$N$5 -> 0 | L3: =Report!$C$6 -> 0 | M3: =Report!$H$6 -> 0 | N3: =波长示值误差与重复性校验!$K3 -> 未检测 | P3: 1004
A4: 1009 | B4: =MID(CELL("filename"),FIND("[",CELL("filename"),1)+1,FIND(".",CELL("filename"),1)-FIND("[",CELL("filename"),1)-1) -> T400 | D4: =波长示值误差与重复性校验!$C4&";"&波长示值误差与重复性校验!$D4&";"&波长示值误差与重复性校验!$E4 -> ;; | E4: =波长示值误差与重复性校验!$F4 | F4: =波长示值误差与重复性校验!$G4 | G4: =波长示值误差与重复性校验!$H4 -> 0 | H4: =Report!$F$5 -> 0 | I4: =NOW() -> 45881.669 | J4: =Report!$N$5 -> 0 | L4: =Report!$C$6 -> 0 | M4: =Report!$H$6 -> 0 | N4: =波长示值误差与重复性校验!$K4 -> 未检测 | P4: 1004
A5: 1010 | B5: =MID(CELL("filename"),FIND("[",CELL("filename"),1)+1,FIND(".",CELL("filename"),1)-FIND("[",CELL("filename"),1)-1) -> T400 | D5: =波长示值误差与重复性校验!$C5&";"&波长示值误差与重复性校验!$D5&";"&波长示值误差与重复性校验!$E5 -> ;; | E5: =波长示值误差与重复性校验!$F5 | F5: =波长示值误差与重复性校验!$G5 | G5: =波长示值误差与重复性校验!$H5 -> 0 | H5: =Report!$F$5 -> 0 | I5: =NOW() -> 45881.669 | J5: =Report!$N$5 -> 0 | L5: =Report!$C$6 -> 0 | M5: =Report!$H$6 -> 0 | N5: =波长示值误差与重复性校验!$K5 -> 未检测 | P5: 1004
A6: 1011 | B6: =MID(CELL("filename"),FIND("[",CELL("filename"),1)+1,FIND(".",CELL("filename"),1)-FIND("[",CELL("filename"),1)-1) -> T400 | D6: =波长示值误差与重复性校验!$C6&";"&波长示值误差与重复性校验!$D6&";"&波长示值误差与重复性校验!$E6 -> ;; | E6: =波长示值误差与重复性校验!$F6 | F6: =波长示值误差与重复性校验!$G6 | G6: =波长示值误差与重复性校验!$H6 -> 0 | H6: =Report!$F$5 -> 0 | I6: =NOW() -> 45881.669 | J6: =Report!$N$5 -> 0 | L6: =Report!$C$6 -> 0 | M6: =Report!$H$6 -> 0 | N6: =波长示值误差与重复性校验!$K6 -> 未检测 | P6: 1004
A7: 2005 | B7: =MID(CELL("filename"),FIND("[",CELL("filename"),1)+1,FIND(".",CELL("filename"),1)-FIND("[",CELL("filename"),1)-1) -> T400 | C7: =透射比示值误差与重复性校验!$C2 -> 7.57 | D7: =透射比示值误差与重复性校验!$D2&";"&透射比示值误差与重复性校验!$E2&";"&透射比示值误差与重复性校验!$F2 -> ;; | E7: =透射比示值误差与重复性校验!$G2 | F7: =透射比示值误差与重复性校验!$H2 | G7: =透射比示值误差与重复性校验!$I2 -> 0 | H7: =Report!$F$5 -> 0 | I7: =NOW() -> 45881.669 | J7: =Report!$N$5 -> 0 | L7: =Report!$C$6 -> 0 | M7: =Report!$H$6 -> 0 | N7: =透射比示值误差与重复性校验!$L2 -> 未检测 | P7: 2002
A8: 2006 | B8: =MID(CELL("filename"),FIND("[",CELL("filename"),1)+1,FIND(".",CELL("filename"),1)-FIND("[",CELL("filename"),1)-1) -> T400 | C8: =透射比示值误差与重复性校验!$C3 -> 10.1 | D8: =透射比示值误差与重复性校验!$D3&";"&透射比示值误差与重复性校验!$E3&";"&透射比示值误差与重复性校验!$F3 -> ;; | E8: =透射比示值误差与重复性校验!$G3 | F8: =透射比示值误差与重复性校验!$H3 | G8: =透射比示值误差与重复性校验!$I3 -> 0 | H8: =Report!$F$5 -> 0 | I8: =NOW() -> 45881.669 | J8: =Report!$N$5 -> 0 | L8: =Report!$C$6 -> 0 | M8: =Report!$H$6 -> 0 | N8: =透射比示值误差与重复性校验!$L3 -> 未检测 | P8: 2002
A9: 2007 | B9: =MID(CELL("filename"),FIND("[",CELL("filename"),1)+1,FIND(".",CELL("filename"),1)-FIND("[",CELL("filename"),1)-1) -> T400 | C9: =透射比示值误差与重复性校验!$C4 -> 10.07 | D9: =透射比示值误差与重复性校验!$D4&";"&透射比示值误差与重复性校验!$E4&";"&透射比示值误差与重复性校验!$F4 -> ;; | E9: =透射比示值误差与重复性校验!$G4 | F9: =透射比示值误差与重复性校验!$H4 | G9: =透射比示值误差与重复性校验!$I4 -> 0 | H9: =Report!$F$5 -> 0 | I9: =NOW() -> 45881.669 | J9: =Report!$N$5 -> 0 | L9: =Report!$C$6 -> 0 | M9: =Report!$H$6 -> 0 | N9: =透射比示值误差与重复性校验!$L4 -> 未检测 | P9: 2002
A10: 2008 | B10: =MID(CELL("filename"),FIND("[",CELL("filename"),1)+1,FIND(".",CELL("filename"),1)-FIND("[",CELL("filename"),1)-1) -> T400 | C10: =透射比示值误差与重复性校验!$C5 -> 18.98 | D10: =透射比示值误差与重复性校验!$D5&";"&透射比示值误差与重复性校验!$E5&";"&透射比示值误差与重复性校验!$F5 -> ;; | E10: =透射比示值误差与重复性校验!$G5 | F10: =透射比示值误差与重复性校验!$H5 | G10: =透射比示值误差与重复性校验!$I5 -> 0 | H10: =Report!$F$5 -> 0 | I10: =NOW() -> 45881.669 | J10: =Report!$N$5 -> 0 | L10: =Report!$C$6 -> 0 | M10: =Report!$H$6 -> 0 | N10: =透射比示值误差与重复性校验!$L5 -> 未检测 | P10: 2003
A11: 2009 | B11: =MID(CELL("filename"),FIND("[",CELL("filename"),1)+1,FIND(".",CELL("filename"),1)-FIND("[",CELL("filename"),1)-1) -> T400 | C11: =透射比示值误差与重复性校验!$C6 -> 20.09 | D11: =透射比示值误差与重复性校验!$D6&";"&透射比示值误差与重复性校验!$E6&";"&透射比示值误差与重复性校验!$F6 -> ;; | E11: =透射比示值误差与重复性校验!$G6 | F11: =透射比示值误差与重复性校验!$H6 | G11: =透射比示值误差与重复性校验!$I6 -> 0 | H11: =Report!$F$5 -> 0 | I11: =NOW() -> 45881.669 | J11: =Report!$N$5 -> 0 | L11: =Report!$C$6 -> 0 | M11: =Report!$H$6 -> 0 | N11: =透射比示值误差与重复性校验!$L6 -> 未检测 | P11: 2003
A12: 2010 | B12: =MID(CELL("filename"),FIND("[",CELL("filename"),1)+1,FIND(".",CELL("filename"),1)-FIND("[",CELL("filename"),1)-1) -> T400 | C12: =透射比示值误差与重复性校验!$C7 -> 20.91 | D12: =透射比示值误差与重复性校验!$D7&";"&透射比示值误差与重复性校验!$E7&";"&透射比示值误差与重复性校验!$F7 -> ;; | E12: =透射比示值误差与重复性校验!$G7 | F12: =透射比示值误差与重复性校验!$H7 | G12: =透射比示值误差与重复性校验!$I7 -> 0 | H12: =Report!$F$5 -> 0 | I12: =NOW() -> 45881.669 | J12: =Report!$N$5 -> 0 | L12: =Report!$C$6 -> 0 | M12: =Report!$H$6 -> 0 | N12: =透射比示值误差与重复性校验!$L7 -> 未检测 | P12: 2003
A13: 2011 | B13: =MID(CELL("filename"),FIND("[",CELL("filename"),1)+1,FIND(".",CELL("filename"),1)-FIND("[",CELL("filename"),1)-1) -> T400 | C13: =透射比示值误差与重复性校验!$C8 -> 29.96 | D13: =透射比示值误差与重复性校验!$D8&";"&透射比示值误差与重复性校验!$E8&";"&透射比示值误差与重复性校验!$F8 -> ;; | E13: =透射比示值误差与重复性校验!$G8 | F13: =透射比示值误差与重复性校验!$H8 | G13: =透射比示值误差与重复性校验!$I8 -> 0 | H13: =Report!$F$5 -> 0 | I13: =NOW() -> 45881.669 | J13: =Report!$N$5 -> 0 | L13: =Report!$C$6 -> 0 | M13: =Report!$H$6 -> 0 | N13: =透射比示值误差与重复性校验!$L8 -> 未检测 | P13: 2004
A14: 2012 | B14: =MID(CELL("filename"),FIND("[",CELL("filename"),1)+1,FIND(".",CELL("filename"),1)-FIND("[",CELL("filename"),1)-1) -> T400 | C14: =透射比示值误差与重复性校验!$C9 -> 30.43 | D14: =透射比示值误差与重复性校验!$D9&";"&透射比示值误差与重复性校验!$E9&";"&透射比示值误差与重复性校验!$F9 -> ;; | E14: =透射比示值误差与重复性校验!$G9 | F14: =透射比示值误差与重复性校验!$H9 | G14: =透射比示值误差与重复性校验!$I9 -> 0 | H14: =Report!$F$5 -> 0 | I14: =NOW() -> 45881.669 | J14: =Report!$N$5 -> 0 | L14: =Report!$C$6 -> 0 | M14: =Report!$H$6 -> 0 | N14: =透射比示值误差与重复性校验!$L9 -> 未检测 | P14: 2004
A15: 2013 | B15: =MID(CELL("filename"),FIND("[",CELL("filename"),1)+1,FIND(".",CELL("filename"),1)-FIND("[",CELL("filename"),1)-1) -> T400 | C15: =透射比示值误差与重复性校验!$C10 -> 28.88 | D15: =透射比示值误差与重复性校验!$D10&";"&透射比示值误差与重复性校验!$E10&";"&透射比示值误差与重复性校验!$F10 -> ;; | E15: =透射比示值误差与重复性校验!$G10 | F15: =透射比示值误差与重复性校验!$H10 | G15: =透射比示值误差与重复性校验!$I10 -> 0 | H15: =Report!$F$5 -> 0 | I15: =NOW() -> 45881.669 | J15: =Report!$N$5 -> 0 | L15: =Report!$C$6 -> 0 | M15: =Report!$H$6 -> 0 | N15: =透射比示值误差与重复性校验!$L10 -> 未检测 | P15: 2004
A16: 3002 | B16: =MID(CELL("filename"),FIND("[",CELL("filename"),1)+1,FIND(".",CELL("filename"),1)-FIND("[",CELL("filename"),1)-1) -> T400 | C16: =杂散光校验!$B2 -> 360 | D16: =杂散光校验!$C2&";"&杂散光校验!$D2&";"&杂散光校验!$E2 -> ;; | H16: =Report!$F$5 -> 0 | I16: =NOW() -> 45881.669 | J16: =Report!$N$5 -> 0 | L16: =Report!$C$6 -> 0 | M16: =Report!$H$6 -> 0 | N16: =杂散光校验!$G2 -> 未检测 | P16: 3002
A17: 4001 | B17: =MID(CELL("filename"),FIND("[",CELL("filename"),1)+1,FIND(".",CELL("filename"),1)-FIND("[",CELL("filename"),1)-1) -> T400 | D17: =基线平直度检验!$B$2 -> 0 | H17: =Report!$F$5 -> 0 | I17: =NOW() -> 45881.669 | J17: =Report!$N$5 -> 0 | L17: =Report!$C$6 -> 0 | M17: =Report!$H$6 -> 0 | N17: =基线平直度检验!$D$2 -> 未检测 | P17: 4001
A18: 5001 | B18: =MID(CELL("filename"),FIND("[",CELL("filename"),1)+1,FIND(".",CELL("filename"),1)-FIND("[",CELL("filename"),1)-1) -> T400 | D18: =基线暗噪声检验!$B$2 -> 0 | H18: =Report!$F$5 -> 0 | I18: =NOW() -> 45881.669 | J18: =Report!$N$5 -> 0 | L18: =Report!$C$6 -> 0 | M18: =Report!$H$6 -> 0 | N18: =基线暗噪声检验!$D$2 -> 未检测 | P18: 5001
A19: 7001 | B19: =MID(CELL("filename"),FIND("[",CELL("filename"),1)+1,FIND(".",CELL("filename"),1)-FIND("[",CELL("filename"),1)-1) -> T400 | C19: =噪声检验!$B2 -> 500 | D19: =噪声检验!$C2 -> 0 | H19: =Report!$F$5 -> 0 | I19: =NOW() -> 45881.669 | J19: =Report!$N$5 -> 0 | L19: =Report!$C$6 -> 0 | M19: =Report!$H$6 -> 0 | N19: =噪声检验!$E2 -> 未检测 | P19: 7001
A20: 7002 | B20: =MID(CELL("filename"),FIND("[",CELL("filename"),1)+1,FIND(".",CELL("filename"),1)-FIND("[",CELL("filename"),1)-1) -> T400 | C20: =噪声检验!$B3 -> 500 | D20: =噪声检验!$C3 -> 0 | H20: =Report!$F$5 -> 0 | I20: =NOW() -> 45881.669 | J20: =Report!$N$5 -> 0 | L20: =Report!$C$6 -> 0 | M20: =Report!$H$6 -> 0 | N20: =噪声检验!$E3 -> 未检测 | P20: 7002
A21: 8001 | B21: =MID(CELL("filename"),FIND("[",CELL("filename"),1)+1,FIND(".",CELL("filename"),1)-FIND("[",CELL("filename"),1)-1) -> T400 | C21: =波长边缘噪声!$B2 -> 1090 | D21: =波长边缘噪声!$C2 -> 0 | H21: =Report!$F$5 -> 0 | I21: =NOW() -> 45881.669 | J21: =Report!$N$5 -> 0 | L21: =Report!$C$6 -> 0 | M21: =Report!$H$6 -> 0 | N21: =波长边缘噪声!$E2 -> 未检测 | P21: 8001
A22: 8002 | B22: =MID(CELL("filename"),FIND("[",CELL("filename"),1)+1,FIND(".",CELL("filename"),1)-FIND("[",CELL("filename"),1)-1) -> T400 | C22: =波长边缘噪声!$B3 -> 1090 | D22: =波长边缘噪声!$C3 -> 0 | H22: =Report!$F$5 -> 0 | I22: =NOW() -> 45881.669 | J22: =Report!$N$5 -> 0 | L22: =Report!$C$6 -> 0 | M22: =Report!$H$6 -> 0 | N22: =波长边缘噪声!$E3 -> 未检测 | P22: 8002
A23: 8003 | B23: =MID(CELL("filename"),FIND("[",CELL("filename"),1)+1,FIND(".",CELL("filename"),1)-FIND("[",CELL("filename"),1)-1) -> T400 | C23: =波长边缘噪声!$B4 -> 335 | D23: =波长边缘噪声!$C4 -> 0 | H23: =Report!$F$5 -> 0 | I23: =NOW() -> 45881.669 | J23: =Report!$N$5 -> 0 | L23: =Report!$C$6 -> 0 | M23: =Report!$H$6 -> 0 | N23: =波长边缘噪声!$E4 -> 未检测 | P23: 8003
A24: 8004 | B24: =MID(CELL("filename"),FIND("[",CELL("filename"),1)+1,FIND(".",CELL("filename"),1)-FIND("[",CELL("filename"),1)-1) -> T400 | C24: =波长边缘噪声!$B5 -> 335 | D24: =波长边缘噪声!$C5 -> 0 | H24: =Report!$F$5 -> 0 | I24: =NOW() -> 45881.669 | J24: =Report!$N$5 -> 0 | L24: =Report!$C$6 -> 0 | M24: =Report!$H$6 -> 0 | N24: =波长边缘噪声!$E5 -> 未检测 | P24: 8004
A25: 9001 | B25: =MID(CELL("filename"),FIND("[",CELL("filename"),1)+1,FIND(".",CELL("filename"),1)-FIND("[",CELL("filename"),1)-1) -> T400 | C25: =漂移检验!$B$2 -> 500 | D25: =漂移检验!$C$2 -> 0 | H25: =Report!$F$5 -> 0 | I25: =NOW() -> 45881.669 | J25: =Report!$N$5 -> 0 | L25: =Report!$C$6 -> 0 | M25: =Report!$H$6 -> 0 | N25: =漂移检验!$E$2 -> 未检测 | P25: 9001

Sheet 管理表
A1: 检验项目
A2: 产品型号 | B2: 父项目编号 | C2: 父项目名称 | D2: 子项目编号 | E2: 子项目名称 | F2: 特征值 | G2: 可允许误差范围 | H2: 波长重复性
A3: T700S | B3: 1000 | C3: 波长示值误差与重复性校验 | D3: 1003 | E3: 镨钕滤光片 | F3: 807.4 | G3: 1.4 | H3: 0.4
A4: T700S | B4: 1000 | C4: 波长示值误差与重复性校验 | D4: 1008 | E4: 钬溶液 | F4: 640.79 | G4: 1.4 | H4: 0.4
A5: T700S | B5: 1000 | C5: 波长示值误差与重复性校验 | D5: 1009 | E5: 钬溶液 | F5: 536.86 | G5: 1.4 | H5: 0.4
A6: T700S | B6: 1000 | C6: 波长示值误差与重复性校验 | D6: 1010 | E6: 钬溶液 | F6: 416.57 | G6: 1.4 | H6: 0.4
A7: T700S | B7: 1000 | C7: 波长示值误差与重复性校验 | D7: 1011 | E7: 钬溶液 | F7: 361.12 | G7: 1.4 | H7: 0.4
A8: T700S | B8: 2000 | C8: 透射比示值误差与重复性校验 | D8: 2005 | E8: 10%中性滤光片 | F8: 635nm | G8: 0.3 | H8: 0.15
A9: T700S | B9: 2000 | C9: 透射比示值误差与重复性校验 | D9: 2006 | E9: 10%中性滤光片 | F9: 546nm | G9: 0.3 | H9: 0.15
A10: T700S | B10: 2000 | C10: 透射比示值误差与重复性校验 | D10: 2007 | E10: 10%中性滤光片 | F10: 440nm | G10: 0.3 | H10: 0.15
A11: T700S | B11: 2000 | C11: 透射比示值误差与重复性校验 | D11: 2008 | E11: 20%中性滤光片 | F11: 635nm | G11: 0.3 | H11: 0.15
A12: T700S | B12: 2000 | C12: 透射比示值误差与重复性校验 | D12: 2009 | E12: 20%中性滤光片 | F12: 546nm | G12: 0.3 | H12: 0.15
A13: T700S | B13: 2000 | C13: 透射比示值误差与重复性校验 | D13: 2010 | E13: 20%中性滤光片 | F13: 440nm | G13: 0.3 | H13: 0.15
A14: T700S | B14: 2000 | C14: 透射比示值误差与重复性校验 | D14: 2011 | E14: 30%中性滤光片 | F14: 635nm | G14: 0.3 | H14: 0.15
A15: T700S | B15: 2000 | C15: 透射比示值误差与重复性校验 | D15: 2012 | E15: 30%中性滤光片 | F15: 546nm | G15: 0.3 | H15: 0.15
A16: T700S | B16: 2000 | C16: 透射比示值误差与重复性校验 | D16: 2013 | E16: 30%中性滤光片 | F16: 440nm | G16: 0.3 | H16: 0.15
A17: T700S | B17: 3000 | C17: 杂散光校验 | D17: 3002 | E17: 亚硝酸钠标准溶液 | F17: 360nm | G17: 0.05
A18: T700S | B18: 4000 | C18: 基线平直度检验 | D18: 4001 | E18: 基线平直度 | G18: 0.002
A19: T700S | B19: 5000 | C19: 基线暗噪声检验 | D19: 5001 | E19: 基线暗噪声 | G19: 0.5
A20: T700S | B20: 7000 | C20: 噪声检验 | D20: 7001 | E20: 500nm100%噪声 | F20: 500 | G20: 0.15
A21: T700S | B21: 7000 | C21: 噪声检验 | D21: 7002 | E21: 500nm0%噪声 | F21: 500 | G21: 0.05
A22: T700S | B22: 8000 | C22: 波长边缘噪声 | D22: 8001 | E22: 1090nm100%噪声 | F22: 1090 | G22: 1
A23: T700S | B23: 8000 | C23: 波长边缘噪声 | D23: 8002 | E23: 1090nm0%噪声 | F23: 1090 | G23: 0.3
A24: T700S | B24: 8000 | C24: 波长边缘噪声 | D24: 8003 | E24: 335nm100%噪声 | F24: 200 | G24: 1
A25: T700S | B25: 8000 | C25: 波长边缘噪声 | D25: 8004 | E25: 335nm0%噪声 | F25: 200 | G25: 0.3
A26: T700S | B26: 9000 | C26: 漂移检验 | D26: 9001 | E26: 漂移检验 | F26: 500nm | G26: 0.2

Sheet 对应信息
A1: 产品编号 | B1: 产品型号 | D1: 父项目名称 | E1: 父项目编号
A2: 1401 | B2: T400 | D2: 波长示值误差与重复性校验 | E2: 1000
A3: 1501 | B3: T500 | D3: 透射比示值误差与重复性校验 | E3: 2000
A4: 1610 | B4: T6新悦 | D4: 杂散光校验 | E4: 3000
A5: 1650 | B5: T6新世纪 | D5: 基线平直度检验 | E5: 4000
D6: 基线暗噪声检验 | E6: 5000
D7: 光谱带宽与仪器最小光谱带宽 | E7: 6000
D8: 噪声检验 | E8: 7000
D9: 波长边缘噪声 | E9: 8000
D10: 漂移检验 | E10: 9000

Sheet 检测项信息
A1: 检测类别 | B1: 项目名称 | C1: 提示 | D1: 方法信息 | E1: 测量信息 | F1: 重复次数 | G1: 重复时间间隔 | H1: 特征值 | I1: 分析方法 | J1: 分析方法 | K1: 灯状态 | L1: 光度模式 | M1: 扫描速度 | N1: 起始波长 | O1: 终止波长 | P1: 扫描间隔 | Q1: 增益 | R1: 光谱带宽 | S1: 时间间隔 | T1: 扫描个数 | U1: 响应时间 | V1: 是否为光谱扫描 | W1: 暗电流物质 | X1: 校零物质 | Y1: 测量物质 | Z1: 父项目编号 | AA1: 子项目编号 | AB1: 标准值
A2: 波长示值误差与重复性校验 | B2: 镨钕滤光片 | D2: =IF(L2="","",字段对应!$B$10&"="&VLOOKUP(L2,基础信息!$I$2:$J$6,2,0)&";")&IF(M2="","",字段对应!$B$11&"="&VLOOKUP(M2,基础信息!$K$2:$L$6,2,0)&";")&IF(N2="","",字段对应!$C$2&"="&N2&","&O2&","&P2&";")&IF(Q2="","",字段对应!$B$13&"="&Q2&";")&IF(R2="","",字段对应!$B$14&"="&R2&";")&IF(U2="","",字段对应!$B$22&"="&U2&";")&IF(K2="","",字段对应!$B$21&"="&VLOOKUP(K2,基础信息!$F$2:$G$4,2,0)) -> PhotoMode=0;ScanSpeed=2;WlRange=810,800,0.2;LampPos=0 | E2: =IF(W2="","",检测项信息!W2&":"&字段对应!$B$16&"|")&IF(X2="","",X2&":"&IF(V2="是",字段对应!$C$17,字段对应!$B$17&";"&IF(H2="","",字段对应!$B$15&"="&检测项信息!H2))&"|")&IF(Y2="",":",Y2&":")&IF(V2="是",字段对应!$C$18,字段对应!$B$18&";"&IF(H2="","",字段对应!$B$15&"="&检测项信息!H2)&IF(AND(T2="",S2=""),"",";"&字段对应!$B$20&"="&T2&";"&字段对应!$B$19&"="&S2)) -> 黑挡块:Dark|空气:BaseLine|镨钕滤光片:Scan | F2: 3 | G2: 1 | H2: 807.4 | I2: =VLOOKUP(J2,字段对应!$D$2:$E$8,2,0) -> Validation.ViewModel.DataStructure.FindPeakAndAverageUVTestTool | J2: 寻峰 | K2: 钨灯 | L2: Abs | M2: 慢速 | N2: 810 | O2: 800 | P2: 0.2 | V2: 是 | W2: 黑挡块 | X2: 空气 | Y2: 镨钕滤光片 | Z2: =VLOOKUP(A2,对应信息!$D$2:$E$10,2,0) -> 1000 | AA2: =IF(Z1=Z2,AA1+1,Z2+1) -> 1001
A3: 波长示值误差与重复性校验 | B3: 钬溶液 | D3: =IF(L3="","",字段对应!$B$10&"="&VLOOKUP(L3,基础信息!$I$2:$J$6,2,0)&";")&IF(M3="","",字段对应!$B$11&"="&VLOOKUP(M3,基础信息!$K$2:$L$6,2,0)&";")&IF(N3="","",字段对应!$C$2&"="&N3&","&O3&","&P3&";")&IF(Q3="","",字段对应!$B$13&"="&Q3&";")&IF(R3="","",字段对应!$B$14&"="&R3&";")&IF(U3="","",字段对应!$B$22&"="&U3&";")&IF(K3="","",字段对应!$B$21&"="&VLOOKUP(K3,基础信息!$F$2:$G$4,2,0)) -> PhotoMode=0;ScanSpeed=1;WlRange=645,335,0.2; | E3: =IF(W3="","",检测项信息!W3&":"&字段对应!$B$16&"|")&IF(X3="","",X3&":"&IF(V3="是",字段对应!$C$17,字段对应!$B$17&";"&IF(H3="","",字段对应!$B$15&"="&检测项信息!H3))&"|")&IF(Y3="",":",Y3&":")&IF(V3="是",字段对应!$C$18,字段对应!$B$18&";"&IF(H3="","",字段对应!$B$15&"="&检测项信息!H3)&IF(AND(T3="",S3=""),"",";"&字段对应!$B$20&"="&T3&";"&字段对应!$B$19&"="&S3)) -> 黑挡块:Dark|空气:BaseLine|钬溶液:Scan | F3: 3 | G3: 1 | H3: 640.7,536.8,416.5,361.0 | I3: =VLOOKUP(J3,字段对应!$D$2:$E$8,2,0) -> Validation.ViewModel.DataStructure.FindPeakAndAverageUVTestTool | J3: 寻峰 | L3: Abs | M3: 中速 | N3: 645 | O3: 335 | P3: 0.2 | V3: 是 | W3: 黑挡块 | X3: 空气 | Y3: 钬溶液 | Z3: =VLOOKUP(A3,对应信息!$D$2:$E$10,2,0) -> 1000 | AA3: =IF(Z2=Z3,AA2+1,Z3+1) -> 1002
A4: 基线平直度检验 | B4: 基线平直度 | D4: =IF(L4="","",字段对应!$B$10&"="&VLOOKUP(L4,基础信息!$I$2:$J$6,2,0)&";")&IF(M4="","",字段对应!$B$11&"="&VLOOKUP(M4,基础信息!$K$2:$L$6,2,0)&";")&IF(N4="","",字段对应!$C$2&"="&N4&","&O4&","&P4&";")&IF(Q4="","",字段对应!$B$13&"="&Q4&";")&IF(R4="","",字段对应!$B$14&"="&R4&";")&IF(U4="","",字段对应!$B$22&"="&U4&";")&IF(K4="","",字段对应!$B$21&"="&VLOOKUP(K4,基础信息!$F$2:$G$4,2,0)) -> PhotoMode=0;ScanSpeed=2;WlRange=1090,335,1; | E4: =IF(W4="","",检测项信息!W4&":"&字段对应!$B$16&"|")&IF(X4="","",X4&":"&IF(V4="是",字段对应!$C$17,字段对应!$B$17&";"&IF(H4="","",字段对应!$B$15&"="&检测项信息!H4))&"|")&IF(Y4="",":",Y4&":")&IF(V4="是",字段对应!$C$18,字段对应!$B$18&";"&IF(H4="","",字段对应!$B$15&"="&检测项信息!H4)&IF(AND(T4="",S4=""),"",";"&字段对应!$B$20&"="&T4&";"&字段对应!$B$19&"="&S4)) -> 黑挡块:Dark|空气:BaseLine|空气:Scan | F4: 1 | I4: =VLOOKUP(J4,字段对应!$D$2:$E$8,2,0) -> Validation.ViewModel.DataStructure.GetMaxDIstanceUVTestTool | J4: 求最大偏移量 | L4: Abs | M4: 慢速 | N4: 1090 | O4: 335 | P4: 1 | V4: 是 | W4: 黑挡块 | X4: 空气 | Y4: 空气 | Z4: =VLOOKUP(A4,对应信息!$D$2:$E$10,2,0) -> 4000 | AA4: =IF(Z3=Z4,AA3+1,Z4+1) -> 4001
A5: 基线暗噪声检验 | B5: 基线暗噪声 | D5: =IF(L5="","",字段对应!$B$10&"="&VLOOKUP(L5,基础信息!$I$2:$J$6,2,0)&";")&IF(M5="","",字段对应!$B$11&"="&VLOOKUP(M5,基础信息!$K$2:$L$6,2,0)&";")&IF(N5="","",字段对应!$C$2&"="&N5&","&O5&","&P5&";")&IF(Q5="","",字段对应!$B$13&"="&Q5&";")&IF(R5="","",字段对应!$B$14&"="&R5&";")&IF(U5="","",字段对应!$B$22&"="&U5&";")&IF(K5="","",字段对应!$B$21&"="&VLOOKUP(K5,基础信息!$F$2:$G$4,2,0)) -> PhotoMode=1;ScanSpeed=2;WlRange=1090,335,1; | E5: =IF(W5="","",检测项信息!W5&":"&字段对应!$B$16&"|")&IF(X5="","",X5&":"&IF(V5="是",字段对应!$C$17,字段对应!$B$17&";"&IF(H5="","",字段对应!$B$15&"="&检测项信息!H5))&"|")&IF(Y5="",":",Y5&":")&IF(V5="是",字段对应!$C$18,字段对应!$B$18&";"&IF(H5="","",字段对应!$B$15&"="&检测项信息!H5)&IF(AND(T5="",S5=""),"",";"&字段对应!$B$20&"="&T5&";"&字段对应!$B$19&"="&S5)) -> 黑挡块:Dark|空气:BaseLine|黑挡块:Scan | F5: 1 | I5: =VLOOKUP(J5,字段对应!$D$2:$E$8,2,0) -> Validation.ViewModel.DataStructure.GetMaxDIstanceUVTestTool | J5: 求最大偏移量 | L5: T% | M5: 慢速 | N5: 1090 | O5: 335 | P5: 1 | V5: 是 | W5: 黑挡块 | X5: 空气 | Y5: 黑挡块 | Z5: =VLOOKUP(A5,对应信息!$D$2:$E$10,2,0) -> 5000 | AA5: =IF(Z4=Z5,AA4+1,Z5+1) -> 5001
A6: 噪声检验 | B6: 500nm100%噪声 | D6: =IF(L6="","",字段对应!$B$10&"="&VLOOKUP(L6,基础信息!$I$2:$J$6,2,0)&";")&IF(M6="","",字段对应!$B$11&"="&VLOOKUP(M6,基础信息!$K$2:$L$6,2,0)&";")&IF(N6="","",字段对应!$C$2&"="&N6&","&O6&","&P6&";")&IF(Q6="","",字段对应!$B$13&"="&Q6&";")&IF(R6="","",字段对应!$B$14&"="&R6&";")&IF(U6="","",字段对应!$B$22&"="&U6&";")&IF(K6="","",字段对应!$B$21&"="&VLOOKUP(K6,基础信息!$F$2:$G$4,2,0)) -> PhotoMode=1;ScanSpeed=1;ResponseTime=0.5; | E6: =IF(W6="","",检测项信息!W6&":"&字段对应!$B$16&"|")&IF(X6="","",X6&":"&IF(V6="是",字段对应!$C$17,字段对应!$B$17&";"&IF(H6="","",字段对应!$B$15&"="&检测项信息!H6))&"|")&IF(Y6="",":",Y6&":")&IF(V6="是",字段对应!$C$18,字段对应!$B$18&";"&IF(H6="","",字段对应!$B$15&"="&检测项信息!H6)&IF(AND(T6="",S6=""),"",";"&字段对应!$B$20&"="&T6&";"&字段对应!$B$19&"="&S6)) -> 黑挡块:Dark|空气:Zero;Wl=500|空气:Measure;Wl=500;totalcount=120;timeinterval=1 | F6: 1 | H6: 500 | I6: =VLOOKUP(J6,字段对应!$D$2:$E$8,2,0) -> Validation.ViewModel.DataStructure.FindMaxOffsetUVTestTool | J6: 最大最小值差 | L6: T% | M6: 中速 | S6: 1 | T6: 120 | U6: 0.5 | V6: 否 | W6: 黑挡块 | X6: 空气 | Y6: 空气 | Z6: =VLOOKUP(A6,对应信息!$D$2:$E$10,2,0) -> 7000 | AA6: =IF(Z5=Z6,AA5+1,Z6+1) -> 7001
A7: 噪声检验 | B7: 500nm0%噪声 | D7: =IF(L7="","",字段对应!$B$10&"="&VLOOKUP(L7,基础信息!$I$2:$J$6,2,0)&";")&IF(M7="","",字段对应!$B$11&"="&VLOOKUP(M7,基础信息!$K$2:$L$6,2,0)&";")&IF(N7="","",字段对应!$C$2&"="&N7&","&O7&","&P7&";")&IF(Q7="","",字段对应!$B$13&"="&Q7&";")&IF(R7="","",字段对应!$B$14&"="&R7&";")&IF(U7="","",字段对应!$B$22&"="&U7&";")&IF(K7="","",字段对应!$B$21&"="&VLOOKUP(K7,基础信息!$F$2:$G$4,2,0)) -> PhotoMode=1;ScanSpeed=1;ResponseTime=0.5; | E7: =IF(W7="","",检测项信息!W7&":"&字段对应!$B$16&"|")&IF(X7="","",X7&":"&IF(V7="是",字段对应!$C$17,字段对应!$B$17&";"&IF(H7="","",字段对应!$B$15&"="&检测项信息!H7))&"|")&IF(Y7="",":",Y7&":")&IF(V7="是",字段对应!$C$18,字段对应!$B$18&";"&IF(H7="","",字段对应!$B$15&"="&检测项信息!H7)&IF(AND(T7="",S7=""),"",";"&字段对应!$B$20&"="&T7&";"&字段对应!$B$19&"="&S7)) -> 黑挡块:Dark|空气:Zero;Wl=500|黑挡块:Measure;Wl=500;totalcount=120;timeinterval=1 | F7: 1 | H7: 500 | I7: =VLOOKUP(J7,字段对应!$D$2:$E$8,2,0) -> Validation.ViewModel.DataStructure.FindMaxOffsetUVTestTool | J7: 最大最小值差 | L7: T% | M7: 中速 | S7: 1 | T7: 120 | U7: 0.5 | V7: 否 | W7: 黑挡块 | X7: 空气 | Y7: 黑挡块 | Z7: =VLOOKUP(A7,对应信息!$D$2:$E$10,2,0) -> 7000 | AA7: =IF(Z6=Z7,AA6+1,Z7+1) -> 7002
A8: 波长边缘噪声 | B8: 1090nm100%噪声 | D8: =IF(L8="","",字段对应!$B$10&"="&VLOOKUP(L8,基础信息!$I$2:$J$6,2,0)&";")&IF(M8="","",字段对应!$B$11&"="&VLOOKUP(M8,基础信息!$K$2:$L$6,2,0)&";")&IF(N8="","",字段对应!$C$2&"="&N8&","&O8&","&P8&";")&IF(Q8="","",字段对应!$B$13&"="&Q8&";")&IF(R8="","",字段对应!$B$14&"="&R8&";")&IF(U8="","",字段对应!$B$22&"="&U8&";")&IF(K8="","",字段对应!$B$21&"="&VLOOKUP(K8,基础信息!$F$2:$G$4,2,0)) -> PhotoMode=1;ScanSpeed=1;ResponseTime=0.5; | E8: =IF(W8="","",检测项信息!W8&":"&字段对应!$B$16&"|")&IF(X8="","",X8&":"&IF(V8="是",字段对应!$C$17,字段对应!$B$17&";"&IF(H8="","",字段对应!$B$15&"="&检测项信息!H8))&"|")&IF(Y8="",":",Y8&":")&IF(V8="是",字段对应!$C$18,字段对应!$B$18&";"&IF(H8="","",字段对应!$B$15&"="&检测项信息!H8)&IF(AND(T8="",S8=""),"",";"&字段对应!$B$20&"="&T8&";"&字段对应!$B$19&"="&S8)) -> 黑挡块:Dark|空气:Zero;Wl=1090|空气:Measure;Wl=1090;totalcount=180;timeinterval=1 | F8: 1 | H8: 1090 | I8: =VLOOKUP(J8,字段对应!$D$2:$E$8,2,0) -> Validation.ViewModel.DataStructure.FindMaxOffsetUVTestTool | J8: 最大最小值差 | L8: T% | M8: 中速 | S8: 1 | T8: 180 | U8: 0.5 | V8: 否 | W8: 黑挡块 | X8: 空气 | Y8: 空气 | Z8: =VLOOKUP(A8,对应信息!$D$2:$E$10,2,0) -> 8000 | AA8: =IF(Z7=Z8,AA7+1,Z8+1) -> 8001
A9: 波长边缘噪声 | B9: 1090nm0%噪声 | D9: =IF(L9="","",字段对应!$B$10&"="&VLOOKUP(L9,基础信息!$I$2:$J$6,2,0)&";")&IF(M9="","",字段对应!$B$11&"="&VLOOKUP(M9,基础信息!$K$2:$L$6,2,0)&";")&IF(N9="","",字段对应!$C$2&"="&N9&","&O9&","&P9&";")&IF(Q9="","",字段对应!$B$13&"="&Q9&";")&IF(R9="","",字段对应!$B$14&"="&R9&";")&IF(U9="","",字段对应!$B$22&"="&U9&";")&IF(K9="","",字段对应!$B$21&"="&VLOOKUP(K9,基础信息!$F$2:$G$4,2,0)) -> PhotoMode=1;ScanSpeed=1;ResponseTime=0.5; | E9: =IF(W9="","",检测项信息!W9&":"&字段对应!$B$16&"|")&IF(X9="","",X9&":"&IF(V9="是",字段对应!$C$17,字段对应!$B$17&";"&IF(H9="","",字段对应!$B$15&"="&检测项信息!H9))&"|")&IF(Y9="",":",Y9&":")&IF(V9="是",字段对应!$C$18,字段对应!$B$18&";"&IF(H9="","",字段对应!$B$15&"="&检测项信息!H9)&IF(AND(T9="",S9=""),"",";"&字段对应!$B$20&"="&T9&";"&字段对应!$B$19&"="&S9)) -> 黑挡块:Dark|空气:Zero;Wl=1090|黑挡块:Measure;Wl=1090;totalcount=180;timeinterval=1 | F9: 1 | H9: 1090 | I9: =VLOOKUP(J9,字段对应!$D$2:$E$8,2,0) -> Validation.ViewModel.DataStructure.FindMaxOffsetUVTestTool | J9: 最大最小值差 | L9: T% | M9: 中速 | S9: 1 | T9: 180 | U9: 0.5 | V9: 否 | W9: 黑挡块 | X9: 空气 | Y9: 黑挡块 | Z9: =VLOOKUP(A9,对应信息!$D$2:$E$10,2,0) -> 8000 | AA9: =IF(Z8=Z9,AA8+1,Z9+1) -> 8002
A10: 波长边缘噪声 | B10: 335nm100%噪声 | D10: =IF(L10="","",字段对应!$B$10&"="&VLOOKUP(L10,基础信息!$I$2:$J$6,2,0)&";")&IF(M10="","",字段对应!$B$11&"="&VLOOKUP(M10,基础信息!$K$2:$L$6,2,0)&";")&IF(N10="","",字段对应!$C$2&"="&N10&","&O10&","&P10&";")&IF(Q10="","",字段对应!$B$13&"="&Q10&";")&IF(R10="","",字段对应!$B$14&"="&R10&";")&IF(U10="","",字段对应!$B$22&"="&U10&";")&IF(K10="","",字段对应!$B$21&"="&VLOOKUP(K10,基础信息!$F$2:$G$4,2,0)) -> PhotoMode=1;ScanSpeed=1;ResponseTime=0.5; | E10: =IF(W10="","",检测项信息!W10&":"&字段对应!$B$16&"|")&IF(X10="","",X10&":"&IF(V10="是",字段对应!$C$17,字段对应!$B$17&";"&IF(H10="","",字段对应!$B$15&"="&检测项信息!H10))&"|")&IF(Y10="",":",Y10&":")&IF(V10="是",字段对应!$C$18,字段对应!$B$18&";"&IF(H10="","",字段对应!$B$15&"="&检测项信息!H10)&IF(AND(T10="",S10=""),"",";"&字段对应!$B$20&"="&T10&";"&字段对应!$B$19&"="&S10)) -> 黑挡块:Dark|空气:Zero;Wl=335|空气:Measure;Wl=335;totalcount=180;timeinterval=1 | F10: 1 | H10: 335 | I10: =VLOOKUP(J10,字段对应!$D$2:$E$8,2,0) -> Validation.ViewModel.DataStructure.FindMaxOffsetUVTestTool | J10: 最大最小值差 | L10: T% | M10: 中速 | S10: 1 | T10: 180 | U10: 0.5 | V10: 否 | W10: 黑挡块 | X10: 空气 | Y10: 空气 | Z10: =VLOOKUP(A10,对应信息!$D$2:$E$10,2,0) -> 8000 | AA10: =IF(Z9=Z10,AA9+1,Z10+1) -> 8003
A11: 波长边缘噪声 | B11: 335nm0%噪声 | D11: =IF(L11="","",字段对应!$B$10&"="&VLOOKUP(L11,基础信息!$I$2:$J$6,2,0)&";")&IF(M11="","",字段对应!$B$11&"="&VLOOKUP(M11,基础信息!$K$2:$L$6,2,0)&";")&IF(N11="","",字段对应!$C$2&"="&N11&","&O11&","&P11&";")&IF(Q11="","",字段对应!$B$13&"="&Q11&";")&IF(R11="","",字段对应!$B$14&"="&R11&";")&IF(U11="","",字段对应!$B$22&"="&U11&";")&IF(K11="","",字段对应!$B$21&"="&VLOOKUP(K11,基础信息!$F$2:$G$4,2,0)) -> PhotoMode=1;ScanSpeed=1;ResponseTime=0.5; | E11: =IF(W11="","",检测项信息!W11&":"&字段对应!$B$16&"|")&IF(X11="","",X11&":"&IF(V11="是",字段对应!$C$17,字段对应!$B$17&";"&IF(H11="","",字段对应!$B$15&"="&检测项信息!H11))&"|")&IF(Y11="",":",Y11&":")&IF(V11="是",字段对应!$C$18,字段对应!$B$18&";"&IF(H11="","",字段对应!$B$15&"="&检测项信息!H11)&IF(AND(T11="",S11=""),"",";"&字段对应!$B$20&"="&T11&";"&字段对应!$B$19&"="&S11)) -> 黑挡块:Dark|空气:Zero;Wl=335|黑挡块:Measure;Wl=335;totalcount=180;timeinterval=1 | F11: 1 | H11: 335 | I11: =VLOOKUP(J11,字段对应!$D$2:$E$8,2,0) -> Validation.ViewModel.DataStructure.FindMaxOffsetUVTestTool | J11: 最大最小值差 | L11: T% | M11: 中速 | S11: 1 | T11: 180 | U11: 0.5 | V11: 否 | W11: 黑挡块 | X11: 空气 | Y11: 黑挡块 | Z11: =VLOOKUP(A11,对应信息!$D$2:$E$10,2,0) -> 8000 | AA11: =IF(Z10=Z11,AA10+1,Z11+1) -> 8004
A12: 杂散光校验 | B12: 360nm杂散光 | D12: =IF(L12="","",字段对应!$B$10&"="&VLOOKUP(L12,基础信息!$I$2:$J$6,2,0)&";")&IF(M12="","",字段对应!$B$11&"="&VLOOKUP(M12,基础信息!$K$2:$L$6,2,0)&";")&IF(N12="","",字段对应!$C$2&"="&N12&","&O12&","&P12&";")&IF(Q12="","",字段对应!$B$13&"="&Q12&";")&IF(R12="","",字段对应!$B$14&"="&R12&";")&IF(U12="","",字段对应!$B$22&"="&U12&";")&IF(K12="","",字段对应!$B$21&"="&VLOOKUP(K12,基础信息!$F$2:$G$4,2,0)) -> PhotoMode=1;ScanSpeed=1; | E12: =IF(W12="","",检测项信息!W12&":"&字段对应!$B$16&"|")&IF(X12="","",X12&":"&IF(V12="是",字段对应!$C$17,字段对应!$B$17&";"&IF(H12="","",字段对应!$B$15&"="&检测项信息!H12))&"|")&IF(Y12="",":",Y12&":")&IF(V12="是",字段对应!$C$18,字段对应!$B$18&";"&IF(H12="","",字段对应!$B$15&"="&检测项信息!H12)&IF(AND(T12="",S12=""),"",";"&字段对应!$B$20&"="&T12&";"&字段对应!$B$19&"="&S12)) -> 黑挡块:Dark|亚硝酸钠空白溶液:Zero;Wl=360|亚硝酸钠溶液:Measure;Wl=360 | F12: 3 | G12: 1 | H12: 360 | I12: =VLOOKUP(J12,字段对应!$D$2:$E$8,2,0) -> Validation.ViewModel.DataStructure.WlPointsUVTestTool | J12: 多次测量 | L12: T% | M12: 中速 | V12: 否 | W12: 黑挡块 | X12: 亚硝酸钠空白溶液 | Y12: 亚硝酸钠溶液 | Z12: =VLOOKUP(A12,对应信息!$D$2:$E$10,2,0) -> 3000 | AA12: =IF(Z11=Z12,AA11+1,Z12+1) -> 3001
A13: 透射比示值误差与重复性校验 | B13: 10%中性滤光片 | D13: =IF(L13="","",字段对应!$B$10&"="&VLOOKUP(L13,基础信息!$I$2:$J$6,2,0)&";")&IF(M13="","",字段对应!$B$11&"="&VLOOKUP(M13,基础信息!$K$2:$L$6,2,0)&";")&IF(N13="","",字段对应!$C$2&"="&N13&","&O13&","&P13&";")&IF(Q13="","",字段对应!$B$13&"="&Q13&";")&IF(R13="","",字段对应!$B$14&"="&R13&";")&IF(U13="","",字段对应!$B$22&"="&U13&";")&IF(K13="","",字段对应!$B$21&"="&VLOOKUP(K13,基础信息!$F$2:$G$4,2,0)) -> PhotoMode=1;ScanSpeed=1; | E13: =IF(W13="","",检测项信息!W13&":"&字段对应!$B$16&"|")&IF(X13="","",X13&":"&IF(V13="是",字段对应!$C$17,字段对应!$B$17&";"&IF(H13="","",字段对应!$B$15&"="&检测项信息!H13))&"|")&IF(Y13="",":",Y13&":")&IF(V13="是",字段对应!$C$18,字段对应!$B$18&";"&IF(H13="","",字段对应!$B$15&"="&检测项信息!H13)&IF(AND(T13="",S13=""),"",";"&字段对应!$B$20&"="&T13&";"&字段对应!$B$19&"="&S13)) -> 黑挡块:Dark|空气:Zero;Wl=635,546,440|10%中性滤光片:Measure;Wl=635,546,440 | F13: 3 | G13: 1 | H13: 635,546,440 | I13: =VLOOKUP(J13,字段对应!$D$2:$E$8,2,0) -> Validation.ViewModel.DataStructure.WlPointsAndAverageUVTestTool | J13: 求平均 | L13: T% | M13: 中速 | V13: 否 | W13: 黑挡块 | X13: 空气 | Y13: 10%中性滤光片 | Z13: =VLOOKUP(A13,对应信息!$D$2:$E$10,2,0) -> 2000 | AA13: =IF(Z12=Z13,AA12+1,Z13+1) -> 2001 | AB13: 7.57,10.1,10.07
A14: 透射比示值误差与重复性校验 | B14: 20%中性滤光片 | D14: =IF(L14="","",字段对应!$B$10&"="&VLOOKUP(L14,基础信息!$I$2:$J$6,2,0)&";")&IF(M14="","",字段对应!$B$11&"="&VLOOKUP(M14,基础信息!$K$2:$L$6,2,0)&";")&IF(N14="","",字段对应!$C$2&"="&N14&","&O14&","&P14&";")&IF(Q14="","",字段对应!$B$13&"="&Q14&";")&IF(R14="","",字段对应!$B$14&"="&R14&";")&IF(U14="","",字段对应!$B$22&"="&U14&";")&IF(K14="","",字段对应!$B$21&"="&VLOOKUP(K14,基础信息!$F$2:$G$4,2,0)) -> PhotoMode=1;ScanSpeed=1; | E14: =IF(W14="","",检测项信息!W14&":"&字段对应!$B$16&"|")&IF(X14="","",X14&":"&IF(V14="是",字段对应!$C$17,字段对应!$B$17&";"&IF(H14="","",字段对应!$B$15&"="&检测项信息!H14))&"|")&IF(Y14="",":",Y14&":")&IF(V14="是",字段对应!$C$18,字段对应!$B$18&";"&IF(H14="","",字段对应!$B$15&"="&检测项信息!H14)&IF(AND(T14="",S14=""),"",";"&字段对应!$B$20&"="&T14&";"&字段对应!$B$19&"="&S14)) -> 黑挡块:Dark|空气:Zero;Wl=635,546,440|20%中性滤光片:Measure;Wl=635,546,440 | F14: 3 | G14: 1 | H14: 635,546,440 | I14: =VLOOKUP(J14,字段对应!$D$2:$E$8,2,0) -> Validation.ViewModel.DataStructure.WlPointsAndAverageUVTestTool | J14: 求平均 | L14: T% | M14: 中速 | V14: 否 | W14: 黑挡块 | X14: 空气 | Y14: 20%中性滤光片 | Z14: =VLOOKUP(A14,对应信息!$D$2:$E$10,2,0) -> 2000 | AA14: =IF(Z13=Z14,AA13+1,Z14+1) -> 2002 | AB14: 18.89,20.09,20.91
A15: 透射比示值误差与重复性校验 | B15: 30%中性滤光片 | D15: =IF(L15="","",字段对应!$B$10&"="&VLOOKUP(L15,基础信息!$I$2:$J$6,2,0)&";")&IF(M15="","",字段对应!$B$11&"="&VLOOKUP(M15,基础信息!$K$2:$L$6,2,0)&";")&IF(N15="","",字段对应!$C$2&"="&N15&","&O15&","&P15&";")&IF(Q15="","",字段对应!$B$13&"="&Q15&";")&IF(R15="","",字段对应!$B$14&"="&R15&";")&IF(U15="","",字段对应!$B$22&"="&U15&";")&IF(K15="","",字段对应!$B$21&"="&VLOOKUP(K15,基础信息!$F$2:$G$4,2,0)) -> PhotoMode=1;ScanSpeed=1; | E15: =IF(W15="","",检测项信息!W15&":"&字段对应!$B$16&"|")&IF(X15="","",X15&":"&IF(V15="是",字段对应!$C$17,字段对应!$B$17&";"&IF(H15="","",字段对应!$B$15&"="&检测项信息!H15))&"|")&IF(Y15="",":",Y15&":")&IF(V15="是",字段对应!$C$18,字段对应!$B$18&";"&IF(H15="","",字段对应!$B$15&"="&检测项信息!H15)&IF(AND(T15="",S15=""),"",";"&字段对应!$B$20&"="&T15&";"&字段对应!$B$19&"="&S15)) -> 黑挡块:Dark|空气:Zero;Wl=635,546,440|30%中性滤光片:Measure;Wl=635,546,440 | F15: 3 | G15: 1 | H15: 635,546,440 | I15: =VLOOKUP(J15,字段对应!$D$2:$E$8,2,0) -> Validation.ViewModel.DataStructure.WlPointsAndAverageUVTestTool | J15: 求平均 | L15: T% | M15: 中速 | V15: 否 | W15: 黑挡块 | X15: 空气 | Y15: 30%中性滤光片 | Z15: =VLOOKUP(A15,对应信息!$D$2:$E$10,2,0) -> 2000 | AA15: =IF(Z14=Z15,AA14+1,Z15+1) -> 2003 | AB15: 29.96,30.43,28.88
A16: 漂移检验 | B16: 漂移检验 | C16: 仪器预热1小时之后进行检验 | D16: =IF(L16="","",字段对应!$B$10&"="&VLOOKUP(L16,基础信息!$I$2:$J$6,2,0)&";")&IF(M16="","",字段对应!$B$11&"="&VLOOKUP(M16,基础信息!$K$2:$L$6,2,0)&";")&IF(N16="","",字段对应!$C$2&"="&N16&","&O16&","&P16&";")&IF(Q16="","",字段对应!$B$13&"="&Q16&";")&IF(R16="","",字段对应!$B$14&"="&R16&";")&IF(U16="","",字段对应!$B$22&"="&U16&";")&IF(K16="","",字段对应!$B$21&"="&VLOOKUP(K16,基础信息!$F$2:$G$4,2,0)) -> PhotoMode=1;ScanSpeed=1;ResponseTime=0.5; | E16: =IF(W16="","",检测项信息!W16&":"&字段对应!$B$16&"|")&IF(X16="","",X16&":"&IF(V16="是",字段对应!$C$17,字段对应!$B$17&";"&IF(H16="","",字段对应!$B$15&"="&检测项信息!H16))&"|")&IF(Y16="",":",Y16&":")&IF(V16="是",字段对应!$C$18,字段对应!$B$18&";"&IF(H16="","",字段对应!$B$15&"="&检测项信息!H16)&IF(AND(T16="",S16=""),"",";"&字段对应!$B$20&"="&T16&";"&字段对应!$B$19&"="&S16)) -> 黑挡块:Dark|空气:Zero;Wl=500|空气:Measure;Wl=500;totalcount=3600;timeinterval=1 | F16: 1 | H16: 500 | I16: =VLOOKUP(J16,字段对应!$D$2:$E$8,2,0) -> Validation.ViewModel.DataStructure.FindMaxOffsetUVTestTool | J16: 最大最小值差 | L16: T% | M16: 中速 | S16: 1 | T16: 3600 | U16: 0.5 | V16: 否 | W16: 黑挡块 | X16: 空气 | Y16: 空气 | Z16: =VLOOKUP(A16,对应信息!$D$2:$E$10,2,0) -> 9000 | AA16: =IF(Z15=Z16,AA15+1,Z16+1) -> 9001

Sheet 仪器状态
A1: 仪器id | B1: 项目 | C1: 能量 | D1: id | E1: 父id
A2: =MID(CELL("filename"),FIND("[",CELL("filename"),1)+1,FIND(".",CELL("filename"),1)-FIND("[",CELL("filename"),1)-1) -> T400 | B2: 关灯，增益1下的RSD值
A3: =MID(CELL("filename"),FIND("[",CELL("filename"),1)+1,FIND(".",CELL("filename"),1)-FIND("[",CELL("filename"),1)-1) -> T400 | B3: 关灯，增益2下的RSD值
A4: =MID(CELL("filename"),FIND("[",CELL("filename"),1)+1,FIND(".",CELL("filename"),1)-FIND("[",CELL("filename"),1)-1) -> T400 | B4: 关灯，增益3下的RSD值
A5: =MID(CELL("filename"),FIND("[",CELL("filename"),1)+1,FIND(".",CELL("filename"),1)-FIND("[",CELL("filename"),1)-1) -> T400 | B5: 关灯，增益4下的RSD值
A6: =MID(CELL("filename"),FIND("[",CELL("filename"),1)+1,FIND(".",CELL("filename"),1)-FIND("[",CELL("filename"),1)-1) -> T400 | B6: 开灯，增益1下的RSD值
A7: =MID(CELL("filename"),FIND("[",CELL("filename"),1)+1,FIND(".",CELL("filename"),1)-FIND("[",CELL("filename"),1)-1) -> T400 | B7: 开灯，增益2下的RSD值
A8: =MID(CELL("filename"),FIND("[",CELL("filename"),1)+1,FIND(".",CELL("filename"),1)-FIND("[",CELL("filename"),1)-1) -> T400 | B8: 开灯，增益3下的RSD值
A9: =MID(CELL("filename"),FIND("[",CELL("filename"),1)+1,FIND(".",CELL("filename"),1)-FIND("[",CELL("filename"),1)-1) -> T400 | B9: 开灯，增益4下的RSD值
A10: =MID(CELL("filename"),FIND("[",CELL("filename"),1)+1,FIND(".",CELL("filename"),1)-FIND("[",CELL("filename"),1)-1) -> T400 | B10: 亚硝酸钠标准溶液-360nm能量 | D10: 3002 | E10: 3002
A11: =MID(CELL("filename"),FIND("[",CELL("filename"),1)+1,FIND(".",CELL("filename"),1)-FIND("[",CELL("filename"),1)-1) -> T400 | B11: 基线平直度-全波长能量 | D11: 4001 | E11: 4001

Sheet 样品池准确度与重复性校验

Sheet 标准值
A1: 测试项 | B1: 检测工具 | C1: 特征值 | D1: 标准值（%）
A2: 透射比示值误差与重复性校验 | B2: 10%中性滤光片 | C2: 635nm | D2: 7.57
C3: 546nm | D3: 10.1
C4: 440nm | D4: 10.07
B5: 20%中性滤光片 | C5: 635nm | D5: 18.98
C6: 546nm | D6: 20.09
C7: 440nm | D7: 20.91
B8: 30%中性滤光片 | C8: 635nm | D8: 29.96
C9: 546nm | D9: 30.43
C10: 440nm | D10: 28.88
A11: 波长示值误差与重复性校验 | B11: 镨钕滤光片 | C11: 807.4
B12: 钬溶液 | C12: 640.7
C13: 536.8
C14: 416.5
C15: 361.0
A17: 修改标准值时，该仪器对应的模板文件必须未打开，同时修改后光标要在未修改的单元格内！方可保存成功！

Sheet 字段对应
A1: 仪器方法标记 | B1: 仪器方法字段 | D1: 算法标记 | E1: 算法字段
A2: 起始波长 | B2: StartWl | C2: WlRange | D2: 寻峰 | E2: Validation.ViewModel.DataStructure.FindPeakAndAverageUVTestTool
A3: 终止波长 | B3: EndWl | D3: 求平均 | E3: Validation.ViewModel.DataStructure.WlPointsAndAverageUVTestTool
A4: 重复次数 | B4: RepeatTimes | D4: 多次测量 | E4: Validation.ViewModel.DataStructure.WlPointsUVTestTool
A5: 重复时间间隔 | B5: RepeatInterval | D5: 最大最小值差 | E5: Validation.ViewModel.DataStructure.FindMaxOffsetUVTestTool
A6: 方法信息 | B6: MethodStr | D6: 求半峰宽 | E6: Validation.ViewModel.DataStructure.FindHalfPeakUVTestTool
A7: 测量信息 | B7: MeasurePara | D7: 求最大偏移量 | E7: Validation.ViewModel.DataStructure.GetMaxDIstanceUVTestTool
A8: 使用物质 | B8: ToolStr | D8: 求漂移 | E8: Validation.ViewModel.DataStructure.GetDriftUVTestTool
A9: 项目名称 | B9: Name
A10: 光度模式 | B10: PhotoMode
A11: 扫描速度 | B11: ScanSpeed
A12: 扫描间隔 | B12: ScanWlInterval
A13: 增益 | B13: Gain
A14: 光谱带宽 | B14: Slit1
A15: 特征值 | B15: Wl
A16: 暗电流 | B16: Dark
A17: 校零 | B17: Zero | C17: BaseLine
A18: 测量 | B18: Measure | C18: Scan
A19: 时间间隔 | B19: timeinterval
A20: 扫描个数 | B20: totalcount
A21: 灯状态 | B21: LampPos
A22: 响应时间 | B22: ResponseTime

Sheet 波长示值误差与重复性校验
A1: 项目名称 | B1: 特征值（nm） | C1: 测量值（nm） | F1: 平均值（nm） | G1: 误差值（nm） | H1: 重复性（nm） | I1: 波长示值误差(nm) | J1: 波长重复性 | K1: 判定结果
A2: 镨钕滤光片 | B2: =标准值!C11 -> 807.4 | F2: =IFERROR(AVERAGE(C2:E2),"") | G2: =IFERROR(F2-B2,"") | H2: =MAX(C2:E2)-MIN(C2:E2) -> 0 | I2: 1.4 | J2: 0.4 | K2: =IF(C2="","未检测",IF(AND(ROUND(ABS(G2),1)<=ROUND(ABS(I2),1),ROUND(H2,1)<=ROUND(J2,1)),"合格","不合格")) -> 未检测
A3: 钬溶液 | B3: =标准值!C12 -> 640.7 | F3: =IFERROR(AVERAGE(C3:E3),"") | G3: =IFERROR(F3-B3,"") | H3: =MAX(C3:E3)-MIN(C3:E3) -> 0 | I3: 1.4 | J3: 0.4 | K3: =IF(C3="","未检测",IF(AND(ROUND(ABS(G3),1)<=ROUND(ABS(I3),1),ROUND(H3,1)<=ROUND(J3,1)),"合格","不合格")) -> 未检测
B4: =标准值!C13 -> 536.8 | F4: =IFERROR(AVERAGE(C4:E4),"") | G4: =IFERROR(F4-B4,"") | H4: =MAX(C4:E4)-MIN(C4:E4) -> 0 | I4: 1.4 | J4: 0.4 | K4: =IF(C4="","未检测",IF(AND(ROUND(ABS(G4),1)<=ROUND(ABS(I4),1),ROUND(H4,1)<=ROUND(J4,1)),"合格","不合格")) -> 未检测
B5: =标准值!C14 -> 416.5 | F5: =IFERROR(AVERAGE(C5:E5),"") | G5: =IFERROR(F5-B5,"") | H5: =MAX(C5:E5)-MIN(C5:E5) -> 0 | I5: 1.4 | J5: 0.4 | K5: =IF(C5="","未检测",IF(AND(ROUND(ABS(G5),1)<=ROUND(ABS(I5),1),ROUND(H5,1)<=ROUND(J5,1)),"合格","不合格")) -> 未检测
B6: =标准值!C15 -> 361.0 | F6: =IFERROR(AVERAGE(C6:E6),"") | G6: =IFERROR(F6-B6,"") | H6: =MAX(C6:E6)-MIN(C6:E6) -> 0 | I6: 1.4 | J6: 0.4 | K6: =IF(C6="","未检测",IF(AND(ROUND(ABS(G6),1)<=ROUND(ABS(I6),1),ROUND(H6,1)<=ROUND(J6,1)),"合格","不合格")) -> 未检测

Sheet 透射比示值误差与重复性校验
A1: 项目名称 | B1: 特征值(nm) | C1: 标准值（%） | D1: 测量值（%） | G1: 平均值（%） | H1: 误差值（%） | I1: 重复性（%） | J1: 透射比示值误差 | K1: 透射比重复性 | L1: 判定结果
A2: 10%中性滤光片 | B2: 635 | C2: =标准值!D2 -> 7.57 | G2: =IFERROR(AVERAGE(D2:F2),"") | H2: =IFERROR(G2-C2,"") | I2: =MAX(ROUND(D2,2),ROUND(E2,2),ROUND(F2,2))-MIN(ROUND(D2,2),ROUND(E2,2),ROUND(F2,2)) -> 0 | J2: 0.3 | K2: 0.15 | L2: =IF(D2="","未检测",IF(E2="","不合格",IF(F2="","不合格",IF(AND(ROUND(ABS(H2),2)<=ROUND(ABS(J2),2),ROUND(I2,2)<=ROUND(K2,2)),"合格","不合格")))) -> 未检测
B3: 546 | C3: =标准值!D3 -> 10.1 | G3: =IFERROR(AVERAGE(D3:F3),"") | H3: =IFERROR(G3-C3,"") | I3: =MAX(ROUND(D3,2),ROUND(E3,2),ROUND(F3,2))-MIN(ROUND(D3,2),ROUND(E3,2),ROUND(F3,2)) -> 0 | J3: 0.3 | K3: 0.15 | L3: =IF(D3="","未检测",IF(E3="","不合格",IF(F3="","不合格",IF(AND(ROUND(ABS(H3),2)<=ROUND(ABS(J3),2),ROUND(I3,2)<=ROUND(K3,2)),"合格","不合格")))) -> 未检测
B4: 440 | C4: =标准值!D4 -> 10.07 | G4: =IFERROR(AVERAGE(D4:F4),"") | H4: =IFERROR(G4-C4,"") | I4: =MAX(ROUND(D4,2),ROUND(E4,2),ROUND(F4,2))-MIN(ROUND(D4,2),ROUND(E4,2),ROUND(F4,2)) -> 0 | J4: 0.3 | K4: 0.15 | L4: =IF(D4="","未检测",IF(E4="","不合格",IF(F4="","不合格",IF(AND(ROUND(ABS(H4),2)<=ROUND(ABS(J4),2),ROUND(I4,2)<=ROUND(K4,2)),"合格","不合格")))) -> 未检测
A5: 20%中性滤光片 | B5: 635 | C5: =标准值!D5 -> 18.98 | G5: =IFERROR(AVERAGE(D5:F5),"") | H5: =IFERROR(G5-C5,"") | I5: =MAX(ROUND(D5,2),ROUND(E5,2),ROUND(F5,2))-MIN(ROUND(D5,2),ROUND(E5,2),ROUND(F5,2)) -> 0 | J5: 0.3 | K5: 0.15 | L5: =IF(D5="","未检测",IF(E5="","不合格",IF(F5="","不合格",IF(AND(ROUND(ABS(H5),2)<=ROUND(ABS(J5),2),ROUND(I5,2)<=ROUND(K5,2)),"合格","不合格")))) -> 未检测
B6: 546 | C6: =标准值!D6 -> 20.09 | G6: =IFERROR(AVERAGE(D6:F6),"") | H6: =IFERROR(G6-C6,"") | I6: =MAX(ROUND(D6,2),ROUND(E6,2),ROUND(F6,2))-MIN(ROUND(D6,2),ROUND(E6,2),ROUND(F6,2)) -> 0 | J6: 0.3 | K6: 0.15 | L6: =IF(D6="","未检测",IF(E6="","不合格",IF(F6="","不合格",IF(AND(ROUND(ABS(H6),2)<=ROUND(ABS(J6),2),ROUND(I6,2)<=ROUND(K6,2)),"合格","不合格")))) -> 未检测
B7: 440 | C7: =标准值!D7 -> 20.91 | G7: =IFERROR(AVERAGE(D7:F7),"") | H7: =IFERROR(G7-C7,"") | I7: =MAX(ROUND(D7,2),ROUND(E7,2),ROUND(F7,2))-MIN(ROUND(D7,2),ROUND(E7,2),ROUND(F7,2)) -> 0 | J7: 0.3 | K7: 0.15 | L7: =IF(D7="","未检测",IF(E7="","不合格",IF(F7="","不合格",IF(AND(ROUND(ABS(H7),2)<=ROUND(ABS(J7),2),ROUND(I7,2)<=ROUND(K7,2)),"合格","不合格")))) -> 未检测
A8: 30%中性滤光片 | B8: 635 | C8: =标准值!D8 -> 29.96 | G8: =IFERROR(AVERAGE(D8:F8),"") | H8: =IFERROR(G8-C8,"") | I8: =MAX(ROUND(D8,2),ROUND(E8,2),ROUND(F8,2))-MIN(ROUND(D8,2),ROUND(E8,2),ROUND(F8,2)) -> 0 | J8: 0.3 | K8: 0.15 | L8: =IF(D8="","未检测",IF(E8="","不合格",IF(F8="","不合格",IF(AND(ROUND(ABS(H8),2)<=ROUND(ABS(J8),2),ROUND(I8,2)<=ROUND(K8,2)),"合格","不合格")))) -> 未检测
B9: 546 | C9: =标准值!D9 -> 30.43 | G9: =IFERROR(AVERAGE(D9:F9),"") | H9: =IFERROR(G9-C9,"") | I9: =MAX(ROUND(D9,2),ROUND(E9,2),ROUND(F9,2))-MIN(ROUND(D9,2),ROUND(E9,2),ROUND(F9,2)) -> 0 | J9: 0.3 | K9: 0.15 | L9: =IF(D9="","未检测",IF(E9="","不合格",IF(F9="","不合格",IF(AND(ROUND(ABS(H9),2)<=ROUND(ABS(J9),2),ROUND(I9,2)<=ROUND(K9,2)),"合格","不合格")))) -> 未检测
B10: 440 | C10: =标准值!D10 -> 28.88 | G10: =IFERROR(AVERAGE(D10:F10),"") | H10: =IFERROR(G10-C10,"") | I10: =MAX(ROUND(D10,2),ROUND(E10,2),ROUND(F10,2))-MIN(ROUND(D10,2),ROUND(E10,2),ROUND(F10,2)) -> 0 | J10: 0.3 | K10: 0.15 | L10: =IF(D10="","未检测",IF(E10="","不合格",IF(F10="","不合格",IF(AND(ROUND(ABS(H10),2)<=ROUND(ABS(J10),2),ROUND(I10,2)<=ROUND(K10,2)),"合格","不合格")))) -> 未检测

Sheet 杂散光校验
A1: 项目名称 | B1: 波长点 | C1: 测量值（%） | F1: 指标要求 | G1: 判定结果
A2: 亚硝酸钠标准溶液 | B2: 360 | F2: 0.05 | G2: =IF(C2="","未检测",IF(D2="","不合格",IF(E2="","不合格",IF(ROUND(ABS(AVERAGE(C2:E2)),4)<ROUND(F2,4),"合格","不合格")))) -> 未检测

Sheet 基线平直度检验
A1: 项目名称 | B1: 测量值（Abs） | C1: 指标要求 | D1: 判定结果
A2: 基线平直度 | C2: 0.002 | D2: =IF(B2="","未检测",IF(OR(B2="",(ABS(B2)>C2)),"不合格","合格")) -> 未检测

Sheet 基线暗噪声检验
A1: 项目名称 | B1: 测量值（%） | C1: 指标要求 | D1: 判定结果
A2: 基线暗噪声 | C2: 0.5 | D2: =IF(B2="","未检测",IF(ABS(ROUND(B2,4))<ROUND(C2,4),"合格","不合格")) -> 未检测

Sheet 噪声检验
A1: 项目名称 | B1: 特征值 | C1: 测量值（%） | D1: 垂直距离范围 | E1: 判定结果
A2: 500nm100%噪声 | B2: 500 | D2: 0.15 | E2: =IF(C2="","未检测",IF(C2<=D2,"合格","不合格")) -> 未检测
A3: 500nm0%噪声 | B3: 500 | D3: 0.05 | E3: =IF(C3="","未检测",IF(C3<=D3,"合格","不合格")) -> 未检测

Sheet 波长边缘噪声
A1: 项目名称 | B1: 测量波长 | C1: 测量值（%） | D1: 垂直距离范围 | E1: 判定结果
A2: 1090nm100%噪声 | B2: 1090 | D2: 1 | E2: =IF(C2="","未检测",IF(C2<=D2,"合格","不合格")) -> 未检测
A3: 1090nm0%噪声 | B3: 1090 | D3: 0.3 | E3: =IF(C3="","未检测",IF(C3<=D3,"合格","不合格")) -> 未检测
A4: 335nm100%噪声 | B4: 335 | D4: 1 | E4: =IF(C4="","未检测",IF(C4<=D4,"合格","不合格")) -> 未检测
A5: 335nm0%噪声 | B5: 335 | D5: 0.3 | E5: =IF(C5="","未检测",IF(C5<=D5,"合格","不合格")) -> 未检测

Sheet 漂移检验
A1: 项目名称 | B1: 测量波长 | C1: 测量值（%） | D1: 指标要求 | E1: 判定结果
A2: 漂移检验 | B2: 500 | D2: 0.2 | E2: =IF(C2="","未检测",IF(C2<=D2,"合格","不合格")) -> 未检测
A3: 漂移检验 | B3: 500 | D3: 0.2 | E3: =IF(C3="","未检测",IF(C3<=D3,"合格","不合格")) -> 未检测
A4: 漂移检验 | B4: 500 | D4: 0.2 | E4: =IF(C4="","未检测",IF(C4<=D4,"合格","不合格")) -> 未检测
A5: 漂移检验 | B5: 500 | D5: 0.2 | E5: =IF(C5="","未检测",IF(C5<=D5,"合格","不合格")) -> 未检测
A6: 漂移检验 | B6: 500 | D6: 0.2 | E6: =IF(C6="","未检测",IF(C6<=D6,"合格","不合格")) -> 未检测
A7: 漂移检验 | B7: 500 | D7: 0.2 | E7: =IF(C7="","未检测",IF(C7<=D7,"合格","不合格")) -> 未检测
A8: 漂移检验 | B8: 500 | D8: 0.2 | E8: =IF(C8="","未检测",IF(C8<=D8,"合格","不合格")) -> 未检测
A9: 漂移检验 | B9: 500 | D9: 0.2 | E9: =IF(C9="","未检测",IF(C9<=D9,"合格","不合格")) -> 未检测
A10: 漂移检验 | B10: 500 | D10: 0.2 | E10: =IF(C10="","未检测",IF(C10<=D10,"合格","不合格")) -> 未检测
A11: 漂移检验 | B11: 500 | D11: 0.2 | E11: =IF(C11="","未检测",IF(C11<=D11,"合格","不合格")) -> 未检测
