Workbook
Name OLE_LINK10: Report!#REF!

Sheet Report
C1: 北京普析通用仪器有限责任公司 | L1: 文件编号 | N1: KF/R-01-003
C2: T500系列紫外可见分光光度计整机检验原始记录表 | L2: 版本/修订 | N2: B/0
L3: 发布/修订日期 | N3: 41010
A4: 产品型号 | D4: 产品编号 | H4: 检验员 | L4: 检验日期 | N4: 复核员
A5: =IFERROR(VLOOKUP(MID(D5,5,4),对应信息!A:B,2,0),"")
A6: 温度(℃) | E6: 相对湿度(%) | L6: 检验结果
A7: 序号 | B7: 检验项目 | E7: 结果
A8: 1 | B8: 波长示值误差与重复性 | C8: 波长示值误差 氘灯： ±1.0nm 镨钕： ±1.0nm 波长重复性 ≤0.2nm | E8: 波长段 | H8: B段
E9: 检测工具 | H9: 镨钕滤光片 | K9: 氘灯 | M9: 氘灯
E10: 标准值(nm) | H10: =波长示值误差与重复性校验!B4 -> 807.4 | K10: =波长示值误差与重复性校验!B2 -> 656.1 | M10: =波长示值误差与重复性校验!B3 -> 486
E11: 测量值（nm） | H11: =波长示值误差与重复性校验!C4 -> 0 | K11: =波长示值误差与重复性校验!C2 -> 0 | M11: =波长示值误差与重复性校验!C3 -> 0
H12: =波长示值误差与重复性校验!D4 -> 0 | K12: =波长示值误差与重复性校验!D2 -> 0 | M12: =波长示值误差与重复性校验!D3 -> 0
H13: =波长示值误差与重复性校验!E4 -> 0 | K13: =波长示值误差与重复性校验!E2 -> 0 | M13: =波长示值误差与重复性校验!E3 -> 0
E14: 平均值(nm) | H14: =波长示值误差与重复性校验!F4 | K14: =波长示值误差与重复性校验!F2 | M14: =波长示值误差与重复性校验!F3
E15: 误差值(nm) | H15: =波长示值误差与重复性校验!G4 | K15: =波长示值误差与重复性校验!G2 | M15: =波长示值误差与重复性校验!G3
E16: 重复性(nm) | H16: =波长示值误差与重复性校验!H4 -> 0 | K16: =波长示值误差与重复性校验!H2 -> 0 | M16: =波长示值误差与重复性校验!H3 -> 0
B17: 波长示值误差与重复性 | C17: 波长示值误差 钬溶液： ±1.0nm 波长重复性 ≤0.2nm | E17: 检测工具 | H17: 钬溶液
E18: 标准值(nm) | H18: =波长示值误差与重复性校验!B5 -> 640.7 | J18: =波长示值误差与重复性校验!B6 -> 536.8 | K18: =波长示值误差与重复性校验!B7 -> 416.5 | L18: =波长示值误差与重复性校验!B8 -> 361.0 | M18: =波长示值误差与重复性校验!B9 -> 287.4 | N18: =波长示值误差与重复性校验!B10 -> 241.0
E20: 测量值（nm） | H20: =波长示值误差与重复性校验!C5 -> 0 | J20: =波长示值误差与重复性校验!C6 -> 0 | K20: =波长示值误差与重复性校验!C7 -> 0 | L20: =波长示值误差与重复性校验!C8 -> 0 | M20: =波长示值误差与重复性校验!C9 -> 0 | N20: =波长示值误差与重复性校验!C10 -> 0
H22: =波长示值误差与重复性校验!D5 -> 0 | J22: =波长示值误差与重复性校验!D6 -> 0 | K22: =波长示值误差与重复性校验!D7 -> 0 | L22: =波长示值误差与重复性校验!D8 -> 0 | M22: =波长示值误差与重复性校验!D9 -> 0 | N22: =波长示值误差与重复性校验!D10 -> 0
H24: =波长示值误差与重复性校验!E5 -> 0 | J24: =波长示值误差与重复性校验!E6 -> 0 | K24: =波长示值误差与重复性校验!E7 -> 0 | L24: =波长示值误差与重复性校验!E8 -> 0 | M24: =波长示值误差与重复性校验!E9 -> 0 | N24: =波长示值误差与重复性校验!E10 -> 0
E26: 平均值(nm) | H26: =波长示值误差与重复性校验!F5 | J26: =波长示值误差与重复性校验!F6 | K26: =波长示值误差与重复性校验!F7 | L26: =波长示值误差与重复性校验!F8 | M26: =波长示值误差与重复性校验!F9 | N26: =波长示值误差与重复性校验!F10
E28: 误差值(nm) | H28: =波长示值误差与重复性校验!G5 | J28: =波长示值误差与重复性校验!G6 | K28: =波长示值误差与重复性校验!G7 | L28: =波长示值误差与重复性校验!G8 | M28: =波长示值误差与重复性校验!G9 | N28: =波长示值误差与重复性校验!G10
E30: 重复性(nm) | H30: =波长示值误差与重复性校验!H5 -> 0 | J30: =波长示值误差与重复性校验!H6 -> 0 | K30: =波长示值误差与重复性校验!H7 -> 0 | L30: =波长示值误差与重复性校验!H8 -> 0 | M30: =波长示值误差与重复性校验!H9 -> 0 | N30: =波长示值误差与重复性校验!H10 -> 0
A32: 2 | B32: 透射比示值误差与重复性 (可见区） | C32: 透射比示值误差 ±0.3% 透射比重复性 ≤0.1% | E32: 检测工具 | H32: 10%中性滤光片、20%中性滤光片、30%中性滤光片 （以标定的标准值为准）
E34: 型号 | G34: 测量点 | I34: =透射比示值误差与重复性校验!B6 -> 635 | L34: =透射比示值误差与重复性校验!B7 -> 546 | N34: =透射比示值误差与重复性校验!B8 -> 440
E35: 10%中性滤光片 | G35: 标准值(%) | I35: =透射比示值误差与重复性校验!C6 -> 7.57 | L35: =透射比示值误差与重复性校验!C7 -> 10.1 | N35: =透射比示值误差与重复性校验!C8 -> 10.07
G36: 测量值(%) | I36: =透射比示值误差与重复性校验!D6 -> 0 | L36: =透射比示值误差与重复性校验!D7 -> 0 | N36: =透射比示值误差与重复性校验!D8 -> 0
I37: =透射比示值误差与重复性校验!E6 -> 0 | L37: =透射比示值误差与重复性校验!E7 -> 0 | N37: =透射比示值误差与重复性校验!E8 -> 0
I38: =透射比示值误差与重复性校验!F6 -> 0 | L38: =透射比示值误差与重复性校验!F7 -> 0 | N38: =透射比示值误差与重复性校验!F8 -> 0
G39: 平均值(%) | I39: =透射比示值误差与重复性校验!G6 | L39: =透射比示值误差与重复性校验!G7 | N39: =透射比示值误差与重复性校验!G8
G40: 误差值(%) | I40: =透射比示值误差与重复性校验!H6 | L40: =透射比示值误差与重复性校验!H7 | N40: =透射比示值误差与重复性校验!H8
G41: 重复性(%) | I41: =透射比示值误差与重复性校验!I6 -> 0 | L41: =透射比示值误差与重复性校验!I7 -> 0 | N41: =透射比示值误差与重复性校验!I8 -> 0
E42: 20%中性滤光片 | G42: 标准值(%) | I42: =透射比示值误差与重复性校验!C9 -> 18.98 | L42: =透射比示值误差与重复性校验!C10 -> 20.09 | N42: =透射比示值误差与重复性校验!C11 -> 20.91
G43: 测量值(%) | I43: =透射比示值误差与重复性校验!D9 -> 0 | L43: =透射比示值误差与重复性校验!D10 -> 0 | N43: =透射比示值误差与重复性校验!D11 -> 0
I44: =透射比示值误差与重复性校验!E9 -> 0 | L44: =透射比示值误差与重复性校验!E10 -> 0 | N44: =透射比示值误差与重复性校验!E11 -> 0
I45: =透射比示值误差与重复性校验!F9 -> 0 | L45: =透射比示值误差与重复性校验!F10 -> 0 | N45: =透射比示值误差与重复性校验!F11 -> 0
G46: 平均值(%) | I46: =透射比示值误差与重复性校验!G9 | L46: =透射比示值误差与重复性校验!G10 | N46: =透射比示值误差与重复性校验!G11
G47: 误差值(%) | I47: =透射比示值误差与重复性校验!H9 | L47: =透射比示值误差与重复性校验!H10 | N47: =透射比示值误差与重复性校验!H11
G48: 重复性(%) | I48: =透射比示值误差与重复性校验!I9 -> 0 | L48: =透射比示值误差与重复性校验!I10 -> 0 | N48: =透射比示值误差与重复性校验!I11 -> 0
...

Sheet 基础信息
A1: 名称 | B1: 特征值 | C1: 标准值 | E1: 是否为光谱扫描 | F1: 灯状态 | G1: 灯状态 | H1: 较零物质 | I1: 光度方式 | J1: 光度方式 | K1: 扫描速度 | L1: 扫描速度 | M1: 扫描间隔(nm) | N1: 重复次数 | O1: 重复时间间隔(S) | P1: 光谱带宽(nm) | Q1: 增益 | R1: 响应时间
A2: 氘灯 | B2: 656.1 | C2: 656.1 | E2: 是 | F2: 钨灯 | G2: 0 | I2: Abs | J2: 0 | K2: 快速 | L2: 0 | N2: 1 | P2: 0.2
A3: 低压汞灯A段 | B3: 253.7 | C3: 253.7 | E3: 否 | F3: 氘灯 | G3: 1 | H3: 其它 | I3: T% | J3: 1 | K3: 中速 | L3: 1 | M3: 0.02 | N3: 2 | O3: 1 | P3: 0.5 | Q3: 1 | R3: 0.5
A4: 低压汞灯B段 | B4: 365.0,435.8,546.1 | C4: 365.0,435.8,546.1 | F4: 汞灯 | G4: 2 | I4: Es | J4: 2 | K4: 慢速 | L4: 2 | M4: 0.1 | N4: 3 | O4: 2 | P4: 1.0 | Q4: 2 | R4: 1
A5: 镨钕滤光片 | B5: 739.2,,807.4 | C5: 739.2,,807.4 | I5: Er | J5: 3 | K5: 最慢速 | L5: 3 | M5: 0.2 | N5: 4 | P5: 2.0 | Q5: 3 | R5: 2
A6: 10%中性滤光片 | B6: 635.0,546.0,440.0 | I6: R% | J6: 4 | M6: 0.5 | N6: 5 | P6: 5.0 | Q6: 4
A7: 20%中性滤光片 | B7: 635.0,546.0,440.1 | M7: 1 | Q7: 5
A8: 30%中性滤光片 | B8: 635.0,546.0,440.2 | M8: 2
A9: 重铬酸钾标准物质 | B9: 350313257235 | C9: 22.9,51.3,13.7,18.2 | M9: 5
A10: 碘化钠溶液 | B10: 220
A11: 亚硝酸钠溶液 | B11: 340360

Sheet 测量结果表
A1: 项目编号 | B1: 仪器ID | C1: 标准值 | D1: 测量值（nm） | E1: 平均值 | F1: 误差值 | G1: 重复性 | H1: 检验员 | I1: 检验日期 | J1: 复核员 | K1: 检验地点 | L1: 温度 | M1: 湿度 | N1: 判定结果 | O1: 其他 | P1: 子项目编号-与检测项信息对应的
A2: 1001 | B2: =MID(CELL("filename"),FIND("[",CELL("filename"),1)+1,FIND(".",CELL("filename"),1)-FIND("[",CELL("filename"),1)-1) -> T500 | D2: =波长示值误差与重复性校验!$C2&";"&波长示值误差与重复性校验!$D2&";"&波长示值误差与重复性校验!$E2 -> ;; | E2: =波长示值误差与重复性校验!$F2 | F2: =波长示值误差与重复性校验!$G2 | G2: =波长示值误差与重复性校验!$H2 -> 0 | H2: =Report!$F$5 -> 0 | I2: =NOW() -> 45881.668 | J2: =Report!$N$5 -> 0 | L2: =Report!$C$6 -> 0 | M2: =Report!$H$6 -> 0 | N2: =波长示值误差与重复性校验!$K2 -> 未检测 | P2: 1001
A3: 1002 | B3: =MID(CELL("filename"),FIND("[",CELL("filename"),1)+1,FIND(".",CELL("filename"),1)-FIND("[",CELL("filename"),1)-1) -> T500 | D3: =波长示值误差与重复性校验!$C3&";"&波长示值误差与重复性校验!$D3&";"&波长示值误差与重复性校验!$E3 -> ;; | E3: =波长示值误差与重复性校验!$F3 | F3: =波长示值误差与重复性校验!$G3 | G3: =波长示值误差与重复性校验!$H3 -> 0 | H3: =Report!$F$5 -> 0 | I3: =NOW() -> 45881.668 | J3: =Report!$N$5 -> 0 | L3: =Report!$C$6 -> 0 | M3: =Report!$H$6 -> 0 | N3: =波长示值误差与重复性校验!$K3 -> 未检测 | P3: 1002
A4: 1003 | B4: =MID(CELL("filename"),FIND("[",CELL("filename"),1)+1,FIND(".",CELL("filename"),1)-FIND("[",CELL("filename"),1)-1) -> T500 | D4: =波长示值误差与重复性校验!$C4&";"&波长示值误差与重复性校验!$D4&";"&波长示值误差与重复性校验!$E4 -> ;; | E4: =波长示值误差与重复性校验!$F4 | F4: =波长示值误差与重复性校验!$G4 | G4: =波长示值误差与重复性校验!$H4 -> 0 | H4: =Report!$F$5 -> 0 | I4: =NOW() -> 45881.668 | J4: =Report!$N$5 -> 0 | L4: =Report!$C$6 -> 0 | M4: =Report!$H$6 -> 0 | N4: =波长示值误差与重复性校验!$K4 -> 未检测 | P4: 1003
A5: 1008 | B5: =MID(CELL("filename"),FIND("[",CELL("filename"),1)+1,FIND(".",CELL("filename"),1)-FIND("[",CELL("filename"),1)-1) -> T500 | D5: =波长示值误差与重复性校验!$C5&";"&波长示值误差与重复性校验!$D5&";"&波长示值误差与重复性校验!$E5 -> ;; | E5: =波长示值误差与重复性校验!$F5 | F5: =波长示值误差与重复性校验!$G5 | G5: =波长示值误差与重复性校验!$H5 -> 0 | H5: =Report!$F$5 -> 0 | I5: =NOW() -> 45881.668 | J5: =Report!$N$5 -> 0 | L5: =Report!$C$6 -> 0 | M5: =Report!$H$6 -> 0 | N5: =波长示值误差与重复性校验!$K5 -> 未检测 | P5: 1004
A6: 1009 | B6: =MID(CELL("filename"),FIND("[",CELL("filename"),1)+1,FIND(".",CELL("filename"),1)-FIND("[",CELL("filename"),1)-1) -> T500 | D6: =波长示值误差与重复性校验!$C6&";"&波长示值误差与重复性校验!$D6&";"&波长示值误差与重复性校验!$E6 -> ;; | E6: =波长示值误差与重复性校验!$F6 | F6: =波长示值误差与重复性校验!$G6 | G6: =波长示值误差与重复性校验!$H6 -> 0 | H6: =Report!$F$5 -> 0 | I6: =NOW() -> 45881.668 | J6: =Report!$N$5 -> 0 | L6: =Report!$C$6 -> 0 | M6: =Report!$H$6 -> 0 | N6: =波长示值误差与重复性校验!$K6 -> 未检测 | P6: 1004
A7: 1010 | B7: =MID(CELL("filename"),FIND("[",CELL("filename"),1)+1,FIND(".",CELL("filename"),1)-FIND("[",CELL("filename"),1)-1) -> T500 | D7: =波长示值误差与重复性校验!$C7&";"&波长示值误差与重复性校验!$D7&";"&波长示值误差与重复性校验!$E7 -> ;; | E7: =波长示值误差与重复性校验!$F7 | F7: =波长示值误差与重复性校验!$G7 | G7: =波长示值误差与重复性校验!$H7 -> 0 | H7: =Report!$F$5 -> 0 | I7: =NOW() -> 45881.668 | J7: =Report!$N$5 -> 0 | L7: =Report!$C$6 -> 0 | M7: =Report!$H$6 -> 0 | N7: =波长示值误差与重复性校验!$K7 -> 未检测 | P7: 1004
A8: 1011 | B8: =MID(CELL("filename"),FIND("[",CELL("filename"),1)+1,FIND(".",CELL("filename"),1)-FIND("[",CELL("filename"),1)-1) -> T500 | D8: =波长示值误差与重复性校验!$C8&";"&波长示值误差与重复性校验!$D8&";"&波长示值误差与重复性校验!$E8 -> ;; | E8: =波长示值误差与重复性校验!$F8 | F8: =波长示值误差与重复性校验!$G8 | G8: =波长示值误差与重复性校验!$H8 -> 0 | H8: =Report!$F$5 -> 0 | I8: =NOW() -> 45881.668 | J8: =Report!$N$5 -> 0 | L8: =Report!$C$6 -> 0 | M8: =Report!$H$6 -> 0 | N8: =波长示值误差与重复性校验!$K8 -> 未检测 | P8: 1004
A9: 1012 | B9: =MID(CELL("filename"),FIND("[",CELL("filename"),1)+1,FIND(".",CELL("filename"),1)-FIND("[",CELL("filename"),1)-1) -> T500 | D9: =波长示值误差与重复性校验!$C9&";"&波长示值误差与重复性校验!$D9&";"&波长示值误差与重复性校验!$E9 -> ;; | E9: =波长示值误差与重复性校验!$F9 | F9: =波长示值误差与重复性校验!$G9 | G9: =波长示值误差与重复性校验!$H9 -> 0 | H9: =Report!$F$5 -> 0 | I9: =NOW() -> 45881.668 | J9: =Report!$N$5 -> 0 | L9: =Report!$C$6 -> 0 | M9: =Report!$H$6 -> 0 | N9: =波长示值误差与重复性校验!$K9 -> 未检测 | P9: 1004
A10: 1013 | B10: =MID(CELL("filename"),FIND("[",CELL("filename"),1)+1,FIND(".",CELL("filename"),1)-FIND("[",CELL("filename"),1)-1) -> T500 | D10: =波长示值误差与重复性校验!$C10&";"&波长示值误差与重复性校验!$D10&";"&波长示值误差与重复性校验!$E10 -> ;; | E10: =波长示值误差与重复性校验!$F10 | F10: =波长示值误差与重复性校验!$G10 | G10: =波长示值误差与重复性校验!$H10 -> 0 | H10: =Report!$F$5 -> 0 | I10: =NOW() -> 45881.668 | J10: =Report!$N$5 -> 0 | L10: =Report!$C$6 -> 0 | M10: =Report!$H$6 -> 0 | N10: =波长示值误差与重复性校验!$K10 -> 未检测 | P10: 1004
A11: 2001 | B11: =MID(CELL("filename"),FIND("[",CELL("filename"),1)+1,FIND(".",CELL("filename"),1)-FIND("[",CELL("filename"),1)-1) -> T500 | C11: =透射比示值误差与重复性校验!$C2 -> 23.2 | D11: =透射比示值误差与重复性校验!$D2&";"&透射比示值误差与重复性校验!$E2&";"&透射比示值误差与重复性校验!$F2 -> ;; | E11: =透射比示值误差与重复性校验!$G2 | F11: =透射比示值误差与重复性校验!$H2 | G11: =透射比示值误差与重复性校验!$I2 -> 0 | H11: =Report!$F$5 -> 0 | I11: =NOW() -> 45881.668 | J11: =Report!$N$5 -> 0 | L11: =Report!$C$6 -> 0 | M11: =Report!$H$6 -> 0 | N11: =透射比示值误差与重复性校验!$L2 -> 未检测 | P11: 2001
A12: 2002 | B12: =MID(CELL("filename"),FIND("[",CELL("filename"),1)+1,FIND(".",CELL("filename"),1)-FIND("[",CELL("filename"),1)-1) -> T500 | C12: =透射比示值误差与重复性校验!$C3 -> 51.58 | D12: =透射比示值误差与重复性校验!$D3&";"&透射比示值误差与重复性校验!$E3&";"&透射比示值误差与重复性校验!$F3 -> ;; | E12: =透射比示值误差与重复性校验!$G3 | F12: =透射比示值误差与重复性校验!$H3 | G12: =透射比示值误差与重复性校验!$I3 -> 0 | H12: =Report!$F$5 -> 0 | I12: =NOW() -> 45881.668 | J12: =Report!$N$5 -> 0 | L12: =Report!$C$6 -> 0 | M12: =Report!$H$6 -> 0 | N12: =透射比示值误差与重复性校验!$L3 -> 未检测 | P12: 2001
A13: 2003 | B13: =MID(CELL("filename"),FIND("[",CELL("filename"),1)+1,FIND(".",CELL("filename"),1)-FIND("[",CELL("filename"),1)-1) -> T500 | C13: =透射比示值误差与重复性校验!$C4 -> 14.06 | D13: =透射比示值误差与重复性校验!$D4&";"&透射比示值误差与重复性校验!$E4&";"&透射比示值误差与重复性校验!$F4 -> ;; | E13: =透射比示值误差与重复性校验!$G4 | F13: =透射比示值误差与重复性校验!$H4 | G13: =透射比示值误差与重复性校验!$I4 -> 0 | H13: =Report!$F$5 -> 0 | I13: =NOW() -> 45881.668 | J13: =Report!$N$5 -> 0 | L13: =Report!$C$6 -> 0 | M13: =Report!$H$6 -> 0 | N13: =透射比示值误差与重复性校验!$L4 -> 未检测 | P13: 2001
A14: 2004 | B14: =MID(CELL("filename"),FIND("[",CELL("filename"),1)+1,FIND(".",CELL("filename"),1)-FIND("[",CELL("filename"),1)-1) -> T500 | C14: =透射比示值误差与重复性校验!$C5 -> 18.42 | D14: =透射比示值误差与重复性校验!$D5&";"&透射比示值误差与重复性校验!$E5&";"&透射比示值误差与重复性校验!$F5 -> ;; | E14: =透射比示值误差与重复性校验!$G5 | F14: =透射比示值误差与重复性校验!$H5 | G14: =透射比示值误差与重复性校验!$I5 -> 0 | H14: =Report!$F$5 -> 0 | I14: =NOW() -> 45881.668 | J14: =Report!$N$5 -> 0 | L14: =Report!$C$6 -> 0 | M14: =Report!$H$6 -> 0 | N14: =透射比示值误差与重复性校验!$L5 -> 未检测 | P14: 2001
A15: 2005 | B15: =MID(CELL("filename"),FIND("[",CELL("filename"),1)+1,FIND(".",CELL("filename"),1)-FIND("[",CELL("filename"),1)-1) -> T500 | C15: =透射比示值误差与重复性校验!$C6 -> 7.57 | D15: =透射比示值误差与重复性校验!$D6&";"&透射比示值误差与重复性校验!$E6&";"&透射比示值误差与重复性校验!$F6 -> ;; | E15: =透射比示值误差与重复性校验!$G6 | F15: =透射比示值误差与重复性校验!$H6 | G15: =透射比示值误差与重复性校验!$I6 -> 0 | H15: =Report!$F$5 -> 0 | I15: =NOW() -> 45881.668 | J15: =Report!$N$5 -> 0 | L15: =Report!$C$6 -> 0 | M15: =Report!$H$6 -> 0 | N15: =透射比示值误差与重复性校验!$L6 -> 未检测 | P15: 2002
A16: 2006 | B16: =MID(CELL("filename"),FIND("[",CELL("filename"),1)+1,FIND(".",CELL("filename"),1)-FIND("[",CELL("filename"),1)-1) -> T500 | C16: =透射比示值误差与重复性校验!$C7 -> 10.1 | D16: =透射比示值误差与重复性校验!$D7&";"&透射比示值误差与重复性校验!$E7&";"&透射比示值误差与重复性校验!$F7 -> ;; | E16: =透射比示值误差与重复性校验!$G7 | F16: =透射比示值误差与重复性校验!$H7 | G16: =透射比示值误差与重复性校验!$I7 -> 0 | H16: =Report!$F$5 -> 0 | I16: =NOW() -> 45881.668 | J16: =Report!$N$5 -> 0 | L16: =Report!$C$6 -> 0 | M16: =Report!$H$6 -> 0 | N16: =透射比示值误差与重复性校验!$L7 -> 未检测 | P16: 2002
A17: 2007 | B17: =MID(CELL("filename"),FIND("[",CELL("filename"),1)+1,FIND(".",CELL("filename"),1)-FIND("[",CELL("filename"),1)-1) -> T500 | C17: =透射比示值误差与重复性校验!$C8 -> 10.07 | D17: =透射比示值误差与重复性校验!$D8&";"&透射比示值误差与重复性校验!$E8&";"&透射比示值误差与重复性校验!$F8 -> ;; | E17: =透射比示值误差与重复性校验!$G8 | F17: =透射比示值误差与重复性校验!$H8 | G17: =透射比示值误差与重复性校验!$I8 -> 0 | H17: =Report!$F$5 -> 0 | I17: =NOW() -> 45881.668 | J17: =Report!$N$5 -> 0 | L17: =Report!$C$6 -> 0 | M17: =Report!$H$6 -> 0 | N17: =透射比示值误差与重复性校验!$L8 -> 未检测 | P17: 2002
A18: 2008 | B18: =MID(CELL("filename"),FIND("[",CELL("filename"),1)+1,FIND(".",CELL("filename"),1)-FIND("[",CELL("filename"),1)-1) -> T500 | C18: =透射比示值误差与重复性校验!$C9 -> 18.98 | D18: =透射比示值误差与重复性校验!$D9&";"&透射比示值误差与重复性校验!$E9&";"&透射比示值误差与重复性校验!$F9 -> ;; | E18: =透射比示值误差与重复性校验!$G9 | F18: =透射比示值误差与重复性校验!$H9 | G18: =透射比示值误差与重复性校验!$I9 -> 0 | H18: =Report!$F$5 -> 0 | I18: =NOW() -> 45881.668 | J18: =Report!$N$5 -> 0 | L18: =Report!$C$6 -> 0 | M18: =Report!$H$6 -> 0 | N18: =透射比示值误差与重复性校验!$L9 -> 未检测 | P18: 2003
A19: 2009 | B19: =MID(CELL("filename"),FIND("[",CELL("filename"),1)+1,FIND(".",CELL("filename"),1)-FIND("[",CELL("filename"),1)-1) -> T500 | C19: =透射比示值误差与重复性校验!$C10 -> 20.09 | D19: =透射比示值误差与重复性校验!$D10&";"&透射比示值误差与重复性校验!$E10&";"&透射比示值误差与重复性校验!$F10 -> ;; | E19: =透射比示值误差与重复性校验!$G10 | F19: =透射比示值误差与重复性校验!$H10 | G19: =透射比示值误差与重复性校验!$I10 -> 0 | H19: =Report!$F$5 -> 0 | I19: =NOW() -> 45881.668 | J19: =Report!$N$5 -> 0 | L19: =Report!$C$6 -> 0 | M19: =Report!$H$6 -> 0 | N19: =透射比示值误差与重复性校验!$L10 -> 未检测 | P19: 2003
A20: 2010 | B20: =MID(CELL("filename"),FIND("[",CELL("filename"),1)+1,FIND(".",CELL("filename"),1)-FIND("[",CELL("filename"),1)-1) -> T500 | C20: =透射比示值误差与重复性校验!$C11 -> 20.91 | D20: =透射比示值误差与重复性校验!$D11&";"&透射比示值误差与重复性校验!$E11&";"&透射比示值误差与重复性校验!$F11 -> ;; | E20: =透射比示值误差与重复性校验!$G11 | F20: =透射比示值误差与重复性校验!$H11 | G20: =透射比示值误差与重复性校验!$I11 -> 0 | H20: =Report!$F$5 -> 0 | I20: =NOW() -> 45881.668 | J20: =Report!$N$5 -> 0 | L20: =Report!$C$6 -> 0 | M20: =Report!$H$6 -> 0 | N20: =透射比示值误差与重复性校验!$L11 -> 未检测 | P20: 2003
A21: 2011 | B21: =MID(CELL("filename"),FIND("[",CELL("filename"),1)+1,FIND(".",CELL("filename"),1)-FIND("[",CELL("filename"),1)-1) -> T500 | C21: =透射比示值误差与重复性校验!$C12 -> 29.96 | D21: =透射比示值误差与重复性校验!$D12&";"&透射比示值误差与重复性校验!$E12&";"&透射比示值误差与重复性校验!$F12 -> ;; | E21: =透射比示值误差与重复性校验!$G12 | F21: =透射比示值误差与重复性校验!$H12 | G21: =透射比示值误差与重复性校验!$I12 -> 0 | H21: =Report!$F$5 -> 0 | I21: =NOW() -> 45881.668 | J21: =Report!$N$5 -> 0 | L21: =Report!$C$6 -> 0 | M21: =Report!$H$6 -> 0 | N21: =透射比示值误差与重复性校验!$L12 -> 未检测 | P21: 2004
A22: 2012 | B22: =MID(CELL("filename"),FIND("[",CELL("filename"),1)+1,FIND(".",CELL("filename"),1)-FIND("[",CELL("filename"),1)-1) -> T500 | C22: =透射比示值误差与重复性校验!$C13 -> 30.43 | D22: =透射比示值误差与重复性校验!$D13&";"&透射比示值误差与重复性校验!$E13&";"&透射比示值误差与重复性校验!$F13 -> ;; | E22: =透射比示值误差与重复性校验!$G13 | F22: =透射比示值误差与重复性校验!$H13 | G22: =透射比示值误差与重复性校验!$I13 -> 0 | H22: =Report!$F$5 -> 0 | I22: =NOW() -> 45881.668 | J22: =Report!$N$5 -> 0 | L22: =Report!$C$6 -> 0 | M22: =Report!$H$6 -> 0 | N22: =透射比示值误差与重复性校验!$L13 -> 未检测 | P22: 2004
A23: 2013 | B23: =MID(CELL("filename"),FIND("[",CELL("filename"),1)+1,FIND(".",CELL("filename"),1)-FIND("[",CELL("filename"),1)-1) -> T500 | C23: =透射比示值误差与重复性校验!$C14 -> 28.88 | D23: =透射比示值误差与重复性校验!$D14&";"&透射比示值误差与重复性校验!$E14&";"&透射比示值误差与重复性校验!$F14 -> ;; | E23: =透射比示值误差与重复性校验!$G14 | F23: =透射比示值误差与重复性校验!$H14 | G23: =透射比示值误差与重复性校验!$I14 -> 0 | H23: =Report!$F$5 -> 0 | I23: =NOW() -> 45881.668 | J23: =Report!$N$5 -> 0 | L23: =Report!$C$6 -> 0 | M23: =Report!$H$6 -> 0 | N23: =透射比示值误差与重复性校验!$L14 -> 未检测 | P23: 2004
A24: 3001 | B24: =MID(CELL("filename"),FIND("[",CELL("filename"),1)+1,FIND(".",CELL("filename"),1)-FIND("[",CELL("filename"),1)-1) -> T500 | C24: =杂散光校验!$B2 -> 220 | D24: =杂散光校验!$C2&";"&杂散光校验!$D2&";"&杂散光校验!$E2 -> ;; | H24: =Report!$F$5 -> 0 | I24: =NOW() -> 45881.668 | J24: =Report!$N$5 -> 0 | L24: =Report!$C$6 -> 0 | M24: =Report!$H$6 -> 0 | N24: =杂散光校验!$G2 -> 未检测 | P24: 3001
A25: 3002 | B25: =MID(CELL("filename"),FIND("[",CELL("filename"),1)+1,FIND(".",CELL("filename"),1)-FIND("[",CELL("filename"),1)-1) -> T500 | C25: =杂散光校验!$B3 -> 360 | D25: =杂散光校验!$C3&";"&杂散光校验!$D3&";"&杂散光校验!$E3 -> ;; | H25: =Report!$F$5 -> 0 | I25: =NOW() -> 45881.668 | J25: =Report!$N$5 -> 0 | L25: =Report!$C$6 -> 0 | M25: =Report!$H$6 -> 0 | N25: =杂散光校验!$G3 -> 未检测 | P25: 3002
A26: 4001 | B26: =MID(CELL("filename"),FIND("[",CELL("filename"),1)+1,FIND(".",CELL("filename"),1)-FIND("[",CELL("filename"),1)-1) -> T500 | D26: =基线平直度检验!$B$2 -> 0 | H26: =Report!$F$5 -> 0 | I26: =NOW() -> 45881.668 | J26: =Report!$N$5 -> 0 | L26: =Report!$C$6 -> 0 | M26: =Report!$H$6 -> 0 | N26: =基线平直度检验!$D$2 -> 未检测 | P26: 4001
A27: 5001 | B27: =MID(CELL("filename"),FIND("[",CELL("filename"),1)+1,FIND(".",CELL("filename"),1)-FIND("[",CELL("filename"),1)-1) -> T500 | D27: =基线暗噪声检验!$B$2 -> 0 | H27: =Report!$F$5 -> 0 | I27: =NOW() -> 45881.668 | J27: =Report!$N$5 -> 0 | L27: =Report!$C$6 -> 0 | M27: =Report!$H$6 -> 0 | N27: =基线暗噪声检验!$D$2 -> 未检测 | P27: 5001
A28: 6002 | B28: =MID(CELL("filename"),FIND("[",CELL("filename"),1)+1,FIND(".",CELL("filename"),1)-FIND("[",CELL("filename"),1)-1) -> T500 | C28: =光谱带宽与仪器最小光谱带宽!$C2 -> 2 | D28: =光谱带宽与仪器最小光谱带宽!$D2 -> 0 | H28: =Report!$F$5 -> 0 | I28: =NOW() -> 45881.668 | J28: =Report!$N$5 -> 0 | L28: =Report!$C$6 -> 0 | M28: =Report!$H$6 -> 0 | N28: =光谱带宽与仪器最小光谱带宽!$G2 -> 未检测 | P28: 6001
A29: 7001 | B29: =MID(CELL("filename"),FIND("[",CELL("filename"),1)+1,FIND(".",CELL("filename"),1)-FIND("[",CELL("filename"),1)-1) -> T500 | C29: =噪声检验!$B2 -> 500 | D29: =噪声检验!$C2 -> 0 | H29: =Report!$F$5 -> 0 | I29: =NOW() -> 45881.668 | J29: =Report!$N$5 -> 0 | L29: =Report!$C$6 -> 0 | M29: =Report!$H$6 -> 0 | N29: =噪声检验!$E2 -> 未检测 | P29: 7001
A30: 7002 | B30: =MID(CELL("filename"),FIND("[",CELL("filename"),1)+1,FIND(".",CELL("filename"),1)-FIND("[",CELL("filename"),1)-1) -> T500 | C30: =噪声检验!$B3 -> 500 | D30: =噪声检验!$C3 -> 0 | H30: =Report!$F$5 -> 0 | I30: =NOW() -> 45881.668 | J30: =Report!$N$5 -> 0 | L30: =Report!$C$6 -> 0 | M30: =Report!$H$6 -> 0 | N30: =噪声检验!$E3 -> 未检测 | P30: 7002
A31: 7003 | B31: =MID(CELL("filename"),FIND("[",CELL("filename"),1)+1,FIND(".",CELL("filename"),1)-FIND("[",CELL("filename"),1)-1) -> T500 | C31: =噪声检验!$B4 -> 250 | D31: =噪声检验!$C4 -> 0 | H31: =Report!$F$5 -> 0 | I31: =NOW() -> 45881.668 | J31: =Report!$N$5 -> 0 | L31: =Report!$C$6 -> 0 | M31: =Report!$H$6 -> 0 | N31: =噪声检验!$E4 -> 未检测 | P31: 7003
A32: 7004 | B32: =MID(CELL("filename"),FIND("[",CELL("filename"),1)+1,FIND(".",CELL("filename"),1)-FIND("[",CELL("filename"),1)-1) -> T500 | C32: =噪声检验!$B5 -> 250 | D32: =噪声检验!$C5 -> 0 | H32: =Report!$F$5 -> 0 | I32: =NOW() -> 45881.668 | J32: =Report!$N$5 -> 0 | L32: =Report!$C$6 -> 0 | M32: =Report!$H$6 -> 0 | N32: =噪声检验!$E5 -> 未检测 | P32: 7004
A33: 8001 | B33: =MID(CELL("filename"),FIND("[",CELL("filename"),1)+1,FIND(".",CELL("filename"),1)-FIND("[",CELL("filename"),1)-1) -> T500 | C33: =波长边缘噪声!$B2 -> 1090 | D33: =波长边缘噪声!$C2 -> 0 | H33: =Report!$F$5 -> 0 | I33: =NOW() -> 45881.668 | J33: =Report!$N$5 -> 0 | L33: =Report!$C$6 -> 0 | M33: =Report!$H$6 -> 0 | N33: =波长边缘噪声!$E2 -> 未检测 | P33: 8001
A34: 8002 | B34: =MID(CELL("filename"),FIND("[",CELL("filename"),1)+1,FIND(".",CELL("filename"),1)-FIND("[",CELL("filename"),1)-1) -> T500 | C34: =波长边缘噪声!$B3 -> 1090 | D34: =波长边缘噪声!$C3 -> 0 | H34: =Report!$F$5 -> 0 | I34: =NOW() -> 45881.668 | J34: =Report!$N$5 -> 0 | L34: =Report!$C$6 -> 0 | M34: =Report!$H$6 -> 0 | N34: =波长边缘噪声!$E3 -> 未检测 | P34: 8002
A35: 8003 | B35: =MID(CELL("filename"),FIND("[",CELL("filename"),1)+1,FIND(".",CELL("filename"),1)-FIND("[",CELL("filename"),1)-1) -> T500 | C35: =波长边缘噪声!$B4 -> 200 | D35: =波长边缘噪声!$C4 -> 0 | H35: =Report!$F$5 -> 0 | I35: =NOW() -> 45881.668 | J35: =Report!$N$5 -> 0 | L35: =Report!$C$6 -> 0 | M35: =Report!$H$6 -> 0 | N35: =波长边缘噪声!$E4 -> 未检测 | P35: 8003
A36: 8004 | B36: =MID(CELL("filename"),FIND("[",CELL("filename"),1)+1,FIND(".",CELL("filename"),1)-FIND("[",CELL("filename"),1)-1) -> T500 | C36: =波长边缘噪声!$B5 -> 200 | D36: =波长边缘噪声!$C5 -> 0 | H36: =Report!$F$5 -> 0 | I36: =NOW() -> 45881.668 | J36: =Report!$N$5 -> 0 | L36: =Report!$C$6 -> 0 | M36: =Report!$H$6 -> 0 | N36: =波长边缘噪声!$E5 -> 未检测 | P36: 8004
A37: 9001 | B37: =MID(CELL("filename"),FIND("[",CELL("filename"),1)+1,FIND(".",CELL("filename"),1)-FIND("[",CELL("filename"),1)-1) -> T500 | C37: =漂移检验!$B$2 -> 500 | D37: =漂移检验!$C$2 -> 0 | H37: =Report!$F$5 -> 0 | I37: =NOW() -> 45881.668 | J37: =Report!$N$5 -> 0 | L37: =Report!$C$6 -> 0 | M37: =Report!$H$6 -> 0 | N37: =漂移检验!$E$2 -> 未检测 | P37: 9001

Sheet 管理表
A1: 检验项目
A2: 产品型号 | B2: 父项目编号 | C2: 父项目名称 | D2: 子项目编号 | E2: 子项目名称 | F2: 特征值 | G2: 可允许误差范围 | H2: 波长重复性
A3: T700S | B3: 1000 | C3: 波长示值误差与重复性校验 | D3: 1001 | E3: 氘灯 | F3: 656.1 | G3: 0.1 | H3: 0.1
A4: T700S | B4: 1000 | C4: 波长示值误差与重复性校验 | D4: 1002 | E4: 氘灯 | F4: 486 | G4: 0.3 | H4: 0.1
A5: T700S | B5: 1000 | C5: 波长示值误差与重复性校验 | D5: 1003 | E5: 镨钕滤光片 | F5: 807.4 | G5: 0.3 | H5: 0.1
A6: T700S | B6: 1000 | C6: 波长示值误差与重复性校验 | D6: 1008 | E6: 钬溶液 | F6: 640.79 | G6: 0.3 | H6: 0.1
A7: T700S | B7: 1000 | C7: 波长示值误差与重复性校验 | D7: 1009 | E7: 钬溶液 | F7: 536.86 | G7: 0.3 | H7: 0.1
A8: T700S | B8: 1000 | C8: 波长示值误差与重复性校验 | D8: 1010 | E8: 钬溶液 | F8: 416.57 | G8: 0.3 | H8: 0.1
A9: T700S | B9: 1000 | C9: 波长示值误差与重复性校验 | D9: 1011 | E9: 钬溶液 | F9: 361.12 | G9: 0.3 | H9: 0.1
A10: T700S | B10: 1000 | C10: 波长示值误差与重复性校验 | D10: 1012 | E10: 钬溶液 | F10: 287.52 | G10: 0.3 | H10: 0.1
A11: T700S | B11: 1000 | C11: 波长示值误差与重复性校验 | D11: 1013 | E11: 钬溶液 | F11: 241.12 | G11: 0.3 | H11: 0.1
A12: T700S | B12: 2000 | C12: 透射比示值误差与重复性校验 | D12: 2001 | E12: 紫外分光光度计标准物质GBW(E)130066 | F12: 350nm | G12: 0.3 | H12: 0.1
A13: T700S | B13: 2000 | C13: 透射比示值误差与重复性校验 | D13: 2002 | E13: 紫外分光光度计标准物质GBW(E)130066 | F13: 313nm | G13: 0.3 | H13: 0.1
A14: T700S | B14: 2000 | C14: 透射比示值误差与重复性校验 | D14: 2003 | E14: 紫外分光光度计标准物质GBW(E)130066 | F14: 257nm | G14: 0.3 | H14: 0.1
A15: T700S | B15: 2000 | C15: 透射比示值误差与重复性校验 | D15: 2004 | E15: 紫外分光光度计标准物质GBW(E)130066 | F15: 235nm | G15: 0.3 | H15: 0.1
A16: T700S | B16: 2000 | C16: 透射比示值误差与重复性校验 | D16: 2005 | E16: 10%中性滤光片 | F16: 635nm | G16: 0.3 | H16: 0.1
... A24: T700S | B24: 2000 | C24: 透射比示值误差与重复性校验 | D24: 2013 | E24: 30%中性滤光片 | F24: 440nm | G24: 0.3 | H24: 0.1
A25: T700S | B25: 3000 | C25: 杂散光校验 | D25: 3001 | E25: 碘化钠标准溶液 | F25: 220nm | G25: 0.01
A26: T700S | B26: 3000 | C26: 杂散光校验 | D26: 3002 | E26: 亚硝酸钠标准溶液 | F26: 360nm | G26: 0.02
A27: T700S | B27: 4000 | C27: 基线平直度检验 | D27: 4001 | E27: 基线平直度 | G27: 0.0005
A28: T700S | B28: 5000 | C28: 基线暗噪声检验 | D28: 5001 | E28: 基线暗噪声 | G28: 0.1
A29: T700S | B29: 6000 | C29: 光谱带宽与仪器最小光谱带宽 | D29: 6002 | E29: 氘灯2.0 | F29: 656.1 | G29: 20
A30: T700S | B30: 7000 | C30: 噪声检验 | D30: 7001 | E30: 500nm100%噪声 | F30: 500 | G30: 0.05
A31: T700S | B31: 7000 | C31: 噪声检验 | D31: 7002 | E31: 500nm0%噪声 | F31: 500 | G31: 0.005
A32: T700S | B32: 7000 | C32: 噪声检验 | D32: 7003 | E32: 250nm100%噪声 | F32: 250 | G32: 0.05
A33: T700S | B33: 7000 | C33: 噪声检验 | D33: 7004 | E33: 250nm0%噪声 | F33: 250 | G33: 0.005
A34: T700S | B34: 8000 | C34: 波长边缘噪声 | D34: 8001 | E34: 1090nm100%噪声 | F34: 1090 | G34: 0.1
A35: T700S | B35: 8000 | C35: 波长边缘噪声 | D35: 8002 | E35: 1090nm0%噪声 | F35: 1090 | G35: 0.02
A36: T700S | B36: 8000 | C36: 波长边缘噪声 | D36: 8003 | E36: 200nm100%噪声 | F36: 200 | G36: 0.1
A37: T700S | B37: 8000 | C37: 波长边缘噪声 | D37: 8004 | E37: 200nm0%噪声 | F37: 200 | G37: 0.02
A38: T700S | B38: 9000 | C38: 漂移检验 | D38: 9001 | E38: 漂移检验 | F38: 500nm | G38: 0.1

Sheet 对应信息
A1: 产品编号 | B1: 产品型号 | D1: 父项目名称 | E1: 父项目编号
A2: 1401 | B2: T400 | D2: 波长示值误差与重复性校验 | E2: 1000
A3: 1501 | B3: T500 | D3: 透射比示值误差与重复性校验 | E3: 2000
A4: 1610 | B4: T6新悦 | D4: 杂散光校验 | E4: 3000
A5: 1650 | B5: T6新世纪 | D5: 基线平直度检验 | E5: 4000
D6: 基线暗噪声检验 | E6: 5000
D7: 光谱带宽与仪器最小光谱带宽 | E7: 6000
D8: 噪声检验 | E8: 7000
D9: 波长边缘噪声 | E9: 8000
D10: 漂移检验 | E10: 9000
D11: 分辨率检验 | E11: 10000

Sheet 检测项信息
A1: 检测类别 | B1: 项目名称 | C1: 提示 | D1: 方法信息 | E1: 测量信息 | F1: 重复次数 | G1: 重复时间间隔 | H1: 特征值 | I1: 分析方法 | J1: 分析方法 | K1: 灯状态 | L1: 光度模式 | M1: 扫描速度 | N1: 起始波长 | O1: 终止波长 | P1: 扫描间隔 | Q1: 增益 | R1: 光谱带宽 | S1: 时间间隔 | T1: 扫描个数 | U1: 响应时间 | V1: 是否为光谱扫描 | W1: 暗电流物质 | X1: 校零物质 | Y1: 测量物质 | Z1: 父项目编号 | AA1: 子项目编号 | AB1: 标准值
A2: 波长示值误差与重复性校验 | B2: 氘灯(656.1) | D2: =IF(L2="","",字段对应!$B$10&"="&VLOOKUP(L2,基础信息!$I$2:$J$6,2,0)&";")&IF(M2="","",字段对应!$B$11&"="&VLOOKUP(M2,基础信息!$K$2:$L$6,2,0)&";")&IF(N2="","",字段对应!$C$2&"="&N2&","&O2&","&P2&";")&IF(Q2="","",字段对应!$B$13&"="&Q2&";")&IF(R2="","",字段对应!$B$14&"="&R2&";")&IF(U2="","",字段对应!$B$22&"="&U2&";")&IF(K2="","",字段对应!$B$21&"="&VLOOKUP(K2,基础信息!$F$2:$G$4,2,0)) -> PhotoMode=2;ScanSpeed=2;WlRange=660,650,0.2;Gain=5;LampPos=1 | E2: =IF(W2="","",检测项信息!W2&":"&字段对应!$B$16&"|")&IF(X2="","",X2&":"&IF(V2="是",字段对应!$C$17,字段对应!$B$17&";"&IF(H2="","",字段对应!$B$15&"="&检测项信息!H2))&"|")&IF(Y2="",":",Y2&":")&IF(V2="是",字段对应!$C$18,字段对应!$B$18&";"&IF(H2="","",字段对应!$B$15&"="&检测项信息!H2)&IF(AND(T2="",S2=""),"",";"&字段对应!$B$20&"="&T2&";"&字段对应!$B$19&"="&S2)) -> 空气:Scan | F2: 3 | G2: 1 | H2: 656.1 | I2: =VLOOKUP(J2,字段对应!$D$2:$E$9,2,0) -> Validation.ViewModel.DataStructure.FindPeakAndAverageUVTestTool | J2: 寻峰 | K2: 氘灯 | L2: Es | M2: 慢速 | N2: 660 | O2: 650 | P2: 0.2 | Q2: 5 | V2: 是 | Y2: 空气 | Z2: =VLOOKUP(A2,对应信息!$D$2:$E$11,2,0) -> 1000 | AA2: =IF(Z1=Z2,AA1+1,Z2+1) -> 1001
A3: 波长示值误差与重复性校验 | B3: 氘灯(486.0) | D3: =IF(L3="","",字段对应!$B$10&"="&VLOOKUP(L3,基础信息!$I$2:$J$6,2,0)&";")&IF(M3="","",字段对应!$B$11&"="&VLOOKUP(M3,基础信息!$K$2:$L$6,2,0)&";")&IF(N3="","",字段对应!$C$2&"="&N3&","&O3&","&P3&";")&IF(Q3="","",字段对应!$B$13&"="&Q3&";")&IF(R3="","",字段对应!$B$14&"="&R3&";")&IF(U3="","",字段对应!$B$22&"="&U3&";")&IF(K3="","",字段对应!$B$21&"="&VLOOKUP(K3,基础信息!$F$2:$G$4,2,0)) -> PhotoMode=2;ScanSpeed=2;WlRange=490,480,0.2;Gain=5;LampPos=1 | E3: =IF(W3="","",检测项信息!W3&":"&字段对应!$B$16&"|")&IF(X3="","",X3&":"&IF(V3="是",字段对应!$C$17,字段对应!$B$17&";"&IF(H3="","",字段对应!$B$15&"="&检测项信息!H3))&"|")&IF(Y3="",":",Y3&":")&IF(V3="是",字段对应!$C$18,字段对应!$B$18&";"&IF(H3="","",字段对应!$B$15&"="&检测项信息!H3)&IF(AND(T3="",S3=""),"",";"&字段对应!$B$20&"="&T3&";"&字段对应!$B$19&"="&S3)) -> 空气:Scan | F3: 3 | G3: 1 | H3: 486 | I3: =VLOOKUP(J3,字段对应!$D$2:$E$9,2,0) -> Validation.ViewModel.DataStructure.FindPeakAndAverageUVTestTool | J3: 寻峰 | K3: 氘灯 | L3: Es | M3: 慢速 | N3: 490 | O3: 480 | P3: 0.2 | Q3: 5 | V3: 是 | Y3: 空气 | Z3: =VLOOKUP(A3,对应信息!$D$2:$E$11,2,0) -> 1000 | AA3: =IF(Z2=Z3,AA2+1,Z3+1) -> 1002
A4: 波长示值误差与重复性校验 | B4: 镨钕滤光片 | D4: =IF(L4="","",字段对应!$B$10&"="&VLOOKUP(L4,基础信息!$I$2:$J$6,2,0)&";")&IF(M4="","",字段对应!$B$11&"="&VLOOKUP(M4,基础信息!$K$2:$L$6,2,0)&";")&IF(N4="","",字段对应!$C$2&"="&N4&","&O4&","&P4&";")&IF(Q4="","",字段对应!$B$13&"="&Q4&";")&IF(R4="","",字段对应!$B$14&"="&R4&";")&IF(U4="","",字段对应!$B$22&"="&U4&";")&IF(K4="","",字段对应!$B$21&"="&VLOOKUP(K4,基础信息!$F$2:$G$4,2,0)) -> PhotoMode=0;ScanSpeed=2;WlRange=810,800,0.2;LampPos=0 | E4: =IF(W4="","",检测项信息!W4&":"&字段对应!$B$16&"|")&IF(X4="","",X4&":"&IF(V4="是",字段对应!$C$17,字段对应!$B$17&";"&IF(H4="","",字段对应!$B$15&"="&检测项信息!H4))&"|")&IF(Y4="",":",Y4&":")&IF(V4="是",字段对应!$C$18,字段对应!$B$18&";"&IF(H4="","",字段对应!$B$15&"="&检测项信息!H4)&IF(AND(T4="",S4=""),"",";"&字段对应!$B$20&"="&T4&";"&字段对应!$B$19&"="&S4)) -> 黑挡块:Dark|空气:BaseLine|镨钕滤光片:Scan | F4: 3 | G4: 1 | H4: 807.4 | I4: =VLOOKUP(J4,字段对应!$D$2:$E$9,2,0) -> Validation.ViewModel.DataStructure.FindPeakAndAverageUVTestTool | J4: 寻峰 | K4: 钨灯 | L4: Abs | M4: 慢速 | N4: 810 | O4: 800 | P4: 0.2 | V4: 是 | W4: 黑挡块 | X4: 空气 | Y4: 镨钕滤光片 | Z4: =VLOOKUP(A4,对应信息!$D$2:$E$11,2,0) -> 1000 | AA4: =IF(Z3=Z4,AA3+1,Z4+1) -> 1003
A5: 波长示值误差与重复性校验 | B5: 钬溶液 | D5: =IF(L5="","",字段对应!$B$10&"="&VLOOKUP(L5,基础信息!$I$2:$J$6,2,0)&";")&IF(M5="","",字段对应!$B$11&"="&VLOOKUP(M5,基础信息!$K$2:$L$6,2,0)&";")&IF(N5="","",字段对应!$C$2&"="&N5&","&O5&","&P5&";")&IF(Q5="","",字段对应!$B$13&"="&Q5&";")&IF(R5="","",字段对应!$B$14&"="&R5&";")&IF(U5="","",字段对应!$B$22&"="&U5&";")&IF(K5="","",字段对应!$B$21&"="&VLOOKUP(K5,基础信息!$F$2:$G$4,2,0)) -> PhotoMode=0;ScanSpeed=1;WlRange=645,235,0.2; | E5: =IF(W5="","",检测项信息!W5&":"&字段对应!$B$16&"|")&IF(X5="","",X5&":"&IF(V5="是",字段对应!$C$17,字段对应!$B$17&";"&IF(H5="","",字段对应!$B$15&"="&检测项信息!H5))&"|")&IF(Y5="",":",Y5&":")&IF(V5="是",字段对应!$C$18,字段对应!$B$18&";"&IF(H5="","",字段对应!$B$15&"="&检测项信息!H5)&IF(AND(T5="",S5=""),"",";"&字段对应!$B$20&"="&T5&";"&字段对应!$B$19&"="&S5)) -> 黑挡块:Dark|空气:BaseLine|钬溶液:Scan | F5: 3 | G5: 1 | H5: 640.7,536.8,416.5,361.0,287.4,241.0 | I5: =VLOOKUP(J5,字段对应!$D$2:$E$9,2,0) -> Validation.ViewModel.DataStructure.FindPeakAndAverageUVTestTool | J5: 寻峰 | L5: Abs | M5: 中速 | N5: 645 | O5: 235 | P5: 0.2 | V5: 是 | W5: 黑挡块 | X5: 空气 | Y5: 钬溶液 | Z5: =VLOOKUP(A5,对应信息!$D$2:$E$11,2,0) -> 1000 | AA5: =IF(Z4=Z5,AA4+1,Z5+1) -> 1004
A6: 光谱带宽与仪器最小光谱带宽 | B6: 氘灯2.0 | D6: =IF(L6="","",字段对应!$B$10&"="&VLOOKUP(L6,基础信息!$I$2:$J$6,2,0)&";")&IF(M6="","",字段对应!$B$11&"="&VLOOKUP(M6,基础信息!$K$2:$L$6,2,0)&";")&IF(N6="","",字段对应!$C$2&"="&N6&","&O6&","&P6&";")&IF(Q6="","",字段对应!$B$13&"="&Q6&";")&IF(R6="","",字段对应!$B$14&"="&R6&";")&IF(U6="","",字段对应!$B$22&"="&U6&";")&IF(K6="","",字段对应!$B$21&"="&VLOOKUP(K6,基础信息!$F$2:$G$4,2,0)) -> PhotoMode=2;ScanSpeed=2;WlRange=660,650,0.2;Gain=5;LampPos=1 | E6: =IF(W6="","",检测项信息!W6&":"&字段对应!$B$16&"|")&IF(X6="","",X6&":"&IF(V6="是",字段对应!$C$17,字段对应!$B$17&";"&IF(H6="","",字段对应!$B$15&"="&检测项信息!H6))&"|")&IF(Y6="",":",Y6&":")&IF(V6="是",字段对应!$C$18,字段对应!$B$18&";"&IF(H6="","",字段对应!$B$15&"="&检测项信息!H6)&IF(AND(T6="",S6=""),"",";"&字段对应!$B$20&"="&T6&";"&字段对应!$B$19&"="&S6)) -> 空气:Scan | F6: 1 | H6: 656.1 | I6: =VLOOKUP(J6,字段对应!$D$2:$E$9,2,0) -> Validation.ViewModel.DataStructure.FindHalfPeakUVTestTool | J6: 求半峰宽 | K6: 氘灯 | L6: Es | M6: 慢速 | N6: 660 | O6: 650 | P6: 0.2 | Q6: 5 | V6: 是 | Y6: 空气 | Z6: =VLOOKUP(A6,对应信息!$D$2:$E$11,2,0) -> 6000 | AA6: =IF(Z5=Z6,AA5+1,Z6+1) -> 6001 | AB6: 2.0
A7: 基线平直度检验 | B7: 基线平直度 | D7: =IF(L7="","",字段对应!$B$10&"="&VLOOKUP(L7,基础信息!$I$2:$J$6,2,0)&";")&IF(M7="","",字段对应!$B$11&"="&VLOOKUP(M7,基础信息!$K$2:$L$6,2,0)&";")&IF(N7="","",字段对应!$C$2&"="&N7&","&O7&","&P7&";")&IF(Q7="","",字段对应!$B$13&"="&Q7&";")&IF(R7="","",字段对应!$B$14&"="&R7&";")&IF(U7="","",字段对应!$B$22&"="&U7&";")&IF(K7="","",字段对应!$B$21&"="&VLOOKUP(K7,基础信息!$F$2:$G$4,2,0)) -> PhotoMode=0;ScanSpeed=2;WlRange=1090,200,1; | E7: =IF(W7="","",检测项信息!W7&":"&字段对应!$B$16&"|")&IF(X7="","",X7&":"&IF(V7="是",字段对应!$C$17,字段对应!$B$17&";"&IF(H7="","",字段对应!$B$15&"="&检测项信息!H7))&"|")&IF(Y7="",":",Y7&":")&IF(V7="是",字段对应!$C$18,字段对应!$B$18&";"&IF(H7="","",字段对应!$B$15&"="&检测项信息!H7)&IF(AND(T7="",S7=""),"",";"&字段对应!$B$20&"="&T7&";"&字段对应!$B$19&"="&S7)) -> 黑挡块:Dark|空气:BaseLine|空气:Scan | F7: 1 | I7: =VLOOKUP(J7,字段对应!$D$2:$E$9,2,0) -> Validation.ViewModel.DataStructure.GetMaxDIstanceUVTestTool | J7: 求最大偏移量 | L7: Abs | M7: 慢速 | N7: 1090 | O7: 200 | P7: 1 | V7: 是 | W7: 黑挡块 | X7: 空气 | Y7: 空气 | Z7: =VLOOKUP(A7,对应信息!$D$2:$E$11,2,0) -> 4000 | AA7: =IF(Z6=Z7,AA6+1,Z7+1) -> 4001
A8: 分辨率检验 | B8: 分辨率 | D8: =IF(L8="","",字段对应!$B$10&"="&VLOOKUP(L8,基础信息!$I$2:$J$6,2,0)&";")&IF(M8="","",字段对应!$B$11&"="&VLOOKUP(M8,基础信息!$K$2:$L$6,2,0)&";")&IF(N8="","",字段对应!$C$2&"="&N8&","&O8&","&P8&";")&IF(Q8="","",字段对应!$B$13&"="&Q8&";")&IF(R8="","",字段对应!$B$14&"="&R8&";")&IF(U8="","",字段对应!$B$22&"="&U8&";")&IF(K8="","",字段对应!$B$21&"="&VLOOKUP(K8,基础信息!$F$2:$G$4,2,0)) -> PhotoMode=0;ScanSpeed=1;WlRange=270,165,0.2; | E8: =IF(W8="","",检测项信息!W8&":"&字段对应!$B$16&"|")&IF(X8="","",X8&":"&IF(V8="是",字段对应!$C$17,字段对应!$B$17&";"&IF(H8="","",字段对应!$B$15&"="&检测项信息!H8))&"|")&IF(Y8="",":",Y8&":")&IF(V8="是",字段对应!$C$18,字段对应!$B$18&";"&IF(H8="","",字段对应!$B$15&"="&检测项信息!H8)&IF(AND(T8="",S8=""),"",";"&字段对应!$B$20&"="&T8&";"&字段对应!$B$19&"="&S8)) -> 黑挡块:Dark|分辨率空白溶液:BaseLine|分辨率溶液:Scan | F8: 1 | I8: =VLOOKUP(J8,字段对应!$D$2:$E$9,2,0) -> Validation.ViewModel.DataStructure.GetRatioOfMaxToMinUVTestTool | J8: 最大最小值比 | L8: Abs | M8: 中速 | N8: 270 | O8: 165 | P8: 0.2 | V8: 是 | W8: 黑挡块 | X8: 分辨率空白溶液 | Y8: 分辨率溶液 | Z8: =VLOOKUP(A8,对应信息!$D$2:$E$11,2,0) -> 10000 | AA8: =IF(Z7=Z8,AA7+1,Z8+1) -> 10001 | AC8: 计算方法是高点除以低点的结果值大于1.4算合格
A9: 基线暗噪声检验 | B9: 基线暗噪声 | D9: =IF(L9="","",字段对应!$B$10&"="&VLOOKUP(L9,基础信息!$I$2:$J$6,2,0)&";")&IF(M9="","",字段对应!$B$11&"="&VLOOKUP(M9,基础信息!$K$2:$L$6,2,0)&";")&IF(N9="","",字段对应!$C$2&"="&N9&","&O9&","&P9&";")&IF(Q9="","",字段对应!$B$13&"="&Q9&";")&IF(R9="","",字段对应!$B$14&"="&R9&";")&IF(U9="","",字段对应!$B$22&"="&U9&";")&IF(K9="","",字段对应!$B$21&"="&VLOOKUP(K9,基础信息!$F$2:$G$4,2,0)) -> PhotoMode=1;ScanSpeed=2;WlRange=1090,200,1; | E9: =IF(W9="","",检测项信息!W9&":"&字段对应!$B$16&"|")&IF(X9="","",X9&":"&IF(V9="是",字段对应!$C$17,字段对应!$B$17&";"&IF(H9="","",字段对应!$B$15&"="&检测项信息!H9))&"|")&IF(Y9="",":",Y9&":")&IF(V9="是",字段对应!$C$18,字段对应!$B$18&";"&IF(H9="","",字段对应!$B$15&"="&检测项信息!H9)&IF(AND(T9="",S9=""),"",";"&字段对应!$B$20&"="&T9&";"&字段对应!$B$19&"="&S9)) -> 黑挡块:Dark|空气:BaseLine|黑挡块:Scan | F9: 1 | I9: =VLOOKUP(J9,字段对应!$D$2:$E$9,2,0) -> Validation.ViewModel.DataStructure.GetMaxDIstanceUVTestTool | J9: 求最大偏移量 | L9: T% | M9: 慢速 | N9: 1090 | O9: 200 | P9: 1 | V9: 是 | W9: 黑挡块 | X9: 空气 | Y9: 黑挡块 | Z9: =VLOOKUP(A9,对应信息!$D$2:$E$11,2,0) -> 5000 | AA9: =IF(Z8=Z9,AA8+1,Z9+1) -> 5001
A10: 噪声检验 | B10: 500nm100%噪声 | D10: =IF(L10="","",字段对应!$B$10&"="&VLOOKUP(L10,基础信息!$I$2:$J$6,2,0)&";")&IF(M10="","",字段对应!$B$11&"="&VLOOKUP(M10,基础信息!$K$2:$L$6,2,0)&";")&IF(N10="","",字段对应!$C$2&"="&N10&","&O10&","&P10&";")&IF(Q10="","",字段对应!$B$13&"="&Q10&";")&IF(R10="","",字段对应!$B$14&"="&R10&";")&IF(U10="","",字段对应!$B$22&"="&U10&";")&IF(K10="","",字段对应!$B$21&"="&VLOOKUP(K10,基础信息!$F$2:$G$4,2,0)) -> PhotoMode=1;ScanSpeed=1;ResponseTime=0.5; | E10: =IF(W10="","",检测项信息!W10&":"&字段对应!$B$16&"|")&IF(X10="","",X10&":"&IF(V10="是",字段对应!$C$17,字段对应!$B$17&";"&IF(H10="","",字段对应!$B$15&"="&检测项信息!H10))&"|")&IF(Y10="",":",Y10&":")&IF(V10="是",字段对应!$C$18,字段对应!$B$18&";"&IF(H10="","",字段对应!$B$15&"="&检测项信息!H10)&IF(AND(T10="",S10=""),"",";"&字段对应!$B$20&"="&T10&";"&字段对应!$B$19&"="&S10)) -> 黑挡块:Dark|空气:Zero;Wl=500|空气:Measure;Wl=500;totalcount=120;timeinterval=1 | F10: 1 | H10: 500 | I10: =VLOOKUP(J10,字段对应!$D$2:$E$9,2,0) -> Validation.ViewModel.DataStructure.FindMaxOffsetUVTestTool | J10: 最大最小值差 | L10: T% | M10: 中速 | S10: 1 | T10: 120 | U10: 0.5 | V10: 否 | W10: 黑挡块 | X10: 空气 | Y10: 空气 | Z10: =VLOOKUP(A10,对应信息!$D$2:$E$11,2,0) -> 7000 | AA10: =IF(Z9=Z10,AA9+1,Z10+1) -> 7001
A11: 噪声检验 | B11: 500nm0%噪声 | D11: =IF(L11="","",字段对应!$B$10&"="&VLOOKUP(L11,基础信息!$I$2:$J$6,2,0)&";")&IF(M11="","",字段对应!$B$11&"="&VLOOKUP(M11,基础信息!$K$2:$L$6,2,0)&";")&IF(N11="","",字段对应!$C$2&"="&N11&","&O11&","&P11&";")&IF(Q11="","",字段对应!$B$13&"="&Q11&";")&IF(R11="","",字段对应!$B$14&"="&R11&";")&IF(U11="","",字段对应!$B$22&"="&U11&";")&IF(K11="","",字段对应!$B$21&"="&VLOOKUP(K11,基础信息!$F$2:$G$4,2,0)) -> PhotoMode=1;ScanSpeed=1;ResponseTime=0.5; | E11: =IF(W11="","",检测项信息!W11&":"&字段对应!$B$16&"|")&IF(X11="","",X11&":"&IF(V11="是",字段对应!$C$17,字段对应!$B$17&";"&IF(H11="","",字段对应!$B$15&"="&检测项信息!H11))&"|")&IF(Y11="",":",Y11&":")&IF(V11="是",字段对应!$C$18,字段对应!$B$18&";"&IF(H11="","",字段对应!$B$15&"="&检测项信息!H11)&IF(AND(T11="",S11=""),"",";"&字段对应!$B$20&"="&T11&";"&字段对应!$B$19&"="&S11)) -> 黑挡块:Dark|空气:Zero;Wl=500|黑挡块:Measure;Wl=500;totalcount=120;timeinterval=1 | F11: 1 | H11: 500 | I11: =VLOOKUP(J11,字段对应!$D$2:$E$9,2,0) -> Validation.ViewModel.DataStructure.FindMaxOffsetUVTestTool | J11: 最大最小值差 | L11: T% | M11: 中速 | S11: 1 | T11: 120 | U11: 0.5 | V11: 否 | W11: 黑挡块 | X11: 空气 | Y11: 黑挡块 | Z11: =VLOOKUP(A11,对应信息!$D$2:$E$11,2,0) -> 7000 | AA11: =IF(Z10=Z11,AA10+1,Z11+1) -> 7002
A12: 噪声检验 | B12: 250nm100%噪声 | D12: =IF(L12="","",字段对应!$B$10&"="&VLOOKUP(L12,基础信息!$I$2:$J$6,2,0)&";")&IF(M12="","",字段对应!$B$11&"="&VLOOKUP(M12,基础信息!$K$2:$L$6,2,0)&";")&IF(N12="","",字段对应!$C$2&"="&N12&","&O12&","&P12&";")&IF(Q12="","",字段对应!$B$13&"="&Q12&";")&IF(R12="","",字段对应!$B$14&"="&R12&";")&IF(U12="","",字段对应!$B$22&"="&U12&";")&IF(K12="","",字段对应!$B$21&"="&VLOOKUP(K12,基础信息!$F$2:$G$4,2,0)) -> PhotoMode=1;ScanSpeed=1;ResponseTime=0.5; | E12: =IF(W12="","",检测项信息!W12&":"&字段对应!$B$16&"|")&IF(X12="","",X12&":"&IF(V12="是",字段对应!$C$17,字段对应!$B$17&";"&IF(H12="","",字段对应!$B$15&"="&检测项信息!H12))&"|")&IF(Y12="",":",Y12&":")&IF(V12="是",字段对应!$C$18,字段对应!$B$18&";"&IF(H12="","",字段对应!$B$15&"="&检测项信息!H12)&IF(AND(T12="",S12=""),"",";"&字段对应!$B$20&"="&T12&";"&字段对应!$B$19&"="&S12)) -> 黑挡块:Dark|空气:Zero;Wl=250|空气:Measure;Wl=250;totalcount=120;timeinterval=1 | F12: 1 | H12: 250 | I12: =VLOOKUP(J12,字段对应!$D$2:$E$9,2,0) -> Validation.ViewModel.DataStructure.FindMaxOffsetUVTestTool | J12: 最大最小值差 | L12: T% | M12: 中速 | S12: 1 | T12: 120 | U12: 0.5 | V12: 否 | W12: 黑挡块 | X12: 空气 | Y12: 空气 | Z12: =VLOOKUP(A12,对应信息!$D$2:$E$11,2,0) -> 7000 | AA12: =IF(Z11=Z12,AA11+1,Z12+1) -> 7003
A13: 噪声检验 | B13: 250nm0%噪声 | D13: =IF(L13="","",字段对应!$B$10&"="&VLOOKUP(L13,基础信息!$I$2:$J$6,2,0)&";")&IF(M13="","",字段对应!$B$11&"="&VLOOKUP(M13,基础信息!$K$2:$L$6,2,0)&";")&IF(N13="","",字段对应!$C$2&"="&N13&","&O13&","&P13&";")&IF(Q13="","",字段对应!$B$13&"="&Q13&";")&IF(R13="","",字段对应!$B$14&"="&R13&";")&IF(U13="","",字段对应!$B$22&"="&U13&";")&IF(K13="","",字段对应!$B$21&"="&VLOOKUP(K13,基础信息!$F$2:$G$4,2,0)) -> PhotoMode=1;ScanSpeed=1;ResponseTime=0.5; | E13: =IF(W13="","",检测项信息!W13&":"&字段对应!$B$16&"|")&IF(X13="","",X13&":"&IF(V13="是",字段对应!$C$17,字段对应!$B$17&";"&IF(H13="","",字段对应!$B$15&"="&检测项信息!H13))&"|")&IF(Y13="",":",Y13&":")&IF(V13="是",字段对应!$C$18,字段对应!$B$18&";"&IF(H13="","",字段对应!$B$15&"="&检测项信息!H13)&IF(AND(T13="",S13=""),"",";"&字段对应!$B$20&"="&T13&";"&字段对应!$B$19&"="&S13)) -> 黑挡块:Dark|空气:Zero;Wl=250|黑挡块:Measure;Wl=250;totalcount=120;timeinterval=1 | F13: 1 | H13: 250 | I13: =VLOOKUP(J13,字段对应!$D$2:$E$9,2,0) -> Validation.ViewModel.DataStructure.FindMaxOffsetUVTestTool | J13: 最大最小值差 | L13: T% | M13: 中速 | S13: 1 | T13: 120 | U13: 0.5 | V13: 否 | W13: 黑挡块 | X13: 空气 | Y13: 黑挡块 | Z13: =VLOOKUP(A13,对应信息!$D$2:$E$11,2,0) -> 7000 | AA13: =IF(Z12=Z13,AA12+1,Z13+1) -> 7004
A14: 波长边缘噪声 | B14: 1090nm100%噪声 | D14: =IF(L14="","",字段对应!$B$10&"="&VLOOKUP(L14,基础信息!$I$2:$J$6,2,0)&";")&IF(M14="","",字段对应!$B$11&"="&VLOOKUP(M14,基础信息!$K$2:$L$6,2,0)&";")&IF(N14="","",字段对应!$C$2&"="&N14&","&O14&","&P14&";")&IF(Q14="","",字段对应!$B$13&"="&Q14&";")&IF(R14="","",字段对应!$B$14&"="&R14&";")&IF(U14="","",字段对应!$B$22&"="&U14&";")&IF(K14="","",字段对应!$B$21&"="&VLOOKUP(K14,基础信息!$F$2:$G$4,2,0)) -> PhotoMode=1;ScanSpeed=1;ResponseTime=0.5; | E14: =IF(W14="","",检测项信息!W14&":"&字段对应!$B$16&"|")&IF(X14="","",X14&":"&IF(V14="是",字段对应!$C$17,字段对应!$B$17&";"&IF(H14="","",字段对应!$B$15&"="&检测项信息!H14))&"|")&IF(Y14="",":",Y14&":")&IF(V14="是",字段对应!$C$18,字段对应!$B$18&";"&IF(H14="","",字段对应!$B$15&"="&检测项信息!H14)&IF(AND(T14="",S14=""),"",";"&字段对应!$B$20&"="&T14&";"&字段对应!$B$19&"="&S14)) -> 黑挡块:Dark|空气:Zero;Wl=1090|空气:Measure;Wl=1090;totalcount=180;timeinterval=1 | F14: 1 | H14: 1090 | I14: =VLOOKUP(J14,字段对应!$D$2:$E$9,2,0) -> Validation.ViewModel.DataStructure.FindMaxOffsetUVTestTool | J14: 最大最小值差 | L14: T% | M14: 中速 | S14: 1 | T14: 180 | U14: 0.5 | V14: 否 | W14: 黑挡块 | X14: 空气 | Y14: 空气 | Z14: =VLOOKUP(A14,对应信息!$D$2:$E$11,2,0) -> 8000 | AA14: =IF(Z13=Z14,AA13+1,Z14+1) -> 8001
A15: 波长边缘噪声 | B15: 1090nm0%噪声 | D15: =IF(L15="","",字段对应!$B$10&"="&VLOOKUP(L15,基础信息!$I$2:$J$6,2,0)&";")&IF(M15="","",字段对应!$B$11&"="&VLOOKUP(M15,基础信息!$K$2:$L$6,2,0)&";")&IF(N15="","",字段对应!$C$2&"="&N15&","&O15&","&P15&";")&IF(Q15="","",字段对应!$B$13&"="&Q15&";")&IF(R15="","",字段对应!$B$14&"="&R15&";")&IF(U15="","",字段对应!$B$22&"="&U15&";")&IF(K15="","",字段对应!$B$21&"="&VLOOKUP(K15,基础信息!$F$2:$G$4,2,0)) -> PhotoMode=1;ScanSpeed=1;ResponseTime=0.5; | E15: =IF(W15="","",检测项信息!W15&":"&字段对应!$B$16&"|")&IF(X15="","",X15&":"&IF(V15="是",字段对应!$C$17,字段对应!$B$17&";"&IF(H15="","",字段对应!$B$15&"="&检测项信息!H15))&"|")&IF(Y15="",":",Y15&":")&IF(V15="是",字段对应!$C$18,字段对应!$B$18&";"&IF(H15="","",字段对应!$B$15&"="&检测项信息!H15)&IF(AND(T15="",S15=""),"",";"&字段对应!$B$20&"="&T15&";"&字段对应!$B$19&"="&S15)) -> 黑挡块:Dark|空气:Zero;Wl=1090|黑挡块:Measure;Wl=1090;totalcount=180;timeinterval=1 | F15: 1 | H15: 1090 | I15: =VLOOKUP(J15,字段对应!$D$2:$E$9,2,0) -> Validation.ViewModel.DataStructure.FindMaxOffsetUVTestTool | J15: 最大最小值差 | L15: T% | M15: 中速 | S15: 1 | T15: 180 | U15: 0.5 | V15: 否 | W15: 黑挡块 | X15: 空气 | Y15: 黑挡块 | Z15: =VLOOKUP(A15,对应信息!$D$2:$E$11,2,0) -> 8000 | AA15: =IF(Z14=Z15,AA14+1,Z15+1) -> 8002
A16: 波长边缘噪声 | B16: 200nm100%噪声 | D16: =IF(L16="","",字段对应!$B$10&"="&VLOOKUP(L16,基础信息!$I$2:$J$6,2,0)&";")&IF(M16="","",字段对应!$B$11&"="&VLOOKUP(M16,基础信息!$K$2:$L$6,2,0)&";")&IF(N16="","",字段对应!$C$2&"="&N16&","&O16&","&P16&";")&IF(Q16="","",字段对应!$B$13&"="&Q16&";")&IF(R16="","",字段对应!$B$14&"="&R16&";")&IF(U16="","",字段对应!$B$22&"="&U16&";")&IF(K16="","",字段对应!$B$21&"="&VLOOKUP(K16,基础信息!$F$2:$G$4,2,0)) -> PhotoMode=1;ScanSpeed=1;ResponseTime=0.5; | E16: =IF(W16="","",检测项信息!W16&":"&字段对应!$B$16&"|")&IF(X16="","",X16&":"&IF(V16="是",字段对应!$C$17,字段对应!$B$17&";"&IF(H16="","",字段对应!$B$15&"="&检测项信息!H16))&"|")&IF(Y16="",":",Y16&":")&IF(V16="是",字段对应!$C$18,字段对应!$B$18&";"&IF(H16="","",字段对应!$B$15&"="&检测项信息!H16)&IF(AND(T16="",S16=""),"",";"&字段对应!$B$20&"="&T16&";"&字段对应!$B$19&"="&S16)) -> 黑挡块:Dark|空气:Zero;Wl=200|空气:Measure;Wl=200;totalcount=180;timeinterval=1 | F16: 1 | H16: 200 | I16: =VLOOKUP(J16,字段对应!$D$2:$E$9,2,0) -> Validation.ViewModel.DataStructure.FindMaxOffsetUVTestTool | J16: 最大最小值差 | L16: T% | M16: 中速 | S16: 1 | T16: 180 | U16: 0.5 | V16: 否 | W16: 黑挡块 | X16: 空气 | Y16: 空气 | Z16: =VLOOKUP(A16,对应信息!$D$2:$E$11,2,0) -> 8000 | AA16: =IF(Z15=Z16,AA15+1,Z16+1) -> 8003
A17: 波长边缘噪声 | B17: 200nm0%噪声 | D17: =IF(L17="","",字段对应!$B$10&"="&VLOOKUP(L17,基础信息!$I$2:$J$6,2,0)&";")&IF(M17="","",字段对应!$B$11&"="&VLOOKUP(M17,基础信息!$K$2:$L$6,2,0)&";")&IF(N17="","",字段对应!$C$2&"="&N17&","&O17&","&P17&";")&IF(Q17="","",字段对应!$B$13&"="&Q17&";")&IF(R17="","",字段对应!$B$14&"="&R17&";")&IF(U17="","",字段对应!$B$22&"="&U17&";")&IF(K17="","",字段对应!$B$21&"="&VLOOKUP(K17,基础信息!$F$2:$G$4,2,0)) -> PhotoMode=1;ScanSpeed=1;ResponseTime=0.5; | E17: =IF(W17="","",检测项信息!W17&":"&字段对应!$B$16&"|")&IF(X17="","",X17&":"&IF(V17="是",字段对应!$C$17,字段对应!$B$17&";"&IF(H17="","",字段对应!$B$15&"="&检测项信息!H17))&"|")&IF(Y17="",":",Y17&":")&IF(V17="是",字段对应!$C$18,字段对应!$B$18&";"&IF(H17="","",字段对应!$B$15&"="&检测项信息!H17)&IF(AND(T17="",S17=""),"",";"&字段对应!$B$20&"="&T17&";"&字段对应!$B$19&"="&S17)) -> 黑挡块:Dark|空气:Zero;Wl=200|黑挡块:Measure;Wl=200;totalcount=180;timeinterval=1 | F17: 1 | H17: 200 | I17: =VLOOKUP(J17,字段对应!$D$2:$E$9,2,0) -> Validation.ViewModel.DataStructure.FindMaxOffsetUVTestTool | J17: 最大最小值差 | L17: T% | M17: 中速 | S17: 1 | T17: 180 | U17: 0.5 | V17: 否 | W17: 黑挡块 | X17: 空气 | Y17: 黑挡块 | Z17: =VLOOKUP(A17,对应信息!$D$2:$E$11,2,0) -> 8000 | AA17: =IF(Z16=Z17,AA16+1,Z17+1) -> 8004
A18: 杂散光校验 | B18: 220nm杂散光 | D18: =IF(L18="","",字段对应!$B$10&"="&VLOOKUP(L18,基础信息!$I$2:$J$6,2,0)&";")&IF(M18="","",字段对应!$B$11&"="&VLOOKUP(M18,基础信息!$K$2:$L$6,2,0)&";")&IF(N18="","",字段对应!$C$2&"="&N18&","&O18&","&P18&";")&IF(Q18="","",字段对应!$B$13&"="&Q18&";")&IF(R18="","",字段对应!$B$14&"="&R18&";")&IF(U18="","",字段对应!$B$22&"="&U18&";")&IF(K18="","",字段对应!$B$21&"="&VLOOKUP(K18,基础信息!$F$2:$G$4,2,0)) -> PhotoMode=1;ScanSpeed=1; | E18: =IF(W18="","",检测项信息!W18&":"&字段对应!$B$16&"|")&IF(X18="","",X18&":"&IF(V18="是",字段对应!$C$17,字段对应!$B$17&";"&IF(H18="","",字段对应!$B$15&"="&检测项信息!H18))&"|")&IF(Y18="",":",Y18&":")&IF(V18="是",字段对应!$C$18,字段对应!$B$18&";"&IF(H18="","",字段对应!$B$15&"="&检测项信息!H18)&IF(AND(T18="",S18=""),"",";"&字段对应!$B$20&"="&T18&";"&字段对应!$B$19&"="&S18)) -> 黑挡块:Dark|碘化钠空白溶液:Zero;Wl=220|碘化钠溶液:Measure;Wl=220 | F18: 3 | G18: 1 | H18: 220 | I18: =VLOOKUP(J18,字段对应!$D$2:$E$9,2,0) -> Validation.ViewModel.DataStructure.WlPointsUVTestTool | J18: 多次测量 | L18: T% | M18: 中速 | V18: 否 | W18: 黑挡块 | X18: 碘化钠空白溶液 | Y18: 碘化钠溶液 | Z18: =VLOOKUP(A18,对应信息!$D$2:$E$11,2,0) -> 3000 | AA18: =IF(Z17=Z18,AA17+1,Z18+1) -> 3001
A19: 杂散光校验 | B19: 360nm杂散光 | D19: =IF(L19="","",字段对应!$B$10&"="&VLOOKUP(L19,基础信息!$I$2:$J$6,2,0)&";")&IF(M19="","",字段对应!$B$11&"="&VLOOKUP(M19,基础信息!$K$2:$L$6,2,0)&";")&IF(N19="","",字段对应!$C$2&"="&N19&","&O19&","&P19&";")&IF(Q19="","",字段对应!$B$13&"="&Q19&";")&IF(R19="","",字段对应!$B$14&"="&R19&";")&IF(U19="","",字段对应!$B$22&"="&U19&";")&IF(K19="","",字段对应!$B$21&"="&VLOOKUP(K19,基础信息!$F$2:$G$4,2,0)) -> PhotoMode=1;ScanSpeed=1; | E19: =IF(W19="","",检测项信息!W19&":"&字段对应!$B$16&"|")&IF(X19="","",X19&":"&IF(V19="是",字段对应!$C$17,字段对应!$B$17&";"&IF(H19="","",字段对应!$B$15&"="&检测项信息!H19))&"|")&IF(Y19="",":",Y19&":")&IF(V19="是",字段对应!$C$18,字段对应!$B$18&";"&IF(H19="","",字段对应!$B$15&"="&检测项信息!H19)&IF(AND(T19="",S19=""),"",";"&字段对应!$B$20&"="&T19&";"&字段对应!$B$19&"="&S19)) -> 黑挡块:Dark|亚硝酸钠空白溶液:Zero;Wl=360|亚硝酸钠溶液:Measure;Wl=360 | F19: 3 | G19: 1 | H19: 360 | I19: =VLOOKUP(J19,字段对应!$D$2:$E$9,2,0) -> Validation.ViewModel.DataStructure.WlPointsUVTestTool | J19: 多次测量 | L19: T% | M19: 中速 | V19: 否 | W19: 黑挡块 | X19: 亚硝酸钠空白溶液 | Y19: 亚硝酸钠溶液 | Z19: =VLOOKUP(A19,对应信息!$D$2:$E$11,2,0) -> 3000 | AA19: =IF(Z18=Z19,AA18+1,Z19+1) -> 3002
A20: 杂散光校验 | B20: 198-200nm杂散光 | D20: =IF(L20="","",字段对应!$B$10&"="&VLOOKUP(L20,基础信息!$I$2:$J$6,2,0)&";")&IF(M20="","",字段对应!$B$11&"="&VLOOKUP(M20,基础信息!$K$2:$L$6,2,0)&";")&IF(N20="","",字段对应!$C$2&"="&N20&","&O20&","&P20&";")&IF(Q20="","",字段对应!$B$13&"="&Q20&";")&IF(R20="","",字段对应!$B$14&"="&R20&";")&IF(U20="","",字段对应!$B$22&"="&U20&";")&IF(K20="","",字段对应!$B$21&"="&VLOOKUP(K20,基础信息!$F$2:$G$4,2,0)) -> PhotoMode=0;ScanSpeed=1; | E20: =IF(W20="","",检测项信息!W20&":"&字段对应!$B$16&"|")&IF(X20="","",X20&":"&IF(V20="是",字段对应!$C$17,字段对应!$B$17&";"&IF(H20="","",字段对应!$B$15&"="&检测项信息!H20))&"|")&IF(Y20="",":",Y20&":")&IF(V20="是",字段对应!$C$18,字段对应!$B$18&";"&IF(H20="","",字段对应!$B$15&"="&检测项信息!H20)&IF(AND(T20="",S20=""),"",";"&字段对应!$B$20&"="&T20&";"&字段对应!$B$19&"="&S20)) -> 黑挡块:Dark|氯化钾空白溶液:Zero;Wl=200,199,198|氯化钾溶液:Measure;Wl=200,199,198 | F20: 3 | G20: 1 | H20: 200,199,198 | I20: =VLOOKUP(J20,字段对应!$D$2:$E$9,2,0) -> Validation.ViewModel.DataStructure.WlPointsUVTestTool | J20: 多次测量 | L20: Abs | M20: 中速 | V20: 否 | W20: 黑挡块 | X20: 氯化钾空白溶液 | Y20: 氯化钾溶液 | Z20: =VLOOKUP(A20,对应信息!$D$2:$E$11,2,0) -> 3000 | AA20: =IF(Z19=Z20,AA19+1,Z20+1) -> 3003 | AC20: 其中有一个点大于2.0就算合格
A21: 透射比示值误差与重复性校验 | B21: 紫外分光光度计标准物质GBW(E)130066 | D21: =IF(L21="","",字段对应!$B$10&"="&VLOOKUP(L21,基础信息!$I$2:$J$6,2,0)&";")&IF(M21="","",字段对应!$B$11&"="&VLOOKUP(M21,基础信息!$K$2:$L$6,2,0)&";")&IF(N21="","",字段对应!$C$2&"="&N21&","&O21&","&P21&";")&IF(Q21="","",字段对应!$B$13&"="&Q21&";")&IF(R21="","",字段对应!$B$14&"="&R21&";")&IF(U21="","",字段对应!$B$22&"="&U21&";")&IF(K21="","",字段对应!$B$21&"="&VLOOKUP(K21,基础信息!$F$2:$G$4,2,0)) -> PhotoMode=1;ScanSpeed=1; | E21: =IF(W21="","",检测项信息!W21&":"&字段对应!$B$16&"|")&IF(X21="","",X21&":"&IF(V21="是",字段对应!$C$17,字段对应!$B$17&";"&IF(H21="","",字段对应!$B$15&"="&检测项信息!H21))&"|")&IF(Y21="",":",Y21&":")&IF(V21="是",字段对应!$C$18,字段对应!$B$18&";"&IF(H21="","",字段对应!$B$15&"="&检测项信息!H21)&IF(AND(T21="",S21=""),"",";"&字段对应!$B$20&"="&T21&";"&字段对应!$B$19&"="&S21)) -> 黑挡块:Dark|紫外分光光度计标准物质空白溶液:Zero;Wl=350,313,257,235|紫外分光光度计标准物质GBW(E)130066:Measure;Wl=350,313,257,235 | F21: 3 | G21: 1 | H21: 350,313,257,235 | I21: =VLOOKUP(J21,字段对应!$D$2:$E$9,2,0) -> Validation.ViewModel.DataStructure.WlPointsAndAverageUVTestTool | J21: 求平均 | L21: T% | M21: 中速 | V21: 否 | W21: 黑挡块 | X21: 紫外分光光度计标准物质空白溶液 | Y21: 紫外分光光度计标准物质GBW(E)130066 | Z21: =VLOOKUP(A21,对应信息!$D$2:$E$11,2,0) -> 2000 | AA21: =IF(Z20=Z21,AA20+1,Z21+1) -> 2001 | AB21: 23.2,51.58,14.06,18.42
A22: 透射比示值误差与重复性校验 | B22: 10%中性滤光片 | D22: =IF(L22="","",字段对应!$B$10&"="&VLOOKUP(L22,基础信息!$I$2:$J$6,2,0)&";")&IF(M22="","",字段对应!$B$11&"="&VLOOKUP(M22,基础信息!$K$2:$L$6,2,0)&";")&IF(N22="","",字段对应!$C$2&"="&N22&","&O22&","&P22&";")&IF(Q22="","",字段对应!$B$13&"="&Q22&";")&IF(R22="","",字段对应!$B$14&"="&R22&";")&IF(U22="","",字段对应!$B$22&"="&U22&";")&IF(K22="","",字段对应!$B$21&"="&VLOOKUP(K22,基础信息!$F$2:$G$4,2,0)) -> PhotoMode=1;ScanSpeed=1; | E22: =IF(W22="","",检测项信息!W22&":"&字段对应!$B$16&"|")&IF(X22="","",X22&":"&IF(V22="是",字段对应!$C$17,字段对应!$B$17&";"&IF(H22="","",字段对应!$B$15&"="&检测项信息!H22))&"|")&IF(Y22="",":",Y22&":")&IF(V22="是",字段对应!$C$18,字段对应!$B$18&";"&IF(H22="","",字段对应!$B$15&"="&检测项信息!H22)&IF(AND(T22="",S22=""),"",";"&字段对应!$B$20&"="&T22&";"&字段对应!$B$19&"="&S22)) -> 黑挡块:Dark|空气:Zero;Wl=635,546,440|10%中性滤光片:Measure;Wl=635,546,440 | F22: 3 | G22: 1 | H22: 635,546,440 | I22: =VLOOKUP(J22,字段对应!$D$2:$E$9,2,0) -> Validation.ViewModel.DataStructure.WlPointsAndAverageUVTestTool | J22: 求平均 | L22: T% | M22: 中速 | V22: 否 | W22: 黑挡块 | X22: 空气 | Y22: 10%中性滤光片 | Z22: =VLOOKUP(A22,对应信息!$D$2:$E$11,2,0) -> 2000 | AA22: =IF(Z21=Z22,AA21+1,Z22+1) -> 2002 | AB22: 7.57,10.1,10.07
A23: 透射比示值误差与重复性校验 | B23: 20%中性滤光片 | D23: =IF(L23="","",字段对应!$B$10&"="&VLOOKUP(L23,基础信息!$I$2:$J$6,2,0)&";")&IF(M23="","",字段对应!$B$11&"="&VLOOKUP(M23,基础信息!$K$2:$L$6,2,0)&";")&IF(N23="","",字段对应!$C$2&"="&N23&","&O23&","&P23&";")&IF(Q23="","",字段对应!$B$13&"="&Q23&";")&IF(R23="","",字段对应!$B$14&"="&R23&";")&IF(U23="","",字段对应!$B$22&"="&U23&";")&IF(K23="","",字段对应!$B$21&"="&VLOOKUP(K23,基础信息!$F$2:$G$4,2,0)) -> PhotoMode=1;ScanSpeed=1; | E23: =IF(W23="","",检测项信息!W23&":"&字段对应!$B$16&"|")&IF(X23="","",X23&":"&IF(V23="是",字段对应!$C$17,字段对应!$B$17&";"&IF(H23="","",字段对应!$B$15&"="&检测项信息!H23))&"|")&IF(Y23="",":",Y23&":")&IF(V23="是",字段对应!$C$18,字段对应!$B$18&";"&IF(H23="","",字段对应!$B$15&"="&检测项信息!H23)&IF(AND(T23="",S23=""),"",";"&字段对应!$B$20&"="&T23&";"&字段对应!$B$19&"="&S23)) -> 黑挡块:Dark|空气:Zero;Wl=635,546,440|20%中性滤光片:Measure;Wl=635,546,440 | F23: 3 | G23: 1 | H23: 635,546,440 | I23: =VLOOKUP(J23,字段对应!$D$2:$E$9,2,0) -> Validation.ViewModel.DataStructure.WlPointsAndAverageUVTestTool | J23: 求平均 | L23: T% | M23: 中速 | V23: 否 | W23: 黑挡块 | X23: 空气 | Y23: 20%中性滤光片 | Z23: =VLOOKUP(A23,对应信息!$D$2:$E$11,2,0) -> 2000 | AA23: =IF(Z22=Z23,AA22+1,Z23+1) -> 2003 | AB23: 18.89,20.09,20.91
A24: 透射比示值误差与重复性校验 | B24: 30%中性滤光片 | D24: =IF(L24="","",字段对应!$B$10&"="&VLOOKUP(L24,基础信息!$I$2:$J$6,2,0)&";")&IF(M24="","",字段对应!$B$11&"="&VLOOKUP(M24,基础信息!$K$2:$L$6,2,0)&";")&IF(N24="","",字段对应!$C$2&"="&N24&","&O24&","&P24&";")&IF(Q24="","",字段对应!$B$13&"="&Q24&";")&IF(R24="","",字段对应!$B$14&"="&R24&";")&IF(U24="","",字段对应!$B$22&"="&U24&";")&IF(K24="","",字段对应!$B$21&"="&VLOOKUP(K24,基础信息!$F$2:$G$4,2,0)) -> PhotoMode=1;ScanSpeed=1; | E24: =IF(W24="","",检测项信息!W24&":"&字段对应!$B$16&"|")&IF(X24="","",X24&":"&IF(V24="是",字段对应!$C$17,字段对应!$B$17&";"&IF(H24="","",字段对应!$B$15&"="&检测项信息!H24))&"|")&IF(Y24="",":",Y24&":")&IF(V24="是",字段对应!$C$18,字段对应!$B$18&";"&IF(H24="","",字段对应!$B$15&"="&检测项信息!H24)&IF(AND(T24="",S24=""),"",";"&字段对应!$B$20&"="&T24&";"&字段对应!$B$19&"="&S24)) -> 黑挡块:Dark|空气:Zero;Wl=635,546,440|30%中性滤光片:Measure;Wl=635,546,440 | F24: 3 | G24: 1 | H24: 635,546,440 | I24: =VLOOKUP(J24,字段对应!$D$2:$E$9,2,0) -> Validation.ViewModel.DataStructure.WlPointsAndAverageUVTestTool | J24: 求平均 | L24: T% | M24: 中速 | V24: 否 | W24: 黑挡块 | X24: 空气 | Y24: 30%中性滤光片 | Z24: =VLOOKUP(A24,对应信息!$D$2:$E$11,2,0) -> 2000 | AA24: =IF(Z23=Z24,AA23+1,Z24+1) -> 2004 | AB24: 29.96,30.43,28.88
A25: 漂移检验 | B25: 漂移检验 | C25: 仪器预热1小时之后进行检验 | D25: =IF(L25="","",字段对应!$B$10&"="&VLOOKUP(L25,基础信息!$I$2:$J$6,2,0)&";")&IF(M25="","",字段对应!$B$11&"="&VLOOKUP(M25,基础信息!$K$2:$L$6,2,0)&";")&IF(N25="","",字段对应!$C$2&"="&N25&","&O25&","&P25&";")&IF(Q25="","",字段对应!$B$13&"="&Q25&";")&IF(R25="","",字段对应!$B$14&"="&R25&";")&IF(U25="","",字段对应!$B$22&"="&U25&";")&IF(K25="","",字段对应!$B$21&"="&VLOOKUP(K25,基础信息!$F$2:$G$4,2,0)) -> PhotoMode=1;ScanSpeed=1;ResponseTime=0.5; | E25: =IF(W25="","",检测项信息!W25&":"&字段对应!$B$16&"|")&IF(X25="","",X25&":"&IF(V25="是",字段对应!$C$17,字段对应!$B$17&";"&IF(H25="","",字段对应!$B$15&"="&检测项信息!H25))&"|")&IF(Y25="",":",Y25&":")&IF(V25="是",字段对应!$C$18,字段对应!$B$18&";"&IF(H25="","",字段对应!$B$15&"="&检测项信息!H25)&IF(AND(T25="",S25=""),"",";"&字段对应!$B$20&"="&T25&";"&字段对应!$B$19&"="&S25)) -> 黑挡块:Dark|空气:Zero;Wl=500|空气:Measure;Wl=500;totalcount=3600;timeinterval=1 | F25: 1 | H25: 500 | I25: =VLOOKUP(J25,字段对应!$D$2:$E$9,2,0) -> Validation.ViewModel.DataStructure.FindMaxOffsetUVTestTool | J25: 最大最小值差 | L25: T% | M25: 中速 | S25: 1 | T25: 3600 | U25: 0.5 | V25: 否 | W25: 黑挡块 | X25: 空气 | Y25: 空气 | Z25: =VLOOKUP(A25,对应信息!$D$2:$E$11,2,0) -> 9000 | AA25: =IF(Z24=Z25,AA24+1,Z25+1) -> 9001

Sheet 仪器状态
A1: 仪器id | B1: 项目 | C1: 能量 | D1: id | E1: 父id
A2: =MID(CELL("filename"),FIND("[",CELL("filename"),1)+1,FIND(".",CELL("filename"),1)-FIND("[",CELL("filename"),1)-1) -> T500 | B2: 关灯，增益1下的RSD值
A3: =MID(CELL("filename"),FIND("[",CELL("filename"),1)+1,FIND(".",CELL("filename"),1)-FIND("[",CELL("filename"),1)-1) -> T500 | B3: 关灯，增益2下的RSD值
A4: =MID(CELL("filename"),FIND("[",CELL("filename"),1)+1,FIND(".",CELL("filename"),1)-FIND("[",CELL("filename"),1)-1) -> T500 | B4: 关灯，增益3下的RSD值
A5: =MID(CELL("filename"),FIND("[",CELL("filename"),1)+1,FIND(".",CELL("filename"),1)-FIND("[",CELL("filename"),1)-1) -> T500 | B5: 关灯，增益4下的RSD值
A6: =MID(CELL("filename"),FIND("[",CELL("filename"),1)+1,FIND(".",CELL("filename"),1)-FIND("[",CELL("filename"),1)-1) -> T500 | B6: 开灯，增益1下的RSD值
A7: =MID(CELL("filename"),FIND("[",CELL("filename"),1)+1,FIND(".",CELL("filename"),1)-FIND("[",CELL("filename"),1)-1) -> T500 | B7: 开灯，增益2下的RSD值
A8: =MID(CELL("filename"),FIND("[",CELL("filename"),1)+1,FIND(".",CELL("filename"),1)-FIND("[",CELL("filename"),1)-1) -> T500 | B8: 开灯，增益3下的RSD值
A9: =MID(CELL("filename"),FIND("[",CELL("filename"),1)+1,FIND(".",CELL("filename"),1)-FIND("[",CELL("filename"),1)-1) -> T500 | B9: 开灯，增益4下的RSD值
A10: =MID(CELL("filename"),FIND("[",CELL("filename"),1)+1,FIND(".",CELL("filename"),1)-FIND("[",CELL("filename"),1)-1) -> T500 | B10: 氘灯656.1能量 | D10: 1001 | E10: 1001
A11: =MID(CELL("filename"),FIND("[",CELL("filename"),1)+1,FIND(".",CELL("filename"),1)-FIND("[",CELL("filename"),1)-1) -> T500 | B11: 氘灯486.0能量 | D11: 1002 | E11: 1002
A12: =MID(CELL("filename"),FIND("[",CELL("filename"),1)+1,FIND(".",CELL("filename"),1)-FIND("[",CELL("filename"),1)-1) -> T500 | B12: 紫外分光光度计标准物质GBW(E)130066-350nm能量 | D12: 2001 | E12: 2001
A13: =MID(CELL("filename"),FIND("[",CELL("filename"),1)+1,FIND(".",CELL("filename"),1)-FIND("[",CELL("filename"),1)-1) -> T500 | B13: 紫外分光光度计标准物质GBW(E)130066-313nm能量 | D13: 2002 | E13: 2001
A14: =MID(CELL("filename"),FIND("[",CELL("filename"),1)+1,FIND(".",CELL("filename"),1)-FIND("[",CELL("filename"),1)-1) -> T500 | B14: 紫外分光光度计标准物质GBW(E)130066-257nm能量 | D14: 2003 | E14: 2001
A15: =MID(CELL("filename"),FIND("[",CELL("filename"),1)+1,FIND(".",CELL("filename"),1)-FIND("[",CELL("filename"),1)-1) -> T500 | B15: 紫外分光光度计标准物质GBW(E)130066-235nm能量 | D15: 2004 | E15: 2001
A16: =MID(CELL("filename"),FIND("[",CELL("filename"),1)+1,FIND(".",CELL("filename"),1)-FIND("[",CELL("filename"),1)-1) -> T500 | B16: 碘化钠标准溶液-220nm能量 | D16: 3001 | E16: 3001
A17: =MID(CELL("filename"),FIND("[",CELL("filename"),1)+1,FIND(".",CELL("filename"),1)-FIND("[",CELL("filename"),1)-1) -> T500 | B17: 亚硝酸钠标准溶液-360nm能量 | D17: 3002 | E17: 3002
A18: =MID(CELL("filename"),FIND("[",CELL("filename"),1)+1,FIND(".",CELL("filename"),1)-FIND("[",CELL("filename"),1)-1) -> T500 | B18: 基线平直度-全波长能量 | D18: 4001 | E18: 4001

Sheet 样品池准确度与重复性校验

Sheet 字段对应
A1: 仪器方法标记 | B1: 仪器方法字段 | D1: 算法标记 | E1: 算法字段
A2: 起始波长 | B2: StartWl | C2: WlRange | D2: 寻峰 | E2: Validation.ViewModel.DataStructure.FindPeakAndAverageUVTestTool
A3: 终止波长 | B3: EndWl | D3: 求平均 | E3: Validation.ViewModel.DataStructure.WlPointsAndAverageUVTestTool
A4: 重复次数 | B4: RepeatTimes | D4: 多次测量 | E4: Validation.ViewModel.DataStructure.WlPointsUVTestTool
A5: 重复时间间隔 | B5: RepeatInterval | D5: 最大最小值差 | E5: Validation.ViewModel.DataStructure.FindMaxOffsetUVTestTool
A6: 方法信息 | B6: MethodStr | D6: 求半峰宽 | E6: Validation.ViewModel.DataStructure.FindHalfPeakUVTestTool
A7: 测量信息 | B7: MeasurePara | D7: 求最大偏移量 | E7: Validation.ViewModel.DataStructure.GetMaxDIstanceUVTestTool
A8: 使用物质 | B8: ToolStr | D8: 求漂移 | E8: Validation.ViewModel.DataStructure.GetDriftUVTestTool
A9: 项目名称 | B9: Name | D9: 最大最小值比 | E9: Validation.ViewModel.DataStructure.GetRatioOfMaxToMinUVTestTool
A10: 光度模式 | B10: PhotoMode
A11: 扫描速度 | B11: ScanSpeed
A12: 扫描间隔 | B12: ScanWlInterval
A13: 增益 | B13: Gain
A14: 光谱带宽 | B14: Slit1
A15: 特征值 | B15: Wl
A16: 暗电流 | B16: Dark
A17: 校零 | B17: Zero | C17: BaseLine
A18: 测量 | B18: Measure | C18: Scan
A19: 时间间隔 | B19: timeinterval
A20: 扫描个数 | B20: totalcount
A21: 灯状态 | B21: LampPos
A22: 响应时间 | B22: ResponseTime

Sheet 标准值
A1: 测试项 | B1: 检测工具 | C1: 特征值 | D1: 标准值（%）
A2: 透射比示值误差与重复性校验 | B2: 紫外分光光度计标准物质GBW(E)130066 | C2: 350nm | D2: 23.2
C3: 313nm | D3: 51.58
C4: 257nm | D4: 14.06
C5: 235nm | D5: 18.42
B6: 10%中性滤光片 | C6: 635nm | D6: 7.57
C7: 546nm | D7: 10.1
C8: 440nm | D8: 10.07
B9: 20%中性滤光片 | C9: 635nm | D9: 18.98
C10: 546nm | D10: 20.09
C11: 440nm | D11: 20.91
B12: 30%中性滤光片 | C12: 635nm | D12: 29.96
C13: 546nm | D13: 30.43
C14: 440nm | D14: 28.88
A15: 波长示值误差与重复性校验 | B15: 镨钕滤光片 | C15: 807.4
B16: 钬溶液 | C16: 640.7
C17: 536.8
C18: 416.5
C19: 361.0
C20: 287.4
C21: 241.0
A23: 修改标准值时，该仪器对应的模板文件必须未打开，同时修改后光标要在未修改的单元格内！方可保存成功！

Sheet 波长示值误差与重复性校验
A1: 项目名称 | B1: 特征值（nm） | C1: 测量值（nm） | F1: 平均值（nm） | G1: 误差值（nm） | H1: 重复性（nm） | I1: 波长示值误差(nm) | J1: 波长重复性 | K1: 判定结果
A2: 氘灯656.1 | B2: 656.1 | F2: =IFERROR(AVERAGE(C2:E2),"") | G2: =IFERROR(F2-B2,"") | H2: =MAX(C2:E2)-MIN(C2:E2) -> 0 | I2: 1 | J2: 0.2 | K2: =IF(C2="","未检测",IF(AND(ROUND(ABS(G2),1)<=ROUND(ABS(I2),1),ROUND(H2,1)<=ROUND(J2,1)),"合格","不合格")) -> 未检测
A3: 氘灯486 | B3: 486 | F3: =IFERROR(AVERAGE(C3:E3),"") | G3: =IFERROR(F3-B3,"") | H3: =MAX(C3:E3)-MIN(C3:E3) -> 0 | I3: 1 | J3: 0.2 | K3: =IF(C3="","未检测",IF(AND(ROUND(ABS(G3),1)<=ROUND(ABS(I3),1),ROUND(H3,1)<=ROUND(J3,1)),"合格","不合格")) -> 未检测
A4: 镨钕滤光片 | B4: =标准值!C15 -> 807.4 | F4: =IFERROR(AVERAGE(C4:E4),"") | G4: =IFERROR(F4-B4,"") | H4: =MAX(C4:E4)-MIN(C4:E4) -> 0 | I4: 1 | J4: 0.2 | K4: =IF(C4="","未检测",IF(AND(ROUND(ABS(G4),1)<=ROUND(ABS(I4),1),ROUND(H4,1)<=ROUND(J4,1)),"合格","不合格")) -> 未检测
A5: 钬溶液 | B5: =标准值!C16 -> 640.7 | F5: =IFERROR(AVERAGE(C5:E5),"") | G5: =IFERROR(F5-B5,"") | H5: =MAX(C5:E5)-MIN(C5:E5) -> 0 | I5: 1 | J5: 0.2 | K5: =IF(C5="","未检测",IF(AND(ROUND(ABS(G5),1)<=ROUND(ABS(I5),1),ROUND(H5,1)<=ROUND(J5,1)),"合格","不合格")) -> 未检测
B6: =标准值!C17 -> 536.8 | F6: =IFERROR(AVERAGE(C6:E6),"") | G6: =IFERROR(F6-B6,"") | H6: =MAX(C6:E6)-MIN(C6:E6) -> 0 | I6: 1 | J6: 0.2 | K6: =IF(C6="","未检测",IF(AND(ROUND(ABS(G6),1)<=ROUND(ABS(I6),1),ROUND(H6,1)<=ROUND(J6,1)),"合格","不合格")) -> 未检测
B7: =标准值!C18 -> 416.5 | F7: =IFERROR(AVERAGE(C7:E7),"") | G7: =IFERROR(F7-B7,"") | H7: =MAX(C7:E7)-MIN(C7:E7) -> 0 | I7: 1 | J7: 0.2 | K7: =IF(C7="","未检测",IF(AND(ROUND(ABS(G7),1)<=ROUND(ABS(I7),1),ROUND(H7,1)<=ROUND(J7,1)),"合格","不合格")) -> 未检测
B8: =标准值!C19 -> 361.0 | F8: =IFERROR(AVERAGE(C8:E8),"") | G8: =IFERROR(F8-B8,"") | H8: =MAX(C8:E8)-MIN(C8:E8) -> 0 | I8: 1 | J8: 0.2 | K8: =IF(C8="","未检测",IF(AND(ROUND(ABS(G8),1)<=ROUND(ABS(I8),1),ROUND(H8,1)<=ROUND(J8,1)),"合格","不合格")) -> 未检测
B9: =标准值!C20 -> 287.4 | F9: =IFERROR(AVERAGE(C9:E9),"") | G9: =IFERROR(F9-B9,"") | H9: =MAX(C9:E9)-MIN(C9:E9) -> 0 | I9: 1 | J9: 0.2 | K9: =IF(C9="","未检测",IF(AND(ROUND(ABS(G9),1)<=ROUND(ABS(I9),1),ROUND(H9,1)<=ROUND(J9,1)),"合格","不合格")) -> 未检测
B10: =标准值!C21 -> 241.0 | F10: =IFERROR(AVERAGE(C10:E10),"") | G10: =IFERROR(F10-B10,"") | H10: =MAX(C10:E10)-MIN(C10:E10) -> 0 | I10: 1 | J10: 0.2 | K10: =IF(C10="","未检测",IF(AND(ROUND(ABS(G10),1)<=ROUND(ABS(I10),1),ROUND(H10,1)<=ROUND(J10,1)),"合格","不合格")) -> 未检测

Sheet 透射比示值误差与重复性校验
A1: 项目名称 | B1: 特征值(nm) | C1: 标准值（%） | D1: 测量值（%） | G1: 平均值（%） | H1: 误差值（%） | I1: 重复性（%） | J1: 透射比示值误差 | K1: 透射比重复性 | L1: 判定结果
A2: 紫外分光光度计标准物质GBW(E)130066 | B2: 350 | C2: =标准值!D2 -> 23.2 | G2: =IFERROR(AVERAGE(D2:F2),"") | H2: =IFERROR(G2-C2,"") | I2: =MAX(ROUND(D2,2),ROUND(E2,2),ROUND(F2,2))-MIN(ROUND(D2,2),ROUND(E2,2),ROUND(F2,2)) -> 0 | J2: 0.3 | K2: 0.15 | L2: =IF(D2="","未检测",IF(E2="","不合格",IF(F2="","不合格",IF(AND(ROUND(ABS(H2),2)<=ROUND(ABS(J2),2),ROUND(I2,2)<=ROUND(K2,2)),"合格","不合格")))) -> 未检测
B3: 313 | C3: =标准值!D3 -> 51.58 | G3: =IFERROR(AVERAGE(D3:F3),"") | H3: =IFERROR(G3-C3,"") | I3: =MAX(ROUND(D3,2),ROUND(E3,2),ROUND(F3,2))-MIN(ROUND(D3,2),ROUND(E3,2),ROUND(F3,2)) -> 0 | J3: 0.3 | K3: 0.15 | L3: =IF(D3="","未检测",IF(E3="","不合格",IF(F3="","不合格",IF(AND(ROUND(ABS(H3),2)<=ROUND(ABS(J3),2),ROUND(I3,2)<=ROUND(K3,2)),"合格","不合格")))) -> 未检测
B4: 257 | C4: =标准值!D4 -> 14.06 | G4: =IFERROR(AVERAGE(D4:F4),"") | H4: =IFERROR(G4-C4,"") | I4: =MAX(ROUND(D4,2),ROUND(E4,2),ROUND(F4,2))-MIN(ROUND(D4,2),ROUND(E4,2),ROUND(F4,2)) -> 0 | J4: 0.3 | K4: 0.15 | L4: =IF(D4="","未检测",IF(E4="","不合格",IF(F4="","不合格",IF(AND(ROUND(ABS(H4),2)<=ROUND(ABS(J4),2),ROUND(I4,2)<=ROUND(K4,2)),"合格","不合格")))) -> 未检测
