Workbook
Name OLE_LINK10: Report!#REF!

Sheet Report
C1: 北京普析通用仪器有限责任公司 | L1: 文件编号
C2: T600T700系列紫外可见分光光度计整机检验原始记录表 | L2: 版本/修订
L3: 发布/修订日期
A4: 产品型号 | D4: 产品编号 | H4: 检验员 | L4: 检验日期 | N4: 复核员
A5: =IFERROR(VLOOKUP(MID(D5,3,5),对应信息!A:B,2,0),"") | D5: T600T700-FixedSlit | H5: dd
A6: 温度(℃) | E6: 相对湿度(%) | L6: 检验结果
A7: UVWin版本号 | E7: UVTouch版本号 | K7: 检验软件版本号 | M7: 2.2.24.1119
A8: 序号 | B8: 检验项目 | E8: 结果
A9: 1 | B9: 波长示值误差与重复性 | C9: 波长示值误差 氘灯： ±0.1nm 镨钕： ±0.3nm 波长重复性 ≤0.1nm | E9: 波长段 | H9: B段
E10: 检测工具 | H10: 镨钕滤光片 | K10: 氘灯 | M10: 氘灯
E11: 标准值(nm) | H11: =波长示值误差与重复性校验!B4 -> 807.4 | K11: =波长示值误差与重复性校验!B2 -> 656.1 | M11: =波长示值误差与重复性校验!B3 -> 486
E12: 测量值（nm） | H12: =波长示值误差与重复性校验!C4 -> 0 | K12: =波长示值误差与重复性校验!C2 -> 0 | M12: =波长示值误差与重复性校验!C3 -> 0
H13: =波长示值误差与重复性校验!D4 -> 0 | K13: =波长示值误差与重复性校验!D2 -> 0 | M13: =波长示值误差与重复性校验!D3 -> 0
H14: =波长示值误差与重复性校验!E4 -> 0 | K14: =波长示值误差与重复性校验!E2 -> 0 | M14: =波长示值误差与重复性校验!E3 -> 0
E15: 平均值(nm) | H15: =波长示值误差与重复性校验!F4 | K15: =波长示值误差与重复性校验!F2 | M15: =波长示值误差与重复性校验!F3
E16: 误差值(nm) | H16: =波长示值误差与重复性校验!G4 | K16: =波长示值误差与重复性校验!G2 | M16: =波长示值误差与重复性校验!G3
E17: 重复性(nm) | H17: =波长示值误差与重复性校验!H4 -> 0 | K17: =波长示值误差与重复性校验!H2 -> 0 | M17: =波长示值误差与重复性校验!H3 -> 0
B18: 波长示值误差与重复性 | C18: 波长示值误差 钬溶液： ±0.3nm 波长重复性 ≤0.1nm | E18: 检测工具 | H18: 钬溶液
E19: 标准值(nm) | H19: =波长示值误差与重复性校验!B5 -> 640.7 | J19: =波长示值误差与重复性校验!B6 -> 536.8 | K19: =波长示值误差与重复性校验!B7 -> 416.5 | L19: =波长示值误差与重复性校验!B8 -> 361.0 | M19: =波长示值误差与重复性校验!B9 -> 287.4 | N19: =波长示值误差与重复性校验!B10 -> 241.0
E21: 测量值（nm） | H21: =波长示值误差与重复性校验!C5 -> 0 | J21: =波长示值误差与重复性校验!C6 -> 0 | K21: =波长示值误差与重复性校验!C7 -> 0 | L21: =波长示值误差与重复性校验!C8 -> 0 | M21: =波长示值误差与重复性校验!C9 -> 0 | N21: =波长示值误差与重复性校验!C10 -> 0
H23: =波长示值误差与重复性校验!D5 -> 0 | J23: =波长示值误差与重复性校验!D6 -> 0 | K23: =波长示值误差与重复性校验!D7 -> 0 | L23: =波长示值误差与重复性校验!D8 -> 0 | M23: =波长示值误差与重复性校验!D9 -> 0 | N23: =波长示值误差与重复性校验!D10 -> 0
H25: =波长示值误差与重复性校验!E5 -> 0 | J25: =波长示值误差与重复性校验!E6 -> 0 | K25: =波长示值误差与重复性校验!E7 -> 0 | L25: =波长示值误差与重复性校验!E8 -> 0 | M25: =波长示值误差与重复性校验!E9 -> 0 | N25: =波长示值误差与重复性校验!E10 -> 0
E27: 平均值(nm) | H27: =波长示值误差与重复性校验!F5 | J27: =波长示值误差与重复性校验!F6 | K27: =波长示值误差与重复性校验!F7 | L27: =波长示值误差与重复性校验!F8 | M27: =波长示值误差与重复性校验!F9 | N27: =波长示值误差与重复性校验!F10
E29: 误差值(nm) | H29: =波长示值误差与重复性校验!G5 | J29: =波长示值误差与重复性校验!G6 | K29: =波长示值误差与重复性校验!G7 | L29: =波长示值误差与重复性校验!G8 | M29: =波长示值误差与重复性校验!G9 | N29: =波长示值误差与重复性校验!G10
E31: 重复性(nm) | H31: =波长示值误差与重复性校验!H5 -> 0 | J31: =波长示值误差与重复性校验!H6 -> 0 | K31: =波长示值误差与重复性校验!H7 -> 0 | L31: =波长示值误差与重复性校验!H8 -> 0 | M31: =波长示值误差与重复性校验!H9 -> 0 | N31: =波长示值误差与重复性校验!H10 -> 0
A33: 2 | B33: 透射比示值误差与重复性 (可见区） | C33: 透射比示值误差 ±0.3% 透射比重复性 ≤0.1% | E33: 检测工具 | H33: 10%中性滤光片、20%中性滤光片、30%中性滤光片 （以标定的标准值为准）
E35: 型号 | G35: 测量点 | I35: =透射比示值误差与重复性校验!B6 -> 635 | L35: =透射比示值误差与重复性校验!B7 -> 546 | N35: =透射比示值误差与重复性校验!B8 -> 440
E36: 10%中性滤光片 | G36: 标准值(%) | I36: =透射比示值误差与重复性校验!C6 -> 7.62 | L36: =透射比示值误差与重复性校验!C7 -> 11.03 | N36: =透射比示值误差与重复性校验!C8 -> 11.46
G37: 测量值(%) | I37: =透射比示值误差与重复性校验!D6 -> 0 | L37: =透射比示值误差与重复性校验!D7 -> 0 | N37: =透射比示值误差与重复性校验!D8 -> 0
I38: =透射比示值误差与重复性校验!E6 -> 0 | L38: =透射比示值误差与重复性校验!E7 -> 0 | N38: =透射比示值误差与重复性校验!E8 -> 0
I39: =透射比示值误差与重复性校验!F6 -> 0 | L39: =透射比示值误差与重复性校验!F7 -> 0 | N39: =透射比示值误差与重复性校验!F8 -> 0
G40: 平均值(%) | I40: =透射比示值误差与重复性校验!G6 | L40: =透射比示值误差与重复性校验!G7 | N40: =透射比示值误差与重复性校验!G8
G41: 误差值(%) | I41: =透射比示值误差与重复性校验!H6 | L41: =透射比示值误差与重复性校验!H7 | N41: =透射比示值误差与重复性校验!H8
G42: 重复性(%) | I42: =透射比示值误差与重复性校验!I6 -> 0 | L42: =透射比示值误差与重复性校验!I7 -> 0 | N42: =透射比示值误差与重复性校验!I8 -> 0
E43: 20%中性滤光片 | G43: 标准值(%) | I43: =透射比示值误差与重复性校验!C9 -> 17.64 | L43: =透射比示值误差与重复性校验!C10 -> 21.74 | N43: =透射比示值误差与重复性校验!C11 -> 21.92
G44: 测量值(%) | I44: =透射比示值误差与重复性校验!D9 -> 0 | L44: =透射比示值误差与重复性校验!D10 -> 0 | N44: =透射比示值误差与重复性校验!D11 -> 0
I45: =透射比示值误差与重复性校验!E9 -> 0 | L45: =透射比示值误差与重复性校验!E10 -> 0 | N45: =透射比示值误差与重复性校验!E11 -> 0
I46: =透射比示值误差与重复性校验!F9 -> 0 | L46: =透射比示值误差与重复性校验!F10 -> 0 | N46: =透射比示值误差与重复性校验!F11 -> 0
G47: 平均值(%) | I47: =透射比示值误差与重复性校验!G9 | L47: =透射比示值误差与重复性校验!G10 | N47: =透射比示值误差与重复性校验!G11
G48: 误差值(%) | I48: =透射比示值误差与重复性校验!H9 | L48: =透射比示值误差与重复性校验!H10 | N48: =透射比示值误差与重复性校验!H11
...

Sheet 基础信息
A1: 名称 | B1: 特征值 | C1: 标准值 | E1: 是否为光谱扫描 | F1: 灯状态 | G1: 灯状态 | H1: 较零物质 | I1: 光度方式 | J1: 光度方式 | K1: 扫描速度 | L1: 扫描速度 | M1: 扫描间隔(nm) | N1: 重复次数 | O1: 重复时间间隔(S) | P1: 光谱带宽(nm) | Q1: 增益 | R1: 响应时间
A2: 氘灯 | B2: 656.1 | C2: 656.1 | E2: 是 | F2: 钨灯 | G2: 0 | I2: Abs | J2: 0 | K2: 极慢 | L2: 0 | N2: 1 | P2: 0.2
A3: 低压汞灯A段 | B3: 253.7 | C3: 253.7 | E3: 否 | F3: 氘灯 | G3: 1 | H3: 其它 | I3: T% | J3: 1 | K3: 慢速 | L3: 1 | M3: 0.02 | N3: 2 | O3: 1 | P3: 0.5 | Q3: 1 | R3: 0.5
A4: 低压汞灯B段 | B4: 365.0,435.8,546.1 | C4: 365.0,435.8,546.1 | F4: 汞灯 | G4: 2 | I4: Es | J4: 2 | K4: 中速 | L4: 2 | M4: 0.1 | N4: 3 | O4: 2 | P4: 1.0 | Q4: 2 | R4: 1
A5: 镨钕滤光片 | B5: 739.2,,807.4 | C5: 739.2,,807.4 | I5: Er | J5: 3 | K5: 快速 | L5: 3 | M5: 0.2 | N5: 4 | P5: 2.0 | Q5: 3 | R5: 2
A6: 10%中性滤光片 | B6: 635.0,546.0,440.0 | I6: R% | J6: 4 | K6: 极快 | L6: 4 | M6: 0.5 | N6: 5 | P6: 5.0 | Q6: 4
A7: 20%中性滤光片 | B7: 635.0,546.0,440.1 | M7: 1 | Q7: 5
A8: 30%中性滤光片 | B8: 635.0,546.0,440.2 | M8: 2
A9: 重铬酸钾标准物质 | B9: 350313257235 | C9: 22.9,51.3,13.7,18.2 | M9: 5
A10: 碘化钠溶液 | B10: 220
A11: 亚硝酸钠溶液 | B11: 340360

Sheet 测量结果表
A1: 项目编号 | B1: 仪器ID | C1: 标准值 | D1: 测量值（nm） | E1: 平均值 | F1: 误差值 | G1: 重复性 | H1: 检验员 | I1: 检验日期 | J1: 复核员 | K1: 检验地点 | L1: 温度 | M1: 湿度 | N1: 判定结果 | O1: 其他 | P1: 子项目编号-与检测项信息对应的
A2: 1001 | B2: =MID(_xlfn.SINGLE(CELL("filename")),FIND("[",_xlfn.SINGLE(CELL("filename")),1)+1,FIND(".",_xlfn.SINGLE(CELL("filename")),1)-FIND("[",_xlfn.SINGLE(CELL("filename")),1)-1) -> T600T700-FixedSlit | D2: =波长示值误差与重复性校验!$C2&";"&波长示值误差与重复性校验!$D2&";"&波长示值误差与重复性校验!$E2 -> ;; | E2: =波长示值误差与重复性校验!$F2 | F2: =波长示值误差与重复性校验!$G2 | G2: =波长示值误差与重复性校验!$H2 -> 0 | H2: =Report!$F$5 -> 0 | I2: =NOW() -> 45881.669 | J2: =Report!$N$5 -> 0 | L2: =Report!$C$6 -> 0 | M2: =Report!$H$6 -> 0 | N2: =波长示值误差与重复性校验!$K2 -> 未检测 | P2: 1001
A3: 1002 | B3: =MID(_xlfn.SINGLE(CELL("filename")),FIND("[",_xlfn.SINGLE(CELL("filename")),1)+1,FIND(".",_xlfn.SINGLE(CELL("filename")),1)-FIND("[",_xlfn.SINGLE(CELL("filename")),1)-1) -> T600T700-FixedSlit | D3: =波长示值误差与重复性校验!$C3&";"&波长示值误差与重复性校验!$D3&";"&波长示值误差与重复性校验!$E3 -> ;; | E3: =波长示值误差与重复性校验!$F3 | F3: =波长示值误差与重复性校验!$G3 | G3: =波长示值误差与重复性校验!$H3 -> 0 | H3: =Report!$F$5 -> 0 | I3: =NOW() -> 45881.669 | J3: =Report!$N$5 -> 0 | L3: =Report!$C$6 -> 0 | M3: =Report!$H$6 -> 0 | N3: =波长示值误差与重复性校验!$K3 -> 未检测 | P3: 1002
A4: 1003 | B4: =MID(_xlfn.SINGLE(CELL("filename")),FIND("[",_xlfn.SINGLE(CELL("filename")),1)+1,FIND(".",_xlfn.SINGLE(CELL("filename")),1)-FIND("[",_xlfn.SINGLE(CELL("filename")),1)-1) -> T600T700-FixedSlit | D4: =波长示值误差与重复性校验!$C4&";"&波长示值误差与重复性校验!$D4&";"&波长示值误差与重复性校验!$E4 -> ;; | E4: =波长示值误差与重复性校验!$F4 | F4: =波长示值误差与重复性校验!$G4 | G4: =波长示值误差与重复性校验!$H4 -> 0 | H4: =Report!$F$5 -> 0 | I4: =NOW() -> 45881.669 | J4: =Report!$N$5 -> 0 | L4: =Report!$C$6 -> 0 | M4: =Report!$H$6 -> 0 | N4: =波长示值误差与重复性校验!$K4 -> 未检测 | P4: 1003
A5: 1008 | B5: =MID(_xlfn.SINGLE(CELL("filename")),FIND("[",_xlfn.SINGLE(CELL("filename")),1)+1,FIND(".",_xlfn.SINGLE(CELL("filename")),1)-FIND("[",_xlfn.SINGLE(CELL("filename")),1)-1) -> T600T700-FixedSlit | D5: =波长示值误差与重复性校验!$C5&";"&波长示值误差与重复性校验!$D5&";"&波长示值误差与重复性校验!$E5 -> ;; | E5: =波长示值误差与重复性校验!$F5 | F5: =波长示值误差与重复性校验!$G5 | G5: =波长示值误差与重复性校验!$H5 -> 0 | H5: =Report!$F$5 -> 0 | I5: =NOW() -> 45881.669 | J5: =Report!$N$5 -> 0 | L5: =Report!$C$6 -> 0 | M5: =Report!$H$6 -> 0 | N5: =波长示值误差与重复性校验!$K5 -> 未检测 | P5: 1004
A6: 1009 | B6: =MID(_xlfn.SINGLE(CELL("filename")),FIND("[",_xlfn.SINGLE(CELL("filename")),1)+1,FIND(".",_xlfn.SINGLE(CELL("filename")),1)-FIND("[",_xlfn.SINGLE(CELL("filename")),1)-1) -> T600T700-FixedSlit | D6: =波长示值误差与重复性校验!$C6&";"&波长示值误差与重复性校验!$D6&";"&波长示值误差与重复性校验!$E6 -> ;; | E6: =波长示值误差与重复性校验!$F6 | F6: =波长示值误差与重复性校验!$G6 | G6: =波长示值误差与重复性校验!$H6 -> 0 | H6: =Report!$F$5 -> 0 | I6: =NOW() -> 45881.669 | J6: =Report!$N$5 -> 0 | L6: =Report!$C$6 -> 0 | M6: =Report!$H$6 -> 0 | N6: =波长示值误差与重复性校验!$K6 -> 未检测 | P6: 1004
A7: 1010 | B7: =MID(_xlfn.SINGLE(CELL("filename")),FIND("[",_xlfn.SINGLE(CELL("filename")),1)+1,FIND(".",_xlfn.SINGLE(CELL("filename")),1)-FIND("[",_xlfn.SINGLE(CELL("filename")),1)-1) -> T600T700-FixedSlit | D7: =波长示值误差与重复性校验!$C7&";"&波长示值误差与重复性校验!$D7&";"&波长示值误差与重复性校验!$E7 -> ;; | E7: =波长示值误差与重复性校验!$F7 | F7: =波长示值误差与重复性校验!$G7 | G7: =波长示值误差与重复性校验!$H7 -> 0 | H7: =Report!$F$5 -> 0 | I7: =NOW() -> 45881.669 | J7: =Report!$N$5 -> 0 | L7: =Report!$C$6 -> 0 | M7: =Report!$H$6 -> 0 | N7: =波长示值误差与重复性校验!$K7 -> 未检测 | P7: 1004
A8: 1011 | B8: =MID(_xlfn.SINGLE(CELL("filename")),FIND("[",_xlfn.SINGLE(CELL("filename")),1)+1,FIND(".",_xlfn.SINGLE(CELL("filename")),1)-FIND("[",_xlfn.SINGLE(CELL("filename")),1)-1) -> T600T700-FixedSlit | D8: =波长示值误差与重复性校验!$C8&";"&波长示值误差与重复性校验!$D8&";"&波长示值误差与重复性校验!$E8 -> ;; | E8: =波长示值误差与重复性校验!$F8 | F8: =波长示值误差与重复性校验!$G8 | G8: =波长示值误差与重复性校验!$H8 -> 0 | H8: =Report!$F$5 -> 0 | I8: =NOW() -> 45881.669 | J8: =Report!$N$5 -> 0 | L8: =Report!$C$6 -> 0 | M8: =Report!$H$6 -> 0 | N8: =波长示值误差与重复性校验!$K8 -> 未检测 | P8: 1004
A9: 1012 | B9: =MID(_xlfn.SINGLE(CELL("filename")),FIND("[",_xlfn.SINGLE(CELL("filename")),1)+1,FIND(".",_xlfn.SINGLE(CELL("filename")),1)-FIND("[",_xlfn.SINGLE(CELL("filename")),1)-1) -> T600T700-FixedSlit | D9: =波长示值误差与重复性校验!$C9&";"&波长示值误差与重复性校验!$D9&";"&波长示值误差与重复性校验!$E9 -> ;; | E9: =波长示值误差与重复性校验!$F9 | F9: =波长示值误差与重复性校验!$G9 | G9: =波长示值误差与重复性校验!$H9 -> 0 | H9: =Report!$F$5 -> 0 | I9: =NOW() -> 45881.669 | J9: =Report!$N$5 -> 0 | L9: =Report!$C$6 -> 0 | M9: =Report!$H$6 -> 0 | N9: =波长示值误差与重复性校验!$K9 -> 未检测 | P9: 1004
A10: 1013 | B10: =MID(_xlfn.SINGLE(CELL("filename")),FIND("[",_xlfn.SINGLE(CELL("filename")),1)+1,FIND(".",_xlfn.SINGLE(CELL("filename")),1)-FIND("[",_xlfn.SINGLE(CELL("filename")),1)-1) -> T600T700-FixedSlit | D10: =波长示值误差与重复性校验!$C10&";"&波长示值误差与重复性校验!$D10&";"&波长示值误差与重复性校验!$E10 -> ;; | E10: =波长示值误差与重复性校验!$F10 | F10: =波长示值误差与重复性校验!$G10 | G10: =波长示值误差与重复性校验!$H10 -> 0 | H10: =Report!$F$5 -> 0 | I10: =NOW() -> 45881.669 | J10: =Report!$N$5 -> 0 | L10: =Report!$C$6 -> 0 | M10: =Report!$H$6 -> 0 | N10: =波长示值误差与重复性校验!$K10 -> 未检测 | P10: 1004
A11: 2001 | B11: =MID(_xlfn.SINGLE(CELL("filename")),FIND("[",_xlfn.SINGLE(CELL("filename")),1)+1,FIND(".",_xlfn.SINGLE(CELL("filename")),1)-FIND("[",_xlfn.SINGLE(CELL("filename")),1)-1) -> T600T700-FixedSlit | C11: =透射比示值误差与重复性校验!$C2 -> 23.2 | D11: =透射比示值误差与重复性校验!$D2&";"&透射比示值误差与重复性校验!$E2&";"&透射比示值误差与重复性校验!$F2 -> ;; | E11: =透射比示值误差与重复性校验!$G2 | F11: =透射比示值误差与重复性校验!$H2 | G11: =透射比示值误差与重复性校验!$I2 -> 0 | H11: =Report!$F$5 -> 0 | I11: =NOW() -> 45881.669 | J11: =Report!$N$5 -> 0 | L11: =Report!$C$6 -> 0 | M11: =Report!$H$6 -> 0 | N11: =透射比示值误差与重复性校验!$L2 -> 未检测 | P11: 2001
A12: 2002 | B12: =MID(_xlfn.SINGLE(CELL("filename")),FIND("[",_xlfn.SINGLE(CELL("filename")),1)+1,FIND(".",_xlfn.SINGLE(CELL("filename")),1)-FIND("[",_xlfn.SINGLE(CELL("filename")),1)-1) -> T600T700-FixedSlit | C12: =透射比示值误差与重复性校验!$C3 -> 51.58 | D12: =透射比示值误差与重复性校验!$D3&";"&透射比示值误差与重复性校验!$E3&";"&透射比示值误差与重复性校验!$F3 -> ;; | E12: =透射比示值误差与重复性校验!$G3 | F12: =透射比示值误差与重复性校验!$H3 | G12: =透射比示值误差与重复性校验!$I3 -> 0 | H12: =Report!$F$5 -> 0 | I12: =NOW() -> 45881.669 | J12: =Report!$N$5 -> 0 | L12: =Report!$C$6 -> 0 | M12: =Report!$H$6 -> 0 | N12: =透射比示值误差与重复性校验!$L3 -> 未检测 | P12: 2001
A13: 2003 | B13: =MID(_xlfn.SINGLE(CELL("filename")),FIND("[",_xlfn.SINGLE(CELL("filename")),1)+1,FIND(".",_xlfn.SINGLE(CELL("filename")),1)-FIND("[",_xlfn.SINGLE(CELL("filename")),1)-1) -> T600T700-FixedSlit | C13: =透射比示值误差与重复性校验!$C4 -> 14.06 | D13: =透射比示值误差与重复性校验!$D4&";"&透射比示值误差与重复性校验!$E4&";"&透射比示值误差与重复性校验!$F4 -> ;; | E13: =透射比示值误差与重复性校验!$G4 | F13: =透射比示值误差与重复性校验!$H4 | G13: =透射比示值误差与重复性校验!$I4 -> 0 | H13: =Report!$F$5 -> 0 | I13: =NOW() -> 45881.669 | J13: =Report!$N$5 -> 0 | L13: =Report!$C$6 -> 0 | M13: =Report!$H$6 -> 0 | N13: =透射比示值误差与重复性校验!$L4 -> 未检测 | P13: 2001
A14: 2004 | B14: =MID(_xlfn.SINGLE(CELL("filename")),FIND("[",_xlfn.SINGLE(CELL("filename")),1)+1,FIND(".",_xlfn.SINGLE(CELL("filename")),1)-FIND("[",_xlfn.SINGLE(CELL("filename")),1)-1) -> T600T700-FixedSlit | C14: =透射比示值误差与重复性校验!$C5 -> 18.42 | D14: =透射比示值误差与重复性校验!$D5&";"&透射比示值误差与重复性校验!$E5&";"&透射比示值误差与重复性校验!$F5 -> ;; | E14: =透射比示值误差与重复性校验!$G5 | F14: =透射比示值误差与重复性校验!$H5 | G14: =透射比示值误差与重复性校验!$I5 -> 0 | H14: =Report!$F$5 -> 0 | I14: =NOW() -> 45881.669 | J14: =Report!$N$5 -> 0 | L14: =Report!$C$6 -> 0 | M14: =Report!$H$6 -> 0 | N14: =透射比示值误差与重复性校验!$L5 -> 未检测 | P14: 2001
A15: 2005 | B15: =MID(_xlfn.SINGLE(CELL("filename")),FIND("[",_xlfn.SINGLE(CELL("filename")),1)+1,FIND(".",_xlfn.SINGLE(CELL("filename")),1)-FIND("[",_xlfn.SINGLE(CELL("filename")),1)-1) -> T600T700-FixedSlit | C15: =透射比示值误差与重复性校验!$C6 -> 7.62 | D15: =透射比示值误差与重复性校验!$D6&";"&透射比示值误差与重复性校验!$E6&";"&透射比示值误差与重复性校验!$F6 -> ;; | E15: =透射比示值误差与重复性校验!$G6 | F15: =透射比示值误差与重复性校验!$H6 | G15: =透射比示值误差与重复性校验!$I6 -> 0 | H15: =Report!$F$5 -> 0 | I15: =NOW() -> 45881.669 | J15: =Report!$N$5 -> 0 | L15: =Report!$C$6 -> 0 | M15: =Report!$H$6 -> 0 | N15: =透射比示值误差与重复性校验!$L6 -> 未检测 | P15: 2002
A16: 2006 | B16: =MID(_xlfn.SINGLE(CELL("filename")),FIND("[",_xlfn.SINGLE(CELL("filename")),1)+1,FIND(".",_xlfn.SINGLE(CELL("filename")),1)-FIND("[",_xlfn.SINGLE(CELL("filename")),1)-1) -> T600T700-FixedSlit | C16: =透射比示值误差与重复性校验!$C7 -> 11.03 | D16: =透射比示值误差与重复性校验!$D7&";"&透射比示值误差与重复性校验!$E7&";"&透射比示值误差与重复性校验!$F7 -> ;; | E16: =透射比示值误差与重复性校验!$G7 | F16: =透射比示值误差与重复性校验!$H7 | G16: =透射比示值误差与重复性校验!$I7 -> 0 | H16: =Report!$F$5 -> 0 | I16: =NOW() -> 45881.669 | J16: =Report!$N$5 -> 0 | L16: =Report!$C$6 -> 0 | M16: =Report!$H$6 -> 0 | N16: =透射比示值误差与重复性校验!$L7 -> 未检测 | P16: 2002
A17: 2007 | B17: =MID(_xlfn.SINGLE(CELL("filename")),FIND("[",_xlfn.SINGLE(CELL("filename")),1)+1,FIND(".",_xlfn.SINGLE(CELL("filename")),1)-FIND("[",_xlfn.SINGLE(CELL("filename")),1)-1) -> T600T700-FixedSlit | C17: =透射比示值误差与重复性校验!$C8 -> 11.46 | D17: =透射比示值误差与重复性校验!$D8&";"&透射比示值误差与重复性校验!$E8&";"&透射比示值误差与重复性校验!$F8 -> ;; | E17: =透射比示值误差与重复性校验!$G8 | F17: =透射比示值误差与重复性校验!$H8 | G17: =透射比示值误差与重复性校验!$I8 -> 0 | H17: =Report!$F$5 -> 0 | I17: =NOW() -> 45881.669 | J17: =Report!$N$5 -> 0 | L17: =Report!$C$6 -> 0 | M17: =Report!$H$6 -> 0 | N17: =透射比示值误差与重复性校验!$L8 -> 未检测 | P17: 2002
A18: 2008 | B18: =MID(_xlfn.SINGLE(CELL("filename")),FIND("[",_xlfn.SINGLE(CELL("filename")),1)+1,FIND(".",_xlfn.SINGLE(CELL("filename")),1)-FIND("[",_xlfn.SINGLE(CELL("filename")),1)-1) -> T600T700-FixedSlit | C18: =透射比示值误差与重复性校验!$C9 -> 17.64 | D18: =透射比示值误差与重复性校验!$D9&";"&透射比示值误差与重复性校验!$E9&";"&透射比示值误差与重复性校验!$F9 -> ;; | E18: =透射比示值误差与重复性校验!$G9 | F18: =透射比示值误差与重复性校验!$H9 | G18: =透射比示值误差与重复性校验!$I9 -> 0 | H18: =Report!$F$5 -> 0 | I18: =NOW() -> 45881.669 | J18: =Report!$N$5 -> 0 | L18: =Report!$C$6 -> 0 | M18: =Report!$H$6 -> 0 | N18: =透射比示值误差与重复性校验!$L9 -> 未检测 | P18: 2003
A19: 2009 | B19: =MID(_xlfn.SINGLE(CELL("filename")),FIND("[",_xlfn.SINGLE(CELL("filename")),1)+1,FIND(".",_xlfn.SINGLE(CELL("filename")),1)-FIND("[",_xlfn.SINGLE(CELL("filename")),1)-1) -> T600T700-FixedSlit | C19: =透射比示值误差与重复性校验!$C10 -> 21.74 | D19: =透射比示值误差与重复性校验!$D10&";"&透射比示值误差与重复性校验!$E10&";"&透射比示值误差与重复性校验!$F10 -> ;; | E19: =透射比示值误差与重复性校验!$G10 | F19: =透射比示值误差与重复性校验!$H10 | G19: =透射比示值误差与重复性校验!$I10 -> 0 | H19: =Report!$F$5 -> 0 | I19: =NOW() -> 45881.669 | J19: =Report!$N$5 -> 0 | L19: =Report!$C$6 -> 0 | M19: =Report!$H$6 -> 0 | N19: =透射比示值误差与重复性校验!$L10 -> 未检测 | P19: 2003
A20: 2010 | B20: =MID(_xlfn.SINGLE(CELL("filename")),FIND("[",_xlfn.SINGLE(CELL("filename")),1)+1,FIND(".",_xlfn.SINGLE(CELL("filename")),1)-FIND("[",_xlfn.SINGLE(CELL("filename")),1)-1) -> T600T700-FixedSlit | C20: =透射比示值误差与重复性校验!$C11 -> 21.92 | D20: =透射比示值误差与重复性校验!$D11&";"&透射比示值误差与重复性校验!$E11&";"&透射比示值误差与重复性校验!$F11 -> ;; | E20: =透射比示值误差与重复性校验!$G11 | F20: =透射比示值误差与重复性校验!$H11 | G20: =透射比示值误差与重复性校验!$I11 -> 0 | H20: =Report!$F$5 -> 0 | I20: =NOW() -> 45881.669 | J20: =Report!$N$5 -> 0 | L20: =Report!$C$6 -> 0 | M20: =Report!$H$6 -> 0 | N20: =透射比示值误差与重复性校验!$L11 -> 未检测 | P20: 2003
A21: 2011 | B21: =MID(_xlfn.SINGLE(CELL("filename")),FIND("[",_xlfn.SINGLE(CELL("filename")),1)+1,FIND(".",_xlfn.SINGLE(CELL("filename")),1)-FIND("[",_xlfn.SINGLE(CELL("filename")),1)-1) -> T600T700-FixedSlit | C21: =透射比示值误差与重复性校验!$C12 -> 23.59 | D21: =透射比示值误差与重复性校验!$D12&";"&透射比示值误差与重复性校验!$E12&";"&透射比示值误差与重复性校验!$F12 -> ;; | E21: =透射比示值误差与重复性校验!$G12 | F21: =透射比示值误差与重复性校验!$H12 | G21: =透射比示值误差与重复性校验!$I12 -> 0 | H21: =Report!$F$5 -> 0 | I21: =NOW() -> 45881.669 | J21: =Report!$N$5 -> 0 | L21: =Report!$C$6 -> 0 | M21: =Report!$H$6 -> 0 | N21: =透射比示值误差与重复性校验!$L12 -> 未检测 | P21: 2004
A22: 2012 | B22: =MID(_xlfn.SINGLE(CELL("filename")),FIND("[",_xlfn.SINGLE(CELL("filename")),1)+1,FIND(".",_xlfn.SINGLE(CELL("filename")),1)-FIND("[",_xlfn.SINGLE(CELL("filename")),1)-1) -> T600T700-FixedSlit | C22: =透射比示值误差与重复性校验!$C13 -> 29.32 | D22: =透射比示值误差与重复性校验!$D13&";"&透射比示值误差与重复性校验!$E13&";"&透射比示值误差与重复性校验!$F13 -> ;; | E22: =透射比示值误差与重复性校验!$G13 | F22: =透射比示值误差与重复性校验!$H13 | G22: =透射比示值误差与重复性校验!$I13 -> 0 | H22: =Report!$F$5 -> 0 | I22: =NOW() -> 45881.669 | J22: =Report!$N$5 -> 0 | L22: =Report!$C$6 -> 0 | M22: =Report!$H$6 -> 0 | N22: =透射比示值误差与重复性校验!$L13 -> 未检测 | P22: 2004
A23: 2013 | B23: =MID(_xlfn.SINGLE(CELL("filename")),FIND("[",_xlfn.SINGLE(CELL("filename")),1)+1,FIND(".",_xlfn.SINGLE(CELL("filename")),1)-FIND("[",_xlfn.SINGLE(CELL("filename")),1)-1) -> T600T700-FixedSlit | C23: =透射比示值误差与重复性校验!$C14 -> 29.91 | D23: =透射比示值误差与重复性校验!$D14&";"&透射比示值误差与重复性校验!$E14&";"&透射比示值误差与重复性校验!$F14 -> ;; | E23: =透射比示值误差与重复性校验!$G14 | F23: =透射比示值误差与重复性校验!$H14 | G23: =透射比示值误差与重复性校验!$I14 -> 0 | H23: =Report!$F$5 -> 0 | I23: =NOW() -> 45881.669 | J23: =Report!$N$5 -> 0 | L23: =Report!$C$6 -> 0 | M23: =Report!$H$6 -> 0 | N23: =透射比示值误差与重复性校验!$L14 -> 未检测 | P23: 2004
A24: 3001 | B24: =MID(_xlfn.SINGLE(CELL("filename")),FIND("[",_xlfn.SINGLE(CELL("filename")),1)+1,FIND(".",_xlfn.SINGLE(CELL("filename")),1)-FIND("[",_xlfn.SINGLE(CELL("filename")),1)-1) -> T600T700-FixedSlit | C24: =杂散光校验!$B2 -> 220 | D24: =杂散光校验!$C2&";"&杂散光校验!$D2&";"&杂散光校验!$E2 -> ;; | H24: =Report!$F$5 -> 0 | I24: =NOW() -> 45881.669 | J24: =Report!$N$5 -> 0 | L24: =Report!$C$6 -> 0 | M24: =Report!$H$6 -> 0 | N24: =杂散光校验!$G2 -> 未检测 | P24: 3001
A25: 3002 | B25: =MID(_xlfn.SINGLE(CELL("filename")),FIND("[",_xlfn.SINGLE(CELL("filename")),1)+1,FIND(".",_xlfn.SINGLE(CELL("filename")),1)-FIND("[",_xlfn.SINGLE(CELL("filename")),1)-1) -> T600T700-FixedSlit | C25: =杂散光校验!$B3 -> 360 | D25: =杂散光校验!$C3&";"&杂散光校验!$D3&";"&杂散光校验!$E3 -> ;; | H25: =Report!$F$5 -> 0 | I25: =NOW() -> 45881.669 | J25: =Report!$N$5 -> 0 | L25: =Report!$C$6 -> 0 | M25: =Report!$H$6 -> 0 | N25: =杂散光校验!$G3 -> 未检测 | P25: 3002
A26: 4001 | B26: =MID(_xlfn.SINGLE(CELL("filename")),FIND("[",_xlfn.SINGLE(CELL("filename")),1)+1,FIND(".",_xlfn.SINGLE(CELL("filename")),1)-FIND("[",_xlfn.SINGLE(CELL("filename")),1)-1) -> T600T700-FixedSlit | D26: =基线平直度检验!$B$2 -> 0 | H26: =Report!$F$5 -> 0 | I26: =NOW() -> 45881.669 | J26: =Report!$N$5 -> 0 | L26: =Report!$C$6 -> 0 | M26: =Report!$H$6 -> 0 | N26: =基线平直度检验!$D$2 -> 未检测 | P26: 4001
A27: 5001 | B27: =MID(_xlfn.SINGLE(CELL("filename")),FIND("[",_xlfn.SINGLE(CELL("filename")),1)+1,FIND(".",_xlfn.SINGLE(CELL("filename")),1)-FIND("[",_xlfn.SINGLE(CELL("filename")),1)-1) -> T600T700-FixedSlit | D27: =基线暗噪声检验!$B$2 -> 0 | H27: =Report!$F$5 -> 0 | I27: =NOW() -> 45881.669 | J27: =Report!$N$5 -> 0 | L27: =Report!$C$6 -> 0 | M27: =Report!$H$6 -> 0 | N27: =基线暗噪声检验!$D$2 -> 未检测 | P27: 5001
A28: 6002 | B28: =MID(_xlfn.SINGLE(CELL("filename")),FIND("[",_xlfn.SINGLE(CELL("filename")),1)+1,FIND(".",_xlfn.SINGLE(CELL("filename")),1)-FIND("[",_xlfn.SINGLE(CELL("filename")),1)-1) -> T600T700-FixedSlit | C28: =光谱带宽与仪器最小光谱带宽!$C2 -> 2 | D28: =光谱带宽与仪器最小光谱带宽!$D2 -> 0 | H28: =Report!$F$5 -> 0 | I28: =NOW() -> 45881.669 | J28: =Report!$N$5 -> 0 | L28: =Report!$C$6 -> 0 | M28: =Report!$H$6 -> 0 | N28: =光谱带宽与仪器最小光谱带宽!$G2 -> 未检测 | P28: 6001
A29: 7001 | B29: =MID(_xlfn.SINGLE(CELL("filename")),FIND("[",_xlfn.SINGLE(CELL("filename")),1)+1,FIND(".",_xlfn.SINGLE(CELL("filename")),1)-FIND("[",_xlfn.SINGLE(CELL("filename")),1)-1) -> T600T700-FixedSlit | C29: =噪声检验!$B2 -> 500 | D29: =噪声检验!$C2 -> 0 | H29: =Report!$F$5 -> 0 | I29: =NOW() -> 45881.669 | J29: =Report!$N$5 -> 0 | L29: =Report!$C$6 -> 0 | M29: =Report!$H$6 -> 0 | N29: =噪声检验!$E2 -> 未检测 | P29: 7001
A30: 7002 | B30: =MID(_xlfn.SINGLE(CELL("filename")),FIND("[",_xlfn.SINGLE(CELL("filename")),1)+1,FIND(".",_xlfn.SINGLE(CELL("filename")),1)-FIND("[",_xlfn.SINGLE(CELL("filename")),1)-1) -> T600T700-FixedSlit | C30: =噪声检验!$B3 -> 500 | D30: =噪声检验!$C3 -> 0 | H30: =Report!$F$5 -> 0 | I30: =NOW() -> 45881.669 | J30: =Report!$N$5 -> 0 | L30: =Report!$C$6 -> 0 | M30: =Report!$H$6 -> 0 | N30: =噪声检验!$E3 -> 未检测 | P30: 7002
A31: 7003 | B31: =MID(_xlfn.SINGLE(CELL("filename")),FIND("[",_xlfn.SINGLE(CELL("filename")),1)+1,FIND(".",_xlfn.SINGLE(CELL("filename")),1)-FIND("[",_xlfn.SINGLE(CELL("filename")),1)-1) -> T600T700-FixedSlit | C31: =噪声检验!$B4 -> 250 | D31: =噪声检验!$C4 -> 0 | H31: =Report!$F$5 -> 0 | I31: =NOW() -> 45881.669 | J31: =Report!$N$5 -> 0 | L31: =Report!$C$6 -> 0 | M31: =Report!$H$6 -> 0 | N31: =噪声检验!$E4 -> 未检测 | P31: 7003
A32: 7004 | B32: =MID(_xlfn.SINGLE(CELL("filename")),FIND("[",_xlfn.SINGLE(CELL("filename")),1)+1,FIND(".",_xlfn.SINGLE(CELL("filename")),1)-FIND("[",_xlfn.SINGLE(CELL("filename")),1)-1) -> T600T700-FixedSlit | C32: =噪声检验!$B5 -> 250 | D32: =噪声检验!$C5 -> 0 | H32: =Report!$F$5 -> 0 | I32: =NOW() -> 45881.669 | J32: =Report!$N$5 -> 0 | L32: =Report!$C$6 -> 0 | M32: =Report!$H$6 -> 0 | N32: =噪声检验!$E5 -> 未检测 | P32: 7004
A33: 8001 | B33: =MID(_xlfn.SINGLE(CELL("filename")),FIND("[",_xlfn.SINGLE(CELL("filename")),1)+1,FIND(".",_xlfn.SINGLE(CELL("filename")),1)-FIND("[",_xlfn.SINGLE(CELL("filename")),1)-1) -> T600T700-FixedSlit | C33: =波长边缘噪声!$B2 -> 1090 | D33: =波长边缘噪声!$C2 -> 0 | H33: =Report!$F$5 -> 0 | I33: =NOW() -> 45881.669 | J33: =Report!$N$5 -> 0 | L33: =Report!$C$6 -> 0 | M33: =Report!$H$6 -> 0 | N33: =波长边缘噪声!$E2 -> 未检测 | P33: 8001
A34: 8002 | B34: =MID(_xlfn.SINGLE(CELL("filename")),FIND("[",_xlfn.SINGLE(CELL("filename")),1)+1,FIND(".",_xlfn.SINGLE(CELL("filename")),1)-FIND("[",_xlfn.SINGLE(CELL("filename")),1)-1) -> T600T700-FixedSlit | C34: =波长边缘噪声!$B3 -> 1090 | D34: =波长边缘噪声!$C3 -> 0 | H34: =Report!$F$5 -> 0 | I34: =NOW() -> 45881.669 | J34: =Report!$N$5 -> 0 | L34: =Report!$C$6 -> 0 | M34: =Report!$H$6 -> 0 | N34: =波长边缘噪声!$E3 -> 未检测 | P34: 8002
A35: 8003 | B35: =MID(_xlfn.SINGLE(CELL("filename")),FIND("[",_xlfn.SINGLE(CELL("filename")),1)+1,FIND(".",_xlfn.SINGLE(CELL("filename")),1)-FIND("[",_xlfn.SINGLE(CELL("filename")),1)-1) -> T600T700-FixedSlit | C35: =波长边缘噪声!$B4 -> 200 | D35: =波长边缘噪声!$C4 -> 0 | H35: =Report!$F$5 -> 0 | I35: =NOW() -> 45881.669 | J35: =Report!$N$5 -> 0 | L35: =Report!$C$6 -> 0 | M35: =Report!$H$6 -> 0 | N35: =波长边缘噪声!$E4 -> 未检测 | P35: 8003
A36: 8004 | B36: =MID(_xlfn.SINGLE(CELL("filename")),FIND("[",_xlfn.SINGLE(CELL("filename")),1)+1,FIND(".",_xlfn.SINGLE(CELL("filename")),1)-FIND("[",_xlfn.SINGLE(CELL("filename")),1)-1) -> T600T700-FixedSlit | C36: =波长边缘噪声!$B5 -> 200 | D36: =波长边缘噪声!$C5 -> 0 | H36: =Report!$F$5 -> 0 | I36: =NOW() -> 45881.669 | J36: =Report!$N$5 -> 0 | L36: =Report!$C$6 -> 0 | M36: =Report!$H$6 -> 0 | N36: =波长边缘噪声!$E5 -> 未检测 | P36: 8004
A37: 9001 | B37: =MID(_xlfn.SINGLE(CELL("filename")),FIND("[",_xlfn.SINGLE(CELL("filename")),1)+1,FIND(".",_xlfn.SINGLE(CELL("filename")),1)-FIND("[",_xlfn.SINGLE(CELL("filename")),1)-1) -> T600T700-FixedSlit | C37: =漂移检验!$B$2 -> 500 | D37: =漂移检验!$C$2 -> 0 | H37: =Report!$F$5 -> 0 | I37: =NOW() -> 45881.669 | J37: =Report!$N$5 -> 0 | L37: =Report!$C$6 -> 0 | M37: =Report!$H$6 -> 0 | N37: =漂移检验!$E$2 -> 未检测 | P37: 9001

Sheet 管理表
A1: 检验项目
A2: 产品型号 | B2: 父项目编号 | C2: 父项目名称 | D2: 子项目编号 | E2: 子项目名称 | F2: 特征值 | G2: 可允许误差范围 | H2: 波长重复性
A3: T700S | B3: 1000 | C3: 波长示值误差与重复性校验 | D3: 1001 | E3: 氘灯 | F3: 656.1 | G3: 0.1 | H3: 0.1
A4: T700S | B4: 1000 | C4: 波长示值误差与重复性校验 | D4: 1002 | E4: 氘灯 | F4: 486 | G4: 0.3 | H4: 0.1
A5: T700S | B5: 1000 | C5: 波长示值误差与重复性校验 | D5: 1003 | E5: 镨钕滤光片 | F5: 807.4 | G5: 0.3 | H5: 0.1
A6: T700S | B6: 1000 | C6: 波长示值误差与重复性校验 | D6: 1008 | E6: 钬溶液 | F6: 640.79 | G6: 0.3 | H6: 0.1
A7: T700S | B7: 1000 | C7: 波长示值误差与重复性校验 | D7: 1009 | E7: 钬溶液 | F7: 536.86 | G7: 0.3 | H7: 0.1
A8: T700S | B8: 1000 | C8: 波长示值误差与重复性校验 | D8: 1010 | E8: 钬溶液 | F8: 416.57 | G8: 0.3 | H8: 0.1
A9: T700S | B9: 1000 | C9: 波长示值误差与重复性校验 | D9: 1011 | E9: 钬溶液 | F9: 361.12 | G9: 0.3 | H9: 0.1
A10: T700S | B10: 1000 | C10: 波长示值误差与重复性校验 | D10: 1012 | E10: 钬溶液 | F10: 287.52 | G10: 0.3 | H10: 0.1
A11: T700S | B11: 1000 | C11: 波长示值误差与重复性校验 | D11: 1013 | E11: 钬溶液 | F11: 241.12 | G11: 0.3 | H11: 0.1
A12: T700S | B12: 2000 | C12: 透射比示值误差与重复性校验 | D12: 2001 | E12: 紫外分光光度计标准物质GBW(E)130066 | F12: 350nm | G12: 0.3 | H12: 0.1
A13: T700S | B13: 2000 | C13: 透射比示值误差与重复性校验 | D13: 2002 | E13: 紫外分光光度计标准物质GBW(E)130066 | F13: 313nm | G13: 0.3 | H13: 0.1
A14: T700S | B14: 2000 | C14: 透射比示值误差与重复性校验 | D14: 2003 | E14: 紫外分光光度计标准物质GBW(E)130066 | F14: 257nm | G14: 0.3 | H14: 0.1
A15: T700S | B15: 2000 | C15: 透射比示值误差与重复性校验 | D15: 2004 | E15: 紫外分光光度计标准物质GBW(E)130066 | F15: 235nm | G15: 0.3 | H15: 0.1
A16: T700S | B16: 2000 | C16: 透射比示值误差与重复性校验 | D16: 2005 | E16: 10%中性滤光片 | F16: 635nm | G16: 0.3 | H16: 0.1
... A24: T700S | B24: 2000 | C24: 透射比示值误差与重复性校验 | D24: 2013 | E24: 30%中性滤光片 | F24: 440nm | G24: 0.3 | H24: 0.1
A25: T700S | B25: 3000 | C25: 杂散光校验 | D25: 3001 | E25: 碘化钠标准溶液 | F25: 220nm | G25: 0.01
A26: T700S | B26: 3000 | C26: 杂散光校验 | D26: 3002 | E26: 亚硝酸钠标准溶液 | F26: 360nm | G26: 0.02
A27: T700S | B27: 4000 | C27: 基线平直度检验 | D27: 4001 | E27: 基线平直度 | G27: 0.0005
A28: T700S | B28: 5000 | C28: 基线暗噪声检验 | D28: 5001 | E28: 基线暗噪声 | G28: 0.1
A29: T700S | B29: 6000 | C29: 光谱带宽与仪器最小光谱带宽 | D29: 6002 | E29: 氘灯2.0 | F29: 656.1 | G29: 20
A30: T700S | B30: 7000 | C30: 噪声检验 | D30: 7001 | E30: 500nm100%噪声 | F30: 500 | G30: 0.05
A31: T700S | B31: 7000 | C31: 噪声检验 | D31: 7002 | E31: 500nm0%噪声 | F31: 500 | G31: 0.005
A32: T700S | B32: 7000 | C32: 噪声检验 | D32: 7003 | E32: 250nm100%噪声 | F32: 250 | G32: 0.05
A33: T700S | B33: 7000 | C33: 噪声检验 | D33: 7004 | E33: 250nm0%噪声 | F33: 250 | G33: 0.005
A34: T700S | B34: 8000 | C34: 波长边缘噪声 | D34: 8001 | E34: 1090nm100%噪声 | F34: 1090 | G34: 0.1
A35: T700S | B35: 8000 | C35: 波长边缘噪声 | D35: 8002 | E35: 1090nm0%噪声 | F35: 1090 | G35: 0.02
A36: T700S | B36: 8000 | C36: 波长边缘噪声 | D36: 8003 | E36: 200nm100%噪声 | F36: 200 | G36: 0.1
A37: T700S | B37: 8000 | C37: 波长边缘噪声 | D37: 8004 | E37: 200nm0%噪声 | F37: 200 | G37: 0.02
A38: T700S | B38: 9000 | C38: 漂移检验 | D38: 9001 | E38: 漂移检验 | F38: 500nm | G38: 0.1

Sheet 对应信息
A1: 产品编号 | B1: 产品型号 | D1: 父项目名称 | E1: 父项目编号
A2: U1601 | B2: T600B | D2: 波长示值误差与重复性校验 | E2: 1000
A3: U1602 | B3: T600A | D3: 透射比示值误差与重复性校验 | E3: 2000
A4: U1603 | B4: T600S | D4: 杂散光校验 | E4: 3000
A5: U1604 | B5: T600AS | D5: 基线平直度检验 | E5: 4000
A6: U1701 | B6: T700B | D6: 基线暗噪声检验 | E6: 5000
A7: U1702 | B7: T700A | D7: 光谱带宽与仪器最小光谱带宽 | E7: 6000
A8: U1703 | B8: T700S | D8: 噪声检验 | E8: 7000
A9: U1704 | B9: T700AS | D9: 波长边缘噪声 | E9: 8000
D10: 漂移检验 | E10: 9000

Sheet 检测项信息
A1: 检测类别 | B1: 项目名称 | C1: 提示 | D1: 方法信息 | E1: 测量信息 | F1: 重复次数 | G1: 重复时间间隔 | H1: 特征值 | I1: 分析方法 | J1: 分析方法 | K1: 灯状态 | L1: 光度模式 | M1: 扫描速度 | N1: 起始波长 | O1: 终止波长 | P1: 扫描间隔 | Q1: 增益 | R1: 光谱带宽 | S1: 时间间隔 | T1: 扫描个数 | U1: 响应时间 | V1: 是否为光谱扫描 | W1: 暗电流物质 | X1: 校零物质 | Y1: 测量物质 | Z1: 父项目编号 | AA1: 子项目编号 | AB1: 标准值
A2: 波长示值误差与重复性校验 | B2: 氘灯(656.1) | D2: =_xlfn.SINGLE(IF(L2="","",字段对应!$B$10&"="&VLOOKUP(L2,基础信息!$I$2:$J$6,2,0)&";"))&_xlfn.SINGLE(IF(M2="","",字段对应!$B$11&"="&VLOOKUP(M2,基础信息!$K$2:$L$6,2,0)&";"))&_xlfn.SINGLE(IF(N2="","",字段对应!$C$2&"="&N2&","&O2&","&P2&";"))&_xlfn.SINGLE(IF(Q2="","",字段对应!$B$13&"="&Q2&";"))&_xlfn.SINGLE(IF(R2="","",字段对应!$B$14&"="&R2&";"))&_xlfn.SINGLE(IF(U2="","",字段对应!$B$22&"="&U2&";"))&_xlfn.SINGLE(IF(K2="","",字段对应!$B$21&"="&VLOOKUP(K2,基础信息!$F$2:$G$4,2,0))) -> PhotoMode=2;ScanSpeed=2;WlRange=660,650,0.02;Gain=4;Slit1=2.0;LampPos=1 | E2: =_xlfn.SINGLE(IF(W2="","",检测项信息!W2&":"&字段对应!$B$16&"|"))&IF(X2="","",X2&":"&IF(V2="是",字段对应!$C$17,字段对应!$B$17&";"&_xlfn.SINGLE(IF(H2="","",字段对应!$B$15&"="&检测项信息!H2)))&"|")&_xlfn.SINGLE(IF(Y2="",":",Y2&":"))&IF(V2="是",字段对应!$C$18,字段对应!$B$18&";"&_xlfn.SINGLE(IF(H2="","",字段对应!$B$15&"="&检测项信息!H2))&_xlfn.SINGLE(IF(AND(T2="",S2=""),"",";"&字段对应!$B$20&"="&T2&";"&字段对应!$B$19&"="&S2))) -> 空气:Scan | F2: 3 | G2: 1 | H2: 656.1 | I2: =VLOOKUP(J2,字段对应!$D$2:$E$8,2,0) -> Validation.ViewModel.DataStructure.FindPeakAndAverageUVTestTool | J2: 寻峰 | K2: 氘灯 | L2: Es | M2: 中速 | N2: 660 | O2: 650 | P2: 0.02 | Q2: 4 | R2: 2.0 | V2: 是 | Y2: 空气 | Z2: =VLOOKUP(A2,对应信息!$D$2:$E$10,2,0) -> 1000 | AA2: =IF(Z1=Z2,AA1+1,Z2+1) -> 1001
A3: 波长示值误差与重复性校验 | B3: 氘灯(486.0) | D3: =_xlfn.SINGLE(IF(L3="","",字段对应!$B$10&"="&VLOOKUP(L3,基础信息!$I$2:$J$6,2,0)&";"))&_xlfn.SINGLE(IF(M3="","",字段对应!$B$11&"="&VLOOKUP(M3,基础信息!$K$2:$L$6,2,0)&";"))&_xlfn.SINGLE(IF(N3="","",字段对应!$C$2&"="&N3&","&O3&","&P3&";"))&_xlfn.SINGLE(IF(Q3="","",字段对应!$B$13&"="&Q3&";"))&_xlfn.SINGLE(IF(R3="","",字段对应!$B$14&"="&R3&";"))&_xlfn.SINGLE(IF(U3="","",字段对应!$B$22&"="&U3&";"))&_xlfn.SINGLE(IF(K3="","",字段对应!$B$21&"="&VLOOKUP(K3,基础信息!$F$2:$G$4,2,0))) -> PhotoMode=2;ScanSpeed=2;WlRange=490,480,0.02;Gain=4;Slit1=2.0;LampPos=1 | E3: =_xlfn.SINGLE(IF(W3="","",检测项信息!W3&":"&字段对应!$B$16&"|"))&IF(X3="","",X3&":"&IF(V3="是",字段对应!$C$17,字段对应!$B$17&";"&_xlfn.SINGLE(IF(H3="","",字段对应!$B$15&"="&检测项信息!H3)))&"|")&_xlfn.SINGLE(IF(Y3="",":",Y3&":"))&IF(V3="是",字段对应!$C$18,字段对应!$B$18&";"&_xlfn.SINGLE(IF(H3="","",字段对应!$B$15&"="&检测项信息!H3))&_xlfn.SINGLE(IF(AND(T3="",S3=""),"",";"&字段对应!$B$20&"="&T3&";"&字段对应!$B$19&"="&S3))) -> 空气:Scan | F3: 3 | G3: 1 | H3: 486 | I3: =VLOOKUP(J3,字段对应!$D$2:$E$8,2,0) -> Validation.ViewModel.DataStructure.FindPeakAndAverageUVTestTool | J3: 寻峰 | K3: 氘灯 | L3: Es | M3: 中速 | N3: 490 | O3: 480 | P3: 0.02 | Q3: 4 | R3: 2.0 | V3: 是 | Y3: 空气 | Z3: =VLOOKUP(A3,对应信息!$D$2:$E$10,2,0) -> 1000 | AA3: =IF(Z2=Z3,AA2+1,Z3+1) -> 1002
A4: 波长示值误差与重复性校验 | B4: 镨钕滤光片 | D4: =_xlfn.SINGLE(IF(L4="","",字段对应!$B$10&"="&VLOOKUP(L4,基础信息!$I$2:$J$6,2,0)&";"))&_xlfn.SINGLE(IF(M4="","",字段对应!$B$11&"="&VLOOKUP(M4,基础信息!$K$2:$L$6,2,0)&";"))&_xlfn.SINGLE(IF(N4="","",字段对应!$C$2&"="&N4&","&O4&","&P4&";"))&_xlfn.SINGLE(IF(Q4="","",字段对应!$B$13&"="&Q4&";"))&_xlfn.SINGLE(IF(R4="","",字段对应!$B$14&"="&R4&";"))&_xlfn.SINGLE(IF(U4="","",字段对应!$B$22&"="&U4&";"))&_xlfn.SINGLE(IF(K4="","",字段对应!$B$21&"="&VLOOKUP(K4,基础信息!$F$2:$G$4,2,0))) -> PhotoMode=0;ScanSpeed=2;WlRange=810,800,0.1;Slit1=2.0; | E4: =_xlfn.SINGLE(IF(W4="","",检测项信息!W4&":"&字段对应!$B$16&"|"))&IF(X4="","",X4&":"&IF(V4="是",字段对应!$C$17,字段对应!$B$17&";"&_xlfn.SINGLE(IF(H4="","",字段对应!$B$15&"="&检测项信息!H4)))&"|")&_xlfn.SINGLE(IF(Y4="",":",Y4&":"))&IF(V4="是",字段对应!$C$18,字段对应!$B$18&";"&_xlfn.SINGLE(IF(H4="","",字段对应!$B$15&"="&检测项信息!H4))&_xlfn.SINGLE(IF(AND(T4="",S4=""),"",";"&字段对应!$B$20&"="&T4&";"&字段对应!$B$19&"="&S4))) -> 黑挡块:Dark|空气:BaseLine|镨钕滤光片:Scan | F4: 3 | G4: 1 | H4: 807.4 | I4: =VLOOKUP(J4,字段对应!$D$2:$E$8,2,0) -> Validation.ViewModel.DataStructure.FindPeakAndAverageUVTestTool | J4: 寻峰 | L4: Abs | M4: 中速 | N4: 810 | O4: 800 | P4: 0.1 | R4: 2.0 | V4: 是 | W4: 黑挡块 | X4: 空气 | Y4: 镨钕滤光片 | Z4: =VLOOKUP(A4,对应信息!$D$2:$E$10,2,0) -> 1000 | AA4: =IF(Z3=Z4,AA3+1,Z4+1) -> 1003
A5: 波长示值误差与重复性校验 | B5: 钬溶液 | D5: =_xlfn.SINGLE(IF(L5="","",字段对应!$B$10&"="&VLOOKUP(L5,基础信息!$I$2:$J$6,2,0)&";"))&_xlfn.SINGLE(IF(M5="","",字段对应!$B$11&"="&VLOOKUP(M5,基础信息!$K$2:$L$6,2,0)&";"))&_xlfn.SINGLE(IF(N5="","",字段对应!$C$2&"="&N5&","&O5&","&P5&";"))&_xlfn.SINGLE(IF(Q5="","",字段对应!$B$13&"="&Q5&";"))&_xlfn.SINGLE(IF(R5="","",字段对应!$B$14&"="&R5&";"))&_xlfn.SINGLE(IF(U5="","",字段对应!$B$22&"="&U5&";"))&_xlfn.SINGLE(IF(K5="","",字段对应!$B$21&"="&VLOOKUP(K5,基础信息!$F$2:$G$4,2,0))) -> PhotoMode=0;ScanSpeed=2;WlRange=645,235,0.1;Slit1=2.0; | E5: =_xlfn.SINGLE(IF(W5="","",检测项信息!W5&":"&字段对应!$B$16&"|"))&IF(X5="","",X5&":"&IF(V5="是",字段对应!$C$17,字段对应!$B$17&";"&_xlfn.SINGLE(IF(H5="","",字段对应!$B$15&"="&检测项信息!H5)))&"|")&_xlfn.SINGLE(IF(Y5="",":",Y5&":"))&IF(V5="是",字段对应!$C$18,字段对应!$B$18&";"&_xlfn.SINGLE(IF(H5="","",字段对应!$B$15&"="&检测项信息!H5))&_xlfn.SINGLE(IF(AND(T5="",S5=""),"",";"&字段对应!$B$20&"="&T5&";"&字段对应!$B$19&"="&S5))) -> 黑挡块:Dark|空气:BaseLine|钬溶液:Scan | F5: 3 | G5: 1 | H5: 640.7,536.8,416.5,361.0,287.4,241.0 | I5: =VLOOKUP(J5,字段对应!$D$2:$E$8,2,0) -> Validation.ViewModel.DataStructure.FindPeakAndAverageUVTestTool | J5: 寻峰 | L5: Abs | M5: 中速 | N5: 645 | O5: 235 | P5: 0.1 | R5: 2.0 | V5: 是 | W5: 黑挡块 | X5: 空气 | Y5: 钬溶液 | Z5: =VLOOKUP(A5,对应信息!$D$2:$E$10,2,0) -> 1000 | AA5: =IF(Z4=Z5,AA4+1,Z5+1) -> 1004
A6: 光谱带宽与仪器最小光谱带宽 | B6: 氘灯2.0 | D6: =_xlfn.SINGLE(IF(L6="","",字段对应!$B$10&"="&VLOOKUP(L6,基础信息!$I$2:$J$6,2,0)&";"))&_xlfn.SINGLE(IF(M6="","",字段对应!$B$11&"="&VLOOKUP(M6,基础信息!$K$2:$L$6,2,0)&";"))&_xlfn.SINGLE(IF(N6="","",字段对应!$C$2&"="&N6&","&O6&","&P6&";"))&_xlfn.SINGLE(IF(Q6="","",字段对应!$B$13&"="&Q6&";"))&_xlfn.SINGLE(IF(R6="","",字段对应!$B$14&"="&R6&";"))&_xlfn.SINGLE(IF(U6="","",字段对应!$B$22&"="&U6&";"))&_xlfn.SINGLE(IF(K6="","",字段对应!$B$21&"="&VLOOKUP(K6,基础信息!$F$2:$G$4,2,0))) -> PhotoMode=2;ScanSpeed=2;WlRange=660,650,0.1;Gain=4;Slit1=2.0;LampPos=1 | E6: =_xlfn.SINGLE(IF(W6="","",检测项信息!W6&":"&字段对应!$B$16&"|"))&IF(X6="","",X6&":"&IF(V6="是",字段对应!$C$17,字段对应!$B$17&";"&_xlfn.SINGLE(IF(H6="","",字段对应!$B$15&"="&检测项信息!H6)))&"|")&_xlfn.SINGLE(IF(Y6="",":",Y6&":"))&IF(V6="是",字段对应!$C$18,字段对应!$B$18&";"&_xlfn.SINGLE(IF(H6="","",字段对应!$B$15&"="&检测项信息!H6))&_xlfn.SINGLE(IF(AND(T6="",S6=""),"",";"&字段对应!$B$20&"="&T6&";"&字段对应!$B$19&"="&S6))) -> 空气:Scan | F6: 1 | H6: 656.1 | I6: =VLOOKUP(J6,字段对应!$D$2:$E$8,2,0) -> Validation.ViewModel.DataStructure.FindHalfPeakUVTestTool | J6: 求半峰宽 | K6: 氘灯 | L6: Es | M6: 中速 | N6: 660 | O6: 650 | P6: 0.1 | Q6: 4 | R6: 2.0 | V6: 是 | Y6: 空气 | Z6: =VLOOKUP(A6,对应信息!$D$2:$E$10,2,0) -> 6000 | AA6: =IF(Z5=Z6,AA5+1,Z6+1) -> 6001 | AB6: 2.0
A7: 基线平直度检验 | B7: 基线平直度 | D7: =_xlfn.SINGLE(IF(L7="","",字段对应!$B$10&"="&VLOOKUP(L7,基础信息!$I$2:$J$6,2,0)&";"))&_xlfn.SINGLE(IF(M7="","",字段对应!$B$11&"="&VLOOKUP(M7,基础信息!$K$2:$L$6,2,0)&";"))&_xlfn.SINGLE(IF(N7="","",字段对应!$C$2&"="&N7&","&O7&","&P7&";"))&_xlfn.SINGLE(IF(Q7="","",字段对应!$B$13&"="&Q7&";"))&_xlfn.SINGLE(IF(R7="","",字段对应!$B$14&"="&R7&";"))&_xlfn.SINGLE(IF(U7="","",字段对应!$B$22&"="&U7&";"))&_xlfn.SINGLE(IF(K7="","",字段对应!$B$21&"="&VLOOKUP(K7,基础信息!$F$2:$G$4,2,0))) -> PhotoMode=0;ScanSpeed=2;WlRange=1090,200,1;Slit1=2.0; | E7: =_xlfn.SINGLE(IF(W7="","",检测项信息!W7&":"&字段对应!$B$16&"|"))&IF(X7="","",X7&":"&IF(V7="是",字段对应!$C$17,字段对应!$B$17&";"&_xlfn.SINGLE(IF(H7="","",字段对应!$B$15&"="&检测项信息!H7)))&"|")&_xlfn.SINGLE(IF(Y7="",":",Y7&":"))&IF(V7="是",字段对应!$C$18,字段对应!$B$18&";"&_xlfn.SINGLE(IF(H7="","",字段对应!$B$15&"="&检测项信息!H7))&_xlfn.SINGLE(IF(AND(T7="",S7=""),"",";"&字段对应!$B$20&"="&T7&";"&字段对应!$B$19&"="&S7))) -> 黑挡块:Dark|空气:BaseLine|空气:Scan | F7: 1 | I7: =VLOOKUP(J7,字段对应!$D$2:$E$8,2,0) -> Validation.ViewModel.DataStructure.GetMaxDIstanceUVTestTool | J7: 求最大偏移量 | L7: Abs | M7: 中速 | N7: 1090 | O7: 200 | P7: 1 | R7: 2.0 | V7: 是 | W7: 黑挡块 | X7: 空气 | Y7: 空气 | Z7: =VLOOKUP(A7,对应信息!$D$2:$E$10,2,0) -> 4000 | AA7: =IF(Z6=Z7,AA6+1,Z7+1) -> 4001
A8: 基线暗噪声检验 | B8: 基线暗噪声 | D8: =_xlfn.SINGLE(IF(L8="","",字段对应!$B$10&"="&VLOOKUP(L8,基础信息!$I$2:$J$6,2,0)&";"))&_xlfn.SINGLE(IF(M8="","",字段对应!$B$11&"="&VLOOKUP(M8,基础信息!$K$2:$L$6,2,0)&";"))&_xlfn.SINGLE(IF(N8="","",字段对应!$C$2&"="&N8&","&O8&","&P8&";"))&_xlfn.SINGLE(IF(Q8="","",字段对应!$B$13&"="&Q8&";"))&_xlfn.SINGLE(IF(R8="","",字段对应!$B$14&"="&R8&";"))&_xlfn.SINGLE(IF(U8="","",字段对应!$B$22&"="&U8&";"))&_xlfn.SINGLE(IF(K8="","",字段对应!$B$21&"="&VLOOKUP(K8,基础信息!$F$2:$G$4,2,0))) -> PhotoMode=1;ScanSpeed=2;WlRange=1090,200,1;Slit1=2.0; | E8: =_xlfn.SINGLE(IF(W8="","",检测项信息!W8&":"&字段对应!$B$16&"|"))&IF(X8="","",X8&":"&IF(V8="是",字段对应!$C$17,字段对应!$B$17&";"&_xlfn.SINGLE(IF(H8="","",字段对应!$B$15&"="&检测项信息!H8)))&"|")&_xlfn.SINGLE(IF(Y8="",":",Y8&":"))&IF(V8="是",字段对应!$C$18,字段对应!$B$18&";"&_xlfn.SINGLE(IF(H8="","",字段对应!$B$15&"="&检测项信息!H8))&_xlfn.SINGLE(IF(AND(T8="",S8=""),"",";"&字段对应!$B$20&"="&T8&";"&字段对应!$B$19&"="&S8))) -> 黑挡块:Dark|空气:BaseLine|黑挡块:Scan | F8: 1 | I8: =VLOOKUP(J8,字段对应!$D$2:$E$8,2,0) -> Validation.ViewModel.DataStructure.GetMaxDIstanceUVTestTool | J8: 求最大偏移量 | L8: T% | M8: 中速 | N8: 1090 | O8: 200 | P8: 1 | R8: 2.0 | V8: 是 | W8: 黑挡块 | X8: 空气 | Y8: 黑挡块 | Z8: =VLOOKUP(A8,对应信息!$D$2:$E$10,2,0) -> 5000 | AA8: =IF(Z7=Z8,AA7+1,Z8+1) -> 5001
A9: 噪声检验 | B9: 500nm100%噪声 | D9: =_xlfn.SINGLE(IF(L9="","",字段对应!$B$10&"="&VLOOKUP(L9,基础信息!$I$2:$J$6,2,0)&";"))&_xlfn.SINGLE(IF(M9="","",字段对应!$B$11&"="&VLOOKUP(M9,基础信息!$K$2:$L$6,2,0)&";"))&_xlfn.SINGLE(IF(N9="","",字段对应!$C$2&"="&N9&","&O9&","&P9&";"))&_xlfn.SINGLE(IF(Q9="","",字段对应!$B$13&"="&Q9&";"))&_xlfn.SINGLE(IF(R9="","",字段对应!$B$14&"="&R9&";"))&_xlfn.SINGLE(IF(U9="","",字段对应!$B$22&"="&U9&";"))&_xlfn.SINGLE(IF(K9="","",字段对应!$B$21&"="&VLOOKUP(K9,基础信息!$F$2:$G$4,2,0))) -> PhotoMode=1;ScanSpeed=2;Slit1=2.0;ResponseTime=1; | E9: =_xlfn.SINGLE(IF(W9="","",检测项信息!W9&":"&字段对应!$B$16&"|"))&IF(X9="","",X9&":"&IF(V9="是",字段对应!$C$17,字段对应!$B$17&";"&_xlfn.SINGLE(IF(H9="","",字段对应!$B$15&"="&检测项信息!H9)))&"|")&_xlfn.SINGLE(IF(Y9="",":",Y9&":"))&IF(V9="是",字段对应!$C$18,字段对应!$B$18&";"&_xlfn.SINGLE(IF(H9="","",字段对应!$B$15&"="&检测项信息!H9))&_xlfn.SINGLE(IF(AND(T9="",S9=""),"",";"&字段对应!$B$20&"="&T9&";"&字段对应!$B$19&"="&S9))) -> 黑挡块:Dark|空气:Zero;Wl=500|空气:Measure;Wl=500;totalcount=120;timeinterval=1 | F9: 1 | H9: 500 | I9: =VLOOKUP(J9,字段对应!$D$2:$E$8,2,0) -> Validation.ViewModel.DataStructure.FindMaxOffsetUVTestTool | J9: 最大最小值差 | L9: T% | M9: 中速 | R9: 2.0 | S9: 1 | T9: 120 | U9: 1 | V9: 否 | W9: 黑挡块 | X9: 空气 | Y9: 空气 | Z9: =VLOOKUP(A9,对应信息!$D$2:$E$10,2,0) -> 7000 | AA9: =IF(Z8=Z9,AA8+1,Z9+1) -> 7001
A10: 噪声检验 | B10: 500nm0%噪声 | D10: =_xlfn.SINGLE(IF(L10="","",字段对应!$B$10&"="&VLOOKUP(L10,基础信息!$I$2:$J$6,2,0)&";"))&_xlfn.SINGLE(IF(M10="","",字段对应!$B$11&"="&VLOOKUP(M10,基础信息!$K$2:$L$6,2,0)&";"))&_xlfn.SINGLE(IF(N10="","",字段对应!$C$2&"="&N10&","&O10&","&P10&";"))&_xlfn.SINGLE(IF(Q10="","",字段对应!$B$13&"="&Q10&";"))&_xlfn.SINGLE(IF(R10="","",字段对应!$B$14&"="&R10&";"))&_xlfn.SINGLE(IF(U10="","",字段对应!$B$22&"="&U10&";"))&_xlfn.SINGLE(IF(K10="","",字段对应!$B$21&"="&VLOOKUP(K10,基础信息!$F$2:$G$4,2,0))) -> PhotoMode=1;ScanSpeed=2;Slit1=2.0;ResponseTime=1; | E10: =_xlfn.SINGLE(IF(W10="","",检测项信息!W10&":"&字段对应!$B$16&"|"))&IF(X10="","",X10&":"&IF(V10="是",字段对应!$C$17,字段对应!$B$17&";"&_xlfn.SINGLE(IF(H10="","",字段对应!$B$15&"="&检测项信息!H10)))&"|")&_xlfn.SINGLE(IF(Y10="",":",Y10&":"))&IF(V10="是",字段对应!$C$18,字段对应!$B$18&";"&_xlfn.SINGLE(IF(H10="","",字段对应!$B$15&"="&检测项信息!H10))&_xlfn.SINGLE(IF(AND(T10="",S10=""),"",";"&字段对应!$B$20&"="&T10&";"&字段对应!$B$19&"="&S10))) -> 黑挡块:Dark|空气:Zero;Wl=500|黑挡块:Measure;Wl=500;totalcount=120;timeinterval=1 | F10: 1 | H10: 500 | I10: =VLOOKUP(J10,字段对应!$D$2:$E$8,2,0) -> Validation.ViewModel.DataStructure.FindMaxOffsetUVTestTool | J10: 最大最小值差 | L10: T% | M10: 中速 | R10: 2.0 | S10: 1 | T10: 120 | U10: 1 | V10: 否 | W10: 黑挡块 | X10: 空气 | Y10: 黑挡块 | Z10: =VLOOKUP(A10,对应信息!$D$2:$E$10,2,0) -> 7000 | AA10: =IF(Z9=Z10,AA9+1,Z10+1) -> 7002
A11: 噪声检验 | B11: 250nm100%噪声 | D11: =_xlfn.SINGLE(IF(L11="","",字段对应!$B$10&"="&VLOOKUP(L11,基础信息!$I$2:$J$6,2,0)&";"))&_xlfn.SINGLE(IF(M11="","",字段对应!$B$11&"="&VLOOKUP(M11,基础信息!$K$2:$L$6,2,0)&";"))&_xlfn.SINGLE(IF(N11="","",字段对应!$C$2&"="&N11&","&O11&","&P11&";"))&_xlfn.SINGLE(IF(Q11="","",字段对应!$B$13&"="&Q11&";"))&_xlfn.SINGLE(IF(R11="","",字段对应!$B$14&"="&R11&";"))&_xlfn.SINGLE(IF(U11="","",字段对应!$B$22&"="&U11&";"))&_xlfn.SINGLE(IF(K11="","",字段对应!$B$21&"="&VLOOKUP(K11,基础信息!$F$2:$G$4,2,0))) -> PhotoMode=1;ScanSpeed=2;Slit1=2.0;ResponseTime=1; | E11: =_xlfn.SINGLE(IF(W11="","",检测项信息!W11&":"&字段对应!$B$16&"|"))&IF(X11="","",X11&":"&IF(V11="是",字段对应!$C$17,字段对应!$B$17&";"&_xlfn.SINGLE(IF(H11="","",字段对应!$B$15&"="&检测项信息!H11)))&"|")&_xlfn.SINGLE(IF(Y11="",":",Y11&":"))&IF(V11="是",字段对应!$C$18,字段对应!$B$18&";"&_xlfn.SINGLE(IF(H11="","",字段对应!$B$15&"="&检测项信息!H11))&_xlfn.SINGLE(IF(AND(T11="",S11=""),"",";"&字段对应!$B$20&"="&T11&";"&字段对应!$B$19&"="&S11))) -> 黑挡块:Dark|空气:Zero;Wl=250|空气:Measure;Wl=250;totalcount=120;timeinterval=1 | F11: 1 | H11: 250 | I11: =VLOOKUP(J11,字段对应!$D$2:$E$8,2,0) -> Validation.ViewModel.DataStructure.FindMaxOffsetUVTestTool | J11: 最大最小值差 | L11: T% | M11: 中速 | R11: 2.0 | S11: 1 | T11: 120 | U11: 1 | V11: 否 | W11: 黑挡块 | X11: 空气 | Y11: 空气 | Z11: =VLOOKUP(A11,对应信息!$D$2:$E$10,2,0) -> 7000 | AA11: =IF(Z10=Z11,AA10+1,Z11+1) -> 7003
A12: 噪声检验 | B12: 250nm0%噪声 | D12: =_xlfn.SINGLE(IF(L12="","",字段对应!$B$10&"="&VLOOKUP(L12,基础信息!$I$2:$J$6,2,0)&";"))&_xlfn.SINGLE(IF(M12="","",字段对应!$B$11&"="&VLOOKUP(M12,基础信息!$K$2:$L$6,2,0)&";"))&_xlfn.SINGLE(IF(N12="","",字段对应!$C$2&"="&N12&","&O12&","&P12&";"))&_xlfn.SINGLE(IF(Q12="","",字段对应!$B$13&"="&Q12&";"))&_xlfn.SINGLE(IF(R12="","",字段对应!$B$14&"="&R12&";"))&_xlfn.SINGLE(IF(U12="","",字段对应!$B$22&"="&U12&";"))&_xlfn.SINGLE(IF(K12="","",字段对应!$B$21&"="&VLOOKUP(K12,基础信息!$F$2:$G$4,2,0))) -> PhotoMode=1;ScanSpeed=2;Slit1=2.0;ResponseTime=1; | E12: =_xlfn.SINGLE(IF(W12="","",检测项信息!W12&":"&字段对应!$B$16&"|"))&IF(X12="","",X12&":"&IF(V12="是",字段对应!$C$17,字段对应!$B$17&";"&_xlfn.SINGLE(IF(H12="","",字段对应!$B$15&"="&检测项信息!H12)))&"|")&_xlfn.SINGLE(IF(Y12="",":",Y12&":"))&IF(V12="是",字段对应!$C$18,字段对应!$B$18&";"&_xlfn.SINGLE(IF(H12="","",字段对应!$B$15&"="&检测项信息!H12))&_xlfn.SINGLE(IF(AND(T12="",S12=""),"",";"&字段对应!$B$20&"="&T12&";"&字段对应!$B$19&"="&S12))) -> 黑挡块:Dark|空气:Zero;Wl=250|黑挡块:Measure;Wl=250;totalcount=120;timeinterval=1 | F12: 1 | H12: 250 | I12: =VLOOKUP(J12,字段对应!$D$2:$E$8,2,0) -> Validation.ViewModel.DataStructure.FindMaxOffsetUVTestTool | J12: 最大最小值差 | L12: T% | M12: 中速 | R12: 2.0 | S12: 1 | T12: 120 | U12: 1 | V12: 否 | W12: 黑挡块 | X12: 空气 | Y12: 黑挡块 | Z12: =VLOOKUP(A12,对应信息!$D$2:$E$10,2,0) -> 7000 | AA12: =IF(Z11=Z12,AA11+1,Z12+1) -> 7004
A13: 波长边缘噪声 | B13: 1090nm100%噪声 | D13: =_xlfn.SINGLE(IF(L13="","",字段对应!$B$10&"="&VLOOKUP(L13,基础信息!$I$2:$J$6,2,0)&";"))&_xlfn.SINGLE(IF(M13="","",字段对应!$B$11&"="&VLOOKUP(M13,基础信息!$K$2:$L$6,2,0)&";"))&_xlfn.SINGLE(IF(N13="","",字段对应!$C$2&"="&N13&","&O13&","&P13&";"))&_xlfn.SINGLE(IF(Q13="","",字段对应!$B$13&"="&Q13&";"))&_xlfn.SINGLE(IF(R13="","",字段对应!$B$14&"="&R13&";"))&_xlfn.SINGLE(IF(U13="","",字段对应!$B$22&"="&U13&";"))&_xlfn.SINGLE(IF(K13="","",字段对应!$B$21&"="&VLOOKUP(K13,基础信息!$F$2:$G$4,2,0))) -> PhotoMode=1;ScanSpeed=2;Slit1=2.0;ResponseTime=1; | E13: =_xlfn.SINGLE(IF(W13="","",检测项信息!W13&":"&字段对应!$B$16&"|"))&IF(X13="","",X13&":"&IF(V13="是",字段对应!$C$17,字段对应!$B$17&";"&_xlfn.SINGLE(IF(H13="","",字段对应!$B$15&"="&检测项信息!H13)))&"|")&_xlfn.SINGLE(IF(Y13="",":",Y13&":"))&IF(V13="是",字段对应!$C$18,字段对应!$B$18&";"&_xlfn.SINGLE(IF(H13="","",字段对应!$B$15&"="&检测项信息!H13))&_xlfn.SINGLE(IF(AND(T13="",S13=""),"",";"&字段对应!$B$20&"="&T13&";"&字段对应!$B$19&"="&S13))) -> 黑挡块:Dark|空气:Zero;Wl=1090|空气:Measure;Wl=1090;totalcount=180;timeinterval=1 | F13: 1 | H13: 1090 | I13: =VLOOKUP(J13,字段对应!$D$2:$E$8,2,0) -> Validation.ViewModel.DataStructure.FindMaxOffsetUVTestTool | J13: 最大最小值差 | L13: T% | M13: 中速 | R13: 2.0 | S13: 1 | T13: 180 | U13: 1 | V13: 否 | W13: 黑挡块 | X13: 空气 | Y13: 空气 | Z13: =VLOOKUP(A13,对应信息!$D$2:$E$10,2,0) -> 8000 | AA13: =IF(Z12=Z13,AA12+1,Z13+1) -> 8001
A14: 波长边缘噪声 | B14: 1090nm0%噪声 | D14: =_xlfn.SINGLE(IF(L14="","",字段对应!$B$10&"="&VLOOKUP(L14,基础信息!$I$2:$J$6,2,0)&";"))&_xlfn.SINGLE(IF(M14="","",字段对应!$B$11&"="&VLOOKUP(M14,基础信息!$K$2:$L$6,2,0)&";"))&_xlfn.SINGLE(IF(N14="","",字段对应!$C$2&"="&N14&","&O14&","&P14&";"))&_xlfn.SINGLE(IF(Q14="","",字段对应!$B$13&"="&Q14&";"))&_xlfn.SINGLE(IF(R14="","",字段对应!$B$14&"="&R14&";"))&_xlfn.SINGLE(IF(U14="","",字段对应!$B$22&"="&U14&";"))&_xlfn.SINGLE(IF(K14="","",字段对应!$B$21&"="&VLOOKUP(K14,基础信息!$F$2:$G$4,2,0))) -> PhotoMode=1;ScanSpeed=2;Slit1=2.0;ResponseTime=1; | E14: =_xlfn.SINGLE(IF(W14="","",检测项信息!W14&":"&字段对应!$B$16&"|"))&IF(X14="","",X14&":"&IF(V14="是",字段对应!$C$17,字段对应!$B$17&";"&_xlfn.SINGLE(IF(H14="","",字段对应!$B$15&"="&检测项信息!H14)))&"|")&_xlfn.SINGLE(IF(Y14="",":",Y14&":"))&IF(V14="是",字段对应!$C$18,字段对应!$B$18&";"&_xlfn.SINGLE(IF(H14="","",字段对应!$B$15&"="&检测项信息!H14))&_xlfn.SINGLE(IF(AND(T14="",S14=""),"",";"&字段对应!$B$20&"="&T14&";"&字段对应!$B$19&"="&S14))) -> 黑挡块:Dark|空气:Zero;Wl=1090|黑挡块:Measure;Wl=1090;totalcount=180;timeinterval=1 | F14: 1 | H14: 1090 | I14: =VLOOKUP(J14,字段对应!$D$2:$E$8,2,0) -> Validation.ViewModel.DataStructure.FindMaxOffsetUVTestTool | J14: 最大最小值差 | L14: T% | M14: 中速 | R14: 2.0 | S14: 1 | T14: 180 | U14: 1 | V14: 否 | W14: 黑挡块 | X14: 空气 | Y14: 黑挡块 | Z14: =VLOOKUP(A14,对应信息!$D$2:$E$10,2,0) -> 8000 | AA14: =IF(Z13=Z14,AA13+1,Z14+1) -> 8002
A15: 波长边缘噪声 | B15: 200nm100%噪声 | D15: =_xlfn.SINGLE(IF(L15="","",字段对应!$B$10&"="&VLOOKUP(L15,基础信息!$I$2:$J$6,2,0)&";"))&_xlfn.SINGLE(IF(M15="","",字段对应!$B$11&"="&VLOOKUP(M15,基础信息!$K$2:$L$6,2,0)&";"))&_xlfn.SINGLE(IF(N15="","",字段对应!$C$2&"="&N15&","&O15&","&P15&";"))&_xlfn.SINGLE(IF(Q15="","",字段对应!$B$13&"="&Q15&";"))&_xlfn.SINGLE(IF(R15="","",字段对应!$B$14&"="&R15&";"))&_xlfn.SINGLE(IF(U15="","",字段对应!$B$22&"="&U15&";"))&_xlfn.SINGLE(IF(K15="","",字段对应!$B$21&"="&VLOOKUP(K15,基础信息!$F$2:$G$4,2,0))) -> PhotoMode=1;ScanSpeed=2;Slit1=2.0;ResponseTime=1; | E15: =_xlfn.SINGLE(IF(W15="","",检测项信息!W15&":"&字段对应!$B$16&"|"))&IF(X15="","",X15&":"&IF(V15="是",字段对应!$C$17,字段对应!$B$17&";"&_xlfn.SINGLE(IF(H15="","",字段对应!$B$15&"="&检测项信息!H15)))&"|")&_xlfn.SINGLE(IF(Y15="",":",Y15&":"))&IF(V15="是",字段对应!$C$18,字段对应!$B$18&";"&_xlfn.SINGLE(IF(H15="","",字段对应!$B$15&"="&检测项信息!H15))&_xlfn.SINGLE(IF(AND(T15="",S15=""),"",";"&字段对应!$B$20&"="&T15&";"&字段对应!$B$19&"="&S15))) -> 黑挡块:Dark|空气:Zero;Wl=200|空气:Measure;Wl=200;totalcount=180;timeinterval=1 | F15: 1 | H15: 200 | I15: =VLOOKUP(J15,字段对应!$D$2:$E$8,2,0) -> Validation.ViewModel.DataStructure.FindMaxOffsetUVTestTool | J15: 最大最小值差 | L15: T% | M15: 中速 | R15: 2.0 | S15: 1 | T15: 180 | U15: 1 | V15: 否 | W15: 黑挡块 | X15: 空气 | Y15: 空气 | Z15: =VLOOKUP(A15,对应信息!$D$2:$E$10,2,0) -> 8000 | AA15: =IF(Z14=Z15,AA14+1,Z15+1) -> 8003
A16: 波长边缘噪声 | B16: 200nm0%噪声 | D16: =_xlfn.SINGLE(IF(L16="","",字段对应!$B$10&"="&VLOOKUP(L16,基础信息!$I$2:$J$6,2,0)&";"))&_xlfn.SINGLE(IF(M16="","",字段对应!$B$11&"="&VLOOKUP(M16,基础信息!$K$2:$L$6,2,0)&";"))&_xlfn.SINGLE(IF(N16="","",字段对应!$C$2&"="&N16&","&O16&","&P16&";"))&_xlfn.SINGLE(IF(Q16="","",字段对应!$B$13&"="&Q16&";"))&_xlfn.SINGLE(IF(R16="","",字段对应!$B$14&"="&R16&";"))&_xlfn.SINGLE(IF(U16="","",字段对应!$B$22&"="&U16&";"))&_xlfn.SINGLE(IF(K16="","",字段对应!$B$21&"="&VLOOKUP(K16,基础信息!$F$2:$G$4,2,0))) -> PhotoMode=1;ScanSpeed=2;Slit1=2.0;ResponseTime=1; | E16: =_xlfn.SINGLE(IF(W16="","",检测项信息!W16&":"&字段对应!$B$16&"|"))&IF(X16="","",X16&":"&IF(V16="是",字段对应!$C$17,字段对应!$B$17&";"&_xlfn.SINGLE(IF(H16="","",字段对应!$B$15&"="&检测项信息!H16)))&"|")&_xlfn.SINGLE(IF(Y16="",":",Y16&":"))&IF(V16="是",字段对应!$C$18,字段对应!$B$18&";"&_xlfn.SINGLE(IF(H16="","",字段对应!$B$15&"="&检测项信息!H16))&_xlfn.SINGLE(IF(AND(T16="",S16=""),"",";"&字段对应!$B$20&"="&T16&";"&字段对应!$B$19&"="&S16))) -> 黑挡块:Dark|空气:Zero;Wl=200|黑挡块:Measure;Wl=200;totalcount=180;timeinterval=1 | F16: 1 | H16: 200 | I16: =VLOOKUP(J16,字段对应!$D$2:$E$8,2,0) -> Validation.ViewModel.DataStructure.FindMaxOffsetUVTestTool | J16: 最大最小值差 | L16: T% | M16: 中速 | R16: 2.0 | S16: 1 | T16: 180 | U16: 1 | V16: 否 | W16: 黑挡块 | X16: 空气 | Y16: 黑挡块 | Z16: =VLOOKUP(A16,对应信息!$D$2:$E$10,2,0) -> 8000 | AA16: =IF(Z15=Z16,AA15+1,Z16+1) -> 8004
A17: 杂散光校验 | B17: 220nm杂散光 | D17: =_xlfn.SINGLE(IF(L17="","",字段对应!$B$10&"="&VLOOKUP(L17,基础信息!$I$2:$J$6,2,0)&";"))&_xlfn.SINGLE(IF(M17="","",字段对应!$B$11&"="&VLOOKUP(M17,基础信息!$K$2:$L$6,2,0)&";"))&_xlfn.SINGLE(IF(N17="","",字段对应!$C$2&"="&N17&","&O17&","&P17&";"))&_xlfn.SINGLE(IF(Q17="","",字段对应!$B$13&"="&Q17&";"))&_xlfn.SINGLE(IF(R17="","",字段对应!$B$14&"="&R17&";"))&_xlfn.SINGLE(IF(U17="","",字段对应!$B$22&"="&U17&";"))&_xlfn.SINGLE(IF(K17="","",字段对应!$B$21&"="&VLOOKUP(K17,基础信息!$F$2:$G$4,2,0))) -> PhotoMode=1;ScanSpeed=2;Slit1=2.0; | E17: =_xlfn.SINGLE(IF(W17="","",检测项信息!W17&":"&字段对应!$B$16&"|"))&IF(X17="","",X17&":"&IF(V17="是",字段对应!$C$17,字段对应!$B$17&";"&_xlfn.SINGLE(IF(H17="","",字段对应!$B$15&"="&检测项信息!H17)))&"|")&_xlfn.SINGLE(IF(Y17="",":",Y17&":"))&IF(V17="是",字段对应!$C$18,字段对应!$B$18&";"&_xlfn.SINGLE(IF(H17="","",字段对应!$B$15&"="&检测项信息!H17))&_xlfn.SINGLE(IF(AND(T17="",S17=""),"",";"&字段对应!$B$20&"="&T17&";"&字段对应!$B$19&"="&S17))) -> 黑挡块:Dark|碘化钠空白溶液:Zero;Wl=220|碘化钠溶液:Measure;Wl=220 | F17: 3 | G17: 1 | H17: 220 | I17: =VLOOKUP(J17,字段对应!$D$2:$E$8,2,0) -> Validation.ViewModel.DataStructure.WlPointsUVTestTool | J17: 多次测量 | L17: T% | M17: 中速 | R17: 2.0 | V17: 否 | W17: 黑挡块 | X17: 碘化钠空白溶液 | Y17: 碘化钠溶液 | Z17: =VLOOKUP(A17,对应信息!$D$2:$E$10,2,0) -> 3000 | AA17: =IF(Z16=Z17,AA16+1,Z17+1) -> 3001
A18: 杂散光校验 | B18: 360nm杂散光 | D18: =_xlfn.SINGLE(IF(L18="","",字段对应!$B$10&"="&VLOOKUP(L18,基础信息!$I$2:$J$6,2,0)&";"))&_xlfn.SINGLE(IF(M18="","",字段对应!$B$11&"="&VLOOKUP(M18,基础信息!$K$2:$L$6,2,0)&";"))&_xlfn.SINGLE(IF(N18="","",字段对应!$C$2&"="&N18&","&O18&","&P18&";"))&_xlfn.SINGLE(IF(Q18="","",字段对应!$B$13&"="&Q18&";"))&_xlfn.SINGLE(IF(R18="","",字段对应!$B$14&"="&R18&";"))&_xlfn.SINGLE(IF(U18="","",字段对应!$B$22&"="&U18&";"))&_xlfn.SINGLE(IF(K18="","",字段对应!$B$21&"="&VLOOKUP(K18,基础信息!$F$2:$G$4,2,0))) -> PhotoMode=1;ScanSpeed=2;Slit1=2.0; | E18: =_xlfn.SINGLE(IF(W18="","",检测项信息!W18&":"&字段对应!$B$16&"|"))&IF(X18="","",X18&":"&IF(V18="是",字段对应!$C$17,字段对应!$B$17&";"&_xlfn.SINGLE(IF(H18="","",字段对应!$B$15&"="&检测项信息!H18)))&"|")&_xlfn.SINGLE(IF(Y18="",":",Y18&":"))&IF(V18="是",字段对应!$C$18,字段对应!$B$18&";"&_xlfn.SINGLE(IF(H18="","",字段对应!$B$15&"="&检测项信息!H18))&_xlfn.SINGLE(IF(AND(T18="",S18=""),"",";"&字段对应!$B$20&"="&T18&";"&字段对应!$B$19&"="&S18))) -> 黑挡块:Dark|亚硝酸钠空白溶液:Zero;Wl=360|亚硝酸钠溶液:Measure;Wl=360 | F18: 3 | G18: 1 | H18: 360 | I18: =VLOOKUP(J18,字段对应!$D$2:$E$8,2,0) -> Validation.ViewModel.DataStructure.WlPointsUVTestTool | J18: 多次测量 | L18: T% | M18: 中速 | R18: 2.0 | V18: 否 | W18: 黑挡块 | X18: 亚硝酸钠空白溶液 | Y18: 亚硝酸钠溶液 | Z18: =VLOOKUP(A18,对应信息!$D$2:$E$10,2,0) -> 3000 | AA18: =IF(Z17=Z18,AA17+1,Z18+1) -> 3002
A19: 透射比示值误差与重复性校验 | B19: 紫外分光光度计标准物质GBW(E)130066 | D19: =_xlfn.SINGLE(IF(L19="","",字段对应!$B$10&"="&VLOOKUP(L19,基础信息!$I$2:$J$6,2,0)&";"))&_xlfn.SINGLE(IF(M19="","",字段对应!$B$11&"="&VLOOKUP(M19,基础信息!$K$2:$L$6,2,0)&";"))&_xlfn.SINGLE(IF(N19="","",字段对应!$C$2&"="&N19&","&O19&","&P19&";"))&_xlfn.SINGLE(IF(Q19="","",字段对应!$B$13&"="&Q19&";"))&_xlfn.SINGLE(IF(R19="","",字段对应!$B$14&"="&R19&";"))&_xlfn.SINGLE(IF(U19="","",字段对应!$B$22&"="&U19&";"))&_xlfn.SINGLE(IF(K19="","",字段对应!$B$21&"="&VLOOKUP(K19,基础信息!$F$2:$G$4,2,0))) -> PhotoMode=1;ScanSpeed=2;Slit1=2.0; | E19: =_xlfn.SINGLE(IF(W19="","",检测项信息!W19&":"&字段对应!$B$16&"|"))&IF(X19="","",X19&":"&IF(V19="是",字段对应!$C$17,字段对应!$B$17&";"&_xlfn.SINGLE(IF(H19="","",字段对应!$B$15&"="&检测项信息!H19)))&"|")&_xlfn.SINGLE(IF(Y19="",":",Y19&":"))&IF(V19="是",字段对应!$C$18,字段对应!$B$18&";"&_xlfn.SINGLE(IF(H19="","",字段对应!$B$15&"="&检测项信息!H19))&_xlfn.SINGLE(IF(AND(T19="",S19=""),"",";"&字段对应!$B$20&"="&T19&";"&字段对应!$B$19&"="&S19))) -> 黑挡块:Dark|紫外分光光度计标准物质空白溶液:Zero;Wl=350,313,257,235|紫外分光光度计标准物质GBW(E)130066:Measure;Wl=350,313,257,235 | F19: 3 | G19: 1 | H19: 350,313,257,235 | I19: =VLOOKUP(J19,字段对应!$D$2:$E$8,2,0) -> Validation.ViewModel.DataStructure.WlPointsAndAverageUVTestTool | J19: 求平均 | L19: T% | M19: 中速 | R19: 2.0 | V19: 否 | W19: 黑挡块 | X19: 紫外分光光度计标准物质空白溶液 | Y19: 紫外分光光度计标准物质GBW(E)130066 | Z19: =VLOOKUP(A19,对应信息!$D$2:$E$10,2,0) -> 2000 | AA19: =IF(Z18=Z19,AA18+1,Z19+1) -> 2001 | AB19: 23.2,51.58,14.06,18.42
A20: 透射比示值误差与重复性校验 | B20: 10%中性滤光片 | D20: =_xlfn.SINGLE(IF(L20="","",字段对应!$B$10&"="&VLOOKUP(L20,基础信息!$I$2:$J$6,2,0)&";"))&_xlfn.SINGLE(IF(M20="","",字段对应!$B$11&"="&VLOOKUP(M20,基础信息!$K$2:$L$6,2,0)&";"))&_xlfn.SINGLE(IF(N20="","",字段对应!$C$2&"="&N20&","&O20&","&P20&";"))&_xlfn.SINGLE(IF(Q20="","",字段对应!$B$13&"="&Q20&";"))&_xlfn.SINGLE(IF(R20="","",字段对应!$B$14&"="&R20&";"))&_xlfn.SINGLE(IF(U20="","",字段对应!$B$22&"="&U20&";"))&_xlfn.SINGLE(IF(K20="","",字段对应!$B$21&"="&VLOOKUP(K20,基础信息!$F$2:$G$4,2,0))) -> PhotoMode=1;ScanSpeed=2;Slit1=2.0; | E20: =_xlfn.SINGLE(IF(W20="","",检测项信息!W20&":"&字段对应!$B$16&"|"))&IF(X20="","",X20&":"&IF(V20="是",字段对应!$C$17,字段对应!$B$17&";"&_xlfn.SINGLE(IF(H20="","",字段对应!$B$15&"="&检测项信息!H20)))&"|")&_xlfn.SINGLE(IF(Y20="",":",Y20&":"))&IF(V20="是",字段对应!$C$18,字段对应!$B$18&";"&_xlfn.SINGLE(IF(H20="","",字段对应!$B$15&"="&检测项信息!H20))&_xlfn.SINGLE(IF(AND(T20="",S20=""),"",";"&字段对应!$B$20&"="&T20&";"&字段对应!$B$19&"="&S20))) -> 黑挡块:Dark|空气:Zero;Wl=635,546,440|10%中性滤光片:Measure;Wl=635,546,440 | F20: 3 | G20: 1 | H20: 635,546,440 | I20: =VLOOKUP(J20,字段对应!$D$2:$E$8,2,0) -> Validation.ViewModel.DataStructure.WlPointsAndAverageUVTestTool | J20: 求平均 | L20: T% | M20: 中速 | R20: 2.0 | V20: 否 | W20: 黑挡块 | X20: 空气 | Y20: 10%中性滤光片 | Z20: =VLOOKUP(A20,对应信息!$D$2:$E$10,2,0) -> 2000 | AA20: =IF(Z19=Z20,AA19+1,Z20+1) -> 2002 | AB20: 7.57,10.1,10.07
A21: 透射比示值误差与重复性校验 | B21: 20%中性滤光片 | D21: =_xlfn.SINGLE(IF(L21="","",字段对应!$B$10&"="&VLOOKUP(L21,基础信息!$I$2:$J$6,2,0)&";"))&_xlfn.SINGLE(IF(M21="","",字段对应!$B$11&"="&VLOOKUP(M21,基础信息!$K$2:$L$6,2,0)&";"))&_xlfn.SINGLE(IF(N21="","",字段对应!$C$2&"="&N21&","&O21&","&P21&";"))&_xlfn.SINGLE(IF(Q21="","",字段对应!$B$13&"="&Q21&";"))&_xlfn.SINGLE(IF(R21="","",字段对应!$B$14&"="&R21&";"))&_xlfn.SINGLE(IF(U21="","",字段对应!$B$22&"="&U21&";"))&_xlfn.SINGLE(IF(K21="","",字段对应!$B$21&"="&VLOOKUP(K21,基础信息!$F$2:$G$4,2,0))) -> PhotoMode=1;ScanSpeed=2;Slit1=2.0; | E21: =_xlfn.SINGLE(IF(W21="","",检测项信息!W21&":"&字段对应!$B$16&"|"))&IF(X21="","",X21&":"&IF(V21="是",字段对应!$C$17,字段对应!$B$17&";"&_xlfn.SINGLE(IF(H21="","",字段对应!$B$15&"="&检测项信息!H21)))&"|")&_xlfn.SINGLE(IF(Y21="",":",Y21&":"))&IF(V21="是",字段对应!$C$18,字段对应!$B$18&";"&_xlfn.SINGLE(IF(H21="","",字段对应!$B$15&"="&检测项信息!H21))&_xlfn.SINGLE(IF(AND(T21="",S21=""),"",";"&字段对应!$B$20&"="&T21&";"&字段对应!$B$19&"="&S21))) -> 黑挡块:Dark|空气:Zero;Wl=635,546,440|20%中性滤光片:Measure;Wl=635,546,440 | F21: 3 | G21: 1 | H21: 635,546,440 | I21: =VLOOKUP(J21,字段对应!$D$2:$E$8,2,0) -> Validation.ViewModel.DataStructure.WlPointsAndAverageUVTestTool | J21: 求平均 | L21: T% | M21: 中速 | R21: 2.0 | V21: 否 | W21: 黑挡块 | X21: 空气 | Y21: 20%中性滤光片 | Z21: =VLOOKUP(A21,对应信息!$D$2:$E$10,2,0) -> 2000 | AA21: =IF(Z20=Z21,AA20+1,Z21+1) -> 2003 | AB21: 18.89,20.09,20.91
A22: 透射比示值误差与重复性校验 | B22: 30%中性滤光片 | D22: =_xlfn.SINGLE(IF(L22="","",字段对应!$B$10&"="&VLOOKUP(L22,基础信息!$I$2:$J$6,2,0)&";"))&_xlfn.SINGLE(IF(M22="","",字段对应!$B$11&"="&VLOOKUP(M22,基础信息!$K$2:$L$6,2,0)&";"))&_xlfn.SINGLE(IF(N22="","",字段对应!$C$2&"="&N22&","&O22&","&P22&";"))&_xlfn.SINGLE(IF(Q22="","",字段对应!$B$13&"="&Q22&";"))&_xlfn.SINGLE(IF(R22="","",字段对应!$B$14&"="&R22&";"))&_xlfn.SINGLE(IF(U22="","",字段对应!$B$22&"="&U22&";"))&_xlfn.SINGLE(IF(K22="","",字段对应!$B$21&"="&VLOOKUP(K22,基础信息!$F$2:$G$4,2,0))) -> PhotoMode=1;ScanSpeed=2;Slit1=2.0; | E22: =_xlfn.SINGLE(IF(W22="","",检测项信息!W22&":"&字段对应!$B$16&"|"))&IF(X22="","",X22&":"&IF(V22="是",字段对应!$C$17,字段对应!$B$17&";"&_xlfn.SINGLE(IF(H22="","",字段对应!$B$15&"="&检测项信息!H22)))&"|")&_xlfn.SINGLE(IF(Y22="",":",Y22&":"))&IF(V22="是",字段对应!$C$18,字段对应!$B$18&";"&_xlfn.SINGLE(IF(H22="","",字段对应!$B$15&"="&检测项信息!H22))&_xlfn.SINGLE(IF(AND(T22="",S22=""),"",";"&字段对应!$B$20&"="&T22&";"&字段对应!$B$19&"="&S22))) -> 黑挡块:Dark|空气:Zero;Wl=635,546,440|30%中性滤光片:Measure;Wl=635,546,440 | F22: 3 | G22: 1 | H22: 635,546,440 | I22: =VLOOKUP(J22,字段对应!$D$2:$E$8,2,0) -> Validation.ViewModel.DataStructure.WlPointsAndAverageUVTestTool | J22: 求平均 | L22: T% | M22: 中速 | R22: 2.0 | V22: 否 | W22: 黑挡块 | X22: 空气 | Y22: 30%中性滤光片 | Z22: =VLOOKUP(A22,对应信息!$D$2:$E$10,2,0) -> 2000 | AA22: =IF(Z21=Z22,AA21+1,Z22+1) -> 2004 | AB22: 29.96,30.43,28.88
A23: 漂移检验 | B23: 漂移检验 | C23: 仪器预热1小时之后进行检验 | D23: =_xlfn.SINGLE(IF(L23="","",字段对应!$B$10&"="&VLOOKUP(L23,基础信息!$I$2:$J$6,2,0)&";"))&_xlfn.SINGLE(IF(M23="","",字段对应!$B$11&"="&VLOOKUP(M23,基础信息!$K$2:$L$6,2,0)&";"))&_xlfn.SINGLE(IF(N23="","",字段对应!$C$2&"="&N23&","&O23&","&P23&";"))&_xlfn.SINGLE(IF(Q23="","",字段对应!$B$13&"="&Q23&";"))&_xlfn.SINGLE(IF(R23="","",字段对应!$B$14&"="&R23&";"))&_xlfn.SINGLE(IF(U23="","",字段对应!$B$22&"="&U23&";"))&_xlfn.SINGLE(IF(K23="","",字段对应!$B$21&"="&VLOOKUP(K23,基础信息!$F$2:$G$4,2,0))) -> PhotoMode=1;ScanSpeed=2;Slit1=2.0;ResponseTime=1; | E23: =_xlfn.SINGLE(IF(W23="","",检测项信息!W23&":"&字段对应!$B$16&"|"))&IF(X23="","",X23&":"&IF(V23="是",字段对应!$C$17,字段对应!$B$17&";"&_xlfn.SINGLE(IF(H23="","",字段对应!$B$15&"="&检测项信息!H23)))&"|")&_xlfn.SINGLE(IF(Y23="",":",Y23&":"))&IF(V23="是",字段对应!$C$18,字段对应!$B$18&";"&_xlfn.SINGLE(IF(H23="","",字段对应!$B$15&"="&检测项信息!H23))&_xlfn.SINGLE(IF(AND(T23="",S23=""),"",";"&字段对应!$B$20&"="&T23&";"&字段对应!$B$19&"="&S23))) -> 黑挡块:Dark|空气:Zero;Wl=500|空气:Measure;Wl=500;totalcount=3600;timeinterval=1 | F23: 1 | H23: 500 | I23: =VLOOKUP(J23,字段对应!$D$2:$E$8,2,0) -> Validation.ViewModel.DataStructure.FindMaxOffsetUVTestTool | J23: 最大最小值差 | L23: T% | M23: 中速 | R23: 2.0 | S23: 1 | T23: 3600 | U23: 1 | V23: 否 | W23: 黑挡块 | X23: 空气 | Y23: 空气 | Z23: =VLOOKUP(A23,对应信息!$D$2:$E$10,2,0) -> 9000 | AA23: =IF(Z22=Z23,AA22+1,Z23+1) -> 9001

Sheet 仪器状态
A1: 仪器id | B1: 项目 | C1: 能量 | D1: id | E1: 父id
A2: =MID(_xlfn.SINGLE(CELL("filename")),FIND("[",_xlfn.SINGLE(CELL("filename")),1)+1,FIND(".",_xlfn.SINGLE(CELL("filename")),1)-FIND("[",_xlfn.SINGLE(CELL("filename")),1)-1) -> T600T700-FixedSlit | B2: 关灯，增益1下的RSD值
A3: =MID(_xlfn.SINGLE(CELL("filename")),FIND("[",_xlfn.SINGLE(CELL("filename")),1)+1,FIND(".",_xlfn.SINGLE(CELL("filename")),1)-FIND("[",_xlfn.SINGLE(CELL("filename")),1)-1) -> T600T700-FixedSlit | B3: 关灯，增益2下的RSD值
A4: =MID(_xlfn.SINGLE(CELL("filename")),FIND("[",_xlfn.SINGLE(CELL("filename")),1)+1,FIND(".",_xlfn.SINGLE(CELL("filename")),1)-FIND("[",_xlfn.SINGLE(CELL("filename")),1)-1) -> T600T700-FixedSlit | B4: 关灯，增益3下的RSD值
A5: =MID(_xlfn.SINGLE(CELL("filename")),FIND("[",_xlfn.SINGLE(CELL("filename")),1)+1,FIND(".",_xlfn.SINGLE(CELL("filename")),1)-FIND("[",_xlfn.SINGLE(CELL("filename")),1)-1) -> T600T700-FixedSlit | B5: 关灯，增益4下的RSD值
A6: =MID(_xlfn.SINGLE(CELL("filename")),FIND("[",_xlfn.SINGLE(CELL("filename")),1)+1,FIND(".",_xlfn.SINGLE(CELL("filename")),1)-FIND("[",_xlfn.SINGLE(CELL("filename")),1)-1) -> T600T700-FixedSlit | B6: 开灯，增益1下的RSD值
A7: =MID(_xlfn.SINGLE(CELL("filename")),FIND("[",_xlfn.SINGLE(CELL("filename")),1)+1,FIND(".",_xlfn.SINGLE(CELL("filename")),1)-FIND("[",_xlfn.SINGLE(CELL("filename")),1)-1) -> T600T700-FixedSlit | B7: 开灯，增益2下的RSD值
A8: =MID(_xlfn.SINGLE(CELL("filename")),FIND("[",_xlfn.SINGLE(CELL("filename")),1)+1,FIND(".",_xlfn.SINGLE(CELL("filename")),1)-FIND("[",_xlfn.SINGLE(CELL("filename")),1)-1) -> T600T700-FixedSlit | B8: 开灯，增益3下的RSD值
A9: =MID(_xlfn.SINGLE(CELL("filename")),FIND("[",_xlfn.SINGLE(CELL("filename")),1)+1,FIND(".",_xlfn.SINGLE(CELL("filename")),1)-FIND("[",_xlfn.SINGLE(CELL("filename")),1)-1) -> T600T700-FixedSlit | B9: 开灯，增益4下的RSD值
A10: =MID(_xlfn.SINGLE(CELL("filename")),FIND("[",_xlfn.SINGLE(CELL("filename")),1)+1,FIND(".",_xlfn.SINGLE(CELL("filename")),1)-FIND("[",_xlfn.SINGLE(CELL("filename")),1)-1) -> T600T700-FixedSlit | B10: 氘灯656.1能量 | D10: 1001 | E10: 1001
A11: =MID(_xlfn.SINGLE(CELL("filename")),FIND("[",_xlfn.SINGLE(CELL("filename")),1)+1,FIND(".",_xlfn.SINGLE(CELL("filename")),1)-FIND("[",_xlfn.SINGLE(CELL("filename")),1)-1) -> T600T700-FixedSlit | B11: 氘灯486.0能量 | D11: 1002 | E11: 1002
A12: =MID(_xlfn.SINGLE(CELL("filename")),FIND("[",_xlfn.SINGLE(CELL("filename")),1)+1,FIND(".",_xlfn.SINGLE(CELL("filename")),1)-FIND("[",_xlfn.SINGLE(CELL("filename")),1)-1) -> T600T700-FixedSlit | B12: 紫外分光光度计标准物质GBW(E)130066-350nm能量 | D12: 2001 | E12: 2001
A13: =MID(_xlfn.SINGLE(CELL("filename")),FIND("[",_xlfn.SINGLE(CELL("filename")),1)+1,FIND(".",_xlfn.SINGLE(CELL("filename")),1)-FIND("[",_xlfn.SINGLE(CELL("filename")),1)-1) -> T600T700-FixedSlit | B13: 紫外分光光度计标准物质GBW(E)130066-313nm能量 | D13: 2002 | E13: 2001
A14: =MID(_xlfn.SINGLE(CELL("filename")),FIND("[",_xlfn.SINGLE(CELL("filename")),1)+1,FIND(".",_xlfn.SINGLE(CELL("filename")),1)-FIND("[",_xlfn.SINGLE(CELL("filename")),1)-1) -> T600T700-FixedSlit | B14: 紫外分光光度计标准物质GBW(E)130066-257nm能量 | D14: 2003 | E14: 2001
A15: =MID(_xlfn.SINGLE(CELL("filename")),FIND("[",_xlfn.SINGLE(CELL("filename")),1)+1,FIND(".",_xlfn.SINGLE(CELL("filename")),1)-FIND("[",_xlfn.SINGLE(CELL("filename")),1)-1) -> T600T700-FixedSlit | B15: 紫外分光光度计标准物质GBW(E)130066-235nm能量 | D15: 2004 | E15: 2001
A16: =MID(_xlfn.SINGLE(CELL("filename")),FIND("[",_xlfn.SINGLE(CELL("filename")),1)+1,FIND(".",_xlfn.SINGLE(CELL("filename")),1)-FIND("[",_xlfn.SINGLE(CELL("filename")),1)-1) -> T600T700-FixedSlit | B16: 碘化钠标准溶液-220nm能量 | D16: 3001 | E16: 3001
A17: =MID(_xlfn.SINGLE(CELL("filename")),FIND("[",_xlfn.SINGLE(CELL("filename")),1)+1,FIND(".",_xlfn.SINGLE(CELL("filename")),1)-FIND("[",_xlfn.SINGLE(CELL("filename")),1)-1) -> T600T700-FixedSlit | B17: 亚硝酸钠标准溶液-360nm能量 | D17: 3002 | E17: 3002
