Workbook
Name OLE_LINK10: Report!#REF!

Sheet Report
C1: 北京普析通用仪器有限责任公司 | L1: 文件编号
C2: T600T700系列紫外可见分光光度计整机检验原始记录表 | L2: 版本/修订
L3: 发布/修订日期
A4: 产品型号 | D4: 产品编号 | H4: 检验员 | L4: 检验日期 | N4: 复核员
A5: =IFERROR(VLOOKUP(MID(D5,3,5),对应信息!A:B,2,0),"") | H5: 123
A6: 温度(℃) | E6: 相对湿度(%) | L6: 检验结果
A7: UVWin版本号 | E7: UVTouch版本号 | K7: 检验软件版本号
A8: 序号 | B8: 检验项目 | E8: 结果
A9: 1 | B9: 样品池重复性 | D9: 准确度：100%±0.1% 重复性：<0.1% | G9: 1号池测量值(%) | J9: =样品池重复性!B2 -> 0 | L9: 重复性(%) | M9: =样品池重复性!B8 -> 0
A10: 2 | B10: 波长拟合 | C10: 检测工具 | E10: 模式 | H10: 增益 | K10: 标准值(nm) | M10: 测量值（nm）
C11: 氘灯 | E11: =波长拟合!C2 -> Es | H11: =波长拟合!D2 -> 4 | K11: =波长拟合!B2 -> 486 | M11: =波长拟合!F2 -> 0
E12: =波长拟合!C3 -> Es | H12: =波长拟合!D3 -> 4 | K12: =波长拟合!B3 -> 656.1 | M12: =波长拟合!F3 -> 0
C13: 镨钕滤光片 | E13: =波长拟合!C4 -> Abs | H13: =波长拟合!D4 -> 0 | K13: =波长拟合!B4 -> 807.4 | M13: =波长拟合!F4 -> 0
C14: 钬溶液 | E14: =波长拟合!C5 -> Abs | H14: =波长拟合!D5 -> 0 | K14: =波长拟合!B5 -> 241 | M14: =波长拟合!F5 -> 0
E15: =波长拟合!C6 -> Abs | H15: =波长拟合!D6 -> 0 | K15: =波长拟合!B6 -> 361 | M15: =波长拟合!F6 -> 0
E16: =波长拟合!C7 -> Abs | H16: =波长拟合!D7 -> 0 | K16: =波长拟合!B7 -> 640.7 | M16: =波长拟合!F7 -> 0
C17: 汞灯 | E17: =波长拟合!C8 -> Es | H17: =波长拟合!D8 -> 3 | K17: =波长拟合!B8 -> 296.7 | M17: =波长拟合!F8 -> 0
E18: =波长拟合!C9 -> Es | H18: =波长拟合!D9 -> 3 | K18: =波长拟合!B9 -> 404.7 | M18: =波长拟合!F9 -> 0
E19: =波长拟合!C10 -> Es | H19: =波长拟合!D10 -> 3 | K19: =波长拟合!B10 -> 435.8 | M19: =波长拟合!F10 -> 0
E20: =波长拟合!C11 -> Es | H20: =波长拟合!D11 -> 3 | K20: =波长拟合!B11 -> 546.1 | M20: =波长拟合!F11 -> 0
A21: 3 | B21: 能量扫描 | C21: 检测工具 | E21: 提示 | I21: 标准值 | K21: 测量值
C22: 氘灯 | E22: 定点波长：486nm | I22: =能量扫描!B2 -> 486 | K22: =能量扫描!C2 -> 0
E23: 波长段：656.1nm | I23: =能量扫描!B3 -> 656.1 | K23: =能量扫描!C3 -> 0
E24: 波长段：1100nm-300nm | I24: =能量扫描!B4 -> 全段
C25: 钨灯 | E25: 波长段：700nm-190nm | I25: =能量扫描!#REF! -> #REF!
A26: 4 | B26: 波长示值误差校验 | C26: 波长示值误差 氘灯： ±0.1nm 镨钕： ±0.3nm 波长重复性 ≤0.1nm | E26: 波长段 | H26: B段
E27: 检测工具 | H27: 氘灯 | K27: 氘灯 | M27: 镨钕滤光片
E28: 标准值(nm) | H28: =波长示值误差校验!B2 -> 656.1 | K28: =波长示值误差校验!B3 -> 486 | M28: =波长示值误差校验!B4 -> 807.4
E29: 测量值（nm） | H29: =波长示值误差校验!C2 -> 0 | K29: =波长示值误差校验!C3 -> 0 | M29: =波长示值误差校验!C4 -> 0
E30: 误差值(nm) | H30: =波长示值误差校验!C3 -> 0 | K30: =波长示值误差校验!C4 -> 0 | M30: =波长示值误差校验!C5 -> 0
B31: 波长示值误差校验 | C31: 波长示值误差 钬溶液： ±0.3nm 波长重复性 ≤0.1nm | E31: 检测工具 | H31: 钬溶液
E32: 标准值(nm) | H32: =波长示值误差校验!B5 -> 640.7 | J32: =波长示值误差校验!B6 -> 536.8 | K32: =波长示值误差校验!B7 -> 416.5 | L32: =波长示值误差校验!B8 -> 361.0 | M32: =波长示值误差校验!B9 -> 287.4 | N32: =波长示值误差校验!B10 -> 241.0
E34: 测量值（nm） | H34: =波长示值误差校验!C5 -> 0 | J34: =波长示值误差校验!C6 -> 0 | K34: =波长示值误差校验!C7 -> 0 | L34: =波长示值误差校验!C8 -> 0 | M34: =波长示值误差校验!C9 -> 0 | N34: =波长示值误差校验!C10 -> 0
E38: 误差值(nm) | H38: =波长示值误差校验!D5 | J38: =波长示值误差校验!D6 | K38: =波长示值误差校验!D7 | L38: =波长示值误差校验!D8 | M38: =波长示值误差校验!D9 | N38: =波长示值误差校验!D10
A41: 5 | B41: 杂散光 | E41: 检验工具 | J41: 1 | K41: 2 | L41: 3 | M41: 结果
C43: 220nm | D43: <0.01% | E43: 碘化钠标准溶液 | H43: 测量值 （%） | J43: =杂散光校验!C2 -> 0 | K43: =杂散光校验!D2 -> 0 | L43: =杂散光校验!E2 -> 0 | M43: =杂散光校验!G2 -> 不合格
C45: 360nm | D45: ≤0.02% | E45: 亚硝酸钠标准溶液 | J45: =杂散光校验!C3 -> 0 | K45: =杂散光校验!D3 -> 0 | L45: =杂散光校验!E3 -> 0 | M45: =杂散光校验!G3 -> 不合格
A47: 6 | B47: 基线平直度 | C47: ≤±0.0005（2.0nm光谱带宽） | H47: 测量值（Abs） | M47: =基线平直度检验!B2 -> 0
A49: 7 | B49: 外观和结构 | C49: 仪器外观应清洁，所有电镀件表面不应有脱皮现象，喷漆表面色泽应均匀，无掉漆与划痕，不得有明显的擦伤、露底、裂纹、起泡现象，外露部件结合处应整齐，无粗糙不平现象。仪器应有下列标志：仪器名称、型号、制造厂名、出厂日期、仪器编号、工作电源电压、频率、制造计量器具许可证标志及编号，仪器的铭牌、二维码的内容及粘贴方向应正确。仪器的各紧固件均应紧固良好，外露螺钉无损伤，生锈，缺失。各按键、开关、指示灯工作正常，电缆线的接插件均能紧密配合且接地良好，启动后无异常杂音。 | N49: 合格□ 不合格□
A51: 检验结论 | C51: 合格 □ 不合格 □
...

Sheet 基础信息
A1: 名称 | B1: 特征值 | C1: 标准值 | E1: 是否为光谱扫描 | F1: 灯状态 | G1: 灯状态 | H1: 较零物质 | I1: 光度方式 | J1: 光度方式 | K1: 扫描速度 | L1: 扫描速度 | M1: 扫描间隔(nm) | N1: 重复次数 | O1: 重复时间间隔(S) | P1: 光谱带宽(nm) | Q1: 增益 | R1: 响应时间
A2: 氘灯 | B2: 656.1 | C2: 656.1 | E2: 是 | F2: 钨灯 | G2: 0 | I2: Abs | J2: 0 | K2: 极慢 | L2: 0 | N2: 1 | P2: 0.2
A3: 低压汞灯A段 | B3: 253.7 | C3: 253.7 | E3: 否 | F3: 氘灯 | G3: 1 | H3: 其它 | I3: T% | J3: 1 | K3: 慢速 | L3: 1 | M3: 0.02 | N3: 2 | O3: 1 | P3: 0.5 | Q3: 1 | R3: 0.5
A4: 低压汞灯B段 | B4: 365.0,435.8,546.1 | C4: 365.0,435.8,546.1 | F4: 汞灯 | G4: 2 | I4: Es | J4: 2 | K4: 中速 | L4: 2 | M4: 0.1 | N4: 3 | O4: 2 | P4: 1.0 | Q4: 2 | R4: 1
A5: 镨钕滤光片 | B5: 739.2,,807.4 | C5: 739.2,,807.4 | I5: Er | J5: 3 | K5: 快速 | L5: 3 | M5: 0.2 | N5: 4 | P5: 2.0 | Q5: 3 | R5: 2
A6: 10%中性滤光片 | B6: 635.0,546.0,440.0 | I6: R% | J6: 4 | K6: 极快 | L6: 4 | M6: 0.5 | N6: 5 | P6: 5.0 | Q6: 4
A7: 20%中性滤光片 | B7: 635.0,546.0,440.1 | M7: 1 | Q7: 5
A8: 30%中性滤光片 | B8: 635.0,546.0,440.2 | M8: 2
A9: 重铬酸钾标准物质 | B9: 350313257235 | C9: 22.9,51.3,13.7,18.2 | M9: 5
A10: 碘化钠溶液 | B10: 220
A11: 亚硝酸钠溶液 | B11: 340360

Sheet 测量结果表
A1: 项目编号 | B1: 仪器ID | C1: 标准值 | D1: 测量值（nm） | E1: 平均值 | F1: 误差值 | G1: 重复性 | H1: 检验员 | I1: 检验日期 | J1: 复核员 | K1: 检验地点 | L1: 温度 | M1: 湿度 | N1: 判定结果 | O1: 其他 | P1: 子项目编号-与检测项信息对应的
A2: 1001 | B2: =MID(CELL("filename"),FIND("[",CELL("filename"),1)+1,FIND(".",CELL("filename"),1)-FIND("[",CELL("filename"),1)-1) -> T600T700-VariableSlit | D2: =波长拟合!$F2 -> 0 | E2: =波长拟合!#REF! -> #REF! | F2: =波长拟合!#REF! -> #REF! | G2: =波长拟合!#REF! -> #REF! | H2: =Report!$F$5 -> 0 | I2: =NOW() -> 45665.617 | J2: =Report!$N$5 -> 0 | L2: =Report!$C$6 -> 0 | M2: =Report!$H$6 -> 0 | N2: =波长拟合!#REF! -> #REF! | P2: 1001
A3: 1002 | B3: =MID(CELL("filename"),FIND("[",CELL("filename"),1)+1,FIND(".",CELL("filename"),1)-FIND("[",CELL("filename"),1)-1) -> T600T700-VariableSlit | D3: =波长拟合!$F3 -> 0 | E3: =波长拟合!#REF! -> #REF! | F3: =波长拟合!#REF! -> #REF! | G3: =波长拟合!#REF! -> #REF! | H3: =Report!$F$5 -> 0 | I3: =NOW() -> 45665.617 | J3: =Report!$N$5 -> 0 | L3: =Report!$C$6 -> 0 | M3: =Report!$H$6 -> 0 | N3: =波长拟合!#REF! -> #REF! | P3: 1002
A4: 1003 | B4: =MID(CELL("filename"),FIND("[",CELL("filename"),1)+1,FIND(".",CELL("filename"),1)-FIND("[",CELL("filename"),1)-1) -> T600T700-VariableSlit | D4: =波长拟合!$F4 -> 0 | E4: =波长拟合!#REF! -> #REF! | F4: =波长拟合!#REF! -> #REF! | G4: =波长拟合!#REF! -> #REF! | H4: =Report!$F$5 -> 0 | I4: =NOW() -> 45665.617 | J4: =Report!$N$5 -> 0 | L4: =Report!$C$6 -> 0 | M4: =Report!$H$6 -> 0 | N4: =波长拟合!#REF! -> #REF! | P4: 1003
A5: 1008 | B5: =MID(CELL("filename"),FIND("[",CELL("filename"),1)+1,FIND(".",CELL("filename"),1)-FIND("[",CELL("filename"),1)-1) -> T600T700-VariableSlit | D5: =波长拟合!$F5 -> 0 | E5: =波长拟合!#REF! -> #REF! | F5: =波长拟合!#REF! -> #REF! | G5: =波长拟合!#REF! -> #REF! | H5: =Report!$F$5 -> 0 | I5: =NOW() -> 45665.617 | J5: =Report!$N$5 -> 0 | L5: =Report!$C$6 -> 0 | M5: =Report!$H$6 -> 0 | N5: =波长拟合!#REF! -> #REF! | P5: 1004
A6: 1009 | B6: =MID(CELL("filename"),FIND("[",CELL("filename"),1)+1,FIND(".",CELL("filename"),1)-FIND("[",CELL("filename"),1)-1) -> T600T700-VariableSlit | D6: =波长拟合!$F6 -> 0 | E6: =波长拟合!#REF! -> #REF! | F6: =波长拟合!#REF! -> #REF! | G6: =波长拟合!#REF! -> #REF! | H6: =Report!$F$5 -> 0 | I6: =NOW() -> 45665.617 | J6: =Report!$N$5 -> 0 | L6: =Report!$C$6 -> 0 | M6: =Report!$H$6 -> 0 | N6: =波长拟合!#REF! -> #REF! | P6: 1004
A7: 1010 | B7: =MID(CELL("filename"),FIND("[",CELL("filename"),1)+1,FIND(".",CELL("filename"),1)-FIND("[",CELL("filename"),1)-1) -> T600T700-VariableSlit | D7: =波长拟合!$F7 -> 0 | E7: =波长拟合!#REF! -> #REF! | F7: =波长拟合!#REF! -> #REF! | G7: =波长拟合!#REF! -> #REF! | H7: =Report!$F$5 -> 0 | I7: =NOW() -> 45665.617 | J7: =Report!$N$5 -> 0 | L7: =Report!$C$6 -> 0 | M7: =Report!$H$6 -> 0 | N7: =波长拟合!#REF! -> #REF! | P7: 1004
A8: 1011 | B8: =MID(CELL("filename"),FIND("[",CELL("filename"),1)+1,FIND(".",CELL("filename"),1)-FIND("[",CELL("filename"),1)-1) -> T600T700-VariableSlit | D8: =波长拟合!$F8 -> 0 | E8: =波长拟合!#REF! -> #REF! | F8: =波长拟合!#REF! -> #REF! | G8: =波长拟合!#REF! -> #REF! | H8: =Report!$F$5 -> 0 | I8: =NOW() -> 45665.617 | J8: =Report!$N$5 -> 0 | L8: =Report!$C$6 -> 0 | M8: =Report!$H$6 -> 0 | N8: =波长拟合!#REF! -> #REF! | P8: 1004
A9: 1012 | B9: =MID(CELL("filename"),FIND("[",CELL("filename"),1)+1,FIND(".",CELL("filename"),1)-FIND("[",CELL("filename"),1)-1) -> T600T700-VariableSlit | D9: =波长拟合!$F9 -> 0 | E9: =波长拟合!#REF! -> #REF! | F9: =波长拟合!#REF! -> #REF! | G9: =波长拟合!#REF! -> #REF! | H9: =Report!$F$5 -> 0 | I9: =NOW() -> 45665.617 | J9: =Report!$N$5 -> 0 | L9: =Report!$C$6 -> 0 | M9: =Report!$H$6 -> 0 | N9: =波长拟合!#REF! -> #REF! | P9: 1004
A10: 1013 | B10: =MID(CELL("filename"),FIND("[",CELL("filename"),1)+1,FIND(".",CELL("filename"),1)-FIND("[",CELL("filename"),1)-1) -> T600T700-VariableSlit | D10: =波长拟合!$F10 -> 0 | E10: =波长拟合!#REF! -> #REF! | F10: =波长拟合!#REF! -> #REF! | G10: =波长拟合!#REF! -> #REF! | H10: =Report!$F$5 -> 0 | I10: =NOW() -> 45665.617 | J10: =Report!$N$5 -> 0 | L10: =Report!$C$6 -> 0 | M10: =Report!$H$6 -> 0 | N10: =波长拟合!#REF! -> #REF! | P10: 1004
A11: 2001 | B11: =MID(CELL("filename"),FIND("[",CELL("filename"),1)+1,FIND(".",CELL("filename"),1)-FIND("[",CELL("filename"),1)-1) -> T600T700-VariableSlit | C11: =#REF! -> #REF! | D11: =#REF!&";"&#REF!&";"&#REF! -> #REF! | E11: =#REF! -> #REF! | F11: =#REF! -> #REF! | G11: =#REF! -> #REF! | H11: =Report!$F$5 -> 0 | I11: =NOW() -> 45665.617 | J11: =Report!$N$5 -> 0 | L11: =Report!$C$6 -> 0 | M11: =Report!$H$6 -> 0 | N11: =#REF! -> #REF! | P11: 2001
A12: 2002 | B12: =MID(CELL("filename"),FIND("[",CELL("filename"),1)+1,FIND(".",CELL("filename"),1)-FIND("[",CELL("filename"),1)-1) -> T600T700-VariableSlit | C12: =#REF! -> #REF! | D12: =#REF!&";"&#REF!&";"&#REF! -> #REF! | E12: =#REF! -> #REF! | F12: =#REF! -> #REF! | G12: =#REF! -> #REF! | H12: =Report!$F$5 -> 0 | I12: =NOW() -> 45665.617 | J12: =Report!$N$5 -> 0 | L12: =Report!$C$6 -> 0 | M12: =Report!$H$6 -> 0 | N12: =#REF! -> #REF! | P12: 2001
A13: 2003 | B13: =MID(CELL("filename"),FIND("[",CELL("filename"),1)+1,FIND(".",CELL("filename"),1)-FIND("[",CELL("filename"),1)-1) -> T600T700-VariableSlit | C13: =#REF! -> #REF! | D13: =#REF!&";"&#REF!&";"&#REF! -> #REF! | E13: =#REF! -> #REF! | F13: =#REF! -> #REF! | G13: =#REF! -> #REF! | H13: =Report!$F$5 -> 0 | I13: =NOW() -> 45665.617 | J13: =Report!$N$5 -> 0 | L13: =Report!$C$6 -> 0 | M13: =Report!$H$6 -> 0 | N13: =#REF! -> #REF! | P13: 2001
A14: 2004 | B14: =MID(CELL("filename"),FIND("[",CELL("filename"),1)+1,FIND(".",CELL("filename"),1)-FIND("[",CELL("filename"),1)-1) -> T600T700-VariableSlit | C14: =#REF! -> #REF! | D14: =#REF!&";"&#REF!&";"&#REF! -> #REF! | E14: =#REF! -> #REF! | F14: =#REF! -> #REF! | G14: =#REF! -> #REF! | H14: =Report!$F$5 -> 0 | I14: =NOW() -> 45665.617 | J14: =Report!$N$5 -> 0 | L14: =Report!$C$6 -> 0 | M14: =Report!$H$6 -> 0 | N14: =#REF! -> #REF! | P14: 2001
A15: 2005 | B15: =MID(CELL("filename"),FIND("[",CELL("filename"),1)+1,FIND(".",CELL("filename"),1)-FIND("[",CELL("filename"),1)-1) -> T600T700-VariableSlit | C15: =#REF! -> #REF! | D15: =#REF!&";"&#REF!&";"&#REF! -> #REF! | E15: =#REF! -> #REF! | F15: =#REF! -> #REF! | G15: =#REF! -> #REF! | H15: =Report!$F$5 -> 0 | I15: =NOW() -> 45665.617 | J15: =Report!$N$5 -> 0 | L15: =Report!$C$6 -> 0 | M15: =Report!$H$6 -> 0 | N15: =#REF! -> #REF! | P15: 2002
A16: 2006 | B16: =MID(CELL("filename"),FIND("[",CELL("filename"),1)+1,FIND(".",CELL("filename"),1)-FIND("[",CELL("filename"),1)-1) -> T600T700-VariableSlit | C16: =#REF! -> #REF! | D16: =#REF!&";"&#REF!&";"&#REF! -> #REF! | E16: =#REF! -> #REF! | F16: =#REF! -> #REF! | G16: =#REF! -> #REF! | H16: =Report!$F$5 -> 0 | I16: =NOW() -> 45665.617 | J16: =Report!$N$5 -> 0 | L16: =Report!$C$6 -> 0 | M16: =Report!$H$6 -> 0 | N16: =#REF! -> #REF! | P16: 2002
A17: 2007 | B17: =MID(CELL("filename"),FIND("[",CELL("filename"),1)+1,FIND(".",CELL("filename"),1)-FIND("[",CELL("filename"),1)-1) -> T600T700-VariableSlit | C17: =#REF! -> #REF! | D17: =#REF!&";"&#REF!&";"&#REF! -> #REF! | E17: =#REF! -> #REF! | F17: =#REF! -> #REF! | G17: =#REF! -> #REF! | H17: =Report!$F$5 -> 0 | I17: =NOW() -> 45665.617 | J17: =Report!$N$5 -> 0 | L17: =Report!$C$6 -> 0 | M17: =Report!$H$6 -> 0 | N17: =#REF! -> #REF! | P17: 2002
A18: 2008 | B18: =MID(CELL("filename"),FIND("[",CELL("filename"),1)+1,FIND(".",CELL("filename"),1)-FIND("[",CELL("filename"),1)-1) -> T600T700-VariableSlit | C18: =#REF! -> #REF! | D18: =#REF!&";"&#REF!&";"&#REF! -> #REF! | E18: =#REF! -> #REF! | F18: =#REF! -> #REF! | G18: =#REF! -> #REF! | H18: =Report!$F$5 -> 0 | I18: =NOW() -> 45665.617 | J18: =Report!$N$5 -> 0 | L18: =Report!$C$6 -> 0 | M18: =Report!$H$6 -> 0 | N18: =#REF! -> #REF! | P18: 2003
A19: 2009 | B19: =MID(CELL("filename"),FIND("[",CELL("filename"),1)+1,FIND(".",CELL("filename"),1)-FIND("[",CELL("filename"),1)-1) -> T600T700-VariableSlit | C19: =#REF! -> #REF! | D19: =#REF!&";"&#REF!&";"&#REF! -> #REF! | E19: =#REF! -> #REF! | F19: =#REF! -> #REF! | G19: =#REF! -> #REF! | H19: =Report!$F$5 -> 0 | I19: =NOW() -> 45665.617 | J19: =Report!$N$5 -> 0 | L19: =Report!$C$6 -> 0 | M19: =Report!$H$6 -> 0 | N19: =#REF! -> #REF! | P19: 2003
A20: 2010 | B20: =MID(CELL("filename"),FIND("[",CELL("filename"),1)+1,FIND(".",CELL("filename"),1)-FIND("[",CELL("filename"),1)-1) -> T600T700-VariableSlit | C20: =#REF! -> #REF! | D20: =#REF!&";"&#REF!&";"&#REF! -> #REF! | E20: =#REF! -> #REF! | F20: =#REF! -> #REF! | G20: =#REF! -> #REF! | H20: =Report!$F$5 -> 0 | I20: =NOW() -> 45665.617 | J20: =Report!$N$5 -> 0 | L20: =Report!$C$6 -> 0 | M20: =Report!$H$6 -> 0 | N20: =#REF! -> #REF! | P20: 2003
A21: 2011 | B21: =MID(CELL("filename"),FIND("[",CELL("filename"),1)+1,FIND(".",CELL("filename"),1)-FIND("[",CELL("filename"),1)-1) -> T600T700-VariableSlit | C21: =#REF! -> #REF! | D21: =#REF!&";"&#REF!&";"&#REF! -> #REF! | E21: =#REF! -> #REF! | F21: =#REF! -> #REF! | G21: =#REF! -> #REF! | H21: =Report!$F$5 -> 0 | I21: =NOW() -> 45665.617 | J21: =Report!$N$5 -> 0 | L21: =Report!$C$6 -> 0 | M21: =Report!$H$6 -> 0 | N21: =#REF! -> #REF! | P21: 2004
A22: 2012 | B22: =MID(CELL("filename"),FIND("[",CELL("filename"),1)+1,FIND(".",CELL("filename"),1)-FIND("[",CELL("filename"),1)-1) -> T600T700-VariableSlit | C22: =#REF! -> #REF! | D22: =#REF!&";"&#REF!&";"&#REF! -> #REF! | E22: =#REF! -> #REF! | F22: =#REF! -> #REF! | G22: =#REF! -> #REF! | H22: =Report!$F$5 -> 0 | I22: =NOW() -> 45665.617 | J22: =Report!$N$5 -> 0 | L22: =Report!$C$6 -> 0 | M22: =Report!$H$6 -> 0 | N22: =#REF! -> #REF! | P22: 2004
A23: 2013 | B23: =MID(CELL("filename"),FIND("[",CELL("filename"),1)+1,FIND(".",CELL("filename"),1)-FIND("[",CELL("filename"),1)-1) -> T600T700-VariableSlit | C23: =#REF! -> #REF! | D23: =#REF!&";"&#REF!&";"&#REF! -> #REF! | E23: =#REF! -> #REF! | F23: =#REF! -> #REF! | G23: =#REF! -> #REF! | H23: =Report!$F$5 -> 0 | I23: =NOW() -> 45665.617 | J23: =Report!$N$5 -> 0 | L23: =Report!$C$6 -> 0 | M23: =Report!$H$6 -> 0 | N23: =#REF! -> #REF! | P23: 2004
A24: 3001 | B24: =MID(CELL("filename"),FIND("[",CELL("filename"),1)+1,FIND(".",CELL("filename"),1)-FIND("[",CELL("filename"),1)-1) -> T600T700-VariableSlit | C24: =#REF! -> #REF! | D24: =#REF!&";"&#REF!&";"&#REF! -> #REF! | H24: =Report!$F$5 -> 0 | I24: =NOW() -> 45665.617 | J24: =Report!$N$5 -> 0 | L24: =Report!$C$6 -> 0 | M24: =Report!$H$6 -> 0 | N24: =#REF! -> #REF! | P24: 3001
A25: 3002 | B25: =MID(CELL("filename"),FIND("[",CELL("filename"),1)+1,FIND(".",CELL("filename"),1)-FIND("[",CELL("filename"),1)-1) -> T600T700-VariableSlit | C25: =#REF! -> #REF! | D25: =#REF!&";"&#REF!&";"&#REF! -> #REF! | H25: =Report!$F$5 -> 0 | I25: =NOW() -> 45665.617 | J25: =Report!$N$5 -> 0 | L25: =Report!$C$6 -> 0 | M25: =Report!$H$6 -> 0 | N25: =#REF! -> #REF! | P25: 3002
A26: 4001 | B26: =MID(CELL("filename"),FIND("[",CELL("filename"),1)+1,FIND(".",CELL("filename"),1)-FIND("[",CELL("filename"),1)-1) -> T600T700-VariableSlit | D26: =样品池重复性!$B$2 -> 0 | H26: =Report!$F$5 -> 0 | I26: =NOW() -> 45665.617 | J26: =Report!$N$5 -> 0 | L26: =Report!$C$6 -> 0 | M26: =Report!$H$6 -> 0 | N26: =样品池重复性!#REF! -> #REF! | P26: 4001
A27: 5001 | B27: =MID(CELL("filename"),FIND("[",CELL("filename"),1)+1,FIND(".",CELL("filename"),1)-FIND("[",CELL("filename"),1)-1) -> T600T700-VariableSlit | D27: =能量扫描!$B$3 -> 656.1 | H27: =Report!$F$5 -> 0 | I27: =NOW() -> 45665.617 | J27: =Report!$N$5 -> 0 | L27: =Report!$C$6 -> 0 | M27: =Report!$H$6 -> 0 | N27: =能量扫描!#REF! -> #REF! | P27: 5001
A28: 6002 | B28: =MID(CELL("filename"),FIND("[",CELL("filename"),1)+1,FIND(".",CELL("filename"),1)-FIND("[",CELL("filename"),1)-1) -> T600T700-VariableSlit | C28: =#REF! -> #REF! | D28: =#REF! -> #REF! | H28: =Report!$F$5 -> 0 | I28: =NOW() -> 45665.617 | J28: =Report!$N$5 -> 0 | L28: =Report!$C$6 -> 0 | M28: =Report!$H$6 -> 0 | N28: =#REF! -> #REF! | P28: 6001
A29: 7001 | B29: =MID(CELL("filename"),FIND("[",CELL("filename"),1)+1,FIND(".",CELL("filename"),1)-FIND("[",CELL("filename"),1)-1) -> T600T700-VariableSlit | C29: =#REF! -> #REF! | D29: =#REF! -> #REF! | H29: =Report!$F$5 -> 0 | I29: =NOW() -> 45665.617 | J29: =Report!$N$5 -> 0 | L29: =Report!$C$6 -> 0 | M29: =Report!$H$6 -> 0 | N29: =#REF! -> #REF! | P29: 7001
A30: 7002 | B30: =MID(CELL("filename"),FIND("[",CELL("filename"),1)+1,FIND(".",CELL("filename"),1)-FIND("[",CELL("filename"),1)-1) -> T600T700-VariableSlit | C30: =#REF! -> #REF! | D30: =#REF! -> #REF! | H30: =Report!$F$5 -> 0 | I30: =NOW() -> 45665.617 | J30: =Report!$N$5 -> 0 | L30: =Report!$C$6 -> 0 | M30: =Report!$H$6 -> 0 | N30: =#REF! -> #REF! | P30: 7002
A31: 7003 | B31: =MID(CELL("filename"),FIND("[",CELL("filename"),1)+1,FIND(".",CELL("filename"),1)-FIND("[",CELL("filename"),1)-1) -> T600T700-VariableSlit | C31: =#REF! -> #REF! | D31: =#REF! -> #REF! | H31: =Report!$F$5 -> 0 | I31: =NOW() -> 45665.617 | J31: =Report!$N$5 -> 0 | L31: =Report!$C$6 -> 0 | M31: =Report!$H$6 -> 0 | N31: =#REF! -> #REF! | P31: 7003
A32: 7004 | B32: =MID(CELL("filename"),FIND("[",CELL("filename"),1)+1,FIND(".",CELL("filename"),1)-FIND("[",CELL("filename"),1)-1) -> T600T700-VariableSlit | C32: =#REF! -> #REF! | D32: =#REF! -> #REF! | H32: =Report!$F$5 -> 0 | I32: =NOW() -> 45665.617 | J32: =Report!$N$5 -> 0 | L32: =Report!$C$6 -> 0 | M32: =Report!$H$6 -> 0 | N32: =#REF! -> #REF! | P32: 7004
A33: 8001 | B33: =MID(CELL("filename"),FIND("[",CELL("filename"),1)+1,FIND(".",CELL("filename"),1)-FIND("[",CELL("filename"),1)-1) -> T600T700-VariableSlit | C33: =#REF! -> #REF! | D33: =#REF! -> #REF! | H33: =Report!$F$5 -> 0 | I33: =NOW() -> 45665.617 | J33: =Report!$N$5 -> 0 | L33: =Report!$C$6 -> 0 | M33: =Report!$H$6 -> 0 | N33: =#REF! -> #REF! | P33: 8001
A34: 8002 | B34: =MID(CELL("filename"),FIND("[",CELL("filename"),1)+1,FIND(".",CELL("filename"),1)-FIND("[",CELL("filename"),1)-1) -> T600T700-VariableSlit | C34: =#REF! -> #REF! | D34: =#REF! -> #REF! | H34: =Report!$F$5 -> 0 | I34: =NOW() -> 45665.617 | J34: =Report!$N$5 -> 0 | L34: =Report!$C$6 -> 0 | M34: =Report!$H$6 -> 0 | N34: =#REF! -> #REF! | P34: 8002
A35: 8003 | B35: =MID(CELL("filename"),FIND("[",CELL("filename"),1)+1,FIND(".",CELL("filename"),1)-FIND("[",CELL("filename"),1)-1) -> T600T700-VariableSlit | C35: =#REF! -> #REF! | D35: =#REF! -> #REF! | H35: =Report!$F$5 -> 0 | I35: =NOW() -> 45665.617 | J35: =Report!$N$5 -> 0 | L35: =Report!$C$6 -> 0 | M35: =Report!$H$6 -> 0 | N35: =#REF! -> #REF! | P35: 8003
A36: 8004 | B36: =MID(CELL("filename"),FIND("[",CELL("filename"),1)+1,FIND(".",CELL("filename"),1)-FIND("[",CELL("filename"),1)-1) -> T600T700-VariableSlit | C36: =#REF! -> #REF! | D36: =#REF! -> #REF! | H36: =Report!$F$5 -> 0 | I36: =NOW() -> 45665.617 | J36: =Report!$N$5 -> 0 | L36: =Report!$C$6 -> 0 | M36: =Report!$H$6 -> 0 | N36: =#REF! -> #REF! | P36: 8004
A37: 9001 | B37: =MID(CELL("filename"),FIND("[",CELL("filename"),1)+1,FIND(".",CELL("filename"),1)-FIND("[",CELL("filename"),1)-1) -> T600T700-VariableSlit | C37: =#REF! -> #REF! | D37: =#REF! -> #REF! | H37: =Report!$F$5 -> 0 | I37: =NOW() -> 45665.617 | J37: =Report!$N$5 -> 0 | L37: =Report!$C$6 -> 0 | M37: =Report!$H$6 -> 0 | N37: =#REF! -> #REF! | P37: 9001

Sheet 管理表
A1: 检验项目
A2: 产品型号 | B2: 父项目编号 | C2: 父项目名称 | D2: 子项目编号 | E2: 子项目名称 | F2: 特征值 | G2: 可允许误差范围 | H2: 波长重复性
A3: T700S | B3: 900 | C3: 样品池重复性 | D3: 901 | E3: 样品池重复性检测 | F3: 546
A4: T700S | B4: 1000 | C4: 波长示值误差与重复性校验 | D4: 1001 | E4: 氘灯 | F4: 656.1 | G4: 0.1 | H4: 0.1
A5: T700S | B5: 1000 | C5: 波长示值误差与重复性校验 | D5: 1002 | E5: 氘灯 | F5: 486 | G5: 0.3 | H5: 0.1
A6: T700S | B6: 1000 | C6: 波长示值误差与重复性校验 | D6: 1003 | E6: 镨钕滤光片 | F6: 807.4 | G6: 0.3 | H6: 0.1
A7: T700S | B7: 1000 | C7: 波长示值误差与重复性校验 | D7: 1008 | E7: 钬溶液 | F7: 640.79 | G7: 0.3 | H7: 0.1
A8: T700S | B8: 1000 | C8: 波长示值误差与重复性校验 | D8: 1009 | E8: 钬溶液 | F8: 536.86 | G8: 0.3 | H8: 0.1
A9: T700S | B9: 1000 | C9: 波长示值误差与重复性校验 | D9: 1010 | E9: 钬溶液 | F9: 416.57 | G9: 0.3 | H9: 0.1
A10: T700S | B10: 1000 | C10: 波长示值误差与重复性校验 | D10: 1011 | E10: 钬溶液 | F10: 361.12 | G10: 0.3 | H10: 0.1
A11: T700S | B11: 1000 | C11: 波长示值误差与重复性校验 | D11: 1012 | E11: 钬溶液 | F11: 287.52 | G11: 0.3 | H11: 0.1
A12: T700S | B12: 1000 | C12: 波长示值误差与重复性校验 | D12: 1013 | E12: 钬溶液 | F12: 241.12 | G12: 0.3 | H12: 0.1
A13: T700S | B13: 2000 | C13: 透射比示值误差与重复性校验 | D13: 2001 | E13: 紫外分光光度计标准物质GBW(E)130066 | F13: 350nm | G13: 0.3 | H13: 0.1
A14: T700S | B14: 2000 | C14: 透射比示值误差与重复性校验 | D14: 2002 | E14: 紫外分光光度计标准物质GBW(E)130066 | F14: 313nm | G14: 0.3 | H14: 0.1
A15: T700S | B15: 2000 | C15: 透射比示值误差与重复性校验 | D15: 2003 | E15: 紫外分光光度计标准物质GBW(E)130066 | F15: 257nm | G15: 0.3 | H15: 0.1
A16: T700S | B16: 2000 | C16: 透射比示值误差与重复性校验 | D16: 2004 | E16: 紫外分光光度计标准物质GBW(E)130066 | F16: 235nm | G16: 0.3 | H16: 0.1
A17: T700S | B17: 2000 | C17: 透射比示值误差与重复性校验 | D17: 2005 | E17: 10%中性滤光片 | F17: 635nm | G17: 0.3 | H17: 0.1
... A25: T700S | B25: 2000 | C25: 透射比示值误差与重复性校验 | D25: 2013 | E25: 30%中性滤光片 | F25: 440nm | G25: 0.3 | H25: 0.1
A26: T700S | B26: 3000 | C26: 杂散光校验 | D26: 3001 | E26: 碘化钠标准溶液 | F26: 220nm | G26: 0.01
A27: T700S | B27: 3000 | C27: 杂散光校验 | D27: 3002 | E27: 亚硝酸钠标准溶液 | F27: 360nm | G27: 0.02
A28: T700S | B28: 4000 | C28: 基线平直度检验 | D28: 4001 | E28: 基线平直度 | G28: 0.0005
A29: T700S | B29: 5000 | C29: 基线暗噪声检验 | D29: 5001 | E29: 基线暗噪声 | G29: 0.1
A30: T700S | B30: 6000 | C30: 光谱带宽与仪器最小光谱带宽 | D30: 6002 | E30: 氘灯2.0 | F30: 656.1 | G30: 20
A31: T700S | B31: 7000 | C31: 噪声检验 | D31: 7001 | E31: 500nm100%噪声 | F31: 500 | G31: 0.05
A32: T700S | B32: 7000 | C32: 噪声检验 | D32: 7002 | E32: 500nm0%噪声 | F32: 500 | G32: 0.005
A33: T700S | B33: 7000 | C33: 噪声检验 | D33: 7003 | E33: 250nm100%噪声 | F33: 250 | G33: 0.05
A34: T700S | B34: 7000 | C34: 噪声检验 | D34: 7004 | E34: 250nm0%噪声 | F34: 250 | G34: 0.005
A35: T700S | B35: 8000 | C35: 波长边缘噪声 | D35: 8001 | E35: 1090nm100%噪声 | F35: 1090 | G35: 0.1
A36: T700S | B36: 8000 | C36: 波长边缘噪声 | D36: 8002 | E36: 1090nm0%噪声 | F36: 1090 | G36: 0.02
A37: T700S | B37: 8000 | C37: 波长边缘噪声 | D37: 8003 | E37: 200nm100%噪声 | F37: 200 | G37: 0.1
A38: T700S | B38: 8000 | C38: 波长边缘噪声 | D38: 8004 | E38: 200nm0%噪声 | F38: 200 | G38: 0.02
A39: T700S | B39: 9000 | C39: 漂移检验 | D39: 9001 | E39: 漂移检验 | F39: 500nm | G39: 0.1

Sheet 对应信息
A1: 产品编号 | B1: 产品型号 | D1: 父项目名称 | E1: 父项目编号
A2: U1601 | B2: T600B | D2: 波长示值误差与重复性校验 | E2: 1000
A3: U1602 | B3: T600A | D3: 透射比示值误差与重复性校验 | E3: 2000
A4: U1603 | B4: T600S | D4: 杂散光校验 | E4: 3000
A5: U1604 | B5: T600AS | D5: 基线平直度检验 | E5: 4000
A6: U1701 | B6: T700B | D6: 基线暗噪声检验 | E6: 5000
A7: U1702 | B7: T700A | D7: 光谱带宽与仪器最小光谱带宽 | E7: 6000
A8: U1703 | B8: T700S | D8: 噪声检验 | E8: 7000
A9: U1704 | B9: T700AS | D9: 波长边缘噪声 | E9: 8000
D10: 漂移检验 | E10: 9000

Sheet 检测项信息
A1: 检测类别 | B1: 项目名称 | C1: 提示 | D1: 方法信息 | E1: 测量信息 | F1: 重复次数 | G1: 重复时间间隔 | H1: 特征值 | I1: 分析方法 | J1: 分析方法 | K1: 灯状态 | L1: 光度模式 | M1: 扫描速度 | N1: 起始波长 | O1: 终止波长 | P1: 扫描间隔 | Q1: 增益 | R1: 光谱带宽 | S1: 时间间隔 | T1: 扫描个数 | U1: 响应时间 | V1: 是否为光谱扫描 | W1: 暗电流物质 | X1: 校零物质 | Y1: 测量物质 | Z1: 父项目编号 | AA1: 子项目编号 | AB1: 标准值
A2: 样品池重复性 | B2: 样品池重复性检测 | D2: =IF(L2="","",字段对应!$B$10&"="&VLOOKUP(L2,基础信息!$I$2:$J$6,2,0)&";")&IF(M2="","",字段对应!$B$11&"="&VLOOKUP(M2,基础信息!$K$2:$L$6,2,0)&";")&IF(N2="","",字段对应!$C$2&"="&N2&","&O2&","&P2&";")&IF(Q2="","",字段对应!$B$13&"="&Q2&";")&IF(R2="","",字段对应!$B$14&"="&R2&";")&IF(U2="","",字段对应!$B$22&"="&U2&";")&IF(K2="","",字段对应!$B$21&"="&VLOOKUP(K2,基础信息!$F$2:$G$4,2,0)) -> PhotoMode=1;ScanSpeed=2;WlRange=660,650,0.1;Slit1=2.0;LampPos=1 | E2: =IF(W2="","",检测项信息!W2&":"&字段对应!$B$16&"|")&IF(X2="","",X2&":"&IF(V2="是",字段对应!$C$17,字段对应!$B$17&";"&IF(H2="","",字段对应!$B$15&"="&检测项信息!H2))&"|")&IF(Y2="",":",Y2&":")&IF(V2="是",字段对应!$C$18,字段对应!$B$18&";"&IF(H2="","",字段对应!$B$15&"="&检测项信息!H2)&IF(AND(T2="",S2=""),"",";"&字段对应!$B$20&"="&T2&";"&字段对应!$B$19&"="&S2)) -> 空气:Zero;Wl=546|空气:Measure;Wl=546 | F2: 1 | H2: 546 | I2: =VLOOKUP(J2,字段对应!$D$2:$E$8,2,0) -> Validation.ViewModel.DataStructure.FindMaxOffsetUVTestTool | J2: 最大最小值差 | K2: 氘灯 | L2: T% | M2: 中速 | N2: 660 | O2: 650 | P2: 0.1 | R2: 2.0 | V2: 否 | X2: 空气 | Y2: 空气 | Z2: =VLOOKUP(A2,对应信息!$D$2:$E$10,2,0) -> #N/A | AA2: =IF(Z1=Z2,AA1+1,Z2+1) -> #N/A | AB2: 2.0
A3: 波长拟合 | B3: 氘灯486.0 | D3: =IF(L3="","",字段对应!$B$10&"="&VLOOKUP(L3,基础信息!$I$2:$J$6,2,0)&";")&IF(M3="","",字段对应!$B$11&"="&VLOOKUP(M3,基础信息!$K$2:$L$6,2,0)&";")&IF(N3="","",字段对应!$C$2&"="&N3&","&O3&","&P3&";")&IF(Q3="","",字段对应!$B$13&"="&Q3&";")&IF(R3="","",字段对应!$B$14&"="&R3&";")&IF(U3="","",字段对应!$B$22&"="&U3&";")&IF(K3="","",字段对应!$B$21&"="&VLOOKUP(K3,基础信息!$F$2:$G$4,2,0)) -> PhotoMode=2;ScanSpeed=2;WlRange=490,480,0.1;Gain=4;Slit1=2.0;LampPos=1 | E3: =IF(W3="","",检测项信息!W3&":"&字段对应!$B$16&"|")&IF(X3="","",X3&":"&IF(V3="是",字段对应!$C$17,字段对应!$B$17&";"&IF(H3="","",字段对应!$B$15&"="&检测项信息!H3))&"|")&IF(Y3="",":",Y3&":")&IF(V3="是",字段对应!$C$18,字段对应!$B$18&";"&IF(H3="","",字段对应!$B$15&"="&检测项信息!H3)&IF(AND(T3="",S3=""),"",";"&字段对应!$B$20&"="&T3&";"&字段对应!$B$19&"="&S3)) -> 空气:Scan | F3: 1 | H3: 486 | I3: =VLOOKUP(J3,字段对应!$D$2:$E$8,2,0) -> Validation.ViewModel.DataStructure.FindPeakAndAverageUVTestTool | J3: 寻峰 | K3: 氘灯 | L3: Es | M3: 中速 | N3: 490 | O3: 480 | P3: 0.1 | Q3: 4 | R3: 2.0 | V3: 是 | Y3: 空气 | Z3: =VLOOKUP(A3,对应信息!$D$2:$E$10,2,0) -> #N/A | AA3: =IF(#REF!=Z3,#REF!+1,Z3+1) -> #REF!
A4: 波长拟合 | B4: 氘灯656.1 | D4: =IF(L4="","",字段对应!$B$10&"="&VLOOKUP(L4,基础信息!$I$2:$J$6,2,0)&";")&IF(M4="","",字段对应!$B$11&"="&VLOOKUP(M4,基础信息!$K$2:$L$6,2,0)&";")&IF(N4="","",字段对应!$C$2&"="&N4&","&O4&","&P4&";")&IF(Q4="","",字段对应!$B$13&"="&Q4&";")&IF(R4="","",字段对应!$B$14&"="&R4&";")&IF(U4="","",字段对应!$B$22&"="&U4&";")&IF(K4="","",字段对应!$B$21&"="&VLOOKUP(K4,基础信息!$F$2:$G$4,2,0)) -> PhotoMode=2;ScanSpeed=2;WlRange=660,650,0.1;Gain=4;Slit1=2.0;LampPos=1 | E4: =IF(W4="","",检测项信息!W4&":"&字段对应!$B$16&"|")&IF(X4="","",X4&":"&IF(V4="是",字段对应!$C$17,字段对应!$B$17&";"&IF(H4="","",字段对应!$B$15&"="&检测项信息!H4))&"|")&IF(Y4="",":",Y4&":")&IF(V4="是",字段对应!$C$18,字段对应!$B$18&";"&IF(H4="","",字段对应!$B$15&"="&检测项信息!H4)&IF(AND(T4="",S4=""),"",";"&字段对应!$B$20&"="&T4&";"&字段对应!$B$19&"="&S4)) -> 空气:Scan | F4: 1 | H4: 656.1 | I4: =VLOOKUP(J4,字段对应!$D$2:$E$8,2,0) -> Validation.ViewModel.DataStructure.FindPeakAndAverageUVTestTool | J4: 寻峰 | K4: 氘灯 | L4: Es | M4: 中速 | N4: 660 | O4: 650 | P4: 0.1 | Q4: 4 | R4: 2.0 | V4: 是 | Y4: 空气 | Z4: =VLOOKUP(A4,对应信息!$D$2:$E$10,2,0) -> #N/A | AA4: =IF(#REF!=Z4,#REF!+1,Z4+1) -> #REF!
A5: 波长拟合 | B5: 镨钕滤光片 | D5: =IF(L5="","",字段对应!$B$10&"="&VLOOKUP(L5,基础信息!$I$2:$J$6,2,0)&";")&IF(M5="","",字段对应!$B$11&"="&VLOOKUP(M5,基础信息!$K$2:$L$6,2,0)&";")&IF(N5="","",字段对应!$C$2&"="&N5&","&O5&","&P5&";")&IF(Q5="","",字段对应!$B$13&"="&Q5&";")&IF(R5="","",字段对应!$B$14&"="&R5&";")&IF(U5="","",字段对应!$B$22&"="&U5&";")&IF(K5="","",字段对应!$B$21&"="&VLOOKUP(K5,基础信息!$F$2:$G$4,2,0)) -> PhotoMode=0;ScanSpeed=2;WlRange=810,800,0.1;Slit1=2.0; | E5: =IF(W5="","",检测项信息!W5&":"&字段对应!$B$16&"|")&IF(X5="","",X5&":"&IF(V5="是",字段对应!$C$17,字段对应!$B$17&";"&IF(H5="","",字段对应!$B$15&"="&检测项信息!H5))&"|")&IF(Y5="",":",Y5&":")&IF(V5="是",字段对应!$C$18,字段对应!$B$18&";"&IF(H5="","",字段对应!$B$15&"="&检测项信息!H5)&IF(AND(T5="",S5=""),"",";"&字段对应!$B$20&"="&T5&";"&字段对应!$B$19&"="&S5)) -> 黑挡块:Dark|空气:BaseLine|镨钕滤光片:Scan | F5: 1 | H5: 807.4 | I5: =VLOOKUP(J5,字段对应!$D$2:$E$8,2,0) -> Validation.ViewModel.DataStructure.FindPeakAndAverageUVTestTool | J5: 寻峰 | L5: Abs | M5: 中速 | N5: 810 | O5: 800 | P5: 0.1 | R5: 2.0 | V5: 是 | W5: 黑挡块 | X5: 空气 | Y5: 镨钕滤光片 | Z5: =VLOOKUP(A5,对应信息!$D$2:$E$10,2,0) -> #N/A | AA5: =IF(Z12=Z5,AA12+1,Z5+1) -> #N/A
A6: 波长拟合 | B6: 钬溶液241.0 | D6: =IF(L6="","",字段对应!$B$10&"="&VLOOKUP(L6,基础信息!$I$2:$J$6,2,0)&";")&IF(M6="","",字段对应!$B$11&"="&VLOOKUP(M6,基础信息!$K$2:$L$6,2,0)&";")&IF(N6="","",字段对应!$C$2&"="&N6&","&O6&","&P6&";")&IF(Q6="","",字段对应!$B$13&"="&Q6&";")&IF(R6="","",字段对应!$B$14&"="&R6&";")&IF(U6="","",字段对应!$B$22&"="&U6&";")&IF(K6="","",字段对应!$B$21&"="&VLOOKUP(K6,基础信息!$F$2:$G$4,2,0)) -> PhotoMode=0;ScanSpeed=2;WlRange=245,235,0.1;Slit1=2.0; | E6: =IF(W6="","",检测项信息!W6&":"&字段对应!$B$16&"|")&IF(X6="","",X6&":"&IF(V6="是",字段对应!$C$17,字段对应!$B$17&";"&IF(H6="","",字段对应!$B$15&"="&检测项信息!H6))&"|")&IF(Y6="",":",Y6&":")&IF(V6="是",字段对应!$C$18,字段对应!$B$18&";"&IF(H6="","",字段对应!$B$15&"="&检测项信息!H6)&IF(AND(T6="",S6=""),"",";"&字段对应!$B$20&"="&T6&";"&字段对应!$B$19&"="&S6)) -> 黑挡块:Dark|空气:BaseLine|钬溶液:Scan | F6: 1 | H6: 241 | I6: =VLOOKUP(J6,字段对应!$D$2:$E$8,2,0) -> Validation.ViewModel.DataStructure.FindPeakAndAverageUVTestTool | J6: 寻峰 | L6: Abs | M6: 中速 | N6: 245 | O6: 235 | P6: 0.1 | R6: 2.0 | V6: 是 | W6: 黑挡块 | X6: 空气 | Y6: 钬溶液 | Z6: =VLOOKUP(A6,对应信息!$D$2:$E$10,2,0) -> #N/A | AA6: =IF(Z5=Z6,AA5+1,Z6+1) -> #N/A
A7: 波长拟合 | B7: 钬溶液361.0 | D7: =IF(L7="","",字段对应!$B$10&"="&VLOOKUP(L7,基础信息!$I$2:$J$6,2,0)&";")&IF(M7="","",字段对应!$B$11&"="&VLOOKUP(M7,基础信息!$K$2:$L$6,2,0)&";")&IF(N7="","",字段对应!$C$2&"="&N7&","&O7&","&P7&";")&IF(Q7="","",字段对应!$B$13&"="&Q7&";")&IF(R7="","",字段对应!$B$14&"="&R7&";")&IF(U7="","",字段对应!$B$22&"="&U7&";")&IF(K7="","",字段对应!$B$21&"="&VLOOKUP(K7,基础信息!$F$2:$G$4,2,0)) -> PhotoMode=0;ScanSpeed=2;WlRange=365,355,0.1;Slit1=2.0; | E7: =IF(W7="","",检测项信息!W7&":"&字段对应!$B$16&"|")&IF(X7="","",X7&":"&IF(V7="是",字段对应!$C$17,字段对应!$B$17&";"&IF(H7="","",字段对应!$B$15&"="&检测项信息!H7))&"|")&IF(Y7="",":",Y7&":")&IF(V7="是",字段对应!$C$18,字段对应!$B$18&";"&IF(H7="","",字段对应!$B$15&"="&检测项信息!H7)&IF(AND(T7="",S7=""),"",";"&字段对应!$B$20&"="&T7&";"&字段对应!$B$19&"="&S7)) -> 黑挡块:Dark|空气:BaseLine|钬溶液:Scan | F7: 1 | H7: 361 | I7: =VLOOKUP(J7,字段对应!$D$2:$E$8,2,0) -> Validation.ViewModel.DataStructure.FindPeakAndAverageUVTestTool | J7: 寻峰 | L7: Abs | M7: 中速 | N7: 365 | O7: 355 | P7: 0.1 | R7: 2.0 | V7: 是 | W7: 黑挡块 | X7: 空气 | Y7: 钬溶液 | Z7: =VLOOKUP(A7,对应信息!$D$2:$E$10,2,0) -> #N/A | AA7: =IF(Z6=Z7,AA6+1,Z7+1) -> #N/A
A8: 波长拟合 | B8: 钬溶液640.7 | D8: =IF(L8="","",字段对应!$B$10&"="&VLOOKUP(L8,基础信息!$I$2:$J$6,2,0)&";")&IF(M8="","",字段对应!$B$11&"="&VLOOKUP(M8,基础信息!$K$2:$L$6,2,0)&";")&IF(N8="","",字段对应!$C$2&"="&N8&","&O8&","&P8&";")&IF(Q8="","",字段对应!$B$13&"="&Q8&";")&IF(R8="","",字段对应!$B$14&"="&R8&";")&IF(U8="","",字段对应!$B$22&"="&U8&";")&IF(K8="","",字段对应!$B$21&"="&VLOOKUP(K8,基础信息!$F$2:$G$4,2,0)) -> PhotoMode=0;ScanSpeed=2;WlRange=645,635,0.1;Slit1=2.0; | E8: =IF(W8="","",检测项信息!W8&":"&字段对应!$B$16&"|")&IF(X8="","",X8&":"&IF(V8="是",字段对应!$C$17,字段对应!$B$17&";"&IF(H8="","",字段对应!$B$15&"="&检测项信息!H8))&"|")&IF(Y8="",":",Y8&":")&IF(V8="是",字段对应!$C$18,字段对应!$B$18&";"&IF(H8="","",字段对应!$B$15&"="&检测项信息!H8)&IF(AND(T8="",S8=""),"",";"&字段对应!$B$20&"="&T8&";"&字段对应!$B$19&"="&S8)) -> 黑挡块:Dark|空气:BaseLine|钬溶液:Scan | F8: 1 | H8: 640.7 | I8: =VLOOKUP(J8,字段对应!$D$2:$E$8,2,0) -> Validation.ViewModel.DataStructure.FindPeakAndAverageUVTestTool | J8: 寻峰 | L8: Abs | M8: 中速 | N8: 645 | O8: 635 | P8: 0.1 | R8: 2.0 | V8: 是 | W8: 黑挡块 | X8: 空气 | Y8: 钬溶液 | Z8: =VLOOKUP(A8,对应信息!$D$2:$E$10,2,0) -> #N/A | AA8: =IF(Z7=Z8,AA7+1,Z8+1) -> #N/A
A9: 波长拟合 | B9: 汞灯296.7 | D9: =IF(L9="","",字段对应!$B$10&"="&VLOOKUP(L9,基础信息!$I$2:$J$6,2,0)&";")&IF(M9="","",字段对应!$B$11&"="&VLOOKUP(M9,基础信息!$K$2:$L$6,2,0)&";")&IF(N9="","",字段对应!$C$2&"="&N9&","&O9&","&P9&";")&IF(Q9="","",字段对应!$B$13&"="&Q9&";")&IF(R9="","",字段对应!$B$14&"="&R9&";")&IF(U9="","",字段对应!$B$22&"="&U9&";")&IF(K9="","",字段对应!$B$21&"="&VLOOKUP(K9,基础信息!$F$2:$G$4,2,0)) -> PhotoMode=2;ScanSpeed=2;WlRange=300,290,0.1;Gain=3;Slit1=2.0;LampPos=2 | E9: =IF(W9="","",检测项信息!W9&":"&字段对应!$B$16&"|")&IF(X9="","",X9&":"&IF(V9="是",字段对应!$C$17,字段对应!$B$17&";"&IF(H9="","",字段对应!$B$15&"="&检测项信息!H9))&"|")&IF(Y9="",":",Y9&":")&IF(V9="是",字段对应!$C$18,字段对应!$B$18&";"&IF(H9="","",字段对应!$B$15&"="&检测项信息!H9)&IF(AND(T9="",S9=""),"",";"&字段对应!$B$20&"="&T9&";"&字段对应!$B$19&"="&S9)) -> 空气:Scan | F9: 1 | H9: 296.7 | I9: =VLOOKUP(J9,字段对应!$D$2:$E$8,2,0) -> Validation.ViewModel.DataStructure.FindPeakAndAverageUVTestTool | J9: 寻峰 | K9: 汞灯 | L9: Es | M9: 中速 | N9: 300 | O9: 290 | P9: 0.1 | Q9: 3 | R9: 2.0 | V9: 是 | Y9: 空气 | Z9: =VLOOKUP(A9,对应信息!$D$2:$E$10,2,0) -> #N/A | AA9: =IF(#REF!=Z9,#REF!+1,Z9+1) -> #REF!
A10: 波长拟合 | B10: 汞灯404.7 | D10: =IF(L10="","",字段对应!$B$10&"="&VLOOKUP(L10,基础信息!$I$2:$J$6,2,0)&";")&IF(M10="","",字段对应!$B$11&"="&VLOOKUP(M10,基础信息!$K$2:$L$6,2,0)&";")&IF(N10="","",字段对应!$C$2&"="&N10&","&O10&","&P10&";")&IF(Q10="","",字段对应!$B$13&"="&Q10&";")&IF(R10="","",字段对应!$B$14&"="&R10&";")&IF(U10="","",字段对应!$B$22&"="&U10&";")&IF(K10="","",字段对应!$B$21&"="&VLOOKUP(K10,基础信息!$F$2:$G$4,2,0)) -> PhotoMode=2;ScanSpeed=2;WlRange=410,400,0.1;Gain=3;Slit1=2.0;LampPos=2 | E10: =IF(W10="","",检测项信息!W10&":"&字段对应!$B$16&"|")&IF(X10="","",X10&":"&IF(V10="是",字段对应!$C$17,字段对应!$B$17&";"&IF(H10="","",字段对应!$B$15&"="&检测项信息!H10))&"|")&IF(Y10="",":",Y10&":")&IF(V10="是",字段对应!$C$18,字段对应!$B$18&";"&IF(H10="","",字段对应!$B$15&"="&检测项信息!H10)&IF(AND(T10="",S10=""),"",";"&字段对应!$B$20&"="&T10&";"&字段对应!$B$19&"="&S10)) -> 空气:Scan | F10: 1 | H10: 404.7 | I10: =VLOOKUP(J10,字段对应!$D$2:$E$8,2,0) -> Validation.ViewModel.DataStructure.FindPeakAndAverageUVTestTool | J10: 寻峰 | K10: 汞灯 | L10: Es | M10: 中速 | N10: 410 | O10: 400 | P10: 0.1 | Q10: 3 | R10: 2.0 | V10: 是 | Y10: 空气 | Z10: =VLOOKUP(A10,对应信息!$D$2:$E$10,2,0) -> #N/A | AA10: =IF(#REF!=Z10,#REF!+1,Z10+1) -> #REF!
A11: 波长拟合 | B11: 汞灯435.8 | D11: =IF(L11="","",字段对应!$B$10&"="&VLOOKUP(L11,基础信息!$I$2:$J$6,2,0)&";")&IF(M11="","",字段对应!$B$11&"="&VLOOKUP(M11,基础信息!$K$2:$L$6,2,0)&";")&IF(N11="","",字段对应!$C$2&"="&N11&","&O11&","&P11&";")&IF(Q11="","",字段对应!$B$13&"="&Q11&";")&IF(R11="","",字段对应!$B$14&"="&R11&";")&IF(U11="","",字段对应!$B$22&"="&U11&";")&IF(K11="","",字段对应!$B$21&"="&VLOOKUP(K11,基础信息!$F$2:$G$4,2,0)) -> PhotoMode=2;ScanSpeed=2;WlRange=440,430,0.1;Gain=3;Slit1=2.0;LampPos=2 | E11: =IF(W11="","",检测项信息!W11&":"&字段对应!$B$16&"|")&IF(X11="","",X11&":"&IF(V11="是",字段对应!$C$17,字段对应!$B$17&";"&IF(H11="","",字段对应!$B$15&"="&检测项信息!H11))&"|")&IF(Y11="",":",Y11&":")&IF(V11="是",字段对应!$C$18,字段对应!$B$18&";"&IF(H11="","",字段对应!$B$15&"="&检测项信息!H11)&IF(AND(T11="",S11=""),"",";"&字段对应!$B$20&"="&T11&";"&字段对应!$B$19&"="&S11)) -> 空气:Scan | F11: 1 | H11: 435.8 | I11: =VLOOKUP(J11,字段对应!$D$2:$E$8,2,0) -> Validation.ViewModel.DataStructure.FindPeakAndAverageUVTestTool | J11: 寻峰 | K11: 汞灯 | L11: Es | M11: 中速 | N11: 440 | O11: 430 | P11: 0.1 | Q11: 3 | R11: 2.0 | V11: 是 | Y11: 空气 | Z11: =VLOOKUP(A11,对应信息!$D$2:$E$10,2,0) -> #N/A | AA11: =IF(#REF!=Z11,#REF!+1,Z11+1) -> #REF!
A12: 波长拟合 | B12: 汞灯546.1 | D12: =IF(L12="","",字段对应!$B$10&"="&VLOOKUP(L12,基础信息!$I$2:$J$6,2,0)&";")&IF(M12="","",字段对应!$B$11&"="&VLOOKUP(M12,基础信息!$K$2:$L$6,2,0)&";")&IF(N12="","",字段对应!$C$2&"="&N12&","&O12&","&P12&";")&IF(Q12="","",字段对应!$B$13&"="&Q12&";")&IF(R12="","",字段对应!$B$14&"="&R12&";")&IF(U12="","",字段对应!$B$22&"="&U12&";")&IF(K12="","",字段对应!$B$21&"="&VLOOKUP(K12,基础信息!$F$2:$G$4,2,0)) -> PhotoMode=2;ScanSpeed=2;WlRange=550,540,0.1;Gain=3;Slit1=2.0;LampPos=2 | E12: =IF(W12="","",检测项信息!W12&":"&字段对应!$B$16&"|")&IF(X12="","",X12&":"&IF(V12="是",字段对应!$C$17,字段对应!$B$17&";"&IF(H12="","",字段对应!$B$15&"="&检测项信息!H12))&"|")&IF(Y12="",":",Y12&":")&IF(V12="是",字段对应!$C$18,字段对应!$B$18&";"&IF(H12="","",字段对应!$B$15&"="&检测项信息!H12)&IF(AND(T12="",S12=""),"",";"&字段对应!$B$20&"="&T12&";"&字段对应!$B$19&"="&S12)) -> 空气:Scan | F12: 1 | H12: 546.1 | I12: =VLOOKUP(J12,字段对应!$D$2:$E$8,2,0) -> Validation.ViewModel.DataStructure.FindPeakAndAverageUVTestTool | J12: 寻峰 | K12: 汞灯 | L12: Es | M12: 中速 | N12: 550 | O12: 540 | P12: 0.1 | Q12: 3 | R12: 2.0 | V12: 是 | Y12: 空气 | Z12: =VLOOKUP(A12,对应信息!$D$2:$E$10,2,0) -> #N/A | AA12: =IF(Z1=Z12,AA1+1,Z12+1) -> #N/A
A13: 能量扫描 | B13: 氘灯486.0 | D13: =IF(L13="","",字段对应!$B$10&"="&VLOOKUP(L13,基础信息!$I$2:$J$6,2,0)&";")&IF(M13="","",字段对应!$B$11&"="&VLOOKUP(M13,基础信息!$K$2:$L$6,2,0)&";")&IF(N13="","",字段对应!$C$2&"="&N13&","&O13&","&P13&";")&IF(Q13="","",字段对应!$B$13&"="&Q13&";")&IF(R13="","",字段对应!$B$14&"="&R13&";")&IF(U13="","",字段对应!$B$22&"="&U13&";")&IF(K13="","",字段对应!$B$21&"="&VLOOKUP(K13,基础信息!$F$2:$G$4,2,0)) -> PhotoMode=2;ScanSpeed=2;WlRange=490,480,0.1;Gain=4;Slit1=2.0; | E13: =IF(W13="","",检测项信息!W13&":"&字段对应!$B$16&"|")&IF(X13="","",X13&":"&IF(V13="是",字段对应!$C$17,字段对应!$B$17&";"&IF(H13="","",字段对应!$B$15&"="&检测项信息!H13))&"|")&IF(Y13="",":",Y13&":")&IF(V13="是",字段对应!$C$18,字段对应!$B$18&";"&IF(H13="","",字段对应!$B$15&"="&检测项信息!H13)&IF(AND(T13="",S13=""),"",";"&字段对应!$B$20&"="&T13&";"&字段对应!$B$19&"="&S13)) -> 空气:Scan | F13: 1 | H13: 486 | I13: =VLOOKUP(J13,字段对应!$D$2:$E$8,2,0) -> Validation.ViewModel.DataStructure.FindPeakAndAverageUVTestTool | J13: 寻峰 | L13: Es | M13: 中速 | N13: 490 | O13: 480 | P13: 0.1 | Q13: 4 | R13: 2.0 | V13: 是 | Y13: 空气 | Z13: =VLOOKUP(A13,对应信息!$D$2:$E$10,2,0) -> #N/A | AA13: =IF(Z8=Z13,AA8+1,Z13+1) -> #N/A
A14: 能量扫描 | B14: 氘灯656.1 | D14: =IF(L14="","",字段对应!$B$10&"="&VLOOKUP(L14,基础信息!$I$2:$J$6,2,0)&";")&IF(M14="","",字段对应!$B$11&"="&VLOOKUP(M14,基础信息!$K$2:$L$6,2,0)&";")&IF(N14="","",字段对应!$C$2&"="&N14&","&O14&","&P14&";")&IF(Q14="","",字段对应!$B$13&"="&Q14&";")&IF(R14="","",字段对应!$B$14&"="&R14&";")&IF(U14="","",字段对应!$B$22&"="&U14&";")&IF(K14="","",字段对应!$B$21&"="&VLOOKUP(K14,基础信息!$F$2:$G$4,2,0)) -> PhotoMode=2;ScanSpeed=2;WlRange=660,650,0.1;Gain=4;Slit1=2.0; | E14: =IF(W14="","",检测项信息!W14&":"&字段对应!$B$16&"|")&IF(X14="","",X14&":"&IF(V14="是",字段对应!$C$17,字段对应!$B$17&";"&IF(H14="","",字段对应!$B$15&"="&检测项信息!H14))&"|")&IF(Y14="",":",Y14&":")&IF(V14="是",字段对应!$C$18,字段对应!$B$18&";"&IF(H14="","",字段对应!$B$15&"="&检测项信息!H14)&IF(AND(T14="",S14=""),"",";"&字段对应!$B$20&"="&T14&";"&字段对应!$B$19&"="&S14)) -> 空气:Scan | F14: 1 | H14: 656.1 | I14: =VLOOKUP(J14,字段对应!$D$2:$E$8,2,0) -> Validation.ViewModel.DataStructure.FindPeakAndAverageUVTestTool | J14: 寻峰 | L14: Es | M14: 中速 | N14: 660 | O14: 650 | P14: 0.1 | Q14: 4 | R14: 2.0 | V14: 是 | Y14: 空气 | Z14: =VLOOKUP(A14,对应信息!$D$2:$E$10,2,0) -> #N/A | AA14: =IF(Z13=Z14,AA13+1,Z14+1) -> #N/A
A15: 能量扫描 | B15: 钨灯 | D15: =IF(L15="","",字段对应!$B$10&"="&VLOOKUP(L15,基础信息!$I$2:$J$6,2,0)&";")&IF(M15="","",字段对应!$B$11&"="&VLOOKUP(M15,基础信息!$K$2:$L$6,2,0)&";")&IF(N15="","",字段对应!$C$2&"="&N15&","&O15&","&P15&";")&IF(Q15="","",字段对应!$B$13&"="&Q15&";")&IF(R15="","",字段对应!$B$14&"="&R15&";")&IF(U15="","",字段对应!$B$22&"="&U15&";")&IF(K15="","",字段对应!$B$21&"="&VLOOKUP(K15,基础信息!$F$2:$G$4,2,0)) -> PhotoMode=2;ScanSpeed=2;WlRange=1100,300,1;Gain=2;Slit1=2.0;ResponseTime=1;LampPos=0 | E15: =IF(W15="","",检测项信息!W15&":"&字段对应!$B$16&"|")&IF(X15="","",X15&":"&IF(V15="是",字段对应!$C$17,字段对应!$B$17&";"&IF(H15="","",字段对应!$B$15&"="&检测项信息!H15))&"|")&IF(Y15="",":",Y15&":")&IF(V15="是",字段对应!$C$18,字段对应!$B$18&";"&IF(H15="","",字段对应!$B$15&"="&检测项信息!H15)&IF(AND(T15="",S15=""),"",";"&字段对应!$B$20&"="&T15&";"&字段对应!$B$19&"="&S15)) -> 空气:Scan | F15: 1 | H15: 500 | I15: =VLOOKUP(J15,字段对应!$D$2:$E$8,2,0) -> Validation.ViewModel.DataStructure.FindPeakAndAverageUVTestTool | J15: 寻峰 | K15: 钨灯 | L15: Es | M15: 中速 | N15: 1100 | O15: 300 | P15: 1 | Q15: 2 | R15: 2.0 | S15: 1 | T15: 120 | U15: 1 | V15: 是 | Y15: 空气 | Z15: =VLOOKUP(A15,对应信息!$D$2:$E$10,2,0) -> #N/A | AA15: =IF(Z14=Z15,AA14+1,Z15+1) -> #N/A
A16: 能量扫描 | B16: 氘灯 | D16: =IF(L16="","",字段对应!$B$10&"="&VLOOKUP(L16,基础信息!$I$2:$J$6,2,0)&";")&IF(M16="","",字段对应!$B$11&"="&VLOOKUP(M16,基础信息!$K$2:$L$6,2,0)&";")&IF(N16="","",字段对应!$C$2&"="&N16&","&O16&","&P16&";")&IF(Q16="","",字段对应!$B$13&"="&Q16&";")&IF(R16="","",字段对应!$B$14&"="&R16&";")&IF(U16="","",字段对应!$B$22&"="&U16&";")&IF(K16="","",字段对应!$B$21&"="&VLOOKUP(K16,基础信息!$F$2:$G$4,2,0)) -> PhotoMode=2;ScanSpeed=2;WlRange=700,190,1;Gain=4;Slit1=2.0;ResponseTime=1;LampPos=1 | E16: =IF(W16="","",检测项信息!W16&":"&字段对应!$B$16&"|")&IF(X16="","",X16&":"&IF(V16="是",字段对应!$C$17,字段对应!$B$17&";"&IF(H16="","",字段对应!$B$15&"="&检测项信息!H16))&"|")&IF(Y16="",":",Y16&":")&IF(V16="是",字段对应!$C$18,字段对应!$B$18&";"&IF(H16="","",字段对应!$B$15&"="&检测项信息!H16)&IF(AND(T16="",S16=""),"",";"&字段对应!$B$20&"="&T16&";"&字段对应!$B$19&"="&S16)) -> 空气:Scan | F16: 1 | H16: 500 | I16: =VLOOKUP(J16,字段对应!$D$2:$E$8,2,0) -> Validation.ViewModel.DataStructure.FindPeakAndAverageUVTestTool | J16: 寻峰 | K16: 氘灯 | L16: Es | M16: 中速 | N16: 700 | O16: 190 | P16: 1 | Q16: 4 | R16: 2.0 | S16: 1 | T16: 120 | U16: 1 | V16: 是 | Y16: 空气 | Z16: =VLOOKUP(A16,对应信息!$D$2:$E$10,2,0) -> #N/A | AA16: =IF(Z15=Z16,AA15+1,Z16+1) -> #N/A
A17: 波长示值误差校验 | B17: 氘灯656.1 | D17: =IF(L17="","",字段对应!$B$10&"="&VLOOKUP(L17,基础信息!$I$2:$J$6,2,0)&";")&IF(M17="","",字段对应!$B$11&"="&VLOOKUP(M17,基础信息!$K$2:$L$6,2,0)&";")&IF(N17="","",字段对应!$C$2&"="&N17&","&O17&","&P17&";")&IF(Q17="","",字段对应!$B$13&"="&Q17&";")&IF(R17="","",字段对应!$B$14&"="&R17&";")&IF(U17="","",字段对应!$B$22&"="&U17&";")&IF(K17="","",字段对应!$B$21&"="&VLOOKUP(K17,基础信息!$F$2:$G$4,2,0)) -> PhotoMode=2;ScanSpeed=2;WlRange=660,650,0.02;Gain=4;Slit1=2.0;LampPos=1 | E17: =IF(W17="","",检测项信息!W17&":"&字段对应!$B$16&"|")&IF(X17="","",X17&":"&IF(V17="是",字段对应!$C$17,字段对应!$B$17&";"&IF(H17="","",字段对应!$B$15&"="&检测项信息!H17))&"|")&IF(Y17="",":",Y17&":")&IF(V17="是",字段对应!$C$18,字段对应!$B$18&";"&IF(H17="","",字段对应!$B$15&"="&检测项信息!H17)&IF(AND(T17="",S17=""),"",";"&字段对应!$B$20&"="&T17&";"&字段对应!$B$19&"="&S17)) -> 空气:Scan | F17: 1 | H17: 656.1 | I17: =VLOOKUP(J17,字段对应!$D$2:$E$8,2,0) -> Validation.ViewModel.DataStructure.FindPeakAndAverageUVTestTool | J17: 寻峰 | K17: 氘灯 | L17: Es | M17: 中速 | N17: 660 | O17: 650 | P17: 0.02 | Q17: 4 | R17: 2.0 | V17: 是 | Y17: 空气 | Z17: =VLOOKUP(A17,对应信息!$D$2:$E$10,2,0) -> #N/A | AA17: =IF(Z15=Z17,AA15+1,Z17+1) -> #N/A
A18: 波长示值误差校验 | B18: 氘灯486.0 | D18: =IF(L18="","",字段对应!$B$10&"="&VLOOKUP(L18,基础信息!$I$2:$J$6,2,0)&";")&IF(M18="","",字段对应!$B$11&"="&VLOOKUP(M18,基础信息!$K$2:$L$6,2,0)&";")&IF(N18="","",字段对应!$C$2&"="&N18&","&O18&","&P18&";")&IF(Q18="","",字段对应!$B$13&"="&Q18&";")&IF(R18="","",字段对应!$B$14&"="&R18&";")&IF(U18="","",字段对应!$B$22&"="&U18&";")&IF(K18="","",字段对应!$B$21&"="&VLOOKUP(K18,基础信息!$F$2:$G$4,2,0)) -> PhotoMode=2;ScanSpeed=2;WlRange=490,480,0.02;Gain=4;Slit1=2.0;LampPos=1 | E18: =IF(W18="","",检测项信息!W18&":"&字段对应!$B$16&"|")&IF(X18="","",X18&":"&IF(V18="是",字段对应!$C$17,字段对应!$B$17&";"&IF(H18="","",字段对应!$B$15&"="&检测项信息!H18))&"|")&IF(Y18="",":",Y18&":")&IF(V18="是",字段对应!$C$18,字段对应!$B$18&";"&IF(H18="","",字段对应!$B$15&"="&检测项信息!H18)&IF(AND(T18="",S18=""),"",";"&字段对应!$B$20&"="&T18&";"&字段对应!$B$19&"="&S18)) -> 空气:Scan | F18: 1 | H18: 486 | I18: =VLOOKUP(J18,字段对应!$D$2:$E$8,2,0) -> Validation.ViewModel.DataStructure.FindPeakAndAverageUVTestTool | J18: 寻峰 | K18: 氘灯 | L18: Es | M18: 中速 | N18: 490 | O18: 480 | P18: 0.02 | Q18: 4 | R18: 2.0 | V18: 是 | Y18: 空气 | Z18: =VLOOKUP(A18,对应信息!$D$2:$E$10,2,0) -> #N/A | AA18: =IF(Z17=Z18,AA17+1,Z18+1) -> #N/A
A19: 波长示值误差校验 | B19: 镨钕滤光片 | D19: =IF(L19="","",字段对应!$B$10&"="&VLOOKUP(L19,基础信息!$I$2:$J$6,2,0)&";")&IF(M19="","",字段对应!$B$11&"="&VLOOKUP(M19,基础信息!$K$2:$L$6,2,0)&";")&IF(N19="","",字段对应!$C$2&"="&N19&","&O19&","&P19&";")&IF(Q19="","",字段对应!$B$13&"="&Q19&";")&IF(R19="","",字段对应!$B$14&"="&R19&";")&IF(U19="","",字段对应!$B$22&"="&U19&";")&IF(K19="","",字段对应!$B$21&"="&VLOOKUP(K19,基础信息!$F$2:$G$4,2,0)) -> PhotoMode=0;ScanSpeed=2;WlRange=810,800,0.1;Slit1=2.0; | E19: =IF(W19="","",检测项信息!W19&":"&字段对应!$B$16&"|")&IF(X19="","",X19&":"&IF(V19="是",字段对应!$C$17,字段对应!$B$17&";"&IF(H19="","",字段对应!$B$15&"="&检测项信息!H19))&"|")&IF(Y19="",":",Y19&":")&IF(V19="是",字段对应!$C$18,字段对应!$B$18&";"&IF(H19="","",字段对应!$B$15&"="&检测项信息!H19)&IF(AND(T19="",S19=""),"",";"&字段对应!$B$20&"="&T19&";"&字段对应!$B$19&"="&S19)) -> 黑挡块:Dark|空气:BaseLine|镨钕滤光片:Scan | F19: 1 | H19: 807.4 | I19: =VLOOKUP(J19,字段对应!$D$2:$E$8,2,0) -> Validation.ViewModel.DataStructure.FindPeakAndAverageUVTestTool | J19: 寻峰 | L19: Abs | M19: 中速 | N19: 810 | O19: 800 | P19: 0.1 | R19: 2.0 | V19: 是 | W19: 黑挡块 | X19: 空气 | Y19: 镨钕滤光片 | Z19: =VLOOKUP(A19,对应信息!$D$2:$E$10,2,0) -> #N/A | AA19: =IF(Z18=Z19,AA18+1,Z19+1) -> #N/A
A20: 波长示值误差校验 | B20: 钬溶液 | D20: =IF(L20="","",字段对应!$B$10&"="&VLOOKUP(L20,基础信息!$I$2:$J$6,2,0)&";")&IF(M20="","",字段对应!$B$11&"="&VLOOKUP(M20,基础信息!$K$2:$L$6,2,0)&";")&IF(N20="","",字段对应!$C$2&"="&N20&","&O20&","&P20&";")&IF(Q20="","",字段对应!$B$13&"="&Q20&";")&IF(R20="","",字段对应!$B$14&"="&R20&";")&IF(U20="","",字段对应!$B$22&"="&U20&";")&IF(K20="","",字段对应!$B$21&"="&VLOOKUP(K20,基础信息!$F$2:$G$4,2,0)) -> PhotoMode=0;ScanSpeed=3;WlRange=645,235,0.1;Slit1=2.0; | E20: =IF(W20="","",检测项信息!W20&":"&字段对应!$B$16&"|")&IF(X20="","",X20&":"&IF(V20="是",字段对应!$C$17,字段对应!$B$17&";"&IF(H20="","",字段对应!$B$15&"="&检测项信息!H20))&"|")&IF(Y20="",":",Y20&":")&IF(V20="是",字段对应!$C$18,字段对应!$B$18&";"&IF(H20="","",字段对应!$B$15&"="&检测项信息!H20)&IF(AND(T20="",S20=""),"",";"&字段对应!$B$20&"="&T20&";"&字段对应!$B$19&"="&S20)) -> 黑挡块:Dark|空气:BaseLine|钬溶液:Scan | F20: 1 | H20: 640.7,536.8,416.5,361.0,287.4,241.0 | I20: =VLOOKUP(J20,字段对应!$D$2:$E$8,2,0) -> Validation.ViewModel.DataStructure.FindPeakAndAverageUVTestTool | J20: 寻峰 | L20: Abs | M20: 快速 | N20: 645 | O20: 235 | P20: 0.1 | R20: 2.0 | V20: 是 | W20: 黑挡块 | X20: 空气 | Y20: 钬溶液 | Z20: =VLOOKUP(A20,对应信息!$D$2:$E$10,2,0) -> #N/A | AA20: =IF(Z19=Z20,AA19+1,Z20+1) -> #N/A
A21: 杂散光校验 | B21: 220nm杂散光 | D21: PhotoMode=1;ScanSpeed=2;Slit1=2.0; | E21: =IF(W21="","",检测项信息!W21&":"&字段对应!$B$16&"|")&IF(X21="","",X21&":"&IF(V21="是",字段对应!$C$17,字段对应!$B$17&";"&IF(H21="","",字段对应!$B$15&"="&检测项信息!H21))&"|")&IF(Y21="",":",Y21&":")&IF(V21="是",字段对应!$C$18,字段对应!$B$18&";"&IF(H21="","",字段对应!$B$15&"="&检测项信息!H21)&IF(AND(T21="",S21=""),"",";"&字段对应!$B$20&"="&T21&";"&字段对应!$B$19&"="&S21)) -> 黑挡块:Dark|碘化钠空白溶液:Zero;Wl=220|碘化钠溶液:Measure;Wl=220 | F21: 3 | G21: 1 | H21: 220 | I21: =VLOOKUP(J21,字段对应!$D$2:$E$8,2,0) -> Validation.ViewModel.DataStructure.WlPointsUVTestTool | J21: 多次测量 | L21: T% | M21: 中速 | R21: 2.0 | V21: 否 | W21: 黑挡块 | X21: 碘化钠空白溶液 | Y21: 碘化钠溶液 | Z21: =VLOOKUP(A21,对应信息!$D$2:$E$10,2,0) -> 3000 | AA21: =IF(Z20=Z21,AA20+1,Z21+1) -> #N/A
A22: 杂散光校验 | B22: 360nm杂散光 | D22: PhotoMode=1;ScanSpeed=2;Slit1=2.0; | E22: =IF(W22="","",检测项信息!W22&":"&字段对应!$B$16&"|")&IF(X22="","",X22&":"&IF(V22="是",字段对应!$C$17,字段对应!$B$17&";"&IF(H22="","",字段对应!$B$15&"="&检测项信息!H22))&"|")&IF(Y22="",":",Y22&":")&IF(V22="是",字段对应!$C$18,字段对应!$B$18&";"&IF(H22="","",字段对应!$B$15&"="&检测项信息!H22)&IF(AND(T22="",S22=""),"",";"&字段对应!$B$20&"="&T22&";"&字段对应!$B$19&"="&S22)) -> 黑挡块:Dark|亚硝酸钠空白溶液:Zero;Wl=360|亚硝酸钠溶液:Measure;Wl=360 | F22: 3 | G22: 1 | H22: 360 | I22: =VLOOKUP(J22,字段对应!$D$2:$E$8,2,0) -> Validation.ViewModel.DataStructure.WlPointsUVTestTool | J22: 多次测量 | L22: T% | M22: 中速 | R22: 2.0 | V22: 否 | W22: 黑挡块 | X22: 亚硝酸钠空白溶液 | Y22: 亚硝酸钠溶液 | Z22: =VLOOKUP(A22,对应信息!$D$2:$E$10,2,0) -> 3000 | AA22: =IF(Z21=Z22,AA21+1,Z22+1) -> #N/A
A23: 基线平直度检验 | B23: 基线平直度 | D23: =IF(L23="","",[1]字段对应!$B$10&"="&VLOOKUP(L23,[1]基础信息!$I$2:$J$6,2,0)&";")&IF(M23="","",[1]字段对应!$B$11&"="&VLOOKUP(M23,[1]基础信息!$K$2:$L$6,2,0)&";")&IF(N23="","",[1]字段对应!$C$2&"="&N23&","&O23&","&P23&";")&IF(Q23="","",[1]字段对应!$B$13&"="&Q23&";")&IF(R23="","",[1]字段对应!$B$14&"="&R23&";")&IF(U23="","",[1]字段对应!$B$22&"="&U23&";")&IF(K23="","",[1]字段对应!$B$21&"="&VLOOKUP(K23,[1]基础信息!$F$2:$G$4,2,0)) -> PhotoMode=0;ScanSpeed=2;WlRange=1090,200,1;Slit1=2.0; | E23: =IF(W23="","",[1]检测项信息!W12&":"&[1]字段对应!$B$16&"|")&IF(X23="","",X23&":"&IF(V23="是",[1]字段对应!$C$17,[1]字段对应!$B$17&";"&IF(H23="","",[1]字段对应!$B$15&"="&[1]检测项信息!H12))&"|")&IF(Y23="",":",Y23&":")&IF(V23="是",[1]字段对应!$C$18,[1]字段对应!$B$18&";"&IF(H23="","",[1]字段对应!$B$15&"="&[1]检测项信息!H12)&IF(AND(T23="",S23=""),"",";"&[1]字段对应!$B$20&"="&T23&";"&[1]字段对应!$B$19&"="&S23)) -> 黑挡块:Dark|空气:BaseLine|空气:Scan | F23: 1 | I23: =VLOOKUP(J23,字段对应!$D$2:$E$8,2,0) -> Validation.ViewModel.DataStructure.GetMaxDIstanceUVTestTool | J23: 求最大偏移量 | L23: Abs | M23: 中速 | N23: 1090 | O23: 200 | P23: 1 | R23: 2.0 | V23: 是 | W23: 黑挡块 | X23: 空气 | Y23: 空气 | Z23: =VLOOKUP(A23,对应信息!$D$2:$E$10,2,0) -> 4000 | AA23: =IF(Z22=Z23,AA22+1,Z23+1) -> 4001

Sheet 仪器状态
A1: 仪器id | B1: 项目 | C1: 能量 | D1: id | E1: 父id
A2: =MID(CELL("filename"),FIND("[",CELL("filename"),1)+1,FIND(".",CELL("filename"),1)-FIND("[",CELL("filename"),1)-1) -> T600T700-VariableSlit | B2: 关灯，增益1下的RSD值
A3: =MID(CELL("filename"),FIND("[",CELL("filename"),1)+1,FIND(".",CELL("filename"),1)-FIND("[",CELL("filename"),1)-1) -> T600T700-VariableSlit | B3: 关灯，增益2下的RSD值
A4: =MID(CELL("filename"),FIND("[",CELL("filename"),1)+1,FIND(".",CELL("filename"),1)-FIND("[",CELL("filename"),1)-1) -> T600T700-VariableSlit | B4: 关灯，增益3下的RSD值
A5: =MID(CELL("filename"),FIND("[",CELL("filename"),1)+1,FIND(".",CELL("filename"),1)-FIND("[",CELL("filename"),1)-1) -> T600T700-VariableSlit | B5: 关灯，增益4下的RSD值
A6: =MID(CELL("filename"),FIND("[",CELL("filename"),1)+1,FIND(".",CELL("filename"),1)-FIND("[",CELL("filename"),1)-1) -> T600T700-VariableSlit | B6: 开灯，增益1下的RSD值
A7: =MID(CELL("filename"),FIND("[",CELL("filename"),1)+1,FIND(".",CELL("filename"),1)-FIND("[",CELL("filename"),1)-1) -> T600T700-VariableSlit | B7: 开灯，增益2下的RSD值
A8: =MID(CELL("filename"),FIND("[",CELL("filename"),1)+1,FIND(".",CELL("filename"),1)-FIND("[",CELL("filename"),1)-1) -> T600T700-VariableSlit | B8: 开灯，增益3下的RSD值
A9: =MID(CELL("filename"),FIND("[",CELL("filename"),1)+1,FIND(".",CELL("filename"),1)-FIND("[",CELL("filename"),1)-1) -> T600T700-VariableSlit | B9: 开灯，增益4下的RSD值
A10: =MID(CELL("filename"),FIND("[",CELL("filename"),1)+1,FIND(".",CELL("filename"),1)-FIND("[",CELL("filename"),1)-1) -> T600T700-VariableSlit | B10: 氘灯656.1能量 | D10: 1001 | E10: 1001
A11: =MID(CELL("filename"),FIND("[",CELL("filename"),1)+1,FIND(".",CELL("filename"),1)-FIND("[",CELL("filename"),1)-1) -> T600T700-VariableSlit | B11: 氘灯486.0能量 | D11: 1002 | E11: 1002
A12: =MID(CELL("filename"),FIND("[",CELL("filename"),1)+1,FIND(".",CELL("filename"),1)-FIND("[",CELL("filename"),1)-1) -> T600T700-VariableSlit | B12: 紫外分光光度计标准物质GBW(E)130066-350nm能量 | D12: 2001 | E12: 2001
A13: =MID(CELL("filename"),FIND("[",CELL("filename"),1)+1,FIND(".",CELL("filename"),1)-FIND("[",CELL("filename"),1)-1) -> T600T700-VariableSlit | B13: 紫外分光光度计标准物质GBW(E)130066-313nm能量 | D13: 2002 | E13: 2001
A14: =MID(CELL("filename"),FIND("[",CELL("filename"),1)+1,FIND(".",CELL("filename"),1)-FIND("[",CELL("filename"),1)-1) -> T600T700-VariableSlit | B14: 紫外分光光度计标准物质GBW(E)130066-257nm能量 | D14: 2003 | E14: 2001
A15: =MID(CELL("filename"),FIND("[",CELL("filename"),1)+1,FIND(".",CELL("filename"),1)-FIND("[",CELL("filename"),1)-1) -> T600T700-VariableSlit | B15: 紫外分光光度计标准物质GBW(E)130066-235nm能量 | D15: 2004 | E15: 2001
A16: =MID(CELL("filename"),FIND("[",CELL("filename"),1)+1,FIND(".",CELL("filename"),1)-FIND("[",CELL("filename"),1)-1) -> T600T700-VariableSlit | B16: 碘化钠标准溶液-220nm能量 | D16: 3001 | E16: 3001
A17: =MID(CELL("filename"),FIND("[",CELL("filename"),1)+1,FIND(".",CELL("filename"),1)-FIND("[",CELL("filename"),1)-1) -> T600T700-VariableSlit | B17: 亚硝酸钠标准溶液-360nm能量 | D17: 3002 | E17: 3002
A18: =MID(CELL("filename"),FIND("[",CELL("filename"),1)+1,FIND(".",CELL("filename"),1)-FIND("[",CELL("filename"),1)-1) -> T600T700-VariableSlit | B18: 基线平直度-全波长能量 | D18: 4001 | E18: 4001

Sheet 样品池准确度与重复性校验

Sheet 标准值
A1: 测试项 | B1: 检测工具 | C1: 特征值 | D1: 标准值（%）
A2: 透射比示值误差与重复性校验 | B2: 紫外分光光度计标准物质GBW(E)130066 | C2: 350nm | D2: 23.2
C3: 313nm | D3: 51.58
C4: 257nm | D4: 14.06
C5: 235nm | D5: 18.42
B6: 10%中性滤光片 | C6: 635nm | D6: 7.62
C7: 546nm | D7: 11.03
C8: 440nm | D8: 11.46
B9: 20%中性滤光片 | C9: 635nm | D9: 17.64
C10: 546nm | D10: 21.74
C11: 440nm | D11: 21.92
B12: 30%中性滤光片 | C12: 635nm | D12: 23.59
C13: 546nm | D13: 29.32
C14: 440nm | D14: 29.91
A15: 波长拟合 | B15: 镨钕滤光片 | C15: 807.4
B16: 钬溶液 | C16: 640.7
C17: 536.8
C18: 416.5
C19: 361.0
C20: 287.4
C21: 241.0
A23: 修改标准值时，该仪器对应的模板文件必须未打开，同时修改后光标要在未修改的单元格内！方可保存成功！

Sheet 字段对应
A1: 仪器方法标记 | B1: 仪器方法字段 | D1: 算法标记 | E1: 算法字段
A2: 起始波长 | B2: StartWl | C2: WlRange | D2: 寻峰 | E2: Validation.ViewModel.DataStructure.FindPeakAndAverageUVTestTool
A3: 终止波长 | B3: EndWl | D3: 求平均 | E3: Validation.ViewModel.DataStructure.WlPointsAndAverageUVTestTool
A4: 重复次数 | B4: RepeatTimes | D4: 多次测量 | E4: Validation.ViewModel.DataStructure.WlPointsUVTestTool
A5: 重复时间间隔 | B5: RepeatInterval | D5: 最大最小值差 | E5: Validation.ViewModel.DataStructure.FindMaxOffsetUVTestTool
A6: 方法信息 | B6: MethodStr | D6: 求半峰宽 | E6: Validation.ViewModel.DataStructure.FindHalfPeakUVTestTool
A7: 测量信息 | B7: MeasurePara | D7: 求最大偏移量 | E7: Validation.ViewModel.DataStructure.GetMaxDIstanceUVTestTool
A8: 使用物质 | B8: ToolStr | D8: 求漂移 | E8: Validation.ViewModel.DataStructure.GetDriftUVTestTool
A9: 项目名称 | B9: Name
A10: 光度模式 | B10: PhotoMode
A11: 扫描速度 | B11: ScanSpeed
A12: 扫描间隔 | B12: ScanWlInterval
A13: 增益 | B13: Gain
A14: 光谱带宽 | B14: Slit1
A15: 特征值 | B15: Wl
A16: 暗电流 | B16: Dark
A17: 校零 | B17: Zero | C17: BaseLine
A18: 测量 | B18: Measure | C18: Scan
A19: 时间间隔 | B19: timeinterval
A20: 扫描个数 | B20: totalcount
A21: 灯状态 | B21: LampPos
A22: 响应时间 | B22: ResponseTime

Sheet 样品池重复性
A1: 项目名称 | B1: 测量值（T%）
A2: 1号
A3: 2号
A4: 3号
A5: 4号
A6: 5号
A7: 检测结果 | B7: {=IF(AND(MAX(B2:B6)-MIN(B2:B6)<0.1,B2:B6>=99.9,B2:B6<=100.1),"合格","不合格")} -> 不合格
A8: 重复性 | B8: =MAX(B2:B6)-MIN(B2:B6) -> 0

Sheet 波长拟合
A1: 项目名称 | B1: 特征值（nm） | C1: 模式 | D1: 增益 | E1: 光源 | F1: 测量值（nm）
A2: 氘灯 | B2: 486 | C2: Es | D2: 4 | E2: 氘灯
B3: 656.1 | C3: Es | D3: 4 | E3: 氘灯
A4: 镨钕滤光片 | B4: 807.4 | C4: Abs
A5: 钬溶液 | B5: 241 | C5: Abs
B6: 361 | C6: Abs
B7: 640.7 | C7: Abs
A8: 汞灯 | B8: 296.7 | C8: Es | D8: 3 | E8: 汞灯
B9: 404.7 | C9: Es | D9: 3 | E9: 汞灯
B10: 435.8 | C10: Es | D10: 3 | E10: 汞灯
B11: 546.1 | C11: Es | D11: 3 | E11: 汞灯

Sheet 能量扫描
A1: 项目名称 | B1: 特征值（nm） | C1: 测量值（nm） | D1: Es
A2: 氘灯486.0 | B2: 486
A3: 氘灯656.1 | B3: 656.1
A4: 钨灯 | B4: 全段
A5: 氘灯 | B5: 全段

Sheet 波长示值误差校验
A1: 项目名称 | B1: 特征值（nm） | C1: 测量值（nm） | D1: 误差值（nm） | E1: 波长示值误差(nm) | F1: 判定结果
A2: 氘灯656.1 | B2: 656.1 | D2: =IF(ISBLANK(C2),"",IF(C2<>"",C2-B2,"")) | E2: 0.1 | F2: =IF(C2="","不合格",IF(AND(ROUND(ABS(D2),1)<=ROUND(ABS(E2),1)),"合格","不合格")) -> 不合格
A3: 氘灯486 | B3: 486 | D3: =IF(ISBLANK(C3),"",IF(C3<>"",C3-B3,"")) | E3: 0.1 | F3: =IF(C3="","不合格",IF(AND(ROUND(ABS(D3),1)<=ROUND(ABS(E3),1)),"合格","不合格")) -> 不合格
A4: 镨钕滤光片 | B4: 807.4 | D4: =IF(ISBLANK(C4),"",IF(C4<>"",C4-B4,"")) | E4: 0.3 | F4: =IF(C4="","不合格",IF(AND(ROUND(ABS(D4),1)<=ROUND(ABS(E4),1)),"合格","不合格")) -> 不合格
A5: 钬溶液 | B5: 640.7 | D5: =IF(ISBLANK(C5),"",IF(C5<>"",C5-B5,"")) | E5: 0.3 | F5: =IF(C5="","不合格",IF(AND(ROUND(ABS(D5),1)<=ROUND(ABS(E5),1)),"合格","不合格")) -> 不合格
B6: 536.8 | D6: =IF(ISBLANK(C6),"",IF(C6<>"",C6-B6,"")) | E6: 0.3 | F6: =IF(C6="","不合格",IF(AND(ROUND(ABS(D6),1)<=ROUND(ABS(E6),1)),"合格","不合格")) -> 不合格
B7: 416.5 | D7: =IF(ISBLANK(C7),"",IF(C7<>"",C7-B7,"")) | E7: 0.3 | F7: =IF(C7="","不合格",IF(AND(ROUND(ABS(D7),1)<=ROUND(ABS(E7),1)),"合格","不合格")) -> 不合格
B8: 361.0 | D8: =IF(ISBLANK(C8),"",IF(C8<>"",C8-B8,"")) | E8: 0.3 | F8: =IF(C8="","不合格",IF(AND(ROUND(ABS(D8),1)<=ROUND(ABS(E8),1)),"合格","不合格")) -> 不合格
B9: 287.4 | D9: =IF(ISBLANK(C9),"",IF(C9<>"",C9-B9,"")) | E9: 0.3 | F9: =IF(C9="","不合格",IF(AND(ROUND(ABS(D9),1)<=ROUND(ABS(E9),1)),"合格","不合格")) -> 不合格
B10: 241.0 | D10: =IF(ISBLANK(C10),"",IF(C10<>"",C10-B10,"")) | E10: 0.3 | F10: =IF(C10="","不合格",IF(AND(ROUND(ABS(D10),1)<=ROUND(ABS(E10),1)),"合格","不合格")) -> 不合格

Sheet 杂散光校验
A1: 项目名称 | B1: 波长点 | C1: 测量值（%） | F1: 指标要求 | G1: 判定结果
A2: 碘化钠标准溶液 | B2: 220 | F2: 0.01 | G2: =IF(C2="","不合格",IF(ROUND(ABS(AVERAGE(C2:E2)),4)<ROUND(F2,4),"合格","不合格")) -> 不合格
A3: 亚硝酸钠标准溶液 | B3: 360 | F3: 0.05 | G3: =IF(C3="","不合格",IF(ROUND(ABS(AVERAGE(C3:E3)),4)<ROUND(F3,4),"合格","不合格")) -> 不合格

Sheet 基线平直度检验
A1: 项目名称 | B1: 测量值（Abs） | C1: 指标要求 | D1: 判定结果
A2: 基线平直度 | C2: 0.0005 | D2: =IF(OR(B2="",(ABS(B2)>C2)),"不合格","合格") -> 不合格
